Workbook

Sheet 청구서
A2: 공사근로자 노무비 청구서(2023년 01월)
A3: 1. | C3: 공 사 명 | F3: : | G3: =#REF! -> #REF!
A4: 2. | C4: 계 약 금 액 | F4: : | G4: ="일금" & TEXT(L4, "[dbnum4] g/표준") & "원정" -> 일금 일십팔억칠천육백칠십팔만칠천원정 | K4: ( | L4: 1876787000 | M4: )
A5: 3. | C5: 계 약 년 월 일 | F5: : | G5: 44197
A6: 4. | C6: 착 공 년 월 일 | F6: : | G6: 44198 | Q6: 661526622 | R6: =Q6*0.1 -> 66152662 | S6: =Q6+R6 -> 7.2767928e+08
A7: 5. | C7: 준 공 년 월 일 | F7: : | G7: 44199 | Q7: =P7/1.1 -> 0 | R7: =Q7*0.1 -> 0 | S7: =SUM(Q7:R7) -> 0
A8: 6. | C8: 노무비총액 | F8: : | G8: ="일금 " & NUMBERSTRING(L8, 1) & "원정" -> 일금 칠억이천칠백육십칠만구천이백팔십사원정 | K8: ( | L8: =S6 -> 7.2767928e+08 | M8: )
A9: 7. | C9: 기지급금액 | F9: : | G9: ="일금 " & NUMBERSTRING(L9, 1) & "원정" -> 일금 영원정 | K9: ( | L9: =집계표!G18 -> 0 | M9: ) | O9: 직불금 | P9: 합계 | Q9: 공급액 | R9: 부가세 | S9: 합계
A10: 8. | C10: 금회청구액 | F10: : | G10: ="일금 " & NUMBERSTRING(L10, 1) & "원정" -> 일금 영원정 | K10: ( | L10: =L11+L13+L15+L17+L19 -> 0 | M10: ) | P10: =L10 -> 0 | Q10: =TRUNC(P10/1.1) -> 0 | R10: =P10-Q10 -> 0 | S10: =Q10+R10 -> 0
C11: (계약상대자) | F11: : | G11: ="일금 " & NUMBERSTRING(L11, 1) & "원정" -> 일금 영원정 | K11: ( | L11: =집계표!H7 -> 0 | M11: ) | O11: 원도급 | P11: =L11 -> 0 | Q11: =TRUNC(P11/1.1) -> 0 | R11: =P11-Q11 -> 0 | S11: =Q11+R11 -> 0
C12: 부강종합건설㈜
C13: (직불하도급사) | F13: : | G13: ="일금 " & NUMBERSTRING(L13, 1) & "원정" -> 일금 영원정 | K13: ( | L13: =집계표!H14 -> 0 | M13: ) | O13: =C14 -> 00건설㈜ | P13: =L13 -> 0 | Q13: =TRUNC(P13/1.1) -> 0 | R13: =P13-Q13 -> 0 | S13: =Q13+R13 -> 0
C14: 00건설㈜
C15: (직불하도급사) | F15: : | G15: ="일금 " & NUMBERSTRING(L15, 1) & "원정" -> 일금 영원정 | K15: ( | L15: =집계표!H13 -> 0 | M15: ) | O15: =C16 -> ㈜00기업 | P15: =L15 -> 0 | Q15: =TRUNC(P15/1.1) -> 0 | R15: =P15-Q15 -> 0 | S15: =Q15+R15 -> 0
C16: ㈜00기업
C17: (직불하도급사) | F17: : | G17: ="일금 " & NUMBERSTRING(L17, 1) & "원정" -> 일금 영원정 | K17: ( | L17: =집계표!H14 -> 0 | M17: ) | O17: =C18 -> ㈜000개발 | P17: =L17 -> 0 | Q17: =TRUNC(P17/1.1) -> 0 | R17: =P17-Q17 -> 0 | S17: =Q17+R17 -> 0
C18: ㈜000개발
C19: (직불하도급사) | F19: : | G19: ="일금 " & NUMBERSTRING(L19, 1) & "원정" -> 일금 영원정 | K19: ( | L19: =집계표!H16 -> 0 | M19: ) | O19: =C20 -> 주식회사 00 | P19: =L19 -> 0 | Q19: =TRUNC(P19/1.1) -> 0 | R19: =P19-Q19 -> 0 | S19: =Q19+R19 -> 0
C20: 주식회사 00
A21: 9. | C21: 잔여금액 | F21: : | G21: ="일금 " & NUMBERSTRING(L21, 1) & "원정" -> 일금 칠억이천칠백육십칠만구천이백팔십사원정 | K21: ( | L21: =L8-L10-L9 -> 7.2767928e+08 | M21: ) | O21: 선지급금 | P21: 합계 | Q21: 공급액 | R21: 부가세 | S21: 합계
A22: 위 금액을 2023 년 01월 노무비(1회)로 청구하오니 아래와 같이 지급하여 주시기 바랍니다.
B23: 구분 | D23: 업 체 명 | H23: 은행명 | I23: 계좌번호(노무비) | J23: 청구액
B24: 계약상대자 | D24: =C12 -> 부강종합건설㈜ | H24: 농협은행 | I24: 355-0062-3586-33 | J24: =L11 -> 0
B25: 직불하도급사 | D25: =C14 -> 00건설㈜
B26: 직불하도급사 | D26: =C16 -> ㈜00기업
B27: 직불하도급사 | D27: =C18 -> ㈜000개발
A29: 붙 임 : 1. 노무자 명부 및 당월 개인별 노무비 청구(지급) 내역서 각 1부.
A32: 2023 년 02 월 일
E35: 계약상대자 : | H35: 회사명 | I35: =O35 -> 부강종합건설㈜ | O35: =D24 -> 부강종합건설㈜
H36: 주소 | I36: =O36 -> 경남 합천군 | O36: 경남 합천군
H37: 대표자 | I37: =O37& " (인)" -> 김 0 0 (인) | O37: 김 0 0
E38: 직불하도급사 : | H38: 회사명 | I38: =O38 -> 00건설㈜ | O38: =C14 -> 00건설㈜
H39: 주소 | I39: =O39 -> 경남 남해군 | O39: 경남 남해군
H40: 대표자 | I40: =O40& " (인)" -> 강 0 0 (인) | O40: 강 0 0
E41: 직불하도급사 : | H41: 회사명 | I41: =O41 -> ㈜00기업 | O41: =C16 -> ㈜00기업
H42: 주소 | I42: =O42 -> 대구광역시 수성구 | O42: 대구광역시 수성구
H43: 대표자 | I43: =O43& " (인)" -> 김 0 0 (인) | O43: 김 0 0
E44: 직불하도급사 : | H44: 회사명 | I44: =O44 -> ㈜000개발 | O44: =C18 -> ㈜000개발
H45: 주소 | I45: =O45 -> 경남 김해시 | O45: 경남 김해시
H46: 대표자 | I46: =O46& " (인)" -> 박 0 0 (인) | O46: 박 0 0
...

Sheet 집계표
A2: 공사근로자 노무비 청구 내역 집계표(2023 년 01 월)
A3: =내역서!A3:D3 -> ○ 공 사 명 : | C3: =청구서!G3 -> #REF!
A4: ○ 노무비 금액： | C4: ="일금 " & NUMBERSTRING(I4, 1) & "원정" -> 일금 칠억이천칠백육십칠만구천이백팔십사원정 | H4: ( | I4: =청구서!L8 -> 7.2767928e+08 | K4: )
A5: ○ 금월 청구금액： | C5: ="일금 " & NUMBERSTRING(I5, 1) & "원정" -> 일금 영원정 | H5: ( | I5: =H18 -> 0 | K5: )
A6: 구 분 | B6: 공 종 | D6: 업 체 명 | E6: 전용계좌번호 | F6: 노무비 금액 | G6: 전월까지 금액 | H6: 금월 청구금액 | J6: 누계 금액
A7: 도급사 | B7: 건축공사 | D7: =청구서!D24 -> 부강종합건설㈜ | E7: 355-0062-3586-33 농협은행(노무비) | F7: =L7-L11 -> 7.2767928e+08 | H7: =내역서!D30 -> 0 | J7: =G7+H7 -> 0 | L7: =청구서!L8 -> 7.2767928e+08
J8: =G8+H8 -> 0 | L8: 0
J9: =G9+H9 -> 0 | L9: 0
A10: 소 계(A) | F10: =SUM(F7:F9) -> 7.2767928e+08 | G10: =SUM(G7:G9) -> 0 | H10: =SUM(H7:I9) -> 0 | J10: =G10+H10 -> 0
A11: 직불 하도 급사 | J11: =G11+H11 -> 0
J12: =G12+H12 -> 0 | L12: 0
J13: =G13+H13 -> 0 | L13: 0
J14: =G14+H14 -> 0 | L14: =F14-G14 -> 0
J15: =G15+H15 -> 0 | L15: 0
G16: 0 | J16: =G16+H16 -> 0 | L16: 0
A17: 소 계(B) | F17: =SUM(F11:F16) -> 0 | G17: =SUM(G14:G16) -> 0 | H17: =SUM(H11:I16) -> 0 | J17: =G17+H17 -> 0 | L17: 0
A18: 합 계(A+B) | F18: =F10+F17 -> 7.2767928e+08 | G18: =G10+G17 -> 0 | H18: =H10+H17 -> 0 | J18: =G18+H18 -> 0 | L18: 20570000

Sheet 내역서
A1: 공사근로자 노무비 청구 내역서(2023 년 01월)
A3: ○ 공 사 명 : | B3: =청구서!G3 -> #REF!
A4: 계약상대자 | B4: 직종 | C4: 근로자성명 | D4: 청구금액 | E4: 은행명 | F4: 계좌번호 | G4: 휴대폰번호
A5: =청구서!O35 -> 부강종합건설㈜ | B5: =IFERROR(VLOOKUP(C5,#REF!,2,0)," ") | C5: =#REF! -> #REF! | D5: =IFERROR(VLOOKUP(C5,#REF!,6,0)," ") | E5: =IFERROR(VLOOKUP(C5,#REF!,7,0)," ") | F5: =IFERROR(VLOOKUP(C5,#REF!,8,0)," ") | G5: =IFERROR(VLOOKUP(C5,#REF!,5,0)," ") | H5: 주소록 탭 기재 후 청구내역서 상 근로자 이름만 적으면 데이터 자동 연결됩니다.
B6: =IFERROR(VLOOKUP(C6,#REF!,2,0)," ") | C6: =#REF! -> #REF! | D6: =IFERROR(VLOOKUP(C6,#REF!,6,0)," ") | E6: =IFERROR(VLOOKUP(C6,#REF!,7,0)," ") | F6: =IFERROR(VLOOKUP(C6,#REF!,8,0)," ") | G6: =IFERROR(VLOOKUP(C6,#REF!,5,0)," ")
B7: =IFERROR(VLOOKUP(C7,#REF!,2,0)," ") | C7: =#REF! -> #REF! | D7: =IFERROR(VLOOKUP(C7,#REF!,6,0)," ") | E7: =IFERROR(VLOOKUP(C7,#REF!,7,0)," ") | F7: =IFERROR(VLOOKUP(C7,#REF!,8,0)," ") | G7: =IFERROR(VLOOKUP(C7,#REF!,5,0)," ")
B8: =IFERROR(VLOOKUP(C8,#REF!,2,0)," ") | C8: C | D8: =IFERROR(VLOOKUP(C8,#REF!,6,0)," ") | E8: =IFERROR(VLOOKUP(C8,#REF!,7,0)," ") | F8: =IFERROR(VLOOKUP(C8,#REF!,8,0)," ") | G8: =IFERROR(VLOOKUP(C8,#REF!,5,0)," ")
B9: =IFERROR(VLOOKUP(C9,#REF!,2,0)," ") | C9: =#REF! -> #REF! | D9: =IFERROR(VLOOKUP(C9,#REF!,6,0)," ") | E9: =IFERROR(VLOOKUP(C9,#REF!,7,0)," ") | F9: =IFERROR(VLOOKUP(C9,#REF!,8,0)," ") | G9: =IFERROR(VLOOKUP(C9,#REF!,5,0)," ")
B10: =IFERROR(VLOOKUP(C10,#REF!,2,0)," ") | C10: =#REF! -> #REF! | D10: =IFERROR(VLOOKUP(C10,#REF!,6,0)," ") | E10: =IFERROR(VLOOKUP(C10,#REF!,7,0)," ") | F10: =IFERROR(VLOOKUP(C10,#REF!,8,0)," ") | G10: =IFERROR(VLOOKUP(C10,#REF!,5,0)," ")
B11: =IFERROR(VLOOKUP(C11,#REF!,2,0)," ") | C11: =#REF! -> #REF! | D11: =IFERROR(VLOOKUP(C11,#REF!,6,0)," ") | E11: =IFERROR(VLOOKUP(C11,#REF!,7,0)," ") | F11: =IFERROR(VLOOKUP(C11,#REF!,8,0)," ") | G11: =IFERROR(VLOOKUP(C11,#REF!,5,0)," ")
B12: =IFERROR(VLOOKUP(C12,#REF!,2,0)," ") | C12: =#REF! -> #REF! | D12: =IFERROR(VLOOKUP(C12,#REF!,6,0)," ") | E12: =IFERROR(VLOOKUP(C12,#REF!,7,0)," ") | F12: =IFERROR(VLOOKUP(C12,#REF!,8,0)," ") | G12: =IFERROR(VLOOKUP(C12,#REF!,5,0)," ")
B13: =IFERROR(VLOOKUP(C13,#REF!,2,0)," ") | C13: =#REF! -> #REF! | D13: =IFERROR(VLOOKUP(C13,#REF!,6,0)," ") | E13: =IFERROR(VLOOKUP(C13,#REF!,7,0)," ") | F13: =IFERROR(VLOOKUP(C13,#REF!,8,0)," ") | G13: =IFERROR(VLOOKUP(C13,#REF!,5,0)," ")
B14: =IFERROR(VLOOKUP(C14,#REF!,2,0)," ") | C14: =#REF! -> #REF! | D14: =IFERROR(VLOOKUP(C14,#REF!,6,0)," ") | E14: =IFERROR(VLOOKUP(C14,#REF!,7,0)," ") | F14: =IFERROR(VLOOKUP(C14,#REF!,8,0)," ") | G14: =IFERROR(VLOOKUP(C14,#REF!,5,0)," ")
B15: =IFERROR(VLOOKUP(C15,#REF!,2,0)," ") | C15: =#REF! -> #REF! | D15: =IFERROR(VLOOKUP(C15,#REF!,6,0)," ") | E15: =IFERROR(VLOOKUP(C15,#REF!,7,0)," ") | F15: =IFERROR(VLOOKUP(C15,#REF!,8,0)," ") | G15: =IFERROR(VLOOKUP(C15,#REF!,5,0)," ")
B16: =IFERROR(VLOOKUP(C16,#REF!,2,0)," ") | C16: =#REF! -> #REF! | D16: =IFERROR(VLOOKUP(C16,#REF!,6,0)," ") | E16: =IFERROR(VLOOKUP(C16,#REF!,7,0)," ") | F16: =IFERROR(VLOOKUP(C16,#REF!,8,0)," ") | G16: =IFERROR(VLOOKUP(C16,#REF!,5,0)," ")
B17: =IFERROR(VLOOKUP(C17,#REF!,2,0)," ") | C17: =#REF! -> #REF! | D17: =IFERROR(VLOOKUP(C17,#REF!,6,0)," ") | E17: =IFERROR(VLOOKUP(C17,#REF!,7,0)," ") | F17: =IFERROR(VLOOKUP(C17,#REF!,8,0)," ") | G17: =IFERROR(VLOOKUP(C17,#REF!,5,0)," ")
B18: =IFERROR(VLOOKUP(C18,#REF!,2,0)," ") | C18: =#REF! -> #REF! | D18: =IFERROR(VLOOKUP(C18,#REF!,6,0)," ") | E18: =IFERROR(VLOOKUP(C18,#REF!,7,0)," ") | F18: =IFERROR(VLOOKUP(C18,#REF!,8,0)," ") | G18: =IFERROR(VLOOKUP(C18,#REF!,5,0)," ")
B19: =IFERROR(VLOOKUP(C19,#REF!,2,0)," ") | C19: =#REF! -> #REF! | D19: =IFERROR(VLOOKUP(C19,#REF!,6,0)," ") | E19: =IFERROR(VLOOKUP(C19,#REF!,7,0)," ") | F19: =IFERROR(VLOOKUP(C19,#REF!,8,0)," ") | G19: =IFERROR(VLOOKUP(C19,#REF!,5,0)," ")
B20: =IFERROR(VLOOKUP(C20,#REF!,2,0)," ") | C20: =#REF! -> #REF! | D20: =IFERROR(VLOOKUP(C20,#REF!,6,0)," ") | E20: =IFERROR(VLOOKUP(C20,#REF!,7,0)," ") | F20: =IFERROR(VLOOKUP(C20,#REF!,8,0)," ") | G20: =IFERROR(VLOOKUP(C20,#REF!,5,0)," ")
... B27: =IFERROR(VLOOKUP(C27,#REF!,2,0)," ") | C27: =#REF! -> #REF! | D27: =IFERROR(VLOOKUP(C27,#REF!,6,0)," ") | E27: =IFERROR(VLOOKUP(C27,#REF!,7,0)," ") | F27: =IFERROR(VLOOKUP(C27,#REF!,8,0)," ") | G27: =IFERROR(VLOOKUP(C27,#REF!,5,0)," ")
A28: [소계1] | D28: =SUM(D5:D27) -> 0
A29: 부가세 | D29: =D28*0.1 -> 0
A30: 청구금액 | D30: =D28+D29 -> 0
A31: 직불하도급사 | B31: 직종 | C31: 근로자성명 | D31: 청구액 | E31: 은행명 | F31: 계좌번호 | G31: 휴대폰번호
B32: =IFERROR(VLOOKUP(C32,#REF!,2,0)," ") | C32: =#REF! -> #REF! | D32: =IFERROR(VLOOKUP(C32,#REF!,6,0)," ") | E32: =IFERROR(VLOOKUP(C32,#REF!,7,0)," ") | F32: =IFERROR(VLOOKUP(C32,#REF!,8,0)," ")
B33: =IFERROR(VLOOKUP(C33,#REF!,2,0)," ") | C33: =#REF! -> #REF! | D33: =IFERROR(VLOOKUP(C33,#REF!,6,0)," ") | E33: =IFERROR(VLOOKUP(C33,#REF!,7,0)," ") | F33: =IFERROR(VLOOKUP(C33,#REF!,8,0)," ")
B34: =IFERROR(VLOOKUP(C34,#REF!,2,0)," ") | C34: =#REF! -> #REF! | D34: =IFERROR(VLOOKUP(C34,#REF!,6,0)," ") | E34: =IFERROR(VLOOKUP(C34,#REF!,7,0)," ") | F34: =IFERROR(VLOOKUP(C34,#REF!,8,0)," ")
B35: =IFERROR(VLOOKUP(C35,#REF!,2,0)," ") | C35: =#REF! -> #REF! | D35: =IFERROR(VLOOKUP(C35,#REF!,6,0)," ") | E35: =IFERROR(VLOOKUP(C35,#REF!,7,0)," ") | F35: =IFERROR(VLOOKUP(C35,#REF!,8,0)," ")
B36: =IFERROR(VLOOKUP(C36,#REF!,2,0)," ") | C36: =#REF! -> #REF! | D36: =IFERROR(VLOOKUP(C36,#REF!,6,0)," ") | E36: =IFERROR(VLOOKUP(C36,#REF!,7,0)," ") | F36: =IFERROR(VLOOKUP(C36,#REF!,8,0)," ")
B37: =IFERROR(VLOOKUP(C37,#REF!,2,0)," ") | C37: =#REF! -> #REF! | D37: =IFERROR(VLOOKUP(C37,#REF!,6,0)," ") | E37: =IFERROR(VLOOKUP(C37,#REF!,7,0)," ") | F37: =IFERROR(VLOOKUP(C37,#REF!,8,0)," ")
B38: =IFERROR(VLOOKUP(C38,#REF!,2,0)," ") | C38: =#REF! -> #REF! | D38: =IFERROR(VLOOKUP(C38,#REF!,6,0)," ") | E38: =IFERROR(VLOOKUP(C38,#REF!,7,0)," ") | F38: =IFERROR(VLOOKUP(C38,#REF!,8,0)," ")
B39: =IFERROR(VLOOKUP(C39,#REF!,2,0)," ") | C39: =#REF! -> #REF! | D39: =IFERROR(VLOOKUP(C39,#REF!,6,0)," ") | E39: =IFERROR(VLOOKUP(C39,#REF!,7,0)," ") | F39: =IFERROR(VLOOKUP(C39,#REF!,8,0)," ")
B40: =IFERROR(VLOOKUP(C40,#REF!,2,0)," ") | C40: =#REF! -> #REF! | D40: =IFERROR(VLOOKUP(C40,#REF!,6,0)," ") | E40: =IFERROR(VLOOKUP(C40,#REF!,7,0)," ") | F40: =IFERROR(VLOOKUP(C40,#REF!,8,0)," ")
B41: =IFERROR(VLOOKUP(C41,#REF!,2,0)," ") | C41: =#REF! -> #REF! | D41: =IFERROR(VLOOKUP(C41,#REF!,6,0)," ") | E41: =IFERROR(VLOOKUP(C41,#REF!,7,0)," ") | F41: =IFERROR(VLOOKUP(C41,#REF!,8,0)," ")
A45: [소계2] | D45: =SUM(D32:D44) -> 0
A46: 부가세 | D46: =D45*0.1 -> 0
A47: 청구금액 | D47: =D45+D46 -> 0
A48: [합 계] | D48: =D28+D45 -> 0
A49: 부가세 | D49: =D48*0.1 -> 0
A50: 청구금액 | D50: =D48+D49 -> 0
...

Sheet 위임장
A1: 위 임 장
A3: 수 임 인
A4: 성 명 | I4: 주 민 번 호 | L4: =IF(ISERROR(VLOOKUP(D4,#REF!,5,0)),"",VLOOKUP(D4,#REF!,5,0))
A5: 주 소 | D5: =IF(ISERROR(VLOOKUP(D4,#REF!,6,0)),"",VLOOKUP(D4,#REF!,6,0))
A6: 연 락 처 | D6: =IF(ISERROR(VLOOKUP(D4,#REF!,7,0)),"",VLOOKUP(D4,#REF!,7,0)) | I6: 계 좌 번 호 | L6: =IF(ISERROR(VLOOKUP(D4,#REF!,9,0)),"",VLOOKUP(D4,#REF!,9,0)) | N6: =IF(ISERROR(VLOOKUP(D4,#REF!,10,0)),"",VLOOKUP(D4,#REF!,10,0))
A8: =" 상기인을 본인의 대리인으로 정하여 ["&V8&"] 「"&V9&"」 하수급인 「"&V10&"」의" -> #REF! | U8: 공사명 | V8: =#REF! -> #REF!
A9: =" 근로자로서 「"&V10&"」이(가) 지급하여야할 ["&V11&" "&W11&"] 노무비를 원수급자인 「"&V9&"」와(과) 하수급인" -> 근로자로서 「(주)하도급 회사」이(가) 지급하여야할 [2023년 1월] 노무비를 원수급자인 「부강종합건설㈜」와(과) 하수급인 | U9: 원도급 회사 | V9: 부강종합건설㈜
A10: =" 「"&V10&"」로부터 수령할 노무비와 기타 모든 사항을 수임인에게 일체의 권한을 위임하고 위임후에 따른" -> 「(주)하도급 회사」로부터 수령할 노무비와 기타 모든 사항을 수임인에게 일체의 권한을 위임하고 위임후에 따른 | U10: 하도급 회사 | V10: (주)하도급 회사
A11: 분실,휭령,공문서 위조등을 포함한 모든 책임을 본인이 감수하며 민,형사상 처벌을 감수할것이며 어떠한 법률적 | U11: 청구 월 | V11: 2023년 | W11: 1월
A12: 책임도 이의를 제기치 않을 것을 서명 날인 합니다
A14: 성 명 | C14: 주 민 번 호 | G14: 주 소 | M14: 청구금액 | P14: 서 명
M15: =IFERROR(VLOOKUP(A15,INDIRECT(#REF!&"!$B$7:$BA$93"),33,FALSE),"")
M16: =IFERROR(VLOOKUP(A16,INDIRECT(#REF!&"!$B$7:$BA$93"),33,FALSE),"")
M17: =IFERROR(VLOOKUP(A17,INDIRECT(#REF!&"!$B$7:$BA$93"),33,FALSE),"")
M18: =IFERROR(VLOOKUP(A18,INDIRECT(#REF!&"!$B$7:$BA$93"),33,FALSE),"")
M19: =IFERROR(VLOOKUP(A19,INDIRECT(#REF!&"!$B$7:$BA$93"),33,FALSE),"")
C20: =IF(ISERROR(VLOOKUP(A20,#REF!,5,0)),"",VLOOKUP(A20,#REF!,5,0)) | G20: =IF(ISERROR(VLOOKUP(A20,#REF!,6,0)),"",VLOOKUP(A20,#REF!,4,0)) | M20: =IFERROR(VLOOKUP(A20,INDIRECT(#REF!&"!$B$7:$BA$93"),33,FALSE),"")
C21: =IF(ISERROR(VLOOKUP(A21,#REF!,5,0)),"",VLOOKUP(A21,#REF!,5,0)) | G21: =IF(ISERROR(VLOOKUP(A21,#REF!,6,0)),"",VLOOKUP(A21,#REF!,4,0)) | M21: =IFERROR(VLOOKUP(A21,INDIRECT(#REF!&"!$B$7:$BA$93"),33,FALSE),"")
C22: =IF(ISERROR(VLOOKUP(A22,#REF!,5,0)),"",VLOOKUP(A22,#REF!,5,0)) | G22: =IF(ISERROR(VLOOKUP(A22,#REF!,6,0)),"",VLOOKUP(A22,#REF!,4,0)) | M22: =IFERROR(VLOOKUP(A22,INDIRECT(#REF!&"!$B$7:$BA$93"),33,FALSE),"")
C23: =IF(ISERROR(VLOOKUP(A23,#REF!,5,0)),"",VLOOKUP(A23,#REF!,5,0)) | G23: =IF(ISERROR(VLOOKUP(A23,#REF!,6,0)),"",VLOOKUP(A23,#REF!,4,0)) | M23: =IFERROR(VLOOKUP(A23,INDIRECT(#REF!&"!$B$7:$BA$93"),33,FALSE),"")
C24: =IF(ISERROR(VLOOKUP(A24,#REF!,5,0)),"",VLOOKUP(A24,#REF!,5,0)) | G24: =IF(ISERROR(VLOOKUP(A24,#REF!,6,0)),"",VLOOKUP(A24,#REF!,4,0)) | M24: =IFERROR(VLOOKUP(A24,INDIRECT(#REF!&"!$B$7:$BA$93"),33,FALSE),"")
C25: =IF(ISERROR(VLOOKUP(A25,#REF!,5,0)),"",VLOOKUP(A25,#REF!,5,0)) | G25: =IF(ISERROR(VLOOKUP(A25,#REF!,6,0)),"",VLOOKUP(A25,#REF!,4,0)) | M25: =IFERROR(VLOOKUP(A25,INDIRECT(#REF!&"!$B$7:$BA$93"),33,FALSE),"")
C26: =IF(ISERROR(VLOOKUP(A26,#REF!,5,0)),"",VLOOKUP(A26,#REF!,5,0)) | G26: =IF(ISERROR(VLOOKUP(A26,#REF!,6,0)),"",VLOOKUP(A26,#REF!,4,0)) | M26: =IFERROR(VLOOKUP(A26,INDIRECT(#REF!&"!$B$7:$BA$93"),33,FALSE),"")
C27: =IF(ISERROR(VLOOKUP(A27,#REF!,5,0)),"",VLOOKUP(A27,#REF!,5,0)) | G27: =IF(ISERROR(VLOOKUP(A27,#REF!,6,0)),"",VLOOKUP(A27,#REF!,4,0)) | M27: =IFERROR(VLOOKUP(A27,INDIRECT(#REF!&"!$B$7:$BA$93"),33,FALSE),"")
C28: =IF(ISERROR(VLOOKUP(A28,#REF!,5,0)),"",VLOOKUP(A28,#REF!,5,0)) | G28: =IF(ISERROR(VLOOKUP(A28,#REF!,6,0)),"",VLOOKUP(A28,#REF!,4,0)) | M28: =IFERROR(VLOOKUP(A28,INDIRECT(#REF!&"!$B$7:$BA$93"),33,FALSE),"")
C29: =IF(ISERROR(VLOOKUP(A29,#REF!,5,0)),"",VLOOKUP(A29,#REF!,5,0)) | G29: =IF(ISERROR(VLOOKUP(A29,#REF!,6,0)),"",VLOOKUP(A29,#REF!,4,0)) | M29: =IFERROR(VLOOKUP(A29,INDIRECT(#REF!&"!$B$7:$BA$93"),33,FALSE),"")
C30: =IF(ISERROR(VLOOKUP(A30,#REF!,5,0)),"",VLOOKUP(A30,#REF!,5,0)) | G30: =IF(ISERROR(VLOOKUP(A30,#REF!,6,0)),"",VLOOKUP(A30,#REF!,4,0)) | M30: =IFERROR(VLOOKUP(A30,INDIRECT(#REF!&"!$B$7:$BA$93"),33,FALSE),"")
C31: =IF(ISERROR(VLOOKUP(A31,#REF!,5,0)),"",VLOOKUP(A31,#REF!,5,0)) | G31: =IF(ISERROR(VLOOKUP(A31,#REF!,6,0)),"",VLOOKUP(A31,#REF!,4,0)) | M31: =IFERROR(VLOOKUP(A31,INDIRECT(#REF!&"!$B$7:$BA$93"),33,FALSE),"")
... C34: =IF(ISERROR(VLOOKUP(A34,#REF!,5,0)),"",VLOOKUP(A34,#REF!,5,0)) | G34: =IF(ISERROR(VLOOKUP(A34,#REF!,6,0)),"",VLOOKUP(A34,#REF!,4,0)) | M34: =IFERROR(VLOOKUP(A34,INDIRECT(#REF!&"!$B$7:$BA$93"),33,FALSE),"")

Sheet 4월
A1: 일용 노무비 지급 명세서
A2: 공 사 명 | C2: 고색2지구 공원 및 공공공지 조성공사 | O2: 기 간 | Y2: 2026 | AC2: 4 | AH2: 청 구 금 액 | AK2: 소 득 세 지방소득세 | AN2: 건강보험 노인장기 | AQ2: 국민연금 고용보험 | AT2: 공제계 | AW2: 실 지급액
A3: 회 사 명 | C3: ㈜아 산 | O3: 46113 | R3: ~ | S3: 46142 | AH3: 33425000 | AK3: 262930 | AN3: 1198200 | AQ3: 574560 | AT3: 2035690 | AW3: 31389310
A5: 번 호 | B5: 성 명 | C5: 주 민 번 호 | G5: 주 소 | O5: 46113 | P5: 46114 | Q5: 46115 | R5: 46116 | S5: 46117 | T5: 46118 | U5: 46119 | V5: 46120 | W5: 46121 | X5: 46122 | Y5: 46123 | Z5: 46124 | AA5: 46125 | AB5: 46126 | AC5: 46127 | AE5: 출력일수 | AG5: 일급 | AH5: 지 급 총 액 | AK5: 소 득 세 | AN5: 건강보험 | AQ5: 국민연금 | AT5: 공제소계 | AW5: 차감 지급액 | AZ5: 영수인
C6: 연 락 처 | G6: 은 행 명 | J6: 계 좌 번 호 | O6: 46128 | P6: 46129 | Q6: 46130 | R6: 46131 | S6: 46132 | T6: 46133 | U6: 46134 | V6: 46135 | W6: 46136 | X6: 46137 | Y6: 46138 | Z6: 46139 | AA6: 46140 | AB6: 46141 | AC6: 46142 | AE6: 출력공수 | AK6: 지방소득세 | AN6: 노인장기 | AQ6: 고용보험 | AT6: 기타
A7: 1 | B7: 오부택 | C7: 651015-1333111 | G7: 경기도 남양주시 도농동 291-34 19/4 | T7: 1 | U7: 1 | V7: 1 | W7: 0.5 | X7: 1 | Y7: 1 | Z7: 1 | AA7: 1 | AB7: 1 | AC7: 1 | AE7: 22 | AG7: 250000 | AH7: 5375000 | AK7: 56700 | AN7: 193230 | AQ7: 60세이상 | AT7: 329360 | AW7: 5045640 | AZ7: 오부택
B8: 작업반장 | C8: 010-8783-1657 | G8: 농협중앙회 | J8: 204030-56-159309 | O8: 1 | P8: 1 | Q8: 1 | S8: 1 | T8: 1 | U8: 1 | V8: 1 | W8: 1 | X8: 1 | Z8: 1 | AB8: 1 | AC8: 1 | AE8: 21.5 | AK8: 5670 | AN8: 25390 | AQ8: 48370
A9: 2 | B9: 하해군 | C9: 630816-1221210 | G9: 경기도 남양주시 진건읍 사릉로용정1길 11 | T9: 1 | U9: 1 | V9: 1 | Y9: 1 | Z9: 1 | AA9: 1 | AB9: 1 | AC9: 1 | AE9: 18 | AG9: 200000 | AH9: 3600000 | AK9: 24300 | AN9: 129420 | AQ9: 60세이상 | AT9: 205550 | AW9: 3394450 | AZ9: 하진욱
B10: 조경공 | C10: 010-4993-9423 | G10: 농협중앙회 | J10: 352-0964-6051-63 | O10: 1 | P10: 1 | Q10: 1 | S10: 1 | T10: 1 | U10: 1 | V10: 1 | W10: 1 | X10: 1 | AC10: 1 | AE10: 18 | AK10: 2430 | AN10: 17000 | AQ10: 32400
A11: 3 | B11: 유수진 | C11: 701126-1241813 | G11: 경기도 포천군 영북면 운천리 528 | T11: 1 | U11: 1 | V11: 1 | W11: 0.5 | X11: 1 | Y11: 1 | Z11: 1 | AA11: 1 | AB11: 1 | AC11: 1 | AE11: 22 | AG11: 190000 | AH11: 4085000 | AK11: 22680 | AN11: 146850 | AQ11: 194030 | AT11: 421870 | AW11: 3663130 | AZ11: 유수진
B12: 조경공 | C12: 010-3124-2716 | G12: 국민은행 | J12: 352601-01-213053 | O12: 1 | P12: 1 | Q12: 1 | S12: 1 | T12: 1 | U12: 1 | V12: 1 | W12: 1 | X12: 1 | Z12: 1 | AB12: 1 | AC12: 1 | AE12: 21.5 | AK12: 2260 | AN12: 19290 | AQ12: 36760
A13: 4 | B13: 김방수 | C13: 650604-1622312 | G13: 경기도 남양주시 경춘로859번길26, B동 204호(금곡동,동익빌라) | T13: 1 | U13: 1 | V13: 1 | W13: 0.5 | X13: 1 | Y13: 1 | Z13: 1 | AA13: 1 | AB13: 1 | AC13: 1 | AE13: 22 | AG13: 190000 | AH13: 4085000 | AK13: 22680 | AN13: 146850 | AQ13: 60세이상 | AT13: 227840 | AW13: 3857160 | AZ13: 김방수
B14: 조경공 | C14: 010-9342-8092 | G14: 농협중앙회 | J14: 204074-51-050436 | O14: 1 | P14: 1 | Q14: 1 | S14: 1 | T14: 1 | U14: 1 | V14: 1 | W14: 1 | X14: 1 | Z14: 1 | AB14: 1 | AC14: 1 | AE14: 21.5 | AK14: 2260 | AN14: 19290 | AQ14: 36760
A15: 5 | B15: 류시현 | C15: 610927-1784016 | G15: 서울특별시 은평구 갈현로29길 53, 지층 B01호 | T15: 1 | U15: 1 | V15: 1 | W15: 0.5 | X15: 1 | Y15: 1 | Z15: 1 | AA15: 1 | AB15: 1 | AC15: 1 | AE15: 22 | AG15: 210000 | AH15: 4515000 | AK15: 34020 | AN15: 162310 | AQ15: 60세이상 | AT15: 261680 | AW15: 4253320 | AZ15: 류시현
B16: 조경공 | C16: 010-7609-0150 | G16: 제일은행 | J16: 580-20-374487 | O16: 1 | P16: 1 | Q16: 1 | S16: 1 | T16: 1 | U16: 1 | V16: 1 | W16: 1 | X16: 1 | Z16: 1 | AB16: 1 | AC16: 1 | AE16: 21.5 | AK16: 3400 | AN16: 21320 | AQ16: 40630
A17: 6 | B17: 박찬구 | C17: 570411-1640313 | G17: 경기도 김포시 하성면 전류리 67-9 | AC17: 1 | AE17: 2 | AG17: 210000 | AH17: 420000 | AK17: 3240 | AN17: 0 | AQ17: 60세이상 | AT17: 3560 | AW17: 416440 | AZ17: 박찬구
B18: 조경공 | C18: 010-9313-6807 | G18: 농협중앙회 | J18: 351-0499-5374-13 | O18: 1 | AE18: 2 | AK18: 320 | AN18: 0 | AQ18: 65세이상
A19: 7 | B19: 박찬식 | C19: 590407-1906717 | G19: 부산광역시 동구 작전동 768-26 | AE19: 1 | AG19: 195000 | AH19: 195000 | AK19: 1210 | AN19: 0 | AQ19: 60세이상 | AT19: 1330 | AW19: 193670 | AZ19: 박찬식
B20: 조경공 | C20: 010-3837-5876 | G20: 농협중앙회 | J20: 211041-56-176755 | O20: 1 | AE20: 1 | AK20: 120 | AN20: 0 | AQ20: 65세이상
A21: 8 | B21: 이찬석 | C21: 651110-1232814 | G21: 경기도 파주시 정담길 123 101동 602호 | AC21: 1 | AE21: 2 | AG21: 195000 | AH21: 390000 | AK21: 2420 | AN21: 0 | AQ21: 60세이상 | AT21: 6170 | AW21: 383830 | AZ21: 이찬석
B22: 조경공 | C22: 010-7671-5881 | G22: 농협중앙회 | J22: 352-1705-3514-03 | O22: 1 | AE22: 2 | AK22: 240 | AN22: 0 | AQ22: 3510
A23: 9 | B23: 이기연 | C23: 590120-1244816 | G23: 경기도 파주시 하지석길 150-67 | AC23: 1 | AE23: 2 | AG23: 180000 | AH23: 360000 | AK23: 1620 | AN23: 0 | AQ23: 60세이상 | AT23: 1780 | AW23: 358220 | AZ23: 이기연
B24: 조경공 | C24: 010-9120-2168 | G24: 농협중앙회 | J24: 215120-52-005803 | O24: 1 | AE24: 2 | AK24: 160 | AN24: 0 | AQ24: 65세이상
A25: 10 | B25: 정연복 | C25: 640909-1324212 | G25: 인천광역시 미추홀구 미추홀대로 657번길 22-1 | X25: 1 | Y25: 1 | Z25: 1 | AA25: 1 | AB25: 1 | AC25: 1 | AE25: 7 | AG25: 200000 | AH25: 1400000 | AK25: 9450 | AN25: 0 | AQ25: 60세이상 | AT25: 22990 | AW25: 1377010 | AZ25: 정연복
B26: 조경공 | C26: 010-2081-4474 | G26: KEB하나은행 | J26: 403-910413-64207 | T26: 1 | AE26: 7 | AK26: 940 | AN26: 0 | AQ26: 12600
A27: 11 | B27: 김학춘 | C27: 690525-1321017 | G27: 인천광역시 미추홀구 길파로35번길 71-1, 102호 | X27: 1 | Y27: 1 | Z27: 1 | AA27: 1 | AB27: 1 | AC27: 1 | AE27: 15 | AG27: 200000 | AH27: 3000000 | AK27: 20250 | AN27: 107850 | AQ27: 142500 | AT27: 313790 | AW27: 2686210 | AZ27: 김학춘
B28: 조경공 | C28: 010-5306-6707 | G28: KEB하나은행 | J28: 259201-04-132579 | O28: 1 | P28: 1 | Q28: 1 | S28: 1 | T28: 1 | U28: 1 | V28: 1 | W28: 1 | X28: 1 | AE28: 15 | AK28: 2020 | AN28: 14170 | AQ28: 27000
A29: 12 | B29: LI ZHEXUN(이철훈) | C29: 621222-5100053 | G29: 인천광역시 미추홀구 수봉남로17번길37 102호(용현동,럭키빌라) | X29: 1 | Y29: 1 | Z29: 1 | AA29: 1 | AB29: 1 | AC29: 1 | AE29: 15 | AG29: 200000 | AH29: 3000000 | AK29: 20250 | AN29: 107850 | AQ29: 60세이상 | AT29: 144290 | AW29: 2855710 | AZ29: LI ZHEXUN (이철훈)
B30: 조경공 | C30: 010-8227-3088 | G30: 국민은행 | J30: 024801-04-446948 | O30: 1 | P30: 1 | Q30: 1 | S30: 1 | T30: 1 | U30: 1 | V30: 1 | W30: 1 | X30: 1 | AE30: 15 | AK30: 2020 | AN30: 14170 | AQ30: 외국인
A31: 13 | B31: CUI CHENGMIN(최성민) | C31: 710413-5100057 | G31: 인천광역시 미추홀구 독정안길 71-20 삼영빌라 | X31: 1 | Y31: 1 | AA31: 1 | AB31: 1 | AC31: 1 | AE31: 6 | AG31: 200000 | AH31: 1200000 | AK31: 8100 | AN31: 0 | AQ31: 0 | AT31: 8910 | AW31: 1191090 | AZ31: CUI CHENGMIN (최성민)
B32: 조경공 | C32: 010-5824-7954 | G32: KEB하나은행 | J32: 620-910226-10107 | O32: 1 | AE32: 6 | AK32: 810 | AN32: 0 | AQ32: 외국인
A33: 14 | B33: JIN YUANTAI(김원태) | C33: 590427-5101290 | G33: 인천광역시 미추홀구 수봉로70번길 3 202동(숭의동) | AE33: 9 | AG33: 200000 | AH33: 1800000 | AK33: 12150 | AN33: 64710 | AQ33: 60세이상 | AT33: 86570 | AW33: 1713430 | AZ33: JIN YUANTAI (김원태)
B34: 조경공 | C34: 010-5540-5904 | G34: KEB하나은행 | J34: 580-910278-79407 | O34: 1 | P34: 1 | Q34: 1 | S34: 1 | T34: 1 | U34: 1 | V34: 1 | W34: 1 | X34: 1 | AE34: 9 | AK34: 1210 | AN34: 8500 | AQ34: 외국인
A35: 15 | AE35: 0 | AH35: 0 | AK35: 0 | AN35: 0 | AQ35: 0 | AT35: 0 | AW35: 0
AE36: 0 | AK36: 0 | AN36: 0 | AQ36: 0
A37: 16 | AE37: 0 | AH37: 0 | AK37: 0 | AN37: 0 | AQ37: 0 | AT37: 0 | AW37: 0
AE38: 0 | AK38: 0 | AN38: 0 | AQ38: 0
A39: 17 | AE39: 0 | AH39: 0 | AK39: 0 | AN39: 0 | AQ39: 0 | AT39: 0 | AW39: 0
AE40: 0 | AK40: 0 | AN40: 0 | AQ40: 0
A41: 18 | AE41: 0 | AH41: 0 | AK41: 0 | AN41: 0 | AQ41: 0 | AT41: 0 | AW41: 0
...

Sheet 각서
B2: 각 서
C4: 공사명 | D4: : | E4: =청구서!G3 -> #REF!
B7: 상기공사에 대하여 공사기간 중 발생한 노무비를 (공사근로자 노무비 구분관리 및
B8: 지급확인제)에 따라 노무비를 청구함에 있어 차후 초과 청구로 인한 문제가 발생 할
B9: 경우 어떠한 조치도 감수하겠기에 각서를 제출합니다.
B21: =청구서!A32 -> 2023 년 02 월 일
F24: 회사명 | G24: : | H24: =청구서!O35 -> 부강종합건설㈜
F25: 주소 | G25: : | H25: =청구서!O36 -> 경남 합천군
F26: 대표이사 | G26: : | H26: =청구서!O37 -> 김 0 0 | I26: (인)
B28: =청구서!A49 -> 경상남도교육지원청귀하

Sheet 계좌입금의뢰신고서
B1: [별지 제13호서식]
B3: 계좌입금의뢰신고서
B5: 귀 교와의 계약거래에 따른 본인(사)의 채권에 대하여는 아래에 지정하는 계좌에 입금시켜 주실 것을 의뢰합니다.
B7: 거 래 은 행 | C7: =청구서!H24 -> 농협은행
B8: 예 금 종 류
B9: 계 좌 번 호 | C9: =청구서!I24 -> 355-0062-3586-33
B10: 예 금 주 | C10: =청구서!D24 -> 부강종합건설㈜
B11: 계 좌 입 금 방 법 | C11: 하도급지킴이
B13: ※ 신고사항의 변경
B14: ①본 약정에 기입된 계좌입금 관련 사항에 변경이 있을 때에는 다시 작성하여 제출하여야 한다.
B15: ②전항의 신고 전에 신고사항의 변경으로 인한 손해에 대하여 국민건강보험공단은 그 책임을 지지 않는다.
B17: =각서!B21 -> 2023 년 02 월 일
B19: 회사명 | C19: =각서!H24 -> 부강종합건설㈜
B20: 주 소 | C20: =각서!H25 -> 경남 합천군
B21: 대표자 | C21: =각서!H26 -> 김 0 0
D24: 인감대조
B27: =각서!B28 -> 경상남도교육지원청귀하

Sheet 근로계약서
L2: 근 로 계 약 서 (현장일용직) | AZ2: =IF(X15<9620,"최저임금 위반, 일당을 올리십시오.","") -> #REF! | BA2: : 2023년 최저시급 9,620원
B4: 사업주 | E4: 상 호 | H4: 아름다운건설㈜ | AB4: 대표이사 | AH4: 김 대 표
E5: 주 소 | H5: 서울 대전 대구 부산 찍고
B6: 근로자 | E6: 성 명 | H6: A | W6: 주민등록번호 | AB6: =VLOOKUP(H6,#REF!,2,FALSE) -> #REF!
E7: 주 소 | H7: =VLOOKUP(AB6,#REF!,2,FALSE) -> #REF! | AB7: 전화번호 | AH7: =VLOOKUP(AB6,#REF!,3,FALSE) -> #REF!
B8: "갑"과 "을"은 아래의 근로조건을 성실히 이행할 것을 약정하고 근로계약을 체결한다. - 아 래 -
B9: 근로장소 | D9: =#REF! -> #REF! | AA9: 공종/수행업무 | AI9: =VLOOKUP(H6,#REF!,52,FALSE) -> #REF!
B10: 계약기간 | D10: =#REF! -> #REF! | H10: ~ | J10: =#REF! -> #REF! | N10: (1개월) 까지로 한다. | S10: 다만, 근로계약 기간 중이라도 천재지변, 동절기 공사중단, 발주처의 공사중단ㆍ
D11: 설계변경ㆍ공사도급계약 중도해지 등 불가피한 사유로 공사를 계속할 수 없거나 "근로자"가 수행하던 공종이 중단된 경우에는 그 때를 계약
D12: 만료일로 하여 하며, 근로계약이 갱신 체결된 경우라도 근로계약의 최대기간은 공사현장의 "근로자"가 수행하던 해당 공종 종료일을 초과하지
D13: 못한다.
D14: * 동의자 성명 : (인)
B15: 임 금 | D15: ① "근로자"의 1일 8시간 기본급은 ( | O15: =AD25 -> #REF! | S15: ) 원, 시간급 | W15: ( | X15: =O15/8 -> #REF! | AB15: ) | AC15: 원으로 하며, 법정수당의 산정방식은 다음과 같다.
D16: ㉠ 연장근로수당: 시간급(=기본급/8시간) x 연장근로시간 x 150%
D17: ㉡ 휴일가산수당: 시간급(=기본급/8시간) x 휴일근로시간 x 150%
D18: ㉢ 야간근로수당: 시간급(=기본급/8시간) x 야간근로시간(22:00~06:00) x 50%
D19: ㉣ 유급주휴수당: 전 주간(월~금)만근한 경우 시간급 x 8시간
D20: ㉤ 연차휴가수당: 1개월(1-말일)간 만근 후, 연차휴가 미사용시 시간급 × 8시간
D21: ㉥ 관공서 공휴일근로수당 : 관공서 공휴일 중 근무한 일수 x 시간급(=기본급/8시간) x 8시간 x 150%
D22: ㉦ 유급관공서휴일수당 : 관공서 공휴일수 x 시간급(=기본급/8시간) x 8시간 x 100%
D23: ② "근로자"의 임금은 제1항의 기본급에 주휴수당, 연장수당, 휴일(국공휴일 포함)수당, 연차수당을 포함한 일급(￦ | AI23: =VLOOKUP(H6,#REF!,32,FALSE) -> #REF!
D24: 곱하여 산정하고, "근로자"는 이와 같은 포괄임금 산정방식에 대하여 동의한다. * 동의자 성명 : (인) | AX24: 2023년 관공서의 공휴일 수 (일X / 토O)
D25: 구성 항목 | G25: 기본급 1주 | M25: 40 | P25: 시간, | R25: 월 환산 | V25: =8*5*4.345 -> 173.8 | X25: 시간, | AA25: =V25/($V$25+$V$26+$V$27+$V$28+$V$29+$V$30)*100 -> 58.563871 | AC25: % | AD25: =ROUND($AI$23*AA25%,-1) -> #REF! | AK25: 원 | AX25: 1월 | AY25: 3 | AZ25: 1/1(일-제외,신정) 1/21,23-24(토,월-화,설날)
G26: 연장근로수당 1주 | M26: 12 | P26: 시간, | R26: 월 환산 | V26: =M26*4.345*1.5 -> 78.21 | X26: 시간, | AA26: =V26/($V$25+$V$26+$V$27+$V$28+$V$29+$V$30)*100 -> 26.353742 | AC26: % | AD26: =ROUND($AI$23*AA26%,-1) -> #REF! | AK26: 원 | AX26: 2월 | AY26: -
G27: 유급주휴수당 1주 | M27: 8 | P27: 시간, | R27: 월 환산 | V27: =8*4.345 -> 34.76 | X27: 시간, | AA27: =V27/($V$25+$V$26+$V$27+$V$28+$V$29+$V$30)*100 -> 11.712774 | AC27: % | AD27: =ROUND($AI$23*AA27%,-1) -> #REF! | AK27: 원 | AX27: 3월 | AY27: 1 | AZ27: 3/1(수,삼일절)
G28: 관공서 공휴일근로수당(月) | M28: 0 | P28: 일, | R28: 월 환산 | V28: =M28*8*1.5 -> 0 | X28: 시간, | AA28: =V28/($V$25+$V$26+$V$27+$V$28+$V$29+$V$30)*100 -> 0 | AC28: % | AD28: =ROUND($AI$23*AA28%,-1) -> #REF! | AK28: 원 | AX28: 4월 | AY28: -
G29: 유급관공서휴일수당(月) | M29: 0 | P29: 일, | R29: 월 환산 | V29: =M29*8*1 -> 0 | X29: 시간, | AA29: =V29/($V$25+$V$26+$V$27+$V$28+$V$29+$V$30)*100 -> 0 | AC29: % | AD29: =ROUND($AI$23*AA29%,-1) -> #REF! | AK29: 원 | AX29: 5월 | AY29: 2 | AZ29: 5/5(금,어린이날) 5/27(토,석가탄신일)
G30: 연차휴가수당 (1월) | M30: 10 | P30: 시간, | R30: 월 환산 | V30: 10 | X30: 시간, | AA30: =V30/($V$25+$V$26+$V$27+$V$28+$V$29+$V$30)*100 -> 3.3696128 | AC30: % | AD30: =ROUND($AI$23*AA30%,-1) -> #REF! | AK30: 원 | AX30: 6월 | AY30: 1 | AZ30: 6/6(화,현충일)
D31: ③ "근로자"의 월급은 매월 ( )일에 지급하며, 지급시 근로소득세 및 고용보험료, 건강보험료, 국민연금 등 제세공과금을 원천징수한 후 | AX31: 7월 | AY31: -
D32: "근로자"의 온라인 통장계좌로 지급함에 동의한다. | R32: ※급여수령 통장 및 계좌번호 : | AA32: =VLOOKUP(AB6,#REF!,5,FALSE)&" "&VLOOKUP(AB6,#REF!,6,FALSE)&", 예금주 "&VLOOKUP(AB6,#REF!,7,FALSE) -> #REF! | AX32: 8월 | AY32: 1 | AZ32: 8/15(화,광복절)
B33: 근로시간 및 휴게시간 | D33: ① 시업 및 종업시간: 07:00 ~ 17:00 ② 소정근로시간은 휴게시간을 제외하고 1일 8시간, 1주 40시간으로 하되 "근로자"는 근로기준법이 정하는 바에 따라 1주일에 12시간의 범위 내에서 연장근로를 수행함에 동의한다. * 동의자 성명 : (인) ③ 휴게시간(09:00 ~ 09:30, 12:00 ~ 13:00, 15:00 ~ 15:30)은 작업장내에서 자유로이 사용할 수 있다. 다만, 현장상황에 따라 변경될수 있다 | AX33: 9월 | AY33: 3일 | AZ33: 9/28-30(목-토,추석)
AX34: 10월 | AY34: 3 | AZ34: 10/3(화,개천절) 10/9(월,한글날)
AX35: 11월 | AY35: -
AX36: 12월 | AY36: 2 | AZ36: 12/25(월,성탄절)
B37: 휴가 | D37: ① 전월에 만근시 1일의 연차휴가를 부여하며, 사용하지 않을 경우 포괄역산하여 지급한다. ② 부여된 연차 휴가는 하기에 대체하여 사용할 수 있다. | AX37: 합계 | AY37: =SUM(AY25:AY36) -> 13
B38: 휴일 | D38: ① 전주간(월-금)만근한 경우 일요일 및 근로자의 날(5.1)은 유급주휴를 부여한다(다만, 현장의 공사일정에 따라 부득이한 경우 주휴일은 일요일이 아닌 평일에 부여할 수 있다. 이 경우 일요일의 근로는 휴일근로가 아닌 통상의 근로일로 본다). ② 토요일은 무급휴무일로 하며 해당일 근무에 대한 임금은 포괄역산한다. 그 외의 휴일은 취업규칙에서 정한 바에 따른다
B39: 근로계약 해지사유 | D39: ① 월 합계 또는 계속하여 3일 이상 결근한 경우, 근로계약은 자동 해지된다. ② 안전수칙 불이행 근무태만, 근무지무단이탈, 취업규칙 불이행으로 2회 이상 경고처분 받은 경우 ③ 정당한 업무지시 불이행 및 고의 또는 중대한 과실로 사고나 손실을 야기시킨 경우 ④ 갑의 사정으로 인하여 계약기간 까지 을의 당 현장 계속 근무가 불필요할 때 ⑤ 신체(고혈압, 디스크포함)·정신상 장애로 해당 업무를 수행할 수 없을 경우 ⑥ 폭행,파괴,태업을 선동하거나 적극 참여하는 등 불법 집단행동 업무방해를 주도하였거나 적극 참여한 경우 ⑦ "사업주"의 동의없이 타 작업장에 취업한 때 및 근로계약기간이 종료되었을 때 ⑧ 그 외"사업주"의 취업규칙상의 징계기준에 해당될 때
B40: 채용결격 사유 | D40: 불법체류자, 지명수배중에 있는자, 채용시 고혈압 및 척추질환등 업무수행에 곤란을 초래할 수 있는 자는 채용될 수 없으며, 위 사실이 추후 발견된 경우 본 근로계약은 취소된다.
B41: 기타근로 조건 | D41: ① 본 계약서상에 명시되지 않은 사항은 당 사 취업규칙 및 근로기준법에 따른다.
D42: ② "근로자"가 계약기간 중 퇴직하고자 할 경우에는 5일 전에 통보하여야 한다.
...
