Workbook
Name __1_0Crite: [1]총괄내역서!#REF!
Name __2_0Extr: [1]총괄내역서!#REF!
Name __3Crite: [1]총괄내역서!#REF!
Name __4Extr: [1]총괄내역서!#REF!
Name _: #REF!
Name _: #REF!
Name _?ó_ü?Ì?æ: #REF!
Name ___A100000: #REF!
Name ___A183154: #REF!
Name ___A69999: #REF!
Name ___A99999: #REF!
Name ___bar10: #REF!
Name ___bar13: #REF!
Name ___bar16: #REF!
Name ___bar19: #REF!
Name ___bar22: #REF!
Name ___bar25: #REF!
Name ___bar29: #REF!
Name ___bar32: #REF!
Name ___ctc1: #REF!
Name ___ctc2: #REF!
Name ___ctc3: #REF!
Name ___dia35: #REF!
Name ___DOG1: #REF!
Name ___DOG2: #REF!
Name ___DOG3: #REF!
Name ___DOG4: #REF!
Name ___ELL1: #REF!
Name ___ELL2: #REF!
Name ___faf98: #REF!
Name ___FBB1: #REF!
Name ___FBB2: #REF!
Name ___FBB3: #REF!
Name ___FHH1: #REF!
Name ___FHH2: #REF!
Name ___FHH3: #REF!
Name ___GHH1: #REF!
Name ___GHH2: #REF!
Name ___HSH1: #REF!
Name ___HSH2: #REF!
Name ___JEA1: #REF!
Name ___JEA2: #REF!
Name ___JOI13: #REF!
Name ___JY1: BlankMacro1
Name ___JY1: BlankMacro1
Name ___KK1: #REF!
Name ___kM1: #REF!
Name ___kM2: #REF!
Name ___kM3: #REF!
Name ___LP1: #REF!
Name ___LP2: #REF!
Name ___MaL1: #REF!
Name ___MaL2: #REF!
Name ___NLL1: #REF!
Name ___NLL2: #REF!
Name ___NLL3: #REF!
Name ___NLL4: #REF!
Name ___NLL5: #REF!
Name ___NMB96: #REF!
Name ___NP1: #REF!

Sheet 갑지
A8: 공사명 : 고기근린공원(사회공헌)조성공사
B11: ▣ 도 급 금 액 : | C11: 일금 | D11: =NUMBERSTRING(H11,1) -> 일십사억팔천사백칠십사만삼천육백구십구 | F11: 원정 | G11: ( | H11: =조경원가계산서!D32 -> 1.4847437e+09 | I11: )
B12: ▣ 전 회 기 성 : | C12: 일금 | D12: =NUMBERSTRING(H12,1) -> 영 | F12: 원정 | G12: ( | H12: =조경원가계산서!E32 -> 0 | I12: )
B13: ▣ 금 회 기 성 : | C13: 일금 | D13: =NUMBERSTRING(H13,1) -> 이억삼천육백오십만 | F13: 원정 | G13: ( | H13: =조경원가계산서!G32 -> 236500000 | I13: )
B14: ▣ 누 계 기 성 : | C14: 일금 | D14: =NUMBERSTRING(H14,1) -> 이억삼천육백오십만 | F14: 원정 | G14: ( | H14: =H12+H13 -> 236500000 | I14: )
B15: ▣ 미 기 성 : | C15: 일금 | D15: =NUMBERSTRING(H15,1) -> 일십이억사천팔백이십사만삼천육백구십구 | F15: 원정 | G15: ( | H15: =H11-H14 -> 1.2482437e+09 | I15: )

Sheet 조경원가계산서
A1: 공 사 원 가 계 산 서( 조 경)
A2: [공사명]고기근린공원(사회공헌) 조성공사(조경)
A3: 비 목 | D3: 도급금액 | E3: 전회기성 | F3: 비율(%) | G3: 금회기성 | H3: 비율(%) | I3: 누계기성 | J3: 비율(%) | K3: 구 성 비 | L3: 비 고 | M3: 정산보험료증감분 산출 | N3: =D4+D8+D12 -> 532681710
N4: =D5+D9+D13 -> 969794840
B5: 재 | C5: 직 접 재 료 비 | D5: 532681710 | F5: =IFERROR(E5/D5,0) -> 0 | G5: =내역서!S9 -> 14830383 | H5: =IFERROR(G5/D5,0) -> 0.027840984 | I5: =E5+G5 -> 14830383 | J5: =IFERROR(I5/D5,0) -> 0.027840984
A6: 순 | B6: 료 | C6: 간 접 재 료 비 | F6: =IFERROR(E6/D6,0) -> 0 | H6: =IFERROR(G6/D6,0) -> 0 | I6: =E6+G6 -> 0 | J6: =IFERROR(I6/D6,0) -> 0
B7: 비 | C7: 작업설,부산물등(△) | F7: =IFERROR(E7/D7,0) -> 0 | H7: =IFERROR(G7/D7,0) -> 0 | I7: =E7+G7 -> 0 | J7: =IFERROR(I7/D7,0) -> 0
C8: [ 소 계 ] | D8: =SUM(D5:D7) -> 532681710 | F8: =IFERROR(E8/D8,0) -> 0 | G8: =G5+G6+G7 -> 14830383 | H8: =IFERROR(G8/D8,0) -> 0.027840984 | I8: =E8+G8 -> 14830383 | J8: =IFERROR(I8/D8,0) -> 0.027840984
A9: 공 | B9: 노 | C9: 직 접 노 무 비 | D9: 392029555 | F9: =IFERROR(E9/D9,0) -> 0 | G9: =내역서!T9 -> 110073033 | H9: =IFERROR(G9/D9,0) -> 0.28077738 | I9: =E9+G9 -> 110073033 | J9: =IFERROR(I9/D9,0) -> 0.28077738
B10: 무 | C10: 간 접 노 무 비 | D10: 56060226 | F10: =IFERROR(E10/D10,0) -> 0 | G10: =INT(G9*N10) -> 15740443 | H10: =IFERROR(G10/D10,0) -> 0.28077737 | I10: =E10+G10 -> 15740443 | J10: =IFERROR(I10/D10,0) -> 0.28077737 | K10: 직접노무비의 *14.3% | N10: 0.143
B11: 비 | C11: [ 소 계 ] | D11: =SUM(D9:D10) -> 448089781 | F11: =IFERROR(E11/D11,0) -> 0 | G11: =G9+G10 -> 125813476 | H11: =IFERROR(G11/D11,0) -> 0.28077738 | I11: =E11+G11 -> 125813476 | J11: =IFERROR(I11/D11,0) -> 0.28077738
C12: 운 반 비 | F12: =IFERROR(E12/D12,0) -> 0 | H12: =IFERROR(G12/D12,0) -> 0 | I12: =E12+G12 -> 0 | J12: =IFERROR(I12/D12,0) -> 0
A13: 사 | C13: 기 계 경 비 | D13: 45083575 | F13: =IFERROR(E13/D13,0) -> 0 | G13: =내역서!U9 -> 15225924 | H13: =IFERROR(G13/D13,0) -> 0.33772663 | I13: =E13+G13 -> 15225924 | J13: =IFERROR(I13/D13,0) -> 0.33772663
C14: 산 재 보 험 료 | D14: 15951996 | F14: =IFERROR(E14/D14,0) -> 0 | G14: =INT(G11*N14) -> 4478959 | H14: =IFERROR(G14/D14,0) -> 0.28077734 | I14: =E14+G14 -> 4478959 | J14: =IFERROR(I14/D14,0) -> 0.28077734 | K14: 노무비의 *3.56% | N14: 0.0356
B15: 경 | C15: 고 용 보 험 료 | D15: 4525706 | F15: =IFERROR(E15/D15,0) -> 0 | G15: =INT(G11*N15) -> 1270716 | H15: =IFERROR(G15/D15,0) -> 0.28077741 | I15: =E15+G15 -> 1270716 | J15: =IFERROR(I15/D15,0) -> 0.28077741 | K15: 노무비의 *1.01% | N15: 0.0101
C16: 건 강 보 험 료 | D16: 16066073 | F16: =IFERROR(E16/D16,0) -> 0 | G16: 340320 | H16: =IFERROR(G16/D16,0) -> 0.021182525 | I16: =E16+G16 -> 340320 | J16: =IFERROR(I16/D16,0) -> 0.021182525 | K16: 직접노무비의 *3.545% | M16: =ROUND(#REF!*0.03545,0) -> #REF! | N16: 0.03545
A17: 원 | C17: 연 금 보 험 료 | D17: 20394168 | F17: =IFERROR(E17/D17,0) -> 0 | H17: =IFERROR(G17/D17,0) -> 0 | I17: =E17+G17 -> 0 | J17: =IFERROR(I17/D17,0) -> 0 | K17: 직접노무비의 *4.5% | M17: =ROUND(#REF!*0.045,0) -> #REF! | N17: 0.045
C18: 노인장기요양보험료 | D18: 2080556 | F18: =IFERROR(E18/D18,0) -> 0 | G18: 44070 | H18: =IFERROR(G18/D18,0) -> 0.021181838 | I18: =E18+G18 -> 44070 | J18: =IFERROR(I18/D18,0) -> 0.021181838 | K18: 건강보험료 *12.95% | M18: =ROUND(#REF!*0.1295,0) -> #REF! | N18: 0.1295
C19: 퇴직공제부금비 | D19: 10423685 | F19: =IFERROR(E19/D19,0) -> 0 | G19: 1077200 | H19: =IFERROR(G19/D19,0) -> 0.10334157 | I19: =E19+G19 -> 1077200 | J19: =IFERROR(I19/D19,0) -> 0.10334157 | K19: 직접노무비의 * 2.3% | M19: =ROUND(#REF!*0.023,0) -> #REF! | N19: 0.023 | O19: 도급자관급 자재비 | P19: =내역서!H11 -> 184377307
C20: 기계대여대금지급보증수수료 | D20: 1745630 | F20: =IFERROR(E20/D20,0) -> 0 | H20: =IFERROR(G20/D20,0) -> 0 | I20: =E20+G20 -> 0 | J20: =IFERROR(I20/D20,0) -> 0 | K20: (재료비+직노비+산경) *0.18% | N20: 0.0018 | O20: A | P20: =INT((D8+D9+P19/1.1)*N21+3250000) -> 16357923
A21: 가 | B21: 비 | C21: 안 전 관 리 비 | D21: 18149619 | F21: =IFERROR(E21/D21,0) -> 0 | G21: =9462500-3000000 -> 6462500 | H21: =IFERROR(G21/D21,0) -> 0.35606808 | I21: =E21+G21 -> 6462500 | J21: =IFERROR(I21/D21,0) -> 0.35606808 | K21: (재료비+직노+도급자관급)*1.2%+3,250,000 | M21: =ROUND((#REF!+#REF!+#REF!)*0.012,0) -> #REF! | N21: 0.012 | O21: B | P21: =INT((((D8+D9)*N21+3250000)*1.2)) -> 17215842
C22: 환 경 보 전 비 | D22: 2909384 | F22: =IFERROR(E22/D22,0) -> 0 | G22: 1000000 | H22: =IFERROR(G22/D22,0) -> 0.34371537 | I22: =E22+G22 -> 1000000 | J22: =IFERROR(I22/D22,0) -> 0.34371537 | K22: (재료비+직노비+산경) *0.3% | N22: 0.003
C23: 기 타 경 비 | D23: 53942432 | F23: =IFERROR(E23/D23,0) -> 0 | G23: =INT((G8+G11)*N23) -> 7735412 | H23: =IFERROR(G23/D23,0) -> 0.14340125 | I23: =E23+G23 -> 7735412 | J23: =IFERROR(I23/D23,0) -> 0.14340125 | K23: (재료비+노무비) *5.5% | M23: =G16*12.95% -> 44071.44 | N23: 0.055
C24: 하도급지급보증수수료 | D24: 785533 | F24: =IFERROR(E24/D24,0) -> 0 | H24: =IFERROR(G24/D24,0) -> 0 | I24: =E24+G24 -> 0 | J24: =IFERROR(I24/D24,0) -> 0 | K24: (재료비+직노비+산출경비) *0.081% | N24: 0.00081
C25: [ 소 계 ] | D25: =SUM(D12:D24) -> 192058357 | F25: =IFERROR(E25/D25,0) -> 0 | G25: =SUM(G12:G24) -> 37635101 | H25: =IFERROR(G25/D25,0) -> 0.19595659 | I25: =E25+G25 -> 37635101 | J25: =IFERROR(I25/D25,0) -> 0.19595659
A26: 계 | D26: =D8+D11+D25 -> 1172829848 | F26: =IFERROR(E26/D26,0) -> 0 | G26: =INT(G8+G11+G25) -> 178278960 | H26: =IFERROR(G26/D26,0) -> 0.15200752 | I26: =E26+G26 -> 178278960 | J26: =IFERROR(I26/D26,0) -> 0.15200752
A27: 일 반 관 리 비 | D27: 70369790 | F27: =IFERROR(E27/D27,0) -> 0 | G27: =INT(G26*N27) -> 10696737 | H27: =IFERROR(G27/D27,0) -> 0.15200752 | I27: =E27+G27 -> 10696737 | J27: =IFERROR(I27/D27,0) -> 0.15200752 | K27: 계의 *6.0% | N27: 0.06
A28: 합 계 | D28: =D26+D27 -> 1243199638 | F28: =IFERROR(E28/D28,0) -> 0 | G28: =INT(G26+G27) -> 188975697 | H28: =IFERROR(G28/D28,0) -> 0.15200752 | I28: =E28+G28 -> 188975697 | J28: =IFERROR(I28/D28,0) -> 0.15200752
A29: 이 윤 | D29: 1.0656736e+08 | F29: =IFERROR(E29/D29,0) -> 0 | G29: =INT(((G11+G25+G27)*N29))-97494 -> 26024303 | H29: =IFERROR(G29/D29,0) -> 0.24420519 | I29: =E29+G29 -> 26024303 | J29: =IFERROR(I29/D29,0) -> 0.24420519 | K29: (노무비+경비+일반관리비) *15.0% | N29: 0.15
A30: 공 급 가 액 (총 원 가) | D30: =D28+D29 -> 1.349767e+09 | F30: =IFERROR(E30/D30,0) -> 0 | G30: =SUM(G28:G29) -> 215000000 | H30: =IFERROR(G30/D30,0) -> 0.15928675 | I30: =E30+G30 -> 215000000 | J30: =IFERROR(I30/D30,0) -> 0.15928675
A31: 부 가 가 치 세 | D31: 134976700 | F31: =IFERROR(E31/D31,0) -> 0 | G31: =INT(G30*N31) -> 21500000 | H31: =IFERROR(G31/D31,0) -> 0.15928675 | I31: =E31+G31 -> 21500000 | J31: =IFERROR(I31/D31,0) -> 0.15928675 | K31: 공급가액의 *10.00% | N31: 0.1
A32: 도 급 액 | D32: =D30+D31 -> 1.4847437e+09 | F32: =IFERROR(E32/D32,0) -> 0 | G32: =SUM(G30:G31) -> 236500000 | H32: =IFERROR(G32/D32,0) -> 0.15928675 | I32: =E32+G32 -> 236500000 | J32: =IFERROR(I32/D32,0) -> 0.15928675
A33: 관 급 자 재 비 | D33: 283710000 | F33: =IFERROR(E33/D33,0) -> 0 | G33: =G34+G35 -> 0 | H33: =IFERROR(G33/D33,0) -> 0 | I33: =E33+G33 -> 0 | J33: =IFERROR(I33/D33,0) -> 0
A34: 1) 도급자관급 | D34: 185372000 | F34: =IFERROR(E34/D34,0) -> 0 | H34: =IFERROR(G34/D34,0) -> 0 | I34: =E34+G34 -> 0 | J34: =IFERROR(I34/D34,0) -> 0
A35: 2) 관급자관급 | D35: 98338000 | F35: =IFERROR(E35/D35,0) -> 0 | H35: =IFERROR(G35/D35,0) -> 0 | I35: =E35+G35 -> 0 | J35: =IFERROR(I35/D35,0) -> 0
A36: 총 공 사 비 | D36: 1.7684537e+09 | F36: =IFERROR(E36/D36,0) -> 0 | G36: =SUM(G32:G33) -> 236500000 | H36: =IFERROR(G36/D36,0) -> 0.13373265 | I36: =E36+G36 -> 236500000 | J36: =IFERROR(I36/D36,0) -> 0.13373265

Sheet 내역서
A1: 제1회 기성내역서 | BU1: 낙찰율조정 | BV1: =+[318]원가계산서!$M$1 -> 0.859356
A2: 공 종 명 | B2: 규 격 | C2: 단위 | D2: 수량 | E2: 도급금액 | G2: 도급단가 | M2: 전회기성 | P2: 금회기성 | S2: 금액 | V2: 누계기성 | Y2: 비 고 | CB2: 합 계 | CD2: 재 료 비 | CF2: 노 무 비 | CH2: 경 비 | CJ2: 비 고
E3: 단 가 | F3: 금 액 | G3: 재료비 | H3: 재료비금액 | I3: 노무비 | J3: 노무비금액 | K3: 경비 | L3: 경비금액 | M3: 수량 | N3: 금액 | O3: 비율(%) | P3: 수량 | Q3: 금액 | R3: 비율(%) | S3: 재료비 | T3: 노무비 | U3: 경비 | V3: 수량 | W3: 금액 | X3: 비율(%) | AF3: 할 증 | AG3: 화폐변환 | AH3: OP값 | AI3: EQ | AJ3: LA | AK3: MA | AL3: 금액계상 | CB3: 단 가 | CC3: 금 액 | CD3: 단 가 | CE3: 금 액 | CF3: 단 가 | CG3: 금 액 | CH3: 단 가 | CI3: 금 액
A4: ■ 고기근린공원(사회공헌) 조성공사 (조경) | C4: 식 | D4: 1 | F4: =H4+J4+L4 -> 969794840 | H4: =TRUNC(H9,0) -> 532681710 | J4: =TRUNC(J9,0) -> 392029555 | L4: =TRUNC(L9,0) -> 45083575 | O4: =IFERROR(N4/$F4,0) -> 0 | Q4: =SUM(S4:U4) -> 140129340 | R4: =IFERROR(Q4/$F4,0) -> 0.1444938 | S4: =TRUNC(S9,0) -> 14830383 | T4: =TRUNC(T9,0) -> 110073033 | U4: =TRUNC(U9,0) -> 15225924 | V4: =M4+P4 -> 0 | W4: =N4+Q4 -> 140129340 | X4: =IFERROR(W4/$F4,0) -> 0.1444938 | AB4: A00 | CC4: 1143751560 | CE4: 659615040 | CG4: 434748520 | CI4: 49388000
A5: 1. 식재공 | C5: 식 | D5: 1 | E5: =G5+I5+K5 -> 477770857 | F5: =H5+J5+L5 -> 477770857 | G5: =H14 -> 226137202 | H5: =TRUNC(G5*D5,0) -> 226137202 | I5: =J14 -> 221230528 | J5: =TRUNC(I5*D5,0) -> 221230528 | K5: =L14 -> 30403127 | L5: =TRUNC(K5*D5,0) -> 30403127 | O5: =IFERROR(N5/$F5,0) -> 0 | Q5: =SUM(S5:U5) -> 95721258 | R5: =IFERROR(Q5/$F5,0) -> 0.20034972 | S5: =S14 -> 9136631 | T5: =T14 -> 75690614 | U5: =U14 -> 10894013 | V5: =M5+P5 -> 0 | W5: =N5+Q5 -> 95721258 | X5: =IFERROR(W5/$F5,0) -> 0.20034972 | AC5: 10 | AD5: * | AE5: A01 | BV5: =HYPERLINK("#내역서!A14","A01 →") -> A01 → | CB5: 543080398 | CC5: 543080398 | CD5: 266195980 | CE5: 266195980 | CF5: 243076433 | CG5: 243076433 | CH5: 33807985 | CI5: 33807985
A6: 2. 시설물공 | C6: 식 | D6: 1 | E6: =G6+I6+K6 -> 260326801 | F6: =H6+J6+L6 -> 260326801 | G6: =H256 -> 143156701 | H6: =TRUNC(G6*D6,0) -> 143156701 | I6: =J256 -> 109419239 | J6: =TRUNC(I6*D6,0) -> 109419239 | K6: =L256 -> 7750861 | L6: =TRUNC(K6*D6,0) -> 7750861 | O6: =IFERROR(N6/$F6,0) -> 0 | Q6: =SUM(S6:U6) -> 44408082 | R6: =IFERROR(Q6/$F6,0) -> 0.1705859 | S6: =S256 -> 5693752 | T6: =T256 -> 34382419 | U6: =U256 -> 4331911 | V6: =M6+P6 -> 0 | W6: =N6+Q6 -> 44408082 | X6: =IFERROR(W6/$F6,0) -> 0.1705859 | AC6: 20 | AD6: * | AE6: A02 | BV6: =HYPERLINK("#내역서!A184","A02 →") -> A02 → | CB6: 267265681 | CC6: 267265681 | CD6: 167713666 | CE6: 167713666 | CF6: 94165207 | CG6: 94165207 | CH6: 5386808 | CI6: 5386808
A7: 3. 포장공 | C7: 식 | D7: 1 | E7: =G7+I7+K7 -> 230056323 | F7: =H7+J7+L7 -> 230056323 | G7: =H297 -> 163387807 | H7: =TRUNC(G7*D7,0) -> 163387807 | I7: =J297 -> 61379788 | J7: =TRUNC(I7*D7,0) -> 61379788 | K7: =L297 -> 5288728 | L7: =TRUNC(K7*D7,0) -> 5288728 | O7: =IFERROR(N7/$F7,0) -> 0 | Q7: =SUM(S7:U7) -> 0 | R7: =IFERROR(Q7/$F7,0) -> 0 | S7: =S297 -> 0 | T7: =T297 -> 0 | U7: =U297 -> 0 | V7: =M7+P7 -> 0 | W7: =N7+Q7 -> 0 | X7: =IFERROR(W7/$F7,0) -> 0 | AC7: 60 | AD7: * | AE7: A03 | BV7: =HYPERLINK("#내역서!A211","A03 →") -> A03 → | CB7: 331495453 | CC7: 331495453 | CD7: 225705394 | CE7: 225705394 | CF7: 97506880 | CG7: 97506880 | CH7: 8283179 | CI7: 8283179
A8: 4. 부대공 | C8: 식 | D8: 1 | E8: =G8+I8+K8 -> 1640859 | F8: =H8+J8+L8 -> 1640859 | G8: =H312 -> 0 | H8: =TRUNC(G8*D8,0) -> 0 | I8: =J312 -> 0 | J8: =TRUNC(I8*D8,0) -> 0 | K8: =L312 -> 1640859 | L8: =TRUNC(K8*D8,0) -> 1640859 | O8: =IFERROR(N8/$F8,0) -> 0 | Q8: =SUM(S8:U8) -> 0 | R8: =IFERROR(Q8/$F8,0) -> 0 | S8: =S312 -> 0 | T8: =T312 -> 0 | U8: =U312 -> 0 | V8: =M8+P8 -> 0 | W8: =N8+Q8 -> 0 | X8: =IFERROR(W8/$F8,0) -> 0 | AC8: 70 | AD8: * | AE8: A04 | AN8: MA+ = | AO8: =(내역서!H5+내역서!H6+내역서!H7+내역서!H8) -> 532681710 | AP8: MA = | AQ8: =$AO8 -> 532681710 | BV8: =HYPERLINK("#내역서!A224","A04 →") -> A04 → | CB8: 1910028 | CC8: 1910028 | CD8: 0 | CE8: 0 | CF8: 0 | CG8: 0 | CH8: 1910028 | CI8: 1910028
A9: 직접공사비 | C9: 식 | D9: 1 | E9: =G9+I9+K9 -> 0 | F9: =H9+J9+L9 -> 969794840 | H9: =TRUNC((H5+H6+H7+H8),0) -> 532681710 | J9: =TRUNC((J5+J6+J7+J8),0) -> 392029555 | L9: =TRUNC((L5+L6+L7+L8),0) -> 45083575 | N9: =TRUNC((N5+N6+N7+N8),0) -> 0 | O9: =IFERROR(N9/$F9,0) -> 0 | Q9: =TRUNC((Q5+Q6+Q7+Q8),0) -> 140129340 | R9: =IFERROR(Q9/$F9,0) -> 0.1444938 | S9: =TRUNC((S5+S6+S7+S8),0) -> 14830383 | T9: =TRUNC((T5+T6+T7+T8),0) -> 110073033 | U9: =TRUNC((U5+U6+U7+U8),0) -> 15225924 | V9: =M9+P9 -> 0 | W9: =N9+Q9 -> 140129340 | X9: =IFERROR(W9/$F9,0) -> 0.1444938 | AC9: 205 | AE9: F | AK9: ma=ma(10,0,70)_x000D_ la=la(10,0,70)_x000D_ eq=eq(10,0,70) | AN9: LA+ = | AO9: =(내역서!J5+내역서!J6+내역서!J7+내역서!J8) -> 392029555 | AP9: LA = | AQ9: =$AO9 -> 392029555 | CB9: 0 | CC9: 1143751560 | CE9: 659615040 | CG9: 434748520 | CI9: 49388000
E10: =G10+I10+K10 -> 0 | F10: =H10+J10+L10 -> 0 | H10: 0 | J10: 0 | L10: 0 | O10: =IFERROR(N10/$F10,0) -> 0 | Q10: =SUM(S10:U10) -> 0 | R10: =IFERROR(Q10/$F10,0) -> 0 | V10: =M10+P10 -> 0 | W10: =N10+Q10 -> 0 | X10: =IFERROR(W10/$F10,0) -> 0 | AC10: 273 | AN10: EQ+ = | AO10: =(내역서!L5+내역서!L6+내역서!L7+내역서!L8) -> 45083575 | AP10: EQ = | AQ10: =$AO10 -> 45083575 | CB10: 0 | CC10: 0 | CE10: 0 | CG10: 0 | CI10: 0
A11: * 관급자재대(도급자관급) | C11: 식 | D11: 1 | E11: =G11+I11+K11 -> 185372000 | F11: =H11+J11+L11 -> 185372000 | G11: =H316 -> 184377307 | H11: =TRUNC(G11*D11,0) -> 184377307 | I11: =J316 -> 0 | J11: =TRUNC(I11*D11,0) -> 0 | K11: =L316 -> 994693 | L11: =TRUNC(K11*D11,0) -> 994693 | O11: =IFERROR(N11/$F11,0) -> 0 | Q11: =SUM(S11:U11) -> 0 | R11: =IFERROR(Q11/$F11,0) -> 0 | S11: =S316 -> 0 | T11: =T316 -> 0 | U11: =U316 -> 0 | V11: =M11+P11 -> 0 | W11: =N11+Q11 -> 0 | X11: =IFERROR(W11/$F11,0) -> 0 | AC11: 307 | AD11: * | AE11: C01 | BV11: =HYPERLINK("#내역서!A228","C01 →") -> C01 → | CB11: 234054000 | CC11: 234054000 | CD11: 232797050 | CE11: 232797050 | CF11: 0 | CG11: 0 | CH11: 1256950 | CI11: 1256950
A12: * 관급자재대(관급자관급) | C12: 식 | D12: 1 | E12: =G12+I12+K12 -> 98338000 | F12: =H12+J12+L12 -> 98338000 | G12: =H332 -> 97810000 | H12: =TRUNC(G12*D12,0) -> 97810000 | I12: =J332 -> 0 | J12: =TRUNC(I12*D12,0) -> 0 | K12: =L332 -> 528000 | L12: =TRUNC(K12*D12,0) -> 528000 | O12: =IFERROR(N12/$F12,0) -> 0 | Q12: =SUM(S12:U12) -> 0 | R12: =IFERROR(Q12/$F12,0) -> 0 | S12: =S332 -> 0 | T12: =T332 -> 0 | U12: =U332 -> 0 | V12: =M12+P12 -> 0 | W12: =N12+Q12 -> 0 | X12: =IFERROR(W12/$F12,0) -> 0 | AC12: 323 | AD12: * | AE12: C02 | BV12: =HYPERLINK("#내역서!A242","C02 →") -> C02 → | CB12: 150608000 | CC12: 150608000 | CD12: 149800000 | CE12: 149800000 | CF12: 0 | CG12: 0 | CH12: 808000 | CI12: 808000
E13: =G13+I13+K13 -> 0 | F13: =H13+J13+L13 -> 0 | H13: 0 | J13: 0 | L13: 0 | O13: =IFERROR(N13/$F13,0) -> 0 | Q13: =SUM(S13:U13) -> 0 | R13: =IFERROR(Q13/$F13,0) -> 0 | V13: =M13+P13 -> 0 | W13: =N13+Q13 -> 0 | X13: =IFERROR(W13/$F13,0) -> 0 | AC13: 340 | AD13: S | CB13: 0 | CC13: 0 | CE13: 0 | CG13: 0 | CI13: 0
A14: 1. 식재공 | C14: 식 | D14: 1 | F14: =H14+J14+L14 -> 477770857 | H14: =SUM(H15+H101+H206+H220+H235+H250) -> 226137202 | J14: =SUM(J15+J101+J206+J220+J235+J250) -> 221230528 | L14: =SUM(L15+L101+L206+L220+L235+L250) -> 30403127 | O14: =IFERROR(N14/$F14,0) -> 0 | Q14: =SUM(S14:U14) -> 95721258 | R14: =IFERROR(Q14/$F14,0) -> 0.20034972 | S14: =SUM(S15+S101+S206+S220+S235+S250) -> 9136631 | T14: =SUM(T15+T101+T206+T220+T235+T250) -> 75690614 | U14: =SUM(U15+U101+U206+U220+U235+U250) -> 10894013 | V14: =M14+P14 -> 0 | W14: =N14+Q14 -> 95721258 | X14: =IFERROR(W14/$F14,0) -> 0.20034972 | AB14: A01 | AM14: =H16+H18+H20+H21+H22+H23+H24+H25+H26+H27+H29+H30+H31+H32+H34+H35+H36+H37+H38+H39+H40+H46+H49+H50+H51+H52+H53+H54+H55+H56+H57+H58+H59+H60+H62+H64+H65 -> 249497 | AN14: =J16+J18+J20+J21+J22+J23+J24+J25+J26+J27+J29+J30+J31+J32+J34+J35+J36+J37+J38+J39+J40+J46+J49+J50+J51+J52+J53+J54+J55+J56+J57+J58+J59+J60+J62+J64+J65 -> 14376913 | AO14: =L16+L18+L20+L21+L22+L23+L24+L25+L26+L27+L29+L30+L31+L32+L34+L35+L36+L37+L38+L39+L40+L46+L49+L50+L51+L52+L53+L54+L55+L56+L57+L58+L59+L60+L62+L64+L65 -> 82252 | CC14: 543080398 | CE14: 266195980 | CG14: 243076433 | CI14: 33807985
A15: .1)수목제거공사 | E15: =G15+I15+K15 -> 0 | F15: =H15+J15+L15 -> 35153353 | H15: =SUM(H16:H99) -> 702995 | J15: =SUM(J16:J99) -> 33799710 | L15: =SUM(L16:L99) -> 650648 | O15: =IFERROR(N15/$F15,0) -> 0 | Q15: =SUM(S15:U15) -> 34629535 | R15: =IFERROR(Q15/$F15,0) -> 0.98509906 | S15: =SUM(S16:S99) -> 696460 | T15: =SUM(T16:T99) -> 33285357 | U15: =SUM(U16:U99) -> 647718 | V15: =M15+P15 -> 0 | W15: =N15+Q15 -> 34629535 | X15: =IFERROR(W15/$F15,0) -> 0.98509906 | AC15: 5 | AM15: =H66+H70+H77+H78+H79+H81+H82+#REF!+H88+H90+H102+H103+H104+H105+H106+H108+H109+H110+H111+H112+H113+H114+H115+H116+H117+H118+H119+H120+H121+H122+H123+H124+H125+H126+H127+H128+H129 -> #REF! | AN15: =J66+J70+J77+J78+J79+J81+J82+#REF!+J88+J90+J102+J103+J104+J105+J106+J108+J109+J110+J111+J112+J113+J114+J115+J116+J117+J118+J119+J120+J121+J122+J123+J124+J125+J126+J127+J128+J129 -> #REF! | AO15: =L66+L70+L77+L78+L79+L81+L82+#REF!+L88+L90+L102+L103+L104+L105+L106+L108+L109+L110+L111+L112+L113+L114+L115+L116+L117+L118+L119+L120+L121+L122+L123+L124+L125+L126+L127+L128+L129 -> #REF! | AP15: =H16+H18+H20+H21+H22+H23+H24+H25+H26+H27+H29+H30+H31+H32+H34+H35+H36+H37+H38+H39+H40+H46+H49+H50+H51+H52+H53+H54+H55+H56+H57+H58+H59+H60+H62+H64+H65 -> 249497 | AQ15: =J16+J18+J20+J21+J22+J23+J24+J25+J26+J27+J29+J30+J31+J32+J34+J35+J36+J37+J38+J39+J40+J46+J49+J50+J51+J52+J53+J54+J55+J56+J57+J58+J59+J60+J62+J64+J65 -> 14376913 | AR15: =L16+L18+L20+L21+L22+L23+L24+L25+L26+L27+L29+L30+L31+L32+L34+L35+L36+L37+L38+L39+L40+L46+L49+L50+L51+L52+L53+L54+L55+L56+L57+L58+L59+L60+L62+L64+L65 -> 82252 | CB15: 0 | CC15: 12809658 | CE15: 213560 | CG15: 12520920 | CI15: 75178
A16: ..소나무 제거 | B16: H8.0xW3.0xR8 | C16: 주 | D16: 3 | E16: =G16+I16+K16 -> 9854 | F16: =H16+J16+L16 -> 29562 | G16: 102 | H16: =TRUNC(G16*D16,0) -> 306 | I16: 9722 | J16: =TRUNC(I16*D16,0) -> 29166 | K16: 30 | L16: =TRUNC(K16*D16,0) -> 90 | O16: =IFERROR(N16/$F16,0) -> 0 | P16: =D16 -> 3 | Q16: =SUM(S16:U16) -> 29562 | R16: =IFERROR(Q16/$F16,0) -> 1 | S16: =TRUNC(G16*$P16,0) -> 306 | T16: =TRUNC(I16*$P16,0) -> 29166 | U16: =TRUNC(K16*$P16,0) -> 90 | V16: =M16+P16 -> 3 | W16: =N16+Q16 -> 29562 | X16: =IFERROR(W16/$F16,0) -> 1 | AA16: =E16-#REF! -> #REF! | AC16: 10 | AE16: HX0020 | AG16: T | AM16: =H130+H131+H134+H142+H143+H144+H145+H146+H147+H148+H149+H150+H151+H152+H153+H154+H155+H158+H163+H164+H165+H170+H171+H172+H173+H174+H175+H176+H177+H178+H179 -> 3367835 | AN16: =J130+J131+J134+J142+J143+J144+J145+J146+J147+J148+J149+J150+J151+J152+J153+J154+J155+J158+J163+J164+J165+J170+J171+J172+J173+J174+J175+J176+J177+J178+J179 -> 18262212 | AO16: =L130+L131+L134+L142+L143+L144+L145+L146+L147+L148+L149+L150+L151+L152+L153+L154+L155+L158+L163+L164+L165+L170+L171+L172+L173+L174+L175+L176+L177+L178+L179 -> 4273561 | AP16: =H66+H70+H77+H78+H79+H81+H82+#REF!+H88+H90 -> #REF! | AQ16: =J66+J70+J77+J78+J79+J81+J82+#REF!+J88+J90 -> #REF! | AR16: =L66+L70+L77+L78+L79+L81+L82+#REF!+L88+L90 -> #REF! | BV16: =HYPERLINK("#일위대가목록!A9","HX0020 →") -> HX0020 → | CB16: 11468 | CC16: 34404 | CD16: 119 | CE16: 357 | CF16: 11314 | CG16: 33942 | CH16: 35 | CI16: 105 | CJ16: No.1
A17: ..소나무 제거 | B17: H5.0xW3.0xR20 | C17: 주 | D17: 3 | E17: =G17+I17+K17 -> 51119 | F17: =H17+J17+L17 -> 153357 | G17: 799 | H17: =TRUNC(G17*D17,0) -> 2397 | I17: 50063 | J17: =TRUNC(I17*D17,0) -> 150189 | K17: 257 | L17: =TRUNC(K17*D17,0) -> 771 | O17: =IFERROR(N17/$F17,0) -> 0 | P17: =D17 -> 3 | Q17: =SUM(S17:U17) -> 153357 | R17: =IFERROR(Q17/$F17,0) -> 1 | S17: =TRUNC(G17*$P17,0) -> 2397 | T17: =TRUNC(I17*$P17,0) -> 150189 | U17: =TRUNC(K17*$P17,0) -> 771 | V17: =M17+P17 -> 3 | W17: =N17+Q17 -> 153357 | X17: =IFERROR(W17/$F17,0) -> 1 | AA17: =E17-#REF! -> #REF! | AC17: 20 | AE17: HX0021 | AG17: T | AM17: =H179+H180+H181+H182+H183+H185+H186+H191+H192+H199+H200+H201+H206+H207+H208+H209+H210+H211+H212+H213+H214+H215+H216+H217+H218+H220+H221+H222+H223+H224 -> 204768025 | AN17: =J179+J180+J181+J182+J183+J185+J186+J191+J192+J199+J200+J201+J206+J207+J208+J209+J210+J211+J212+J213+J214+J215+J216+J217+J218+J220+J221+J222+J223+J224 -> 79858195 | AO17: =L179+L180+L181+L182+L183+L185+L186+L191+L192+L199+L200+L201+L206+L207+L208+L209+L210+L211+L212+L213+L214+L215+L216+L217+L218+L220+L221+L222+L223+L224 -> 4888309 | BV17: =HYPERLINK("#일위대가목록!A10","HX0021 →") -> HX0021 → | CB17: 91691 | CC17: 91691 | CD17: 1614 | CE17: 1614 | CF17: 89527 | CG17: 89527 | CH17: 550 | CI17: 550 | CJ17: No.2
A18: ..소나무 제거 | B18: H5.0xW3.0xR25 | C18: 주 | D18: 1 | E18: =G18+I18+K18 -> 78794 | F18: =H18+J18+L18 -> 78794 | G18: 1387 | H18: =TRUNC(G18*D18,0) -> 1387 | I18: 76935 | J18: =TRUNC(I18*D18,0) -> 76935 | K18: 472 | L18: =TRUNC(K18*D18,0) -> 472 | O18: =IFERROR(N18/$F18,0) -> 0 | P18: =D18 -> 1 | Q18: =SUM(S18:U18) -> 78794 | R18: =IFERROR(Q18/$F18,0) -> 1 | S18: =TRUNC(G18*$P18,0) -> 1387 | T18: =TRUNC(I18*$P18,0) -> 76935 | U18: =TRUNC(K18*$P18,0) -> 472 | V18: =M18+P18 -> 1 | W18: =N18+Q18 -> 78794 | X18: =IFERROR(W18/$F18,0) -> 1 | AA18: =E18-#REF! -> #REF! | AC18: 20 | AE18: HX0021 | AG18: T | AM18: =H180+H181+H182+H183+H185+H186+H191+H192+H199+H200+H201+H202+H207+H208+H209+H210+H211+H212+H213+H214+H215+H216+H217+H218+H219+H221+H222+H223+H224+H225 -> 94483169 | AN18: =J180+J181+J182+J183+J185+J186+J191+J192+J199+J200+J201+J202+J207+J208+J209+J210+J211+J212+J213+J214+J215+J216+J217+J218+J219+J221+J222+J223+J224+J225 -> 31889025 | AO18: =L180+L181+L182+L183+L185+L186+L191+L192+L199+L200+L201+L202+L207+L208+L209+L210+L211+L212+L213+L214+L215+L216+L217+L218+L219+L221+L222+L223+L224+L225 -> 2792988 | BV18: =HYPERLINK("#일위대가목록!A10","HX0021 →") -> HX0021 → | CB18: 91691 | CC18: 91691 | CD18: 1614 | CE18: 1614 | CF18: 89527 | CG18: 89527 | CH18: 550 | CI18: 550 | CJ18: No.2
A19: ..소나무 제거 | B19: H7.0xW3.5xR32 | C19: 주 | D19: 1 | E19: =G19+I19+K19 -> 163535 | F19: =H19+J19+L19 -> 163535 | G19: 3068 | H19: =TRUNC(G19*D19,0) -> 3068 | I19: 159502 | J19: =TRUNC(I19*D19,0) -> 159502 | K19: 965 | L19: =TRUNC(K19*D19,0) -> 965 | O19: =IFERROR(N19/$F19,0) -> 0 | P19: =D19 -> 1 | Q19: =SUM(S19:U19) -> 163535 | R19: =IFERROR(Q19/$F19,0) -> 1 | S19: =TRUNC(G19*$P19,0) -> 3068 | T19: =TRUNC(I19*$P19,0) -> 159502 | U19: =TRUNC(K19*$P19,0) -> 965 | V19: =M19+P19 -> 1 | W19: =N19+Q19 -> 163535 | X19: =IFERROR(W19/$F19,0) -> 1 | AA19: =E19-#REF! -> #REF! | AC19: 500 | AE19: HX0055 | AG19: T | BV19: =HYPERLINK("#일위대가목록!A44","HX0055 →") -> HX0055 → | CB19: 190302 | CC19: 190302 | CD19: 3571 | CE19: 3571 | CF19: 185607 | CG19: 185607 | CH19: 1124 | CI19: 1124 | CJ19: No.36
A20: ..스트로브잣나무 제거 | B20: H10.0xR30 | C20: 주 | D20: 15 | E20: =G20+I20+K20 -> 146977 | F20: =H20+J20+L20 -> 2204655 | G20: 2667 | H20: =TRUNC(G20*D20,0) -> 40005 | I20: 143492 | J20: =TRUNC(I20*D20,0) -> 2152380 | K20: 818 | L20: =TRUNC(K20*D20,0) -> 12270 | O20: =IFERROR(N20/$F20,0) -> 0 | P20: =D20 -> 15 | Q20: =SUM(S20:U20) -> 2204655 | R20: =IFERROR(Q20/$F20,0) -> 1 | S20: =TRUNC(G20*$P20,0) -> 40005 | T20: =TRUNC(I20*$P20,0) -> 2152380 | U20: =TRUNC(K20*$P20,0) -> 12270 | V20: =M20+P20 -> 15 | W20: =N20+Q20 -> 2204655 | X20: =IFERROR(W20/$F20,0) -> 1 | AA20: =E20-#REF! -> #REF! | AC20: 30 | AE20: HX0022 | AG20: T | AM20: =H226+H227+H228+H229+H230+H231+H232+H233+H234+H236+H237+H238+H239+H240+H241+H242+H243+H244+H245+H246+H247+H248+H249+H251+H252+H253+H254 -> 112549125 | AN20: =J226+J227+J228+J229+J230+J231+J232+J233+J234+J236+J237+J238+J239+J240+J241+J242+J243+J244+J245+J246+J247+J248+J249+J251+J252+J253+J254 -> 47910404 | AO20: =L226+L227+L228+L229+L230+L231+L232+L233+L234+L236+L237+L238+L239+L240+L241+L242+L243+L244+L245+L246+L247+L248+L249+L251+L252+L253+L254 -> 0 | BV20: =HYPERLINK("#일위대가목록!A11","HX0022 →") -> HX0022 → | CB20: 171033 | CC20: 342066 | CD20: 3104 | CE20: 6208 | CF20: 166977 | CG20: 333954 | CH20: 952 | CI20: 1904 | CJ20: No.3
A21: ..스트로브잣나무 제거 | B21: H8.0xR18 | C21: 주 | D21: 17 | E21: =G21+I21+K21 -> 42303 | F21: =H21+J21+L21 -> 719151 | G21: 640 | H21: =TRUNC(G21*D21,0) -> 10880 | I21: 41457 | J21: =TRUNC(I21*D21,0) -> 704769 | K21: 206 | L21: =TRUNC(K21*D21,0) -> 3502 | O21: =IFERROR(N21/$F21,0) -> 0 | P21: =D21 -> 17 | Q21: =SUM(S21:U21) -> 719151 | R21: =IFERROR(Q21/$F21,0) -> 1 | S21: =TRUNC(G21*$P21,0) -> 10880 | T21: =TRUNC(I21*$P21,0) -> 704769 | U21: =TRUNC(K21*$P21,0) -> 3502 | V21: =M21+P21 -> 17 | W21: =N21+Q21 -> 719151 | X21: =IFERROR(W21/$F21,0) -> 1 | AA21: =E21-#REF! -> #REF! | AC21: 40 | AE21: HX0023 | AG21: T | BV21: =HYPERLINK("#일위대가목록!A12","HX0023 →") -> HX0023 → | CB21: 49228 | CC21: 886104 | CD21: 745 | CE21: 13410 | CF21: 48243 | CG21: 868374 | CH21: 240 | CI21: 4320 | CJ21: No.4
A22: ..스트로브잣나무 제거 | B22: H7.0xR24 | C22: 주 | D22: 25 | E22: =G22+I22+K22 -> 78644 | F22: =H22+J22+L22 -> 1966100 | G22: 1360 | H22: =TRUNC(G22*D22,0) -> 34000 | I22: 76846 | J22: =TRUNC(I22*D22,0) -> 1921150 | K22: 438 | L22: =TRUNC(K22*D22,0) -> 10950 | O22: =IFERROR(N22/$F22,0) -> 0 | P22: =D22 -> 25 | Q22: =SUM(S22:U22) -> 1966100 | R22: =IFERROR(Q22/$F22,0) -> 1 | S22: =TRUNC(G22*$P22,0) -> 34000 | T22: =TRUNC(I22*$P22,0) -> 1921150 | U22: =TRUNC(K22*$P22,0) -> 10950 | V22: =M22+P22 -> 25 | W22: =N22+Q22 -> 1966100 | X22: =IFERROR(W22/$F22,0) -> 1 | AA22: =E22-#REF! -> #REF! | AC22: 50 | AE22: HX0024 | AG22: T | BV22: =HYPERLINK("#일위대가목록!A13","HX0024 →") -> HX0024 → | CB22: 91516 | CC22: 640612 | CD22: 1583 | CE22: 11081 | CF22: 89423 | CG22: 625961 | CH22: 510 | CI22: 3570 | CJ22: No.5
A23: ..스트로브잣나무 제거 | B23: H7.0xR22 | C23: 주 | D23: 12 | E23: =G23+I23+K23 -> 51321 | F23: =H23+J23+L23 -> 615852 | G23: 835 | H23: =TRUNC(G23*D23,0) -> 10020 | I23: 50182 | J23: =TRUNC(I23*D23,0) -> 602184 | K23: 304 | L23: =TRUNC(K23*D23,0) -> 3648 | O23: =IFERROR(N23/$F23,0) -> 0 | P23: =D23 -> 12 | Q23: =SUM(S23:U23) -> 615852 | R23: =IFERROR(Q23/$F23,0) -> 1 | S23: =TRUNC(G23*$P23,0) -> 10020 | T23: =TRUNC(I23*$P23,0) -> 602184 | U23: =TRUNC(K23*$P23,0) -> 3648 | V23: =M23+P23 -> 12 | W23: =N23+Q23 -> 615852 | X23: =IFERROR(W23/$F23,0) -> 1 | AA23: =E23-#REF! -> #REF! | AC23: 60 | AE23: HX0025 | AG23: T | BV23: =HYPERLINK("#일위대가목록!A14","HX0025 →") -> HX0025 → | CB23: 59722 | CC23: 716664 | CD23: 972 | CE23: 11664 | CF23: 58396 | CG23: 700752 | CH23: 354 | CI23: 4248 | CJ23: No.6
A24: ..스트로브잣나무 제거 | B24: H7.0xR20 | C24: 주 | D24: 21 | E24: =G24+I24+K24 -> 51119 | F24: =H24+J24+L24 -> 1073499 | G24: 799 | H24: =TRUNC(G24*D24,0) -> 16779 | I24: 50063 | J24: =TRUNC(I24*D24,0) -> 1051323 | K24: 257 | L24: =TRUNC(K24*D24,0) -> 5397 | O24: =IFERROR(N24/$F24,0) -> 0 | P24: =D24 -> 21 | Q24: =SUM(S24:U24) -> 1073499 | R24: =IFERROR(Q24/$F24,0) -> 1 | S24: =TRUNC(G24*$P24,0) -> 16779 | T24: =TRUNC(I24*$P24,0) -> 1051323 | U24: =TRUNC(K24*$P24,0) -> 5397 | V24: =M24+P24 -> 21 | W24: =N24+Q24 -> 1073499 | X24: =IFERROR(W24/$F24,0) -> 1 | AA24: =E24-#REF! -> #REF! | AC24: 80 | AE24: HX0026 | AG24: T | BV24: =HYPERLINK("#일위대가목록!A15","HX0026 →") -> HX0026 → | CB24: 59487 | CC24: 237948 | CD24: 930 | CE24: 3720 | CF24: 58257 | CG24: 233028 | CH24: 300 | CI24: 1200 | CJ24: No.7
A25: ..스트로브잣나무 제거 | B25: H7.0xR15 | C25: 주 | D25: 31 | E25: =G25+I25+K25 -> 30359 | F25: =H25+J25+L25 -> 941129 | G25: 421 | H25: =TRUNC(G25*D25,0) -> 13051 | I25: 29805 | J25: =TRUNC(I25*D25,0) -> 923955 | K25: 133 | L25: =TRUNC(K25*D25,0) -> 4123 | O25: =IFERROR(N25/$F25,0) -> 0 | P25: =D25 -> 31 | Q25: =SUM(S25:U25) -> 941129 | R25: =IFERROR(Q25/$F25,0) -> 1 | S25: =TRUNC(G25*$P25,0) -> 13051 | T25: =TRUNC(I25*$P25,0) -> 923955 | U25: =TRUNC(K25*$P25,0) -> 4123 | V25: =M25+P25 -> 31 | W25: =N25+Q25 -> 941129 | X25: =IFERROR(W25/$F25,0) -> 1 | AA25: =E25-#REF! -> #REF! | AC25: 100 | AE25: HX0027 | AG25: T | BV25: =HYPERLINK("#일위대가목록!A16","HX0027 →") -> HX0027 → | CB25: 35329 | CC25: 529935 | CD25: 490 | CE25: 7350 | CF25: 34684 | CG25: 520260 | CH25: 155 | CI25: 2325 | CJ25: No.8
A26: ..스트로브잣나무 제거 | B26: H6.0xR18 | C26: 주 | D26: 0 | O26: =IFERROR(N26/$F26,0) -> 0 | P26: =D26 -> 0 | Q26: =SUM(S26:U26) -> 0 | R26: =IFERROR(Q26/$F26,0) -> 0 | S26: =TRUNC(G26*$P26,0) -> 0 | T26: =TRUNC(I26*$P26,0) -> 0 | U26: =TRUNC(K26*$P26,0) -> 0 | V26: =M26+P26 -> 0 | W26: =N26+Q26 -> 0 | X26: =IFERROR(W26/$F26,0) -> 0 | AA26: =E26-#REF! -> #REF! | AC26: 110 | AE26: HX0028 | AG26: T | BV26: =HYPERLINK("#일위대가목록!A17","HX0028 →") -> HX0028 → | CB26: 49228 | CC26: 1624524 | CD26: 745 | CE26: 24585 | CF26: 48243 | CG26: 1592019 | CH26: 240 | CI26: 7920 | CJ26: No.9
A27: ..스트로브잣나무 제거 | B27: H4.0xR15 | C27: 주 | O27: =IFERROR(N27/$F27,0) -> 0 | P27: =D27 -> 0 | Q27: =SUM(S27:U27) -> 0 | R27: =IFERROR(Q27/$F27,0) -> 0 | S27: =TRUNC(G27*$P27,0) -> 0 | T27: =TRUNC(I27*$P27,0) -> 0 | U27: =TRUNC(K27*$P27,0) -> 0 | V27: =M27+P27 -> 0 | W27: =N27+Q27 -> 0 | X27: =IFERROR(W27/$F27,0) -> 0 | AA27: =E27-#REF! -> #REF! | AC27: 120 | AE27: HX0029 | AG27: T | BV27: =HYPERLINK("#일위대가목록!A18","HX0029 →") -> HX0029 → | CB27: 35329 | CC27: 388619 | CD27: 490 | CE27: 5390 | CF27: 34684 | CG27: 381524 | CH27: 155 | CI27: 1705 | CJ27: No.10
A28: ..스트로브잣나무 제거 | B28: H4.0xR12 | C28: 주 | D28: 22 | E28: =G28+I28+K28 -> 24608 | F28: =H28+J28+L28 -> 541376 | G28: 302 | H28: =TRUNC(G28*D28,0) -> 6644 | I28: 24216 | J28: =TRUNC(I28*D28,0) -> 532752 | K28: 90 | L28: =TRUNC(K28*D28,0) -> 1980 | O28: =IFERROR(N28/$F28,0) -> 0 | P28: =D28 -> 22 | Q28: =SUM(S28:U28) -> 541376 | R28: =IFERROR(Q28/$F28,0) -> 1 | S28: =TRUNC(G28*$P28,0) -> 6644 | T28: =TRUNC(I28*$P28,0) -> 532752 | U28: =TRUNC(K28*$P28,0) -> 1980 | V28: =M28+P28 -> 22 | W28: =N28+Q28 -> 541376 | X28: =IFERROR(W28/$F28,0) -> 1 | AA28: =E28-#REF! -> #REF! | AC28: 120 | AE28: HX0029 | AG28: T | BV28: =HYPERLINK("#일위대가목록!A18","HX0029 →") -> HX0029 → | CB28: 35329 | CC28: 388619 | CD28: 490 | CE28: 5390 | CF28: 34684 | CG28: 381524 | CH28: 155 | CI28: 1705 | CJ28: No.10
A29: ..전나무 제거 | B29: H7.0xW2.0 | C29: 주 | D29: 0 | E29: =G29+I29+K29 -> 0 | F29: =H29+J29+L29 -> 0 | O29: =IFERROR(N29/$F29,0) -> 0 | P29: =D29 -> 0 | Q29: =SUM(S29:U29) -> 0 | R29: =IFERROR(Q29/$F29,0) -> 0 | S29: =TRUNC(G29*$P29,0) -> 0 | T29: =TRUNC(I29*$P29,0) -> 0 | U29: =TRUNC(K29*$P29,0) -> 0 | V29: =M29+P29 -> 0 | W29: =N29+Q29 -> 0 | X29: =IFERROR(W29/$F29,0) -> 0 | AA29: =E29-#REF! -> #REF! | AC29: 130 | AE29: HX0030 | AG29: T | BV29: =HYPERLINK("#일위대가목록!A19","HX0030 →") -> HX0030 → | CB29: 16038 | CC29: 64152 | CD29: 941 | CE29: 3764 | CF29: 14018 | CG29: 56072 | CH29: 1079 | CI29: 4316 | CJ29: No.11
A30: ..전나무 제거 | B30: H7.0xR18 | C30: 주 | D30: 16 | E30: =G30+I30+K30 -> 42303 | F30: =H30+J30+L30 -> 676848 | G30: 640 | H30: =TRUNC(G30*D30,0) -> 10240 | I30: 41457 | J30: =TRUNC(I30*D30,0) -> 663312 | K30: 206 | L30: =TRUNC(K30*D30,0) -> 3296 | O30: =IFERROR(N30/$F30,0) -> 0 | P30: =D30 -> 16 | Q30: =SUM(S30:U30) -> 676848 | R30: =IFERROR(Q30/$F30,0) -> 1 | S30: =TRUNC(G30*$P30,0) -> 10240 | T30: =TRUNC(I30*$P30,0) -> 663312 | U30: =TRUNC(K30*$P30,0) -> 3296 | V30: =M30+P30 -> 16 | W30: =N30+Q30 -> 676848 | X30: =IFERROR(W30/$F30,0) -> 1 | AA30: =E30-#REF! -> #REF! | AC30: 140 | AE30: HX0031 | AG30: T | BV30: =HYPERLINK("#일위대가목록!A20","HX0031 →") -> HX0031 → | CB30: 49228 | CC30: 492280 | CD30: 745 | CE30: 7450 | CF30: 48243 | CG30: 482430 | CH30: 240 | CI30: 2400 | CJ30: No.12
A31: ..전나무 제거 | B31: H5.5xW3.0 | C31: 주 | E31: =G31+I31+K31 -> 0 | F31: =H31+J31+L31 -> 0 | L31: =TRUNC(K31*D31,0) -> 0 | O31: =IFERROR(N31/$F31,0) -> 0 | P31: =D31 -> 0 | Q31: =SUM(S31:U31) -> 0 | R31: =IFERROR(Q31/$F31,0) -> 0 | S31: =TRUNC(G31*$P31,0) -> 0 | T31: =TRUNC(I31*$P31,0) -> 0 | U31: =TRUNC(K31*$P31,0) -> 0 | V31: =M31+P31 -> 0 | W31: =N31+Q31 -> 0 | X31: =IFERROR(W31/$F31,0) -> 0 | AA31: =E31-#REF! -> #REF! | AC31: 150 | AE31: HX0032 | AG31: T | BV31: =HYPERLINK("#일위대가목록!A21","HX0032 →") -> HX0032 → | CB31: 37556 | CC31: 112668 | CD31: 891 | CE31: 2673 | CF31: 36001 | CG31: 108003 | CH31: 664 | CI31: 1992 | CJ31: No.13
A32: ..전나무 제거 | B32: H5.0xR20 | C32: 주 | D32: 7 | E32: =G32+I32+K32 -> 51119 | F32: =H32+J32+L32 -> 357833 | G32: 799 | H32: =TRUNC(G32*D32,0) -> 5593 | I32: 50063 | J32: =TRUNC(I32*D32,0) -> 350441 | K32: 257 | L32: =TRUNC(K32*D32,0) -> 1799 | O32: =IFERROR(N32/$F32,0) -> 0 | P32: =D32 -> 7 | Q32: =SUM(S32:U32) -> 357833 | R32: =IFERROR(Q32/$F32,0) -> 1 | S32: =TRUNC(G32*$P32,0) -> 5593 | T32: =TRUNC(I32*$P32,0) -> 350441 | U32: =TRUNC(K32*$P32,0) -> 1799 | V32: =M32+P32 -> 7 | W32: =N32+Q32 -> 357833 | X32: =IFERROR(W32/$F32,0) -> 1 | AA32: =E32-#REF! -> #REF! | AC32: 170 | AE32: HX0033 | AG32: T | BV32: =HYPERLINK("#일위대가목록!A22","HX0033 →") -> HX0033 → | CB32: 59487 | CC32: 178461 | CD32: 930 | CE32: 2790 | CF32: 58257 | CG32: 174771 | CH32: 300 | CI32: 900 | CJ32: No.14
A33: ..전나무 제거 | B33: H7.0xR26 | C33: 주 | D33: 6 | E33: =G33+I33+K33 -> 103445 | F33: =H33+J33+L33 -> 620670 | G33: 1814 | H33: =TRUNC(G33*D33,0) -> 10884 | I33: 101053 | J33: =TRUNC(I33*D33,0) -> 606318 | K33: 578 | L33: =TRUNC(K33*D33,0) -> 3468 | O33: =IFERROR(N33/$F33,0) -> 0 | P33: =D33 -> 6 | Q33: =SUM(S33:U33) -> 620670 | R33: =IFERROR(Q33/$F33,0) -> 1 | S33: =TRUNC(G33*$P33,0) -> 10884 | T33: =TRUNC(I33*$P33,0) -> 606318 | U33: =TRUNC(K33*$P33,0) -> 3468 | V33: =M33+P33 -> 6 | W33: =N33+Q33 -> 620670 | X33: =IFERROR(W33/$F33,0) -> 1 | AA33: =E33-#REF! -> #REF! | AC33: 170 | AE33: HX0033 | AG33: T | BV33: =HYPERLINK("#일위대가목록!A22","HX0033 →") -> HX0033 → | CB33: 59487 | CC33: 178461 | CD33: 930 | CE33: 2790 | CF33: 58257 | CG33: 174771 | CH33: 300 | CI33: 900 | CJ33: No.14
A34: ..전나무 제거 | B34: H3.5xW1.8 | C34: 주 | D34: 7 | E34: =G34+I34+K34 -> 24759 | F34: =H34+J34+L34 -> 173313 | G34: 329 | H34: =TRUNC(G34*D34,0) -> 2303 | I34: 24306 | J34: =TRUNC(I34*D34,0) -> 170142 | K34: 124 | L34: =TRUNC(K34*D34,0) -> 868 | O34: =IFERROR(N34/$F34,0) -> 0 | P34: =D34 -> 7 | Q34: =SUM(S34:U34) -> 173313 | R34: =IFERROR(Q34/$F34,0) -> 1 | S34: =TRUNC(G34*$P34,0) -> 2303 | T34: =TRUNC(I34*$P34,0) -> 170142 | U34: =TRUNC(K34*$P34,0) -> 868 | V34: =M34+P34 -> 7 | W34: =N34+Q34 -> 173313 | X34: =IFERROR(W34/$F34,0) -> 1 | AA34: =E34-#REF! -> #REF! | AC34: 190 | AE34: HX0034 | AG34: T | BV34: =HYPERLINK("#일위대가목록!A23","HX0034 →") -> HX0034 → | CB34: 28813 | CC34: 172878 | CD34: 384 | CE34: 2304 | CF34: 28284 | CG34: 169704 | CH34: 145 | CI34: 870 | CJ34: No.15
A35: ..전나무 제거 | B35: H3.0xW1.5 | C35: 주 | D35: 13 | E35: =G35+I35+K35 -> 19115 | F35: =H35+J35+L35 -> 248495 | G35: 213 | H35: =TRUNC(G35*D35,0) -> 2769 | I35: 18830 | J35: =TRUNC(I35*D35,0) -> 244790 | K35: 72 | L35: =TRUNC(K35*D35,0) -> 936 | O35: =IFERROR(N35/$F35,0) -> 0 | P35: =D35 -> 13 | Q35: =SUM(S35:U35) -> 248495 | R35: =IFERROR(Q35/$F35,0) -> 1 | S35: =TRUNC(G35*$P35,0) -> 2769 | T35: =TRUNC(I35*$P35,0) -> 244790 | U35: =TRUNC(K35*$P35,0) -> 936 | V35: =M35+P35 -> 13 | W35: =N35+Q35 -> 248495 | X35: =IFERROR(W35/$F35,0) -> 1 | AA35: =E35-#REF! -> #REF! | AC35: 210 | AE35: HX0035 | AG35: T | BV35: =HYPERLINK("#일위대가목록!A24","HX0035 →") -> HX0035 → | CB35: 22244 | CC35: 244684 | CD35: 248 | CE35: 2728 | CF35: 21912 | CG35: 241032 | CH35: 84 | CI35: 924 | CJ35: No.16
A36: ..주목 제거 | B36: H2.5xW2.0 | C36: 주 | D36: 3 | E36: =G36+I36+K36 -> 19013 | F36: =H36+J36+L36 -> 57039 | G36: 195 | H36: =TRUNC(G36*D36,0) -> 585 | I36: 18770 | J36: =TRUNC(I36*D36,0) -> 56310 | K36: 48 | L36: =TRUNC(K36*D36,0) -> 144 | O36: =IFERROR(N36/$F36,0) -> 0 | P36: =D36 -> 3 | Q36: =SUM(S36:U36) -> 57039 | R36: =IFERROR(Q36/$F36,0) -> 1 | S36: =TRUNC(G36*$P36,0) -> 585 | T36: =TRUNC(I36*$P36,0) -> 56310 | U36: =TRUNC(K36*$P36,0) -> 144 | V36: =M36+P36 -> 3 | W36: =N36+Q36 -> 57039 | X36: =IFERROR(W36/$F36,0) -> 1 | AA36: =E36-#REF! -> #REF! | AC36: 230 | AE36: HX0036 | AG36: T | BV36: =HYPERLINK("#일위대가목록!A25","HX0036 →") -> HX0036 → | CB36: 22126 | CC36: 66378 | CD36: 227 | CE36: 681 | CF36: 21842 | CG36: 65526 | CH36: 57 | CI36: 171 | CJ36: No.17
A37: ..주목 제거 | B37: H2.5xW1.2 | C37: 주 | D37: 2 | E37: =G37+I37+K37 -> 9854 | F37: =H37+J37+L37 -> 19708 | G37: 102 | H37: =TRUNC(G37*D37,0) -> 204 | I37: 9722 | J37: =TRUNC(I37*D37,0) -> 19444 | K37: 30 | L37: =TRUNC(K37*D37,0) -> 60 | O37: =IFERROR(N37/$F37,0) -> 0 | P37: =D37 -> 2 | Q37: =SUM(S37:U37) -> 19708 | R37: =IFERROR(Q37/$F37,0) -> 1 | S37: =TRUNC(G37*$P37,0) -> 204 | T37: =TRUNC(I37*$P37,0) -> 19444 | U37: =TRUNC(K37*$P37,0) -> 60 | V37: =M37+P37 -> 2 | W37: =N37+Q37 -> 19708 | X37: =IFERROR(W37/$F37,0) -> 1 | AA37: =E37-#REF! -> #REF! | AC37: 250 | AE37: HX0037 | AG37: T | BV37: =HYPERLINK("#일위대가목록!A26","HX0037 →") -> HX0037 → | CB37: 11468 | CC37: 22936 | CD37: 119 | CE37: 238 | CF37: 11314 | CG37: 22628 | CH37: 35 | CI37: 70 | CJ37: No.18
A38: ..소나무묘목 제거 | B38: H0.8xR3 | C38: 주 | D38: 100 | E38: =G38+I38+K38 -> 622 | F38: =H38+J38+L38 -> 62200 | G38: 8 | H38: =TRUNC(G38*D38,0) -> 800 | I38: 603 | J38: =TRUNC(I38*D38,0) -> 60300 | K38: 11 | L38: =TRUNC(K38*D38,0) -> 1100 | O38: =IFERROR(N38/$F38,0) -> 0 | Q38: =SUM(S38:U38) -> 0 | R38: =IFERROR(Q38/$F38,0) -> 0 | S38: =TRUNC(G38*$P38,0) -> 0 | T38: =TRUNC(I38*$P38,0) -> 0 | U38: =TRUNC(K38*$P38,0) -> 0 | V38: =M38+P38 -> 0 | W38: =N38+Q38 -> 0 | X38: =IFERROR(W38/$F38,0) -> 0 | AA38: =E38-#REF! -> #REF! | AC38: 270 | AE38: HX0038 | AG38: T | BV38: =HYPERLINK("#일위대가목록!A27","HX0038 →") -> HX0038 → | CB38: 725 | CC38: 72500 | CD38: 10 | CE38: 1000 | CF38: 702 | CG38: 70200 | CH38: 13 | CI38: 1300 | CJ38: No.19
A39: ..가중나무 제거 | B39: H3.5xB6 | C39: 주 | D39: 9 | E39: =G39+I39+K39 -> 9854 | F39: =H39+J39+L39 -> 88686 | G39: 102 | H39: =TRUNC(G39*D39,0) -> 918 | I39: 9722 | J39: =TRUNC(I39*D39,0) -> 87498 | K39: 30 | L39: =TRUNC(K39*D39,0) -> 270 | O39: =IFERROR(N39/$F39,0) -> 0 | Q39: =SUM(S39:U39) -> 0 | R39: =IFERROR(Q39/$F39,0) -> 0 | S39: =TRUNC(G39*$P39,0) -> 0 | T39: =TRUNC(I39*$P39,0) -> 0 | U39: =TRUNC(K39*$P39,0) -> 0 | V39: =M39+P39 -> 0 | W39: =N39+Q39 -> 0 | X39: =IFERROR(W39/$F39,0) -> 0 | AA39: =E39-#REF! -> #REF! | AC39: 330 | AE39: HX0039 | AG39: T | BV39: =HYPERLINK("#일위대가목록!A28","HX0039 →") -> HX0039 → | CB39: 11468 | CC39: 103212 | CD39: 119 | CE39: 1071 | CF39: 11314 | CG39: 101826 | CH39: 35 | CI39: 315 | CJ39: No.20
A40: ..감나무 제거 | B40: H2.0xR4 | C40: 주 | D40: 2 | E40: =G40+I40+K40 -> 6926 | F40: =H40+J40+L40 -> 13852 | G40: 57 | H40: =TRUNC(G40*D40,0) -> 114 | I40: 6849 | J40: =TRUNC(I40*D40,0) -> 13698 | K40: 20 | L40: =TRUNC(K40*D40,0) -> 40 | O40: =IFERROR(N40/$F40,0) -> 0 | Q40: =SUM(S40:U40) -> 0 | R40: =IFERROR(Q40/$F40,0) -> 0 | S40: =TRUNC(G40*$P40,0) -> 0 | T40: =TRUNC(I40*$P40,0) -> 0 | U40: =TRUNC(K40*$P40,0) -> 0 | V40: =M40+P40 -> 0 | W40: =N40+Q40 -> 0 | X40: =IFERROR(W40/$F40,0) -> 0 | AA40: =E40-#REF! -> #REF! | AC40: 350 | AE40: HX0040 | AG40: T | BV40: =HYPERLINK("#일위대가목록!A29","HX0040 →") -> HX0040 → | CB40: 8062 | CC40: 16124 | CD40: 67 | CE40: 134 | CF40: 7971 | CG40: 15942 | CH40: 24 | CI40: 48 | CJ40: No.21
...

Sheet 일위대가목록 (신규)
A1: 일위대가목록(신규)
A2: 공 종 명 | B2: 규 격 | C2: 수 량 | D2: 단 위 | E2: 합 계 | F2: 재 료 비 | H2: 노 무 비 | J2: 경 비 | K2: 비 고 | V2: 재료비 | W2: 노무비 | X2: 경 비 | Y2: 합 계 | AA2: 비교검토
A3: ='일위대가_호표(신규)'!A752 -> No.1 수목이식(굴취,가식,정식) | B3: ='일위대가_호표(신규)'!B752 -> R38 | C3: ='일위대가_호표(신규)'!C752 -> 1 | D3: ='일위대가_호표(신규)'!D752 -> 주 | E3: =F3+H3+J3 -> 1471634 | F3: ='일위대가_호표(신규)'!H759 -> 156588 | H3: ='일위대가_호표(신규)'!J759 -> 1044292 | J3: ='일위대가_호표(신규)'!L759 -> 270754 | M3: NX1510 | N3: F | V3: 1054 | W3: 3467 | X3: 1338 | Y3: 5859 | AA3: =EXACT($E3,$Y3) -> FALSE | AC3: =HYPERLINK("#일위대가_산근!A4","NX1510 →") -> NX1510 →
A4: ='일위대가_호표(신규)'!A761 -> No.2 수목이식(굴취,가식,정식) | B4: ='일위대가_호표(신규)'!B761 -> R30 | C4: ='일위대가_호표(신규)'!C761 -> 1 | D4: ='일위대가_호표(신규)'!D761 -> 주 | E4: =F4+H4+J4 -> 1464617 | F4: ='일위대가_호표(신규)'!H768 -> 149571 | H4: ='일위대가_호표(신규)'!J768 -> 1044292 | J4: ='일위대가_호표(신규)'!L768 -> 270754 | M4: NX1510 | N4: F | V4: 1054 | W4: 3467 | X4: 1338 | Y4: 5859 | AA4: =EXACT($E4,$Y4) -> FALSE | AC4: =HYPERLINK("#일위대가_산근!A4","NX1510 →") -> NX1510 →
A5: ='일위대가_호표(신규)'!A770 -> No.3 수목이식(굴취,가식,정식) | B5: ='일위대가_호표(신규)'!B770 -> R22 | C5: ='일위대가_호표(신규)'!C770 -> 1 | D5: ='일위대가_호표(신규)'!D770 -> 주 | E5: =F5+H5+J5 -> 1065463 | F5: ='일위대가_호표(신규)'!H777 -> 107248 | H5: ='일위대가_호표(신규)'!J777 -> 773548 | J5: ='일위대가_호표(신규)'!L777 -> 184667 | M5: N1070 | N5: F | V5: 300 | W5: 4328 | X5: 381 | Y5: 5009 | AA5: =EXACT($E5,$Y5) -> FALSE | AC5: =HYPERLINK("#일위대가_산근!A27","N1070 →") -> N1070 →
A6: ='일위대가_호표(신규)'!A779 -> No.4 수목이식(굴취,가식,정식) | B6: ='일위대가_호표(신규)'!B779 -> R20 | C6: ='일위대가_호표(신규)'!C779 -> 1 | D6: ='일위대가_호표(신규)'!D779 -> 주 | E6: =F6+H6+J6 -> 1064751 | F6: ='일위대가_호표(신규)'!H786 -> 106536 | H6: ='일위대가_호표(신규)'!J786 -> 773548 | J6: ='일위대가_호표(신규)'!L786 -> 184667 | M6: N0860 | N6: F | V6: 285 | W6: 940 | X6: 363 | Y6: 1588 | AA6: =EXACT($E6,$Y6) -> FALSE | AC6: =HYPERLINK("#일위대가_산근!A58","N0860 →") -> N0860 →
A7: ='일위대가_호표(신규)'!A788 -> No.5 수목이식(굴취,가식,정식) | B7: ='일위대가_호표(신규)'!B788 -> R15 | C7: ='일위대가_호표(신규)'!C788 -> 1 | D7: ='일위대가_호표(신규)'!D788 -> 주 | E7: =F7+H7+J7 -> 515421 | F7: ='일위대가_호표(신규)'!H795 -> 60715 | H7: ='일위대가_호표(신규)'!J795 -> 412770 | J7: ='일위대가_호표(신규)'!L795 -> 41936 | M7: N1010 | N7: F | V7: 445 | W7: 6329 | X7: 370 | Y7: 7144 | AA7: =EXACT($E7,$Y7) -> FALSE | AC7: =HYPERLINK("#일위대가_산근!A83","N1010 →") -> N1010 →
A8: ='일위대가_호표(신규)'!A1141 -> No.6 휴게데크A-1 | B8: ='일위대가_호표(신규)'!B1141 -> A=38.0m2 | C8: ='일위대가_호표(신규)'!C1141 -> 1 | D8: ='일위대가_호표(신규)'!D1141 -> 개소 | E8: =F8+H8+J8 -> 6021596 | F8: ='일위대가_호표(신규)'!H1158 -> 1407546 | H8: ='일위대가_호표(신규)'!J1158 -> 4546159 | J8: ='일위대가_호표(신규)'!L1158 -> 67891 | M8: N0800 | N8: F | V8: 20 | W8: 386 | X8: 6 | Y8: 412 | AA8: =EXACT($E8,$Y8) -> FALSE | AC8: =HYPERLINK("#일위대가_산근!A116","N0800 →") -> N0800 →
A9: ='일위대가_호표(신규)'!A1582 -> No.7 조경 유용석 쌓기 및 놓기 | B9: ='일위대가_호표(신규)'!B1582 | C9: ='일위대가_호표(신규)'!C1582 -> 1 | D9: ='일위대가_호표(신규)'!D1582 -> ton | E9: =F9+H9+J9 -> 118742 | F9: ='일위대가_호표(신규)'!H1587 -> 9291 | H9: ='일위대가_호표(신규)'!J1587 -> 97656 | J9: ='일위대가_호표(신규)'!L1587 -> 11795 | M9: N0300 | N9: F | V9: 1106 | W9: 8824 | X9: 1041 | Y9: 10971 | AA9: =EXACT($E9,$Y9) -> FALSE | AC9: =HYPERLINK("#일위대가_산근!A132","N0300 →") -> N0300 →
A10: ='일위대가_호표(신규)'!A1831 -> No.8 계단A | B10: ='일위대가_호표(신규)'!B1831 -> W3000x12단, H150 | C10: ='일위대가_호표(신규)'!C1831 -> 1 | D10: ='일위대가_호표(신규)'!D1831 -> 개소 | E10: =F10+H10+J10 -> 4845039 | F10: ='일위대가_호표(신규)'!H1850 -> 2704290 | H10: ='일위대가_호표(신규)'!J1850 -> 1283848 | J10: ='일위대가_호표(신규)'!L1850 -> 856901 | M10: HX0020 | N10: T | V10: 114 | W10: 11314 | X10: 35 | Y10: 11463 | AA10: =EXACT($E10,$Y10) -> FALSE | AC10: =HYPERLINK("#일위대가_호표!A4","HX0020 →") -> HX0020 →
A11: ='일위대가_호표(신규)'!A1852 -> No.9 계단B | B11: ='일위대가_호표(신규)'!B1852 -> W1500x18단, H150 | C11: ='일위대가_호표(신규)'!C1852 -> 1 | D11: ='일위대가_호표(신규)'!D1852 -> 개소 | E11: =F11+H11+J11 -> 3382505 | F11: ='일위대가_호표(신규)'!H1871 -> 1960439 | H11: ='일위대가_호표(신규)'!J1871 -> 820038 | J11: ='일위대가_호표(신규)'!L1871 -> 602028 | M11: HX0021 | N11: T | V11: 1547 | W11: 89527 | X11: 550 | Y11: 91624 | AA11: =EXACT($E11,$Y11) -> FALSE | AC11: =HYPERLINK("#일위대가_호표!A8","HX0021 →") -> HX0021 →
A12: ='일위대가_호표(신규)'!A1873 -> No.10 계단C | B12: ='일위대가_호표(신규)'!B1873 -> W2000x4단, H150 | C12: ='일위대가_호표(신규)'!C1873 -> 1 | D12: ='일위대가_호표(신규)'!D1873 -> 개소 | E12: =F12+H12+J12 -> 817520 | F12: ='일위대가_호표(신규)'!H1890 -> 533331 | H12: ='일위대가_호표(신규)'!J1890 -> 129311 | J12: ='일위대가_호표(신규)'!L1890 -> 154878 | M12: HX0022 | N12: T | V12: 2970 | W12: 166977 | X12: 952 | Y12: 170899 | AA12: =EXACT($E12,$Y12) -> FALSE | AC12: =HYPERLINK("#일위대가_호표!A12","HX0022 →") -> HX0022 →
A13: ='일위대가_호표(신규)'!A1892 -> No.11 계단D | B13: ='일위대가_호표(신규)'!B1892 -> W2000x11단, H150 | C13: ='일위대가_호표(신규)'!C1892 -> 1 | D13: ='일위대가_호표(신규)'!D1892 -> 개소 | E13: =F13+H13+J13 -> 2645092 | F13: ='일위대가_호표(신규)'!H1911 -> 1568377 | H13: ='일위대가_호표(신규)'!J1911 -> 597024 | J13: ='일위대가_호표(신규)'!L1911 -> 479691 | M13: HX0023 | N13: T | V13: 713 | W13: 48243 | X13: 240 | Y13: 49196 | AA13: =EXACT($E13,$Y13) -> FALSE | AC13: =HYPERLINK("#일위대가_호표!A16","HX0023 →") -> HX0023 →
A14: ='일위대가_호표(신규)'!A1913 -> No.12 데크계단A | B14: ='일위대가_호표(신규)'!B1913 -> W2000xH150 | C14: ='일위대가_호표(신규)'!C1913 -> 1 | D14: ='일위대가_호표(신규)'!D1913 -> 개소 | E14: =F14+H14+J14 -> 4795258 | F14: ='일위대가_호표(신규)'!H1932 -> 1034318 | H14: ='일위대가_호표(신규)'!J1932 -> 3699996 | J14: ='일위대가_호표(신규)'!L1932 -> 60944 | M14: HX0024 | N14: T | V14: 1516 | W14: 89423 | X14: 510 | Y14: 91449 | AA14: =EXACT($E14,$Y14) -> FALSE | AC14: =HYPERLINK("#일위대가_호표!A20","HX0024 →") -> HX0024 →
A15: ='일위대가_호표(신규)'!A1934 -> No.13 데크계단B | B15: ='일위대가_호표(신규)'!B1934 -> W1500xH150 | C15: ='일위대가_호표(신규)'!C1934 -> 1 | D15: ='일위대가_호표(신규)'!D1934 -> 개소 | E15: =F15+H15+J15 -> 4079250 | F15: ='일위대가_호표(신규)'!H1953 -> 900792 | H15: ='일위대가_호표(신규)'!J1953 -> 3124391 | J15: ='일위대가_호표(신규)'!L1953 -> 54067 | M15: HX0025 | N15: T | V15: 933 | W15: 58396 | X15: 354 | Y15: 59683 | AA15: =EXACT($E15,$Y15) -> FALSE | AC15: =HYPERLINK("#일위대가_호표!A24","HX0025 →") -> HX0025 →
A16: ='일위대가_호표(신규)'!A1955 -> No.14 데크계단C | B16: ='일위대가_호표(신규)'!B1955 -> W2000xH150 | C16: ='일위대가_호표(신규)'!C1955 -> 1 | D16: ='일위대가_호표(신규)'!D1955 -> 개소 | E16: =F16+H16+J16 -> 5469058 | F16: ='일위대가_호표(신규)'!H1974 -> 1183819 | H16: ='일위대가_호표(신규)'!J1974 -> 4215342 | J16: ='일위대가_호표(신규)'!L1974 -> 69897 | M16: HX0026 | N16: T | V16: 891 | W16: 58257 | X16: 300 | Y16: 59448 | AA16: =EXACT($E16,$Y16) -> FALSE | AC16: =HYPERLINK("#일위대가_호표!A28","HX0026 →") -> HX0026 →
A17: ='일위대가_호표(신규)'!A1976 -> No.15 데크계단D | B17: ='일위대가_호표(신규)'!B1976 -> W1500xH150 | C17: ='일위대가_호표(신규)'!C1976 -> 1 | D17: ='일위대가_호표(신규)'!D1976 -> 개소 | E17: =F17+H17+J17 -> 1928415 | F17: ='일위대가_호표(신규)'!H1995 -> 409658 | H17: ='일위대가_호표(신규)'!J1995 -> 1493730 | J17: ='일위대가_호표(신규)'!L1995 -> 25027 | M17: HX0027 | N17: T | V17: 469 | W17: 34684 | X17: 155 | Y17: 35308 | AA17: =EXACT($E17,$Y17) -> FALSE | AC17: =HYPERLINK("#일위대가_호표!A32","HX0027 →") -> HX0027 →
A18: ='일위대가_호표(신규)'!A1997 -> No.16 데크계단E | B18: ='일위대가_호표(신규)'!B1997 -> W2000xH150 | C18: ='일위대가_호표(신규)'!C1997 -> 1 | D18: ='일위대가_호표(신규)'!D1997 -> 개소 | E18: =F18+H18+J18 -> 1312622 | F18: ='일위대가_호표(신규)'!H2016 -> 280532 | H18: ='일위대가_호표(신규)'!J2016 -> 1014857 | J18: ='일위대가_호표(신규)'!L2016 -> 17233 | M18: HX0028 | N18: T | V18: 713 | W18: 48243 | X18: 240 | Y18: 49196 | AA18: =EXACT($E18,$Y18) -> FALSE | AC18: =HYPERLINK("#일위대가_호표!A36","HX0028 →") -> HX0028 →
A19: ='일위대가_호표(신규)'!A2018 -> No.17 데크계단F | B19: ='일위대가_호표(신규)'!B2018 -> W1500xH150 | C19: ='일위대가_호표(신규)'!C2018 -> 1 | D19: ='일위대가_호표(신규)'!D2018 -> 개소 | E19: =F19+H19+J19 -> 3851067 | F19: ='일위대가_호표(신규)'!H2037 -> 840643 | H19: ='일위대가_호표(신규)'!J2037 -> 2958818 | J19: ='일위대가_호표(신규)'!L2037 -> 51606 | M19: HX0029 | N19: T | V19: 469 | W19: 34684 | X19: 155 | Y19: 35308 | AA19: =EXACT($E19,$Y19) -> FALSE | AC19: =HYPERLINK("#일위대가_호표!A40","HX0029 →") -> HX0029 →
A20: ='일위대가_호표(신규)'!A2039 -> No.18 데크계단G | B20: ='일위대가_호표(신규)'!B2039 -> W1500xH150 | C20: ='일위대가_호표(신규)'!C2039 -> 1 | D20: ='일위대가_호표(신규)'!D2039 -> 개소 | E20: =F20+H20+J20 -> 712852 | F20: ='일위대가_호표(신규)'!H2058 -> 157522 | H20: ='일위대가_호표(신규)'!J2058 -> 545409 | J20: ='일위대가_호표(신규)'!L2058 -> 9921 | M20: HX0030 | N20: T | V20: 936 | W20: 14018 | X20: 1079 | Y20: 16033 | AA20: =EXACT($E20,$Y20) -> FALSE | AC20: =HYPERLINK("#일위대가_호표!A44","HX0030 →") -> HX0030 →
A21: ='일위대가_호표(신규)'!A2067 -> No.19 계류 | B21: ='일위대가_호표(신규)'!B2067 -> A=180.0m2 | C21: ='일위대가_호표(신규)'!C2067 -> 1 | D21: ='일위대가_호표(신규)'!D2067 -> 개소 | E21: =F21+H21+J21 -> 40891860 | F21: ='일위대가_호표(신규)'!H2083 -> 16257101 | H21: ='일위대가_호표(신규)'!J2083 -> 21248077 | J21: ='일위대가_호표(신규)'!L2083 -> 3386682 | M21: HX0031 | N21: T | V21: 713 | W21: 48243 | X21: 240 | Y21: 49196 | AA21: =EXACT($E21,$Y21) -> FALSE | AC21: =HYPERLINK("#일위대가_호표!A48","HX0031 →") -> HX0031 →
A22: ='일위대가_호표(신규)'!A2102 -> No.20 휴게데크C | B22: ='일위대가_호표(신규)'!B2102 -> A=84.0m2 | C22: ='일위대가_호표(신규)'!C2102 -> 1 | D22: ='일위대가_호표(신규)'!D2102 -> 개소 | E22: =F22+H22+J22 -> 13940815 | F22: ='일위대가_호표(신규)'!H2123 -> 3116792 | H22: ='일위대가_호표(신규)'!J2123 -> 10667291 | J22: ='일위대가_호표(신규)'!L2123 -> 156732 | M22: HX0032 | N22: T | V22: 870 | W22: 36001 | X22: 664 | Y22: 37535 | AA22: =EXACT($E22,$Y22) -> FALSE | AC22: =HYPERLINK("#일위대가_호표!A52","HX0032 →") -> HX0032 →
A23: ='일위대가_호표(신규)'!A2137 -> No.21 점자블럭(점형) | B23: ='일위대가_호표(신규)'!B2137 -> T60 | C23: ='일위대가_호표(신규)'!C2137 -> 1 | D23: ='일위대가_호표(신규)'!D2137 -> EA | E23: =F23+H23+J23 -> 6234 | F23: ='일위대가_호표(신규)'!H2146 -> 4768 | H23: ='일위대가_호표(신규)'!J2146 -> 766 | J23: ='일위대가_호표(신규)'!L2146 -> 700 | M23: HX0033 | N23: T | V23: 891 | W23: 58257 | X23: 300 | Y23: 59448 | AA23: =EXACT($E23,$Y23) -> FALSE | AC23: =HYPERLINK("#일위대가_호표!A56","HX0033 →") -> HX0033 →
A24: ='일위대가_호표(신규)'!A2148 -> No.22 점자블럭(선형) | B24: ='일위대가_호표(신규)'!B2148 -> T60 | C24: ='일위대가_호표(신규)'!C2148 -> 1 | D24: ='일위대가_호표(신규)'!D2148 -> EA | E24: =F24+H24+J24 -> 6234 | F24: ='일위대가_호표(신규)'!H2157 -> 4768 | H24: ='일위대가_호표(신규)'!J2157 -> 766 | J24: ='일위대가_호표(신규)'!L2157 -> 700 | M24: HX0034 | N24: T | V24: 369 | W24: 28284 | X24: 145 | Y24: 28798 | AA24: =EXACT($E24,$Y24) -> FALSE | AC24: =HYPERLINK("#일위대가_호표!A60","HX0034 →") -> HX0034 →
A25: ='일위대가_호표(신규)'!A2159 -> No.23 낙엽수 조형전정(1회) | B25: ='일위대가_호표(신규)'!B2159 -> B11(R13)미만 | C25: 1 | D25: 주 | E25: =F25+H25+J25 -> 24008 | F25: ='일위대가_호표(신규)'!H2163 -> 0 | H25: ='일위대가_호표(신규)'!J2163 -> 23538 | J25: ='일위대가_호표(신규)'!L2163 -> 470 | M25: HX0035 | N25: T | V25: 238 | W25: 21912 | X25: 84 | Y25: 22234 | AA25: =EXACT($E25,$Y25) -> FALSE | AC25: =HYPERLINK("#일위대가_호표!A64","HX0035 →") -> HX0035 →
A26: ='일위대가_호표(신규)'!A2165 -> No.24 낙엽수 조형전정(1회) | B26: ='일위대가_호표(신규)'!B2165 -> B11~21미만(R13~25미만) | C26: 1 | D26: 주 | E26: =F26+H26+J26 -> 31009 | F26: ='일위대가_호표(신규)'!H2170 -> 1118 | H26: ='일위대가_호표(신규)'!J2170 -> 27414 | J26: ='일위대가_호표(신규)'!L2170 -> 2477
A27: ='일위대가_호표(신규)'!A2172 -> No.25 낙엽수 조형전정(1회) | B27: ='일위대가_호표(신규)'!B2172 -> B21~31미만(R25~37미만) | C27: 1 | D27: 주 | E27: =F27+H27+J27 -> 49825 | F27: ='일위대가_호표(신규)'!H2177 -> 1721 | H27: ='일위대가_호표(신규)'!J2177 -> 44251 | J27: ='일위대가_호표(신규)'!L2177 -> 3853
A28: ='일위대가_호표(신규)'!A2179 -> No.26 낙엽수 조형전정(1회) | B28: ='일위대가_호표(신규)'!B2179 -> B31~41미만(R37~49미만) | C28: 1 | D28: 주 | E28: =F28+H28+J28 -> 83388 | F28: ='일위대가_호표(신규)'!H2184 -> 2882 | H28: ='일위대가_호표(신규)'!J2184 -> 74054 | J28: ='일위대가_호표(신규)'!L2184 -> 6452
A29: ='일위대가_호표(신규)'!A2186 -> No.27 낙엽수 조형전정(1회) | B29: ='일위대가_호표(신규)'!B2186 -> B41~51미만(R49~61미만) | C29: 1 | D29: 주 | E29: =F29+H29+J29 -> 125318 | F29: ='일위대가_호표(신규)'!H2191 -> 4302 | H29: ='일위대가_호표(신규)'!J2191 -> 111369 | J29: ='일위대가_호표(신규)'!L2191 -> 9647
A30: ='일위대가_호표(신규)'!A2193 -> No.28 상록수 조형전정(1회) | B30: ='일위대가_호표(신규)'!B2193 -> B11(R13)미만 | C30: 1 | D30: 주 | E30: =F30+H30+J30 -> 19625 | F30: ='일위대가_호표(신규)'!H2197 -> 0 | H30: ='일위대가_호표(신규)'!J2197 -> 19625 | J30: ='일위대가_호표(신규)'!L2197 -> 0
A31: ='일위대가_호표(신규)'!A2199 -> No.29 상록수 조형전정(1회) | B31: ='일위대가_호표(신규)'!B2199 -> B11~21미만(R13~25미만) | C31: 1 | D31: 주 | E31: =F31+H31+J31 -> 28779 | F31: ='일위대가_호표(신규)'!H2204 -> 946 | H31: ='일위대가_호표(신규)'!J2204 -> 25687 | J31: ='일위대가_호표(신규)'!L2204 -> 2146
A32: ='일위대가_호표(신규)'!A2206 -> No.30 상록수 조형전정(1회) | B32: ='일위대가_호표(신규)'!B2206 -> B21~31미만(R25~37미만) | C32: 1 | D32: 주 | E32: =F32+H32+J32 -> 43528 | F32: ='일위대가_호표(신규)'!H2211 -> 1505 | H32: ='일위대가_호표(신규)'!J2211 -> 38653 | J32: ='일위대가_호표(신규)'!L2211 -> 3370 | M32: HX0036 | N32: T | V32: 217 | W32: 21842 | X32: 57 | Y32: 22116 | AA32: =EXACT($E32,$Y32) -> FALSE | AC32: =HYPERLINK("#일위대가_호표!A68","HX0036 →") -> HX0036 →
A33: ='일위대가_호표(신규)'!A2213 -> No.31 상록수 조형전정(1회) | B33: ='일위대가_호표(신규)'!B2213 -> B31~41미만(R37~49미만) | C33: 1 | D33: 주 | E33: =F33+H33+J33 -> 70312 | F33: ='일위대가_호표(신규)'!H2218 -> 2452 | H33: ='일위대가_호표(신규)'!J2218 -> 62383 | J33: ='일위대가_호표(신규)'!L2218 -> 5477 | M33: HX0037 | N33: T | V33: 114 | W33: 11314 | X33: 35 | Y33: 11463 | AA33: =EXACT($E33,$Y33) -> FALSE | AC33: =HYPERLINK("#일위대가_호표!A72","HX0037 →") -> HX0037 →

Sheet 일위대가_호표(신규)
A1: 신규 일위대가_호표
A2: 공 종 명 | B2: 규 격 | C2: 수량 | D2: 단위 | E2: 합 계 | G2: 재 료 비 | I2: 노 무 비 | K2: 경 비 | M2: 비 고
E3: 단 가 | F3: 금 액 | G3: 단 가 | H3: 금 액 | I3: 단 가 | J3: 금 액 | K3: 단 가 | L3: 금 액 | S3: 할 증 | T3: 화폐변환 | U3: OP값 | V3: EQ | W3: LA | X3: MA | Y3: 금액계상
A4: No.1 소나무 제거 | B4: H8.0xW3.0xR8 | C4: 1 | D4: 주 | F4: =H4+J4+L4 -> 11468 | H4: =TRUNC(H5+H6,0) -> 119 | J4: =TRUNC(J5+J6,0) -> 11314 | L4: =TRUNC(L5+L6,0) -> 35 | O4: HX0020
A5: 벌목 및 제근 | B5: B7(R8) | C5: 1 | D5: 주 | E5: =G5+I5+K5 -> 11411 | F5: =H5+J5+L5 -> 11411 | G5: =일위대가목록!F203 -> 109 | H5: =TRUNC(G5*C5,1) -> 109 | I5: =일위대가목록!H203 -> 11280 | J5: =TRUNC(I5*C5,1) -> 11280 | K5: =일위대가목록!J203 -> 22 | L5: =TRUNC(K5*C5,1) -> 22 | P5: 10 | R5: NT1015 | T5: T | BI5: =HYPERLINK("#일위대가목록!A198","NT1015 →") -> NT1015 →
A6: 폐기물집적 및 상차 | B6: BH0.6m3 | C6: 0.01 | D6: m3 | E6: =G6+I6+K6 -> 5859 | F6: =H6+J6+L6 -> 58.4 | G6: =일위대가목록!F3 -> 1054 | H6: =TRUNC(G6*C6,1) -> 10.5 | I6: =일위대가목록!H3 -> 3467 | J6: =TRUNC(I6*C6,1) -> 34.6 | K6: =일위대가목록!J3 -> 1338 | L6: =TRUNC(K6*C6,1) -> 13.3 | P6: 20 | R6: NX1510 | T6: F | BI6: =HYPERLINK("#일위대가목록!A3","NX1510 →") -> NX1510 →
A8: No.2 소나무 제거 | B8: H5.0xW3.0xR25 | C8: 1 | D8: 주 | F8: =H8+J8+L8 -> 91691 | H8: =TRUNC(H9+H10,0) -> 1614 | J8: =TRUNC(J9+J10,0) -> 89527 | L8: =TRUNC(L9+L10,0) -> 550 | O8: HX0021
A9: 벌목 및 제근 | B9: B20(R24~25) | C9: 1 | D9: 주 | E9: =G9+I9+K9 -> 90521 | F9: =H9+J9+L9 -> 90521 | G9: =일위대가목록!F204 -> 1404 | H9: =TRUNC(G9*C9,1) -> 1404 | I9: =일위대가목록!H204 -> 88834 | J9: =TRUNC(I9*C9,1) -> 88834 | K9: =일위대가목록!J204 -> 283 | L9: =TRUNC(K9*C9,1) -> 283 | P9: 10 | R9: NT1060 | T9: T | BI9: =HYPERLINK("#일위대가목록!A199","NT1060 →") -> NT1060 →
A10: 폐기물집적 및 상차 | B10: BH0.6m3 | C10: 0.2 | D10: m3 | E10: =G10+I10+K10 -> 5859 | F10: =H10+J10+L10 -> 1171.8 | G10: =일위대가목록!F3 -> 1054 | H10: =TRUNC(G10*C10,1) -> 210.8 | I10: =일위대가목록!H3 -> 3467 | J10: =TRUNC(I10*C10,1) -> 693.4 | K10: =일위대가목록!J3 -> 1338 | L10: =TRUNC(K10*C10,1) -> 267.6 | P10: 20 | R10: NX1510 | T10: F | BI10: =HYPERLINK("#일위대가목록!A3","NX1510 →") -> NX1510 →
A12: No.3 스트로브잣나무 제거 | B12: H10.0xR30 | C12: 1 | D12: 주 | F12: =H12+J12+L12 -> 171033 | H12: =TRUNC(H13+H14,0) -> 3104 | J12: =TRUNC(J13+J14,0) -> 166977 | L12: =TRUNC(L13+L14,0) -> 952 | O12: HX0022
A13: 벌목 및 제근 | B13: B26(R30) | C13: 1 | D13: 주 | E13: =G13+I13+K13 -> 169335 | F13: =H13+J13+L13 -> 169335 | G13: =일위대가목록!F205 -> 2799 | H13: =TRUNC(G13*C13,1) -> 2799 | I13: =일위대가목록!H205 -> 165972 | J13: =TRUNC(I13*C13,1) -> 165972 | K13: =일위대가목록!J205 -> 564 | L13: =TRUNC(K13*C13,1) -> 564 | P13: 10 | R13: NT1080 | T13: T | BI13: =HYPERLINK("#일위대가목록!A200","NT1080 →") -> NT1080 →
A14: 폐기물집적 및 상차 | B14: BH0.6m3 | C14: 0.29 | D14: m3 | E14: =G14+I14+K14 -> 5859 | F14: =H14+J14+L14 -> 1699 | G14: =일위대가목록!F3 -> 1054 | H14: =TRUNC(G14*C14,1) -> 305.6 | I14: =일위대가목록!H3 -> 3467 | J14: =TRUNC(I14*C14,1) -> 1005.4 | K14: =일위대가목록!J3 -> 1338 | L14: =TRUNC(K14*C14,1) -> 388 | P14: 20 | R14: NX1510 | T14: F | BI14: =HYPERLINK("#일위대가목록!A3","NX1510 →") -> NX1510 →
A16: No.4 스트로브잣나무 제거 | B16: H8.0xR18 | C16: 1 | D16: 주 | F16: =H16+J16+L16 -> 49228 | H16: =TRUNC(H17+H18,0) -> 745 | J16: =TRUNC(J17+J18,0) -> 48243 | L16: =TRUNC(L17+L18,0) -> 240 | O16: HX0023
A17: 벌목 및 제근 | B17: B14(R17~18) | C17: 1 | D17: 주 | E17: =G17+I17+K17 -> 48760 | F17: =H17+J17+L17 -> 48760 | G17: =일위대가목록!F206 -> 661 | H17: =TRUNC(G17*C17,1) -> 661 | I17: =일위대가목록!H206 -> 47966 | J17: =TRUNC(I17*C17,1) -> 47966 | K17: =일위대가목록!J206 -> 133 | L17: =TRUNC(K17*C17,1) -> 133 | P17: 10 | R17: NT1045 | T17: T | BI17: =HYPERLINK("#일위대가목록!A201","NT1045 →") -> NT1045 →
A18: 폐기물집적 및 상차 | B18: BH0.6m3 | C18: 0.08 | D18: m3 | E18: =G18+I18+K18 -> 5859 | F18: =H18+J18+L18 -> 468.6 | G18: =일위대가목록!F3 -> 1054 | H18: =TRUNC(G18*C18,1) -> 84.3 | I18: =일위대가목록!H3 -> 3467 | J18: =TRUNC(I18*C18,1) -> 277.3 | K18: =일위대가목록!J3 -> 1338 | L18: =TRUNC(K18*C18,1) -> 107 | P18: 20 | R18: NX1510 | T18: F | BI18: =HYPERLINK("#일위대가목록!A3","NX1510 →") -> NX1510 →
A20: No.5 스트로브잣나무 제거 | B20: H7.0xR24 | C20: 1 | D20: 주 | F20: =H20+J20+L20 -> 91516 | H20: =TRUNC(H21+H22,0) -> 1583 | J20: =TRUNC(J21+J22,0) -> 89423 | L20: =TRUNC(L21+L22,0) -> 510 | O20: HX0024
A21: 벌목 및 제근 | B21: B20(R24) | C21: 1 | D21: 주 | E21: =G21+I21+K21 -> 90521 | F21: =H21+J21+L21 -> 90521 | G21: =일위대가목록!F204 -> 1404 | H21: =TRUNC(G21*C21,1) -> 1404 | I21: =일위대가목록!H204 -> 88834 | J21: =TRUNC(I21*C21,1) -> 88834 | K21: =일위대가목록!J204 -> 283 | L21: =TRUNC(K21*C21,1) -> 283 | P21: 10 | R21: NT1060 | T21: T | BI21: =HYPERLINK("#일위대가목록!A199","NT1060 →") -> NT1060 →
A22: 폐기물집적 및 상차 | B22: BH0.6m3 | C22: 0.17 | D22: m3 | E22: =G22+I22+K22 -> 5859 | F22: =H22+J22+L22 -> 995.8 | G22: =일위대가목록!F3 -> 1054 | H22: =TRUNC(G22*C22,1) -> 179.1 | I22: =일위대가목록!H3 -> 3467 | J22: =TRUNC(I22*C22,1) -> 589.3 | K22: =일위대가목록!J3 -> 1338 | L22: =TRUNC(K22*C22,1) -> 227.4 | P22: 20 | R22: NX1510 | T22: F | BI22: =HYPERLINK("#일위대가목록!A3","NX1510 →") -> NX1510 →
A24: No.6 스트로브잣나무 제거 | B24: H7.0xR22 | C24: 1 | D24: 주 | F24: =H24+J24+L24 -> 59722 | H24: =TRUNC(H25+H26,0) -> 972 | J24: =TRUNC(J25+J26,0) -> 58396 | L24: =TRUNC(L25+L26,0) -> 354 | O24: HX0025
A25: 벌목 및 제근 | B25: B16(R20~22) | C25: 1 | D25: 주 | E25: =G25+I25+K25 -> 58903 | F25: =H25+J25+L25 -> 58903 | G25: =일위대가목록!F207 -> 825 | H25: =TRUNC(G25*C25,1) -> 825 | I25: =일위대가목록!H207 -> 57911 | J25: =TRUNC(I25*C25,1) -> 57911 | K25: =일위대가목록!J207 -> 167 | L25: =TRUNC(K25*C25,1) -> 167 | P25: 10 | R25: NT1050 | T25: T | BI25: =HYPERLINK("#일위대가목록!A202","NT1050 →") -> NT1050 →
A26: 폐기물집적 및 상차 | B26: BH0.6m3 | C26: 0.14 | D26: m3 | E26: =G26+I26+K26 -> 5859 | F26: =H26+J26+L26 -> 820.1 | G26: =일위대가목록!F3 -> 1054 | H26: =TRUNC(G26*C26,1) -> 147.5 | I26: =일위대가목록!H3 -> 3467 | J26: =TRUNC(I26*C26,1) -> 485.3 | K26: =일위대가목록!J3 -> 1338 | L26: =TRUNC(K26*C26,1) -> 187.3 | P26: 20 | R26: NX1510 | T26: F | BI26: =HYPERLINK("#일위대가목록!A3","NX1510 →") -> NX1510 →
A28: No.7 스트로브잣나무 제거 | B28: H7.0xR20 | C28: 1 | D28: 주 | F28: =H28+J28+L28 -> 59487 | H28: =TRUNC(H29+H30,0) -> 930 | J28: =TRUNC(J29+J30,0) -> 58257 | L28: =TRUNC(L29+L30,0) -> 300 | O28: HX0026
A29: 벌목 및 제근 | B29: B16(R20~22) | C29: 1 | D29: 주 | E29: =G29+I29+K29 -> 58903 | F29: =H29+J29+L29 -> 58903 | G29: =일위대가목록!F207 -> 825 | H29: =TRUNC(G29*C29,1) -> 825 | I29: =일위대가목록!H207 -> 57911 | J29: =TRUNC(I29*C29,1) -> 57911 | K29: =일위대가목록!J207 -> 167 | L29: =TRUNC(K29*C29,1) -> 167 | P29: 10 | R29: NT1050 | T29: T | BI29: =HYPERLINK("#일위대가목록!A202","NT1050 →") -> NT1050 →
A30: 폐기물집적 및 상차 | B30: BH0.6m3 | C30: 0.1 | D30: m3 | E30: =G30+I30+K30 -> 5859 | F30: =H30+J30+L30 -> 585.9 | G30: =일위대가목록!F3 -> 1054 | H30: =TRUNC(G30*C30,1) -> 105.4 | I30: =일위대가목록!H3 -> 3467 | J30: =TRUNC(I30*C30,1) -> 346.7 | K30: =일위대가목록!J3 -> 1338 | L30: =TRUNC(K30*C30,1) -> 133.8 | P30: 20 | R30: NX1510 | T30: F | BI30: =HYPERLINK("#일위대가목록!A3","NX1510 →") -> NX1510 →
A32: No.8 스트로브잣나무 제거 | B32: H7.0xR15 | C32: 1 | D32: 주 | F32: =H32+J32+L32 -> 35329 | H32: =TRUNC(H33+H34,0) -> 490 | J32: =TRUNC(J33+J34,0) -> 34684 | L32: =TRUNC(L33+L34,0) -> 155 | O32: HX0027
