Workbook

Sheet 갑지
A8: 공사명 : 고기근린공원(사회공헌)조성공사
B11: ▣ 도 급 금 액 : | C11: 일금 | D11: =NUMBERSTRING(H11,1) -> 팔억일천팔백오십육만 | F11: 원정 | G11: ( | H11: =토목원가계산서!D32 -> 8.1856e+08 | I11: )
B12: ▣ 전 회 기 성 : | C12: 일금 | D12: =NUMBERSTRING(H12,1) -> 영 | F12: 원정 | G12: ( | H12: =토목원가계산서!E32 -> 0 | I12: )
B13: ▣ 금 회 기 성 : | C13: 일금 | D13: =NUMBERSTRING(H13,1) -> 이억일천칠백오십팔만 | F13: 원정 | G13: ( | H13: =토목원가계산서!G32 -> 217580000 | I13: )
B14: ▣ 누 계 기 성 : | C14: 일금 | D14: =NUMBERSTRING(H14,1) -> 이억일천칠백오십팔만 | F14: 원정 | G14: ( | H14: =H12+H13 -> 217580000 | I14: )
B15: ▣ 미 기 성 : | C15: 일금 | D15: =NUMBERSTRING(H15,1) -> 육억구십팔만 | F15: 원정 | G15: ( | H15: =H11-H14 -> 6.0098e+08 | I15: )

Sheet 토목원가계산서
A1: 공 사 원 가 계 산 서( 토 목)
A2: [공사명]고기근린공원(사회공헌) 조성공사(토목) | N2: 주공정
A3: 비 목 | D3: 도급금액 | E3: 전회기성 | F3: 비율(%) | G3: 금회기성 | H3: 비율(%) | I3: 누계기성 | J3: 비율(%) | K3: 구 성 비 | L3: 비 고 | M3: 정산보험료증감분 산출
N4: 조경종합적용
B5: 재 | C5: 직 접 재 료 비 | D5: 128998292 | F5: =IFERROR(E5/D5,0) -> 0 | G5: =내역서!S9 -> 29756977 | H5: =IFERROR(G5/D5,0) -> 0.23067729 | I5: =E5+G5 -> 29756977 | J5: =IFERROR(I5/D5,0) -> 0.23067729
A6: 순 | B6: 료 | C6: 간 접 재 료 비 | F6: =IFERROR(E6/D6,0) -> 0 | H6: =IFERROR(G6/D6,0) -> 0 | I6: =E6+G6 -> 0 | J6: =IFERROR(I6/D6,0) -> 0
B7: 비 | C7: 작업설,부산물등(△) | F7: =IFERROR(E7/D7,0) -> 0 | H7: =IFERROR(G7/D7,0) -> 0 | I7: =E7+G7 -> 0 | J7: =IFERROR(I7/D7,0) -> 0
C8: [ 소 계 ] | D8: =SUM(D5:D7) -> 128998292 | F8: =IFERROR(E8/D8,0) -> 0 | G8: =G5+G6+G7 -> 29756977 | H8: =IFERROR(G8/D8,0) -> 0.23067729 | I8: =E8+G8 -> 29756977 | J8: =IFERROR(I8/D8,0) -> 0.23067729
A9: 공 | B9: 노 | C9: 직 접 노 무 비 | D9: 290768141 | F9: =IFERROR(E9/D9,0) -> 0 | G9: =내역서!T9 -> 77572233 | H9: =IFERROR(G9/D9,0) -> 0.26678381 | I9: =E9+G9 -> 77572233 | J9: =IFERROR(I9/D9,0) -> 0.26678381
B10: 무 | C10: 간 접 노 무 비 | D10: 41579844 | F10: =IFERROR(E10/D10,0) -> 0 | G10: =INT(G9*N10) -> 11092829 | H10: =IFERROR(G10/D10,0) -> 0.26678381 | I10: =E10+G10 -> 11092829 | J10: =IFERROR(I10/D10,0) -> 0.26678381 | K10: 직접노무비의 *14.3% | N10: 0.143
B11: 비 | C11: [ 소 계 ] | D11: =SUM(D9:D10) -> 332347985 | F11: =IFERROR(E11/D11,0) -> 0 | G11: =G9+G10 -> 88665062 | H11: =IFERROR(G11/D11,0) -> 0.26678381 | I11: =E11+G11 -> 88665062 | J11: =IFERROR(I11/D11,0) -> 0.26678381
C12: 운 반 비 | F12: =IFERROR(E12/D12,0) -> 0 | H12: =IFERROR(G12/D12,0) -> 0 | I12: =E12+G12 -> 0 | J12: =IFERROR(I12/D12,0) -> 0
A13: 사 | C13: 기 계 경 비 | D13: 79339367 | F13: =IFERROR(E13/D13,0) -> 0 | G13: =내역서!U9 -> 32559060 | H13: =IFERROR(G13/D13,0) -> 0.41037711 | I13: =E13+G13 -> 32559060 | J13: =IFERROR(I13/D13,0) -> 0.41037711
C14: 산 재 보 험 료 | D14: 11831588 | F14: =IFERROR(E14/D14,0) -> 0 | G14: =INT(G11*N14) -> 3156476 | H14: =IFERROR(G14/D14,0) -> 0.2667838 | I14: =E14+G14 -> 3156476 | J14: =IFERROR(I14/D14,0) -> 0.2667838 | K14: 노무비의 *3.56% | N14: 0.0356
B15: 경 | C15: 고 용 보 험 료 | D15: 3356714 | F15: =IFERROR(E15/D15,0) -> 0 | G15: =INT(G11*N15) -> 895517 | H15: =IFERROR(G15/D15,0) -> 0.26678382 | I15: =E15+G15 -> 895517 | J15: =IFERROR(I15/D15,0) -> 0.26678382 | K15: 노무비의 *1.01% | N15: 0.0101
C16: 건 강 보 험 료 | D16: 11730751 | F16: =IFERROR(E16/D16,0) -> 0 | H16: =IFERROR(G16/D16,0) -> 0 | I16: =E16+G16 -> 0 | J16: =IFERROR(I16/D16,0) -> 0 | K16: 직접노무비의 *3.545% | M16: =ROUND(#REF!*0.03545,0) -> #REF! | N16: 0.03545
A17: 원 | C17: 연 금 보 험 료 | D17: 14890940 | F17: =IFERROR(E17/D17,0) -> 0 | H17: =IFERROR(G17/D17,0) -> 0 | I17: =E17+G17 -> 0 | J17: =IFERROR(I17/D17,0) -> 0 | K17: 직접노무비의 *4.5% | M17: =ROUND(#REF!*0.045,0) -> #REF! | N17: 0.045
C18: 노인장기요양보험료 | D18: 1519131 | F18: =IFERROR(E18/D18,0) -> 0 | H18: =IFERROR(G18/D18,0) -> 0 | I18: =E18+G18 -> 0 | J18: =IFERROR(I18/D18,0) -> 0 | K18: 건강보험료 *12.95% | M18: =ROUND(#REF!*0.1295,0) -> #REF! | N18: 0.1295
C19: 퇴직공제부금비 | D19: 7610925 | F19: =IFERROR(E19/D19,0) -> 0 | H19: =IFERROR(G19/D19,0) -> 0 | I19: =E19+G19 -> 0 | J19: =IFERROR(I19/D19,0) -> 0 | K19: 직접노무비의 * 2.3% | M19: =ROUND(#REF!*0.023,0) -> #REF! | N19: 0.023 | O19: 도급자관급 | P19: =내역서!H11 -> 86781280
C20: 기계대여대금지급보증수수료 | D20: 898390 | F20: =IFERROR(E20/D20,0) -> 0 | H20: =IFERROR(G20/D20,0) -> 0 | I20: =E20+G20 -> 0 | J20: =IFERROR(I20/D20,0) -> 0 | K20: (재료비+직노비+산경) *0.18% | N20: 0.0018 | O20: A | P20: =(D8+D9+P19/1.1)*N21 -> 5983902.1
A21: 가 | B21: 비 | C21: 안 전 관 리 비 | D21: 6531859 | F21: =IFERROR(E21/D21,0) -> 0 | G21: 3000000 | H21: =IFERROR(G21/D21,0) -> 0.45928732 | I21: =E21+G21 -> 3000000 | J21: =IFERROR(I21/D21,0) -> 0.45928732 | K21: (재료비+직노+도급자관급)*1.2%+3,250,000 | M21: =ROUND((#REF!+#REF!+#REF!)*0.012,0) -> #REF! | N21: 0.012 | O21: B | P21: =(((D8+D9)*N21)*1.2) -> 6044636.6
C22: 환 경 보 전 비 | D22: 1497317 | F22: =IFERROR(E22/D22,0) -> 0 | G22: 1400000 | H22: =IFERROR(G22/D22,0) -> 0.93500575 | I22: =E22+G22 -> 1400000 | J22: =IFERROR(I22/D22,0) -> 0.93500575 | K22: (재료비+직노비+산경) *0.3% | N22: 0.003
C23: 기 타 경 비 | D23: 25374045 | F23: =IFERROR(E23/D23,0) -> 0 | G23: =INT((G8+G11)*N23) -> 6513212 | H23: =IFERROR(G23/D23,0) -> 0.25668797 | I23: =E23+G23 -> 6513212 | J23: =IFERROR(I23/D23,0) -> 0.25668797 | K23: (재료비+노무비) *5.5% | N23: 0.055
C24: 하도급지급보증수수료 | D24: 404275 | F24: =IFERROR(E24/D24,0) -> 0 | H24: =IFERROR(G24/D24,0) -> 0 | I24: =E24+G24 -> 0 | J24: =IFERROR(I24/D24,0) -> 0 | K24: (재료비+직노비+산출경비) *0.081% | N24: 0.00081
C25: [ 소 계 ] | D25: =SUM(D12:D24) -> 164985302 | F25: =IFERROR(E25/D25,0) -> 0 | G25: =SUM(G12:G24) -> 47524265 | H25: =IFERROR(G25/D25,0) -> 0.28805151 | I25: =E25+G25 -> 47524265 | J25: =IFERROR(I25/D25,0) -> 0.28805151
A26: 계 | D26: =D8+D11+D25 -> 626331579 | F26: =IFERROR(E26/D26,0) -> 0 | G26: =INT(G8+G11+G25) -> 165946304 | H26: =IFERROR(G26/D26,0) -> 0.2649496 | I26: =E26+G26 -> 165946304 | J26: =IFERROR(I26/D26,0) -> 0.2649496
A27: 일 반 관 리 비 | D27: 37579894 | F27: =IFERROR(E27/D27,0) -> 0 | G27: =INT(G26*N27) -> 9956778 | H27: =IFERROR(G27/D27,0) -> 0.2649496 | I27: =E27+G27 -> 9956778 | J27: =IFERROR(I27/D27,0) -> 0.2649496 | K27: 계의 *6.0% | N27: 0.06
A28: 합 계 | D28: =D26+D27 -> 663911473 | F28: =IFERROR(E28/D28,0) -> 0 | G28: =INT(G26+G27) -> 175903082 | H28: =IFERROR(G28/D28,0) -> 0.2649496 | I28: =E28+G28 -> 175903082 | J28: =IFERROR(I28/D28,0) -> 0.2649496
A29: 이 윤 | D29: 80233982 | F29: =IFERROR(E29/D29,0) -> 0 | G29: =INT(((G11+G25+G27)*N29))-24997 -> 21896918 | H29: =IFERROR(G29/D29,0) -> 0.27291327 | I29: =E29+G29 -> 21896918 | J29: =IFERROR(I29/D29,0) -> 0.27291327 | K29: (노무비+경비+일반관리비) *15.0% | N29: 0.15
A30: 공 급 가 액 (총 원 가) | D30: =D28+D29 -> 7.4414545e+08 | F30: =IFERROR(E30/D30,0) -> 0 | G30: =SUM(G28:G29) -> 197800000 | H30: =IFERROR(G30/D30,0) -> 0.26580825 | I30: =E30+G30 -> 197800000 | J30: =IFERROR(I30/D30,0) -> 0.26580825
A31: 부 가 가 치 세 | D31: 74414545 | F31: =IFERROR(E31/D31,0) -> 0 | G31: =INT(G30*N31) -> 19780000 | H31: =IFERROR(G31/D31,0) -> 0.26580825 | I31: =E31+G31 -> 19780000 | J31: =IFERROR(I31/D31,0) -> 0.26580825 | K31: 공급가액의 *10.00% | N31: 0.1
A32: 도 급 액 | D32: =D30+D31 -> 8.1856e+08 | F32: =IFERROR(E32/D32,0) -> 0 | G32: =SUM(G30:G31) -> 217580000 | H32: =IFERROR(G32/D32,0) -> 0.26580825 | I32: =E32+G32 -> 217580000 | J32: =IFERROR(I32/D32,0) -> 0.26580825
A33: 관 급 자 재 비 | D33: 87240000 | F33: =IFERROR(E33/D33,0) -> 0 | G33: =G34+G35 -> 87240000 | I33: =I34+I35 -> 86781280
A34: 1) 도급자관급 | D34: 87240000 | F34: =IFERROR(E34/D34,0) -> 0 | G34: =내역서!F107 -> 87240000 | I34: =내역서!H107 -> 86781280
A35: 2) 관급자관급 | F35: =IFERROR(E35/D35,0) -> 0
A36: 총 공 사 비 | D36: 9.058e+08 | F36: =IFERROR(E36/D36,0) -> 0 | G36: =SUM(G32:G33) -> 304820000 | I36: =SUM(I32:I33) -> 304361280

Sheet 내역서
A1: 제1회 기성내역서 | BT1: 낙찰율조정 | BU1: =+[1]원가계산서!$M$1 -> 0.859356
A2: 공 종 명 | B2: 규 격 | C2: 단위 | D2: 수량 | E2: 도 급 금액 | G2: 도급단가 | M2: 전회기성 | P2: 금회기성 | S2: 금액 | V2: 누계기성 | Y2: 비고 | CA2: 합 계 | CC2: 재 료 비 | CE2: 노 무 비 | CG2: 경 비 | CI2: 비 고
E3: 단 가 | F3: 금 액 | G3: 재료비 | H3: 재료비금액 | I3: 노무비 | J3: 노무비금액 | K3: 경비 | L3: 경비금액 | M3: 수량 | N3: 금액 | O3: 비율(%) | P3: 수량 | Q3: 금액 | R3: 비율(%) | S3: 재료비 | T3: 노무비 | U3: 경비 | V3: 수량 | W3: 금액 | X3: 비율(%) | AE3: 할 증 | AF3: 화폐변환 | AG3: OP값 | AH3: EQ | AI3: LA | AJ3: MA | AK3: 금액계상 | CA3: 단 가 | CB3: 금 액 | CC3: 단 가 | CD3: 금 액 | CE3: 단 가 | CF3: 금 액 | CG3: 단 가 | CH3: 금 액
A4: ■ 고기근린공원(사회공헌) 조성공사 (토목) | C4: 식 | D4: 1 | F4: =H4+J4+L4 -> 499105800 | H4: =TRUNC(H5+H6+H7+H8,0) -> 128998292 | J4: =TRUNC(J5+J6+J7+J8,0) -> 290768141 | L4: =TRUNC(L5+L6+L7+L8,0) -> 79339367 | O4: =IFERROR(N4/F4,0) -> 0 | Q4: =SUM(S4:U4) -> 0 | R4: =IFERROR(Q4/F4,0) -> 0 | V4: =M4+P4 -> 0 | W4: =N4+Q4 -> 0 | X4: =IFERROR(W4/F4,0) -> 0 | Z4: 구미 천연가스 냉각탑 구조물공사(CC-02) | AA4: A | CB4: 534111775 | CD4: 131808974 | CF4: 285215447 | CH4: 117087354
A5: 1. 토공 및 철거공 | C5: 식 | D5: 1 | E5: =G5+I5+K5 -> 147855095 | F5: =H5+J5+L5 -> 147855095 | G5: =H13 -> 25872443 | H5: =TRUNC(G5*D5,0) -> 25872443 | I5: =J13 -> 87253547 | J5: =TRUNC(I5*D5,0) -> 87253547 | K5: =L13 -> 34729105 | L5: =TRUNC(K5*D5,0) -> 34729105 | O5: =IFERROR(N5/F5,0) -> 0 | Q5: =SUM(S5:U5) -> 43234623 | R5: =IFERROR(Q5/F5,0) -> 0.29241213 | S5: =S13 -> 6945193 | T5: =T13 -> 26468927 | U5: =U13 -> 9820503 | X5: =IFERROR(W5/F5,0) -> 0 | AB5: 10 | AD5: A01 | BU5: =HYPERLINK("#내역서!A12","A01 →") -> A01 → | CA5: 135927963 | CB5: 135927963 | CC5: 25228975 | CD5: 25228975 | CE5: 78917934 | CF5: 78917934 | CG5: 31781054 | CH5: 31781054
A6: 2. 우수,오수,상수공 | C6: 식 | D6: 1 | E6: =G6+I6+K6 -> 249127758 | F6: =H6+J6+L6 -> 249127758 | G6: =H30 -> 69934323 | H6: =TRUNC(G6*D6,0) -> 69934323 | I6: =J30 -> 169464217 | J6: =TRUNC(I6*D6,0) -> 169464217 | K6: =L30 -> 9729218 | L6: =TRUNC(K6*D6,0) -> 9729218 | O6: =IFERROR(N6/F6,0) -> 0 | Q6: =SUM(S6:U6) -> 63349207 | R6: =IFERROR(Q6/F6,0) -> 0.25428402 | S6: =S30 -> 22679324 | T6: =T30 -> 38487046 | U6: =U30 -> 2182837 | X6: =IFERROR(W6/F6,0) -> 0 | AB6: 20 | AD6: A02 | BU6: =HYPERLINK("#내역서!A28","A02 →") -> A02 → | CA6: 223387024 | CB6: 223387024 | CC6: 42285506 | CD6: 42285506 | CE6: 170530411 | CF6: 170530411 | CG6: 10571107 | CH6: 10571107
A7: 3. 포장공 | C7: 식 | D7: 1 | E7: =G7+I7+K7 -> 52288564 | F7: =H7+J7+L7 -> 52288564 | G7: =H75 -> 33012526 | H7: =TRUNC(G7*D7,0) -> 33012526 | I7: =J75 -> 17001377 | J7: =TRUNC(I7*D7,0) -> 17001377 | K7: =L75 -> 2274661 | L7: =TRUNC(K7*D7,0) -> 2274661 | O7: =IFERROR(N7/F7,0) -> 0 | Q7: =SUM(S7:U7) -> 0 | R7: =IFERROR(Q7/F7,0) -> 0 | S7: =S75 -> 0 | T7: =T75 -> 0 | U7: =U75 -> 0 | X7: =IFERROR(W7/F7,0) -> 0 | AB7: 30 | AD7: A03 | BU7: =HYPERLINK("#내역서!A70","A03 →") -> A03 → | CA7: 103918045 | CB7: 103918045 | CC7: 64294493 | CD7: 64294493 | CE7: 35767102 | CF7: 35767102 | CG7: 3856450 | CH7: 3856450
A8: 4. 부대공 | C8: 식 | D8: 1 | E8: =G8+I8+K8 -> 49834383 | F8: =H8+J8+L8 -> 49834383 | G8: =H96 -> 179000 | H8: =TRUNC(G8*D8,0) -> 179000 | I8: =J96 -> 17049000 | J8: =TRUNC(I8*D8,0) -> 17049000 | K8: =L96 -> 32606383 | L8: =TRUNC(K8*D8,0) -> 32606383 | O8: =IFERROR(N8/F8,0) -> 0 | Q8: =SUM(S8:U8) -> 33304440 | R8: =IFERROR(Q8/F8,0) -> 0.66830244 | S8: =S96 -> 132460 | T8: =T96 -> 12616260 | U8: =U96 -> 20555720 | X8: =IFERROR(W8/F8,0) -> 0 | AB8: 40 | AD8: A04 | BU8: =HYPERLINK("#내역서!A91","A04 →") -> A04 → | CA8: 70878743 | CB8: 70878743 | CC8: 0 | CD8: 0 | CE8: 0 | CF8: 0 | CG8: 70878743 | CH8: 70878743
A9: 직접공사비 | F9: =SUM(F5:F8) -> 499105800 | H9: =SUM(H5:H8) -> 128998292 | J9: =SUM(J5:J8) -> 290768141 | L9: =SUM(L5:L8) -> 79339367 | O9: =IFERROR(N9/F9,0) -> 0 | Q9: =SUM(S9:U9) -> 139888270 | R9: =IFERROR(Q9/F9,0) -> 0.28027779 | S9: =SUM(S5:S8) -> 29756977 | T9: =SUM(T5:T8) -> 77572233 | U9: =SUM(U5:U8) -> 32559060 | X9: =IFERROR(W9/F9,0) -> 0
E10: =G10+I10+K10 -> 0 | F10: =H10+J10+L10 -> 0 | H10: 0 | J10: 0 | L10: 0 | O10: =IFERROR(N10/F10,0) -> 0 | Q10: =SUM(S10:U10) -> 0 | R10: =IFERROR(Q10/F10,0) -> 0 | X10: =IFERROR(W10/F10,0) -> 0 | AB10: 50 | CA10: 0 | CB10: 0 | CD10: 0 | CF10: 0 | CH10: 0
A11: - 관급자재 - | C11: 식 | D11: 1 | E11: =G11+I11+K11 -> 87240000 | F11: =H11+J11+L11 -> 87240000 | G11: =H107 -> 86781280 | H11: =TRUNC(G11*D11,0) -> 86781280 | I11: =J107 -> 0 | J11: =TRUNC(I11*D11,0) -> 0 | K11: =L107 -> 458720 | L11: =TRUNC(K11*D11,0) -> 458720 | O11: =IFERROR(N11/F11,0) -> 0 | Q11: =SUM(S11:U11) -> 0 | R11: =IFERROR(Q11/F11,0) -> 0 | X11: =IFERROR(W11/F11,0) -> 0 | AB11: 60 | AC11: * | AD11: A05 | BU11: =HYPERLINK("#내역서!A101","A05 →") -> A05 → | CA11: 104870000 | CB11: 104870000 | CC11: 104311617 | CD11: 104311617 | CE11: 0 | CF11: 0 | CG11: 558383 | CH11: 558383
E12: =G12+I12+K12 -> 0 | F12: =H12+J12+L12 -> 0 | H12: 0 | J12: 0 | L12: 0 | O12: =IFERROR(N12/F12,0) -> 0 | Q12: =SUM(S12:U12) -> 0 | R12: =IFERROR(Q12/F12,0) -> 0 | X12: =IFERROR(W12/F12,0) -> 0 | AB12: 70 | AC12: S | CA12: 0 | CB12: 0 | CD12: 0 | CF12: 0 | CH12: 0
A13: 1. 토공 및 철거공 | C13: 식 | D13: 1 | F13: =H13+J13+L13 -> 147855095 | H13: =TRUNC(H14+H15+H16+H17+H18+H19+H20+H21+H22+H23+H24+H25+H26+H27+H28,0) -> 25872443 | J13: =TRUNC(J14+J15+J16+J17+J18+J19+J20+J21+J22+J23+J24+J25+J26+J27+J28,0) -> 87253547 | L13: =TRUNC(L14+L15+L16+L17+L18+L19+L20+L21+L22+L23+L24+L25+L26+L27+L28,0) -> 34729105 | O13: =IFERROR(N13/F13,0) -> 0 | Q13: =SUM(S13:U13) -> 43234623 | R13: =IFERROR(Q13/F13,0) -> 0.29241213 | S13: =TRUNC(S14+S15+S16+S17+S18+S19+S20+S21+S22+S23+S24+S25+S26+S27+S28,0) -> 6945193 | T13: =TRUNC(T14+T15+T16+T17+T18+T19+T20+T21+T22+T23+T24+T25+T26+T27+T28,0) -> 26468927 | U13: =TRUNC(U14+U15+U16+U17+U18+U19+U20+U21+U22+U23+U24+U25+U26+U27+U28,0) -> 9820503 | X13: =IFERROR(W13/F13,0) -> 0 | AA13: A01 | CB13: 135927963 | CD13: 25228975 | CF13: 78917934 | CH13: 31781054
A14: 흙깍기 | B14: 토사 | C14: M3 | D14: 4942 | E14: =G14+I14+K14 -> 1792 | F14: =H14+J14+L14 -> 8856064 | G14: 553 | H14: =TRUNC(G14*D14,0) -> 2732926 | I14: 781 | J14: =TRUNC(I14*D14,0) -> 3859702 | K14: 458 | L14: =TRUNC(K14*D14,0) -> 2263436 | O14: =IFERROR(N14/F14,0) -> 0 | P14: ='[2]토공 집계표'!$C$11 -> 1410.1371 | Q14: =SUM(S14:U14) -> 2526964 | R14: =IFERROR(Q14/F14,0) -> 0.28533714 | S14: =TRUNC(G14*P14,0) -> 779805 | T14: =TRUNC(I14*P14,0) -> 1101317 | U14: =TRUNC(K14*P14,0) -> 645842 | X14: =IFERROR(W14/F14,0) -> 0 | AB14: 10 | AD14: H00100200 | AF14: A | BU14: =HYPERLINK("#일위대가목록!A3","H00100200 →") -> H00100200 → | CA14: 2087 | CB14: 10313954 | CC14: 644 | CD14: 3182648 | CE14: 909 | CF14: 4492278 | CG14: 534 | CH14: 2639028 | CI14: No.1
A15: 흙쌓기 | B15: 주간(토사) | C15: M3 | D15: 2846 | E15: =G15+I15+K15 -> 1493 | F15: =H15+J15+L15 -> 4249078 | G15: 372 | H15: =TRUNC(G15*D15,0) -> 1058712 | I15: 807 | J15: =TRUNC(I15*D15,0) -> 2296722 | K15: 314 | L15: =TRUNC(K15*D15,0) -> 893644 | O15: =IFERROR(N15/F15,0) -> 0 | P15: ='[2]토공 집계표'!$D$11 -> 1120.0033 | Q15: =SUM(S15:U15) -> 1672164 | R15: =IFERROR(Q15/F15,0) -> 0.39353573 | S15: =TRUNC(G15*P15,0) -> 416641 | T15: =TRUNC(I15*P15,0) -> 903842 | U15: =TRUNC(K15*P15,0) -> 351681 | X15: =IFERROR(W15/F15,0) -> 0 | AB15: 20 | AD15: K1010240 | AF15: A | BU15: =HYPERLINK("#일위대가목록!A4","K1010240 →") -> K1010240 → | CA15: 1740 | CB15: 4952040 | CC15: 434 | CD15: 1235164 | CE15: 940 | CF15: 2675240 | CG15: 366 | CH15: 1041636 | CI15: No.2
A16: 흙쌓기 | B16: 주간(토사)(비다짐) | C16: M3 | D16: 3653 | E16: =G16+I16+K16 -> 447 | F16: =H16+J16+L16 -> 1632891 | G16: 138 | H16: =TRUNC(G16*D16,0) -> 504114 | I16: 195 | J16: =TRUNC(I16*D16,0) -> 712335 | K16: 114 | L16: =TRUNC(K16*D16,0) -> 416442 | O16: =IFERROR(N16/F16,0) -> 0 | P16: ='[2]토공 집계표'!$E$11 -> 127.53476 | Q16: =SUM(S16:U16) -> 57006 | R16: =IFERROR(Q16/F16,0) -> 0.034911087 | S16: =TRUNC(G16*P16,0) -> 17599 | T16: =TRUNC(I16*P16,0) -> 24869 | U16: =TRUNC(K16*P16,0) -> 14538 | X16: =IFERROR(W16/F16,0) -> 0 | AB16: 30 | AD16: K1010241 | AF16: A | BU16: =HYPERLINK("#일위대가목록!A5","K1010241 →") -> K1010241 → | CA16: 521 | CB16: 1903213 | CC16: 161 | CD16: 588133 | CE16: 227 | CF16: 829231 | CG16: 133 | CH16: 485849 | CI16: No.3
A17: 유용토운반 | B17: 주간(토사) | C17: M3 | D17: 3653 | E17: =G17+I17+K17 -> 1276 | F17: =H17+J17+L17 -> 4661228 | G17: 394 | H17: =TRUNC(G17*D17,0) -> 1439282 | I17: 556 | J17: =TRUNC(I17*D17,0) -> 2031068 | K17: 326 | L17: =TRUNC(K17*D17,0) -> 1190878 | O17: =IFERROR(N17/F17,0) -> 0 | P17: ='[2]토공 집계표'!$E$11 -> 127.53476 | Q17: =SUM(S17:U17) -> 162733 | R17: =IFERROR(Q17/F17,0) -> 0.034912045 | S17: =TRUNC(G17*P17,0) -> 50248 | T17: =TRUNC(I17*P17,0) -> 70909 | U17: =TRUNC(K17*P17,0) -> 41576 | X17: =IFERROR(W17/F17,0) -> 0 | AB17: 40 | AD17: K1010250 | AF17: A | BU17: =HYPERLINK("#일위대가목록!A6","K1010250 →") -> K1010250 → | CA17: 1487 | CB17: 5432011 | CC17: 459 | CD17: 1676727 | CE17: 648 | CF17: 2367144 | CG17: 380 | CH17: 1388140 | CI17: No.4
A18: 표토제거 | B18: (답외구간) | C18: M2 | D18: 53183 | E18: =G18+I18+K18 -> 215 | F18: =H18+J18+L18 -> 11434345 | G18: 85 | H18: =TRUNC(G18*D18,0) -> 4520555 | I18: 73 | J18: =TRUNC(I18*D18,0) -> 3882359 | K18: 57 | L18: =TRUNC(K18*D18,0) -> 3031431 | O18: =IFERROR(N18/F18,0) -> 0 | P18: ='[2]토공 집계표'!$F$11 -> 14395.46 | Q18: =SUM(S18:U18) -> 3095023 | R18: =IFERROR(Q18/F18,0) -> 0.27067777 | S18: =TRUNC(G18*P18,0) -> 1223614 | T18: =TRUNC(I18*P18,0) -> 1050868 | U18: =TRUNC(K18*P18,0) -> 820541 | X18: =IFERROR(W18/F18,0) -> 0 | AB18: 50 | AD18: SA00220 | AF18: A | BU18: =HYPERLINK("#일위대가목록!A7","SA00220 →") -> SA00220 → | CA18: 252 | CB18: 13402116 | CC18: 100 | CD18: 5318300 | CE18: 85 | CF18: 4520555 | CG18: 67 | CH18: 3563261 | CI18: No.5
A19: 벌개제근 | C19: M2 | D19: 53183 | E19: =G19+I19+K19 -> 414 | F19: =H19+J19+L19 -> 22017762 | G19: 26 | H19: =TRUNC(G19*D19,0) -> 1382758 | I19: 335 | J19: =TRUNC(I19*D19,0) -> 17816305 | K19: 53 | L19: =TRUNC(K19*D19,0) -> 2818699 | O19: =IFERROR(N19/F19,0) -> 0 | P19: ='[2]토공 집계표'!$G$11 -> 14395.46 | Q19: =SUM(S19:U19) -> 5959719 | R19: =IFERROR(Q19/F19,0) -> 0.27067778 | S19: =TRUNC(G19*P19,0) -> 374281 | T19: =TRUNC(I19*P19,0) -> 4822479 | U19: =TRUNC(K19*P19,0) -> 762959 | X19: =IFERROR(W19/F19,0) -> 0 | AB19: 60 | AD19: SA00230 | AF19: T | BU19: =HYPERLINK("#일위대가목록!A41","SA00230 →") -> SA00230 → | CA19: 483 | CB19: 25687389 | CC19: 31 | CD19: 1648673 | CE19: 390 | CF19: 20741370 | CG19: 62 | CH19: 3297346 | CI19: No.6
A20: 터파기(기계) | B20: 토사 | C20: M3 | D20: 39 | E20: =G20+I20+K20 -> 1374 | F20: =H20+J20+L20 -> 53586 | G20: 329 | H20: =TRUNC(G20*D20,0) -> 12831 | I20: 722 | J20: =TRUNC(I20*D20,0) -> 28158 | K20: 323 | L20: =TRUNC(K20*D20,0) -> 12597 | O20: =IFERROR(N20/F20,0) -> 0 | P20: ='[2]토공 집계표'!$H$11 -> 6.51 | Q20: =SUM(S20:U20) -> 8943 | R20: =IFERROR(Q20/F20,0) -> 0.16689061 | S20: =TRUNC(G20*P20,0) -> 2141 | T20: =TRUNC(I20*P20,0) -> 4700 | U20: =TRUNC(K20*P20,0) -> 2102 | X20: =IFERROR(W20/F20,0) -> 0 | AB20: 70 | AD20: K1020118 | AF20: A | BU20: =HYPERLINK("#일위대가목록!A8","K1020118 →") -> K1020118 → | CA20: 1600 | CB20: 62400 | CC20: 383 | CD20: 14937 | CE20: 841 | CF20: 32799 | CG20: 376 | CH20: 14664 | CI20: No.7
A21: 되메우기및다짐(기계) | B21: 토사 | C21: M3 | D21: 48 | E21: =G21+I21+K21 -> 11478 | F21: =H21+J21+L21 -> 550944 | G21: 908 | H21: =TRUNC(G21*D21,0) -> 43584 | I21: 9446 | J21: =TRUNC(I21*D21,0) -> 453408 | K21: 1124 | L21: =TRUNC(K21*D21,0) -> 53952 | O21: =IFERROR(N21/F21,0) -> 0 | P21: ='[2]토공 집계표'!$I$11 -> 7.97 | Q21: =SUM(S21:U21) -> 91478 | R21: =IFERROR(Q21/F21,0) -> 0.16603865 | S21: =TRUNC(G21*P21,0) -> 7236 | T21: =TRUNC(I21*P21,0) -> 75284 | U21: =TRUNC(K21*P21,0) -> 8958 | X21: =IFERROR(W21/F21,0) -> 0 | AB21: 80 | AD21: K1040213 | AF21: A | BU21: =HYPERLINK("#일위대가목록!A9","K1040213 →") -> K1040213 → | CA21: 13359 | CB21: 641232 | CC21: 1057 | CD21: 50736 | CE21: 10993 | CF21: 527664 | CG21: 1309 | CH21: 62832 | CI21: No.8
A22: 아스팔트 포장절단 | B22: 주간 | C22: M | D22: 548 | E22: =G22+I22+K22 -> 1804 | F22: =H22+J22+L22 -> 988592 | G22: 538 | H22: =TRUNC(G22*D22,0) -> 294824 | I22: 1224 | J22: =TRUNC(I22*D22,0) -> 670752 | K22: 42 | L22: =TRUNC(K22*D22,0) -> 23016 | O22: =IFERROR(N22/F22,0) -> 0 | P22: ='[2]토공 집계표'!$J$11 -> 30 | Q22: =SUM(S22:U22) -> 54120 | R22: =IFERROR(Q22/F22,0) -> 0.054744526 | S22: =TRUNC(G22*P22,0) -> 16140 | T22: =TRUNC(I22*P22,0) -> 36720 | U22: =TRUNC(K22*P22,0) -> 1260 | X22: =IFERROR(W22/F22,0) -> 0 | AB22: 90 | AD22: K2010110 | AF22: A | BU22: =HYPERLINK("#일위대가목록!A10","K2010110 →") -> K2010110 → | CA22: 2101 | CB22: 1151348 | CC22: 627 | CD22: 343596 | CE22: 1425 | CF22: 780900 | CG22: 49 | CH22: 26852 | CI22: No.9
A23: 아스팔트 깨기 | B23: 주간 | C23: M3 | D23: 127 | E23: =G23+I23+K23 -> 7163 | F23: =H23+J23+L23 -> 909701 | G23: 1056 | H23: =TRUNC(G23*D23,0) -> 134112 | I23: 4173 | J23: =TRUNC(I23*D23,0) -> 529971 | K23: 1934 | L23: =TRUNC(K23*D23,0) -> 245618 | O23: =IFERROR(N23/F23,0) -> 0 | P23: ='[2]토공 집계표'!$K$11 -> 78.15 | Q23: =SUM(S23:U23) -> 559787 | R23: =IFERROR(Q23/F23,0) -> 0.61535274 | S23: =TRUNC(G23*P23,0) -> 82526 | T23: =TRUNC(I23*P23,0) -> 326119 | U23: =TRUNC(K23*P23,0) -> 151142 | X23: =IFERROR(W23/F23,0) -> 0 | AB23: 100 | AD23: K2010210 | AF23: A | BU23: =HYPERLINK("#일위대가목록!A11","K2010210 →") -> K2010210 → | CA23: 8337 | CB23: 1058799 | CC23: 1229 | CD23: 156083 | CE23: 4857 | CF23: 616839 | CG23: 2251 | CH23: 285877 | CI23: No.10
A24: 콘크리트 포장절단 | B24: 주간 | C24: M | D24: 10 | E24: =G24+I24+K24 -> 1945 | F24: =H24+J24+L24 -> 19450 | G24: 556 | H24: =TRUNC(G24*D24,0) -> 5560 | I24: 1344 | J24: =TRUNC(I24*D24,0) -> 13440 | K24: 45 | L24: =TRUNC(K24*D24,0) -> 450 | O24: =IFERROR(N24/F24,0) -> 0 | P24: ='[2]토공 집계표'!$L$11 -> 10 | Q24: =SUM(S24:U24) -> 19450 | R24: =IFERROR(Q24/F24,0) -> 1 | S24: =TRUNC(G24*P24,0) -> 5560 | T24: =TRUNC(I24*P24,0) -> 13440 | U24: =TRUNC(K24*P24,0) -> 450 | X24: =IFERROR(W24/F24,0) -> 0 | AB24: 110 | AD24: K2010120 | AF24: A | BU24: =HYPERLINK("#일위대가목록!A12","K2010120 →") -> K2010120 → | CA24: 2265 | CB24: 22650 | CC24: 647 | CD24: 6470 | CE24: 1565 | CF24: 15650 | CG24: 53 | CH24: 530 | CI24: No.11
A25: 철근콘크리트 깨기 | B25: 30cm미만 | C25: M3 | D25: 1049 | E25: =G25+I25+K25 -> 46845 | F25: =H25+J25+L25 -> 49140405 | G25: 6899 | H25: =TRUNC(G25*D25,0) -> 7237051 | I25: 27272 | J25: =TRUNC(I25*D25,0) -> 28608328 | K25: 12674 | L25: =TRUNC(K25*D25,0) -> 13295026 | O25: =IFERROR(N25/F25,0) -> 0 | P25: ='[2]토공 집계표'!$M$11 -> 52.056329 | Q25: =SUM(S25:U25) -> 2438577 | R25: =IFERROR(Q25/F25,0) -> 0.049624683 | S25: =TRUNC(G25*P25,0) -> 359136 | T25: =TRUNC(I25*P25,0) -> 1419680 | U25: =TRUNC(K25*P25,0) -> 659761 | X25: =IFERROR(W25/F25,0) -> 0 | AB25: 120 | AD25: K2010330 | AF25: A | BU25: =HYPERLINK("#일위대가목록!A13","K2010330 →") -> K2010330 → | CA25: 54514 | CB25: 57185186 | CC25: 8029 | CD25: 8422421 | CE25: 31736 | CF25: 33291064 | CG25: 14749 | CH25: 15471701 | CI25: No.12
A26: 무근콘크리트 깨기 | B26: 30cm미만 | C26: M3 | D26: 720.72 | E26: =G26+I26+K26 -> 28374 | F26: =H26+J26+L26 -> 20449708 | G26: 3674 | H26: =TRUNC(G26*D26,0) -> 2647925 | I26: 17947 | J26: =TRUNC(I26*D26,0) -> 12934761 | K26: 6753 | L26: =TRUNC(K26*D26,0) -> 4867022 | O26: =IFERROR(N26/F26,0) -> 0 | P26: ='[2]토공 집계표'!$N$11 -> 538 | Q26: =SUM(S26:U26) -> 15265212 | R26: =IFERROR(Q26/F26,0) -> 0.74647579 | S26: =TRUNC(G26*P26,0) -> 1976612 | T26: =TRUNC(I26*P26,0) -> 9655486 | U26: =TRUNC(K26*P26,0) -> 3633114 | X26: =IFERROR(W26/F26,0) -> 0 | AB26: 130 | AD26: K2010310 | AF26: A | BU26: =HYPERLINK("#일위대가목록!A14","K2010310 →") -> K2010310 → | CA26: 33020 | CB26: 2542540 | CC26: 4276 | CD26: 329252 | CE26: 20885 | CF26: 1608145 | CG26: 7859 | CH26: 605143 | CI26: No.13
A27: 자연석철거 | B27: 6-8목 | D27: 324.9 | E27: =G27+I27+K27 -> 28374 | F27: =H27+J27+L27 -> 9218711 | G27: 3674 | H27: =TRUNC(G27*D27,0) -> 1193682 | I27: 17947 | J27: =TRUNC(I27*D27,0) -> 5830980 | K27: 6753 | L27: =TRUNC(K27*D27,0) -> 2194049 | O27: =IFERROR(N27/F27,0) -> 0 | P27: ='[2]철거공 집계표'!$J$16 -> 308.84 | Q27: =SUM(S27:U27) -> 8763025 | R27: =IFERROR(Q27/F27,0) -> 0.95056945 | S27: =TRUNC(G27*P27,0) -> 1134678 | T27: =TRUNC(I27*P27,0) -> 5542751 | U27: =TRUNC(K27*P27,0) -> 2085596 | X27: =IFERROR(W27/F27,0) -> 0
A28: 폐기물적재 | B28: 주간 | C28: M3 | D28: 2083.2899 | E28: =G28+I28+K28 -> 6563 | F28: =H28+J28+L28 -> 13672630 | G28: 1279 | H28: =TRUNC(G28*D28,0) -> 2664527 | I28: 3641 | J28: =TRUNC(I28*D28,0) -> 7585258 | K28: 1643 | L28: =TRUNC(K28*D28,0) -> 3422845 | O28: =IFERROR(N28/F28,0) -> 0 | P28: ='[2]토공 집계표'!$R$11 -> 390.13008 | Q28: =SUM(S28:U28) -> 2560422 | R28: =IFERROR(Q28/F28,0) -> 0.18726624 | S28: =TRUNC(G28*P28,0) -> 498976 | T28: =TRUNC(I28*P28,0) -> 1420463 | U28: =TRUNC(K28*P28,0) -> 640983 | X28: =IFERROR(W28/F28,0) -> 0 | AB28: 140 | AD28: K2010500 | AF28: A | BU28: =HYPERLINK("#일위대가목록!A15","K2010500 →") -> K2010500 → | CA28: 7639 | CB28: 11573085 | CC28: 1489 | CD28: 2255835 | CE28: 4237 | CF28: 6419055 | CG28: 1913 | CH28: 2898195 | CI28: No.14
E29: =G29+I29+K29 -> 0 | F29: =H29+J29+L29 -> 0 | H29: 0 | J29: 0 | L29: 0 | O29: =IFERROR(N29/F29,0) -> 0 | Q29: =SUM(S29:U29) -> 0 | R29: =IFERROR(Q29/F29,0) -> 0 | S29: =TRUNC(G29*P29,0) -> 0 | T29: =TRUNC(I29*P29,0) -> 0 | U29: =TRUNC(K29*P29,0) -> 0 | X29: =IFERROR(W29/F29,0) -> 0 | AB29: 160 | CA29: 0 | CB29: 0 | CD29: 0 | CF29: 0 | CH29: 0
A30: 2. 우수,오수,상수공 | C30: 식 | D30: 1 | F30: =H30+J30+L30 -> 249127758 | H30: =SUM(H31:H72) -> 69934323 | J30: =SUM(J31:J72) -> 169464217 | L30: =SUM(L31:L72) -> 9729218 | O30: =IFERROR(N30/F30,0) -> 0 | Q30: =SUM(S30:U30) -> 63349207 | R30: =IFERROR(Q30/F30,0) -> 0.25428402 | S30: =SUM(S31:S72) -> 22679324 | T30: =SUM(T31:T72) -> 38487046 | U30: =SUM(U31:U72) -> 2182837 | X30: =IFERROR(W30/F30,0) -> 0 | AA30: A02 | AL30: =H31+H32+H33+H34+H35+H36+H37+H38+H39+H40+H41+H42+H43+H44+H45+H46+H47+H48+H49+H51+H52+H54+H55+H56+H57+H58+H59+H60+H62+H63+H64+H65+H66+H67+H68+H69+H70 -> 62431907 | AM30: =J31+J32+J33+J34+J35+J36+J37+J38+J39+J40+J41+J42+J43+J44+J45+J46+J47+J48+J49+J51+J52+J54+J55+J56+J57+J58+J59+J60+J62+J63+J64+J65+J66+J67+J68+J69+J70 -> 167075637 | AN30: =L31+L32+L33+L34+L35+L36+L37+L38+L39+L40+L41+L42+L43+L44+L45+L46+L47+L48+L49+L51+L52+L54+L55+L56+L57+L58+L59+L60+L62+L63+L64+L65+L66+L67+L68+L69+L70 -> 9669334 | CB30: 223387024 | CD30: 42285506 | CF30: 170530411 | CH30: 10571107
A31: 터파기(기계) | B31: 토사 | C31: M3 | D31: 3318.57 | E31: =G31+I31+K31 -> 1374 | F31: =H31+J31+L31 -> 4559714 | G31: 329 | H31: =TRUNC(G31*D31,0) -> 1091809 | I31: 722 | J31: =TRUNC(I31*D31,0) -> 2396007 | K31: 323 | L31: =TRUNC(K31*D31,0) -> 1071898 | O31: =IFERROR(N31/F31,0) -> 0 | P31: =[3]배수공집계표!$C$45 -> 948.46 | Q31: =SUM(S31:U31) -> 1303183 | R31: =IFERROR(Q31/F31,0) -> 0.28580367 | S31: =TRUNC(G31*P31,0) -> 312043 | T31: =TRUNC(I31*P31,0) -> 684788 | U31: =TRUNC(K31*P31,0) -> 306352 | X31: =IFERROR(W31/F31,0) -> 0 | AB31: 10 | AD31: K1020118 | AF31: A | AL31: =H71+H72 -> 14976 | AM31: =J71+J72 -> 164058 | AN31: =L71+L72 -> 0 | BU31: =HYPERLINK("#일위대가목록!A8","K1020118 →") -> K1020118 → | CA31: 1600 | CB31: 4000000 | CC31: 383 | CD31: 957500 | CE31: 841 | CF31: 2102500 | CG31: 376 | CH31: 940000 | CI31: No.7
A32: 터파기(인력) | B32: 토사 | C32: M | D32: 680.23 | E32: =G32+I32+K32 -> 37331 | F32: =H32+J32+L32 -> 25393666 | G32: 0 | H32: =TRUNC(G32*D32,0) -> 0 | I32: 37331 | J32: =TRUNC(I32*D32,0) -> 25393666 | K32: 0 | L32: =TRUNC(K32*D32,0) -> 0 | O32: =IFERROR(N32/F32,0) -> 0 | P32: =[3]배수공집계표!$D$45 -> 246.26 | Q32: =SUM(S32:U32) -> 9193132 | R32: =IFERROR(Q32/F32,0) -> 0.36202461 | S32: =TRUNC(G32*P32,0) -> 0 | T32: =TRUNC(I32*P32,0) -> 9193132 | U32: =TRUNC(K32*P32,0) -> 0 | X32: =IFERROR(W32/F32,0) -> 0 | AB32: 20 | AD32: H1021200000 | AF32: T | BU32: =HYPERLINK("#일위대가목록!A42","H1021200000 →") -> H1021200000 → | CA32: 43441 | CB32: 19027158 | CC32: 0 | CD32: 0 | CE32: 43441 | CF32: 19027158 | CG32: 0 | CH32: 0 | CI32: No.15
A33: 흙쌓기 | B33: 주간(토사)(비다짐) | C33: M3 | D33: 706.68 | E33: =G33+I33+K33 -> 447 | F33: =H33+J33+L33 -> 315884 | G33: 138 | H33: =TRUNC(G33*D33,0) -> 97521 | I33: 195 | J33: =TRUNC(I33*D33,0) -> 137802 | K33: 114 | L33: =TRUNC(K33*D33,0) -> 80561 | O33: =IFERROR(N33/F33,0) -> 0 | P33: =[3]배수공집계표!$E$45 -> 197.26 | Q33: =SUM(S33:U33) -> 88173 | R33: =IFERROR(Q33/F33,0) -> 0.27913095 | S33: =TRUNC(G33*P33,0) -> 27221 | T33: =TRUNC(I33*P33,0) -> 38465 | U33: =TRUNC(K33*P33,0) -> 22487 | X33: =IFERROR(W33/F33,0) -> 0 | AB33: 30 | AD33: K1010241 | AF33: A | BU33: =HYPERLINK("#일위대가목록!A5","K1010241 →") -> K1010241 → | CA33: 521 | CB33: 295928 | CC33: 161 | CD33: 91448 | CE33: 227 | CF33: 128936 | CG33: 133 | CH33: 75544 | CI33: No.3
A34: 유용토운반 | B34: 주간(토사) | C34: M3 | D34: 706.68 | E34: =G34+I34+K34 -> 1276 | F34: =H34+J34+L34 -> 901722 | G34: 394 | H34: =TRUNC(G34*D34,0) -> 278431 | I34: 556 | J34: =TRUNC(I34*D34,0) -> 392914 | K34: 326 | L34: =TRUNC(K34*D34,0) -> 230377 | O34: =IFERROR(N34/F34,0) -> 0 | P34: =[3]배수공집계표!$E$45 -> 197.26 | Q34: =SUM(S34:U34) -> 251702 | R34: =IFERROR(Q34/F34,0) -> 0.27913481 | S34: =TRUNC(G34*P34,0) -> 77720 | T34: =TRUNC(I34*P34,0) -> 109676 | U34: =TRUNC(K34*P34,0) -> 64306 | X34: =IFERROR(W34/F34,0) -> 0 | AB34: 40 | AD34: K1010250 | AF34: A | BU34: =HYPERLINK("#일위대가목록!A6","K1010250 →") -> K1010250 → | CA34: 1487 | CB34: 844616 | CC34: 459 | CD34: 260712 | CE34: 648 | CF34: 368064 | CG34: 380 | CH34: 215840 | CI34: No.4
A35: 되메우기및다짐(기계) | B35: 토사 | C35: M3 | D35: 2723.82 | E35: =G35+I35+K35 -> 11478 | F35: =H35+J35+L35 -> 31264004 | G35: 908 | H35: =TRUNC(G35*D35,0) -> 2473228 | I35: 9446 | J35: =TRUNC(I35*D35,0) -> 25729203 | K35: 1124 | L35: =TRUNC(K35*D35,0) -> 3061573 | O35: =IFERROR(N35/F35,0) -> 0 | P35: =[3]배수공집계표!$F$45 -> 790.7 | Q35: =SUM(S35:U35) -> 9075653 | R35: =IFERROR(Q35/F35,0) -> 0.29029081 | S35: =TRUNC(G35*P35,0) -> 717955 | T35: =TRUNC(I35*P35,0) -> 7468952 | U35: =TRUNC(K35*P35,0) -> 888746 | X35: =IFERROR(W35/F35,0) -> 0 | AB35: 50 | AD35: K1040213 | AF35: A | BU35: =HYPERLINK("#일위대가목록!A9","K1040213 →") -> K1040213 → | CA35: 13359 | CB35: 26731359 | CC35: 1057 | CD35: 2115057 | CE35: 10993 | CF35: 21996993 | CG35: 1309 | CH35: 2619309 | CI35: No.8
A36: 되메우기및다짐(인력) | B36: 토사 | C36: M3 | D36: 568.29 | E36: =G36+I36+K36 -> 22664 | F36: =H36+J36+L36 -> 12879723 | G36: 554 | H36: =TRUNC(G36*D36,0) -> 314832 | I36: 21363 | J36: =TRUNC(I36*D36,0) -> 12140379 | K36: 747 | L36: =TRUNC(K36*D36,0) -> 424512 | O36: =IFERROR(N36/F36,0) -> 0 | P36: =[3]배수공집계표!$G$45 -> 206.76 | Q36: =SUM(S36:U36) -> 4686007 | R36: =IFERROR(Q36/F36,0) -> 0.36382824 | S36: =TRUNC(G36*P36,0) -> 114545 | T36: =TRUNC(I36*P36,0) -> 4417013 | U36: =TRUNC(K36*P36,0) -> 154449 | X36: =IFERROR(W36/F36,0) -> 0 | AB36: 60 | AD36: K1040214 | AF36: A | BU36: =HYPERLINK("#일위대가목록!A16","K1040214 →") -> K1040214 → | CA36: 26375 | CB36: 9732375 | CC36: 645 | CD36: 238005 | CE36: 24860 | CF36: 9173340 | CG36: 870 | CH36: 321030 | CI36: No.16
A37: 기초잡석부설및다짐 | C37: M3 | D37: 101.72 | E37: =G37+I37+K37 -> 34190 | F37: =H37+J37+L37 -> 3477805 | G37: 23880 | H37: =TRUNC(G37*D37,0) -> 2429073 | I37: 9294 | J37: =TRUNC(I37*D37,0) -> 945385 | K37: 1016 | L37: =TRUNC(K37*D37,0) -> 103347 | O37: =IFERROR(N37/F37,0) -> 0 | P37: =[3]배수공집계표!$H$45 -> 15.28 | Q37: =SUM(S37:U37) -> 522422 | R37: =IFERROR(Q37/F37,0) -> 0.15021601 | S37: =TRUNC(G37*P37,0) -> 364886 | T37: =TRUNC(I37*P37,0) -> 142012 | U37: =TRUNC(K37*P37,0) -> 15524 | X37: =IFERROR(W37/F37,0) -> 0 | AB37: 70 | AD37: K2030210 | AF37: T | BU37: =HYPERLINK("#일위대가목록!A43","K2030210 →") -> K2030210 → | CA37: 39788 | CB37: 4893924 | CC37: 27789 | CD37: 3418047 | CE37: 10816 | CF37: 1330368 | CG37: 1183 | CH37: 145509 | CI37: No.17
A38: 모래채움및다짐 | C38: M3 | D38: 186.53 | E38: =G38+I38+K38 -> 47173 | F38: =H38+J38+L38 -> 8799179 | G38: 42722 | H38: =TRUNC(G38*D38,0) -> 7968934 | I38: 4051 | J38: =TRUNC(I38*D38,0) -> 755633 | K38: 400 | L38: =TRUNC(K38*D38,0) -> 74612 | O38: =IFERROR(N38/F38,0) -> 0 | P38: =[3]배수공집계표!$I$45 -> 73.89 | Q38: =SUM(S38:U38) -> 3485612 | R38: =IFERROR(Q38/F38,0) -> 0.39612923 | S38: =TRUNC(G38*P38,0) -> 3156728 | T38: =TRUNC(I38*P38,0) -> 299328 | U38: =TRUNC(K38*P38,0) -> 29556 | X38: =IFERROR(W38/F38,0) -> 0 | AB38: 80 | AD38: K1050214-1 | AF38: A | BU38: =HYPERLINK("#일위대가목록!A17","K1050214-1 →") -> K1050214-1 → | CA38: 54894 | CB38: 3403428 | CC38: 49714 | CD38: 3082268 | CE38: 4714 | CF38: 292268 | CG38: 466 | CH38: 28892 | CI38: No.18
A39: CON'C 타설(굴삭기) | B39: 무근 | C39: M3 | D39: 66.16 | E39: =G39+I39+K39 -> 24221 | F39: =H39+J39+L39 -> 1602460 | G39: 2146 | H39: =TRUNC(G39*D39,0) -> 141979 | I39: 19290 | J39: =TRUNC(I39*D39,0) -> 1276226 | K39: 2785 | L39: =TRUNC(K39*D39,0) -> 184255 | O39: =IFERROR(N39/F39,0) -> 0 | P39: =[3]배수공집계표!$J$45 -> 8.94 | Q39: =SUM(S39:U39) -> 216534 | R39: =IFERROR(Q39/F39,0) -> 0.13512599 | S39: =TRUNC(G39*P39,0) -> 19185 | T39: =TRUNC(I39*P39,0) -> 172452 | U39: =TRUNC(K39*P39,0) -> 24897 | X39: =IFERROR(W39/F39,0) -> 0 | AB39: 90 | AD39: K3021812 | AF39: A | BU39: =HYPERLINK("#일위대가목록!A18","K3021812 →") -> K3021812 → | CA39: 28187 | CB39: 2226773 | CC39: 2498 | CD39: 197342 | CE39: 22448 | CF39: 1773392 | CG39: 3241 | CH39: 256039 | CI39: No.19
A40: CON'C 타설(펌프차) | B40: 철근 | C40: M3 | D40: 128.33 | E40: =G40+I40+K40 -> 29433 | F40: =H40+J40+L40 -> 3777135 | G40: 2433 | H40: =TRUNC(G40*D40,0) -> 312226 | I40: 21892 | J40: =TRUNC(I40*D40,0) -> 2809400 | K40: 5108 | L40: =TRUNC(K40*D40,0) -> 655509 | O40: =IFERROR(N40/F40,0) -> 0 | P40: =[3]배수공집계표!$K$45 -> 25.66 | Q40: =SUM(S40:U40) -> 755249 | R40: =IFERROR(Q40/F40,0) -> 0.19995287 | S40: =TRUNC(G40*P40,0) -> 62430 | T40: =TRUNC(I40*P40,0) -> 561748 | U40: =TRUNC(K40*P40,0) -> 131071 | X40: =IFERROR(W40/F40,0) -> 0 | AB40: 100 | AD40: K3032412 | AF40: A | BU40: =HYPERLINK("#일위대가목록!A19","K3032412 →") -> K3032412 → | CA40: 34252 | CB40: 4692524 | CC40: 2832 | CD40: 387984 | CE40: 25476 | CF40: 3490212 | CG40: 5944 | CH40: 814328 | CI40: No.20
...

Sheet 일위대가목록(신규)
A1: 일위대가목록(신규)
A2: 공 종 명 | B2: 규 격 | C2: 수 량 | D2: 단 위 | E2: 합 계 | F2: 재 료 비 | G2: 노 무 비 | H2: 경 비 | I2: 비 고 | T2: 재료비 | U2: 노무비 | V2: 경 비 | W2: 합 계 | Y2: 비교검토
A3: #11 터파기 | B3: BH 0.6M3, 인력10% | C3: 1 | D3: m3 | E3: =F3+G3+H3 -> 4950 | F3: =[4]일위대가_산근!C4 -> 292 | G3: =[4]일위대가_산근!D4 -> 4277 | H3: =[4]일위대가_산근!E4 -> 381 | K3: N1070 | L3: F | T3: 275 | U3: 4277 | V3: 381 | W3: 4933 | Y3: =EXACT($E3,$W3) -> FALSE
A4: #12 잔토처리 | B4: BH 0.6M3 | C4: 1 | D4: m3 | E4: =F4+G4+H4 -> 1561 | F4: =[4]일위대가_산근!C35 -> 278 | G4: =[4]일위대가_산근!D35 -> 920 | H4: =[4]일위대가_산근!E35 -> 363 | K4: N0860 | L4: F | T4: 261 | U4: 920 | V4: 363 | W4: 1544 | Y4: =EXACT($E4,$W4) -> FALSE
A5: #13 되메우기및다짐 | B5: BH 0.6M3, P.C 1.5ton, 인력10% | C5: 1 | D5: m3 | E5: =F5+G5+H5 -> 6988 | F5: =[4]일위대가_산근!C60 -> 440 | G5: =[4]일위대가_산근!D60 -> 6160 | H5: =[4]일위대가_산근!E60 -> 388 | K5: N1010 | L5: F | T5: 396 | U5: 6160 | V5: 370 | W5: 6926 | Y5: =EXACT($E5,$W5) -> FALSE
A6: #14 혼합골재부설 및 다짐 | B6: 기계:인력=9:1 | C6: 1 | D6: m3 | E6: =F6+G6+H6 -> 10702 | F6: =[4]일위대가_산근!C93 -> 1075 | G6: =[4]일위대가_산근!D93 -> 8587 | H6: =[4]일위대가_산근!E93 -> 1040 | K6: N0300 | L6: F | T6: 1013 | U6: 8589 | V6: 1041 | W6: 10643 | Y6: =EXACT($E6,$W6) -> FALSE
A7: ='일위대가_호표(신규)'!A3 -> No.1 PE관 설치 | B7: ='일위대가_호표(신규)'!B3 -> Φ200 | E7: =F7+G7+H7 -> 25314 | F7: ='일위대가_호표(신규)'!H9 -> 18130 | G7: ='일위대가_호표(신규)'!J9 -> 6976 | H7: ='일위대가_호표(신규)'!L9 -> 208
A8: ='일위대가_호표(신규)'!A11 -> No.2 스틸그레이팅 설치 | B8: ='일위대가_호표(신규)'!B11 -> 무소음닥타일 | C8: ='일위대가_호표(신규)'!C11 -> 1 | D8: ='일위대가_호표(신규)'!D11 -> M2 | E8: =F8+G8+H8 -> 285978 | F8: ='일위대가_호표(신규)'!H14 -> 272360 | G8: ='일위대가_호표(신규)'!J14 -> 13618 | H8: ='일위대가_호표(신규)'!L14 -> 0
A9: ='일위대가_호표(신규)'!A16 -> No.3 유공관설치 | B9: ='일위대가_호표(신규)'!B16 -> W310 | C9: ='일위대가_호표(신규)'!C16 -> 1 | D9: ='일위대가_호표(신규)'!D16 -> m | E9: =F9+G9+H9 -> 31404 | F9: ='일위대가_호표(신규)'!H24 -> 21691 | G9: ='일위대가_호표(신규)'!J24 -> 9515 | H9: ='일위대가_호표(신규)'!L24 -> 198
A10: ='일위대가_호표(신규)'!A26 -> No.4 P.V.C관 접합 및 부설 | B10: ='일위대가_호표(신규)'!B26 -> 고무링접합,150m적용 | C10: ='일위대가_호표(신규)'!C26 -> 1 | D10: ='일위대가_호표(신규)'!D26 -> m | E10: =F10+G10+H10 -> 7175 | F10: ='일위대가_호표(신규)'!H29 -> 0 | G10: ='일위대가_호표(신규)'!J29 -> 7175 | H10: ='일위대가_호표(신규)'!L29 -> 0
A11: ='일위대가_호표(신규)'!A31 -> No.5 가설방음벽(RPP) | B11: ='일위대가_호표(신규)'!B31 -> 방음벽3m+방진망1m | C11: 1 | D11: m | E11: =F11+G11+H11 -> 91887 | F11: ='일위대가_호표(신규)'!H33 -> 358 | G11: ='일위대가_호표(신규)'!J33 -> 36530 | H11: ='일위대가_호표(신규)'!L33 -> 54999

Sheet 일위대가_호표(신규)
A1: 공 종 명 | B1: 규 격 | C1: 수량 | D1: 단위 | E1: 합 계 | G1: 재 료 비 | I1: 노 무 비 | K1: 경 비 | M1: 비 고
E2: 단 가 | F2: 금 액 | G2: 단 가 | H2: 금 액 | I2: 단 가 | J2: 금 액 | K2: 단 가 | L2: 금 액 | S2: 할 증 | T2: 화폐변환 | U2: OP값 | V2: EQ | W2: LA | X2: MA | Y2: 금액계상
A3: No.1 PE관 설치 | B3: Φ200 | C3: 1 | D3: M | F3: =H3+J3+L3 -> 29000 | H3: =TRUNC(H5+H6+H7+H8,0) -> 20769 | J3: =TRUNC(J5+J6+J7+J8,0) -> 7992 | L3: =TRUNC(L5+L6+L7+L8,0) -> 239 | O3: K50200200
A4: (2025년 건설공사표준품셈 6-5-2 밴드 접합 및 부설 | E4: =G4+I4+K4 -> 0 | F4: =H4+J4+L4 -> 0 | H4: 0 | J4: 0 | L4: 0 | P4: 10
A5: PE관 | B5: Φ200mm | C5: 1.05 | D5: M | E5: =G5+I5+K5 -> 19780 | F5: =H5+J5+L5 -> 20769 | G5: =[4]자재조서!E5 -> 19780 | H5: =TRUNC(G5*C5,0) -> 20769 | I5: 0 | K5: 0 | P5: 20 | R5: M5380200
A6: 배 관 공(부설)(2/13/6) | C6: 0.0256 | D6: 인 | E6: =G6+I6+K6 -> 229482 | F6: =H6+J6+L6 -> 5874 | G6: 0 | I6: =[4]노임!D3 -> 229482 | J6: =TRUNC(I6*C6,0) -> 5874 | K6: 0 | N6: 56900017030 | P6: 30 | R6: L028
A7: 보통인부(부설)(1/13/6) | C7: 0.0128 | D7: 인 | E7: =G7+I7+K7 -> 165545 | F7: =H7+J7+L7 -> 2118 | G7: 0 | I7: =[4]노임!D4 -> 165545 | J7: =TRUNC(I7*C7,0) -> 2118 | K7: 0 | P7: 40 | R7: L085
A8: 공구손료 | B8: 인력품의3% | C8: 1 | D8: 식 | E8: =G8+I8+K8 -> 0 | F8: =H8+J8+L8 -> 239 | H8: 0 | J8: 0 | L8: =TRUNC((((J6*[4]전역변수!C34)+(J7*[4]전역변수!C34))*0.03),0) -> 239 | P8: 50 | R8: F | X8: EQ=LA(30,0,40)*0.03 | AA8: EQ+ = | AB8: =(('일위대가_호표(신규)'!J6*[4]전역변수!C34)+('일위대가_호표(신규)'!J7*[4]전역변수!C34))*0.03 -> 239.76 | AC8: EQ = | AD8: =$AB7 -> 0
A9: 낙찰율적용 | B9: 87.295% | F9: =H9+J9+L9 -> 25314 | H9: =TRUNC(H3*$B9) -> 18130 | J9: =TRUNC(J3*$B9) -> 6976 | L9: =TRUNC(L3*$B9) -> 208 | P9: 60
A11: No.2 스틸그레이팅 설치 | B11: 무소음닥타일 | C11: 1 | D11: M2 | F11: =H11+J11+L11 -> 327600 | H11: =TRUNC(H12,0) -> 312000 | J11: =TRUNC(J13,0) -> 15600 | L11: =TRUNC(L13,0) -> 0 | O11: K60000210
A12: 스틸그레이팅 | B12: 중하중 395*995*52 | C12: 1 | D12: M2 | E12: =G12+I12+K12 -> 312000 | F12: =H12+J12+L12 -> 312000 | G12: =[4]자재조서!E4 -> 312000 | H12: =TRUNC(G12*C12,0) -> 312000 | I12: 0 | K12: 0 | P12: 10 | Q12: * | R12: M1572002
A13: 설치비 | B13: 재료비의5% | C13: 1 | D13: 식 | E13: =G13+I13+K13 -> 0 | F13: =H13+J13+L13 -> 15600 | H13: 0 | J13: =TRUNC((H12*5/100),0) -> 15600 | L13: 0 | P13: 20 | R13: F | X13: .LA=MA(10)*5/100 | AA13: LA+ = | AB13: ='일위대가_호표(신규)'!H12*5/100 -> 15600 | AC13: LA = | AD13: =$AB12 -> 0
A14: 낙찰율적용 | B14: 87.295% | F14: =H14+J14+L14 -> 285978 | H14: =TRUNC(H11*$B14) -> 272360 | J14: =TRUNC(J11*$B14) -> 13618 | L14: =TRUNC(L11*$B14) -> 0 | P14: 60
A16: No.3 유공관설치 | B16: W310 | C16: 1 | D16: m | F16: =H16+J16+L16 -> 35975 | H16: =TRUNC(H17+H18+H19+H20+H21+H22+H23,0) -> 24848 | J16: =TRUNC(J17+J18+J19+J20+J21+J22+J23,0) -> 10900 | L16: =TRUNC(L17+L18+L19+L20+L21+L22+L23,0) -> 227 | O16: HW0081
A17: 터파기 | B17: BH 0.6M3, 인력10% | C17: 0.25 | D17: m3 | E17: =G17+I17+K17 -> 4950 | F17: =H17+J17+L17 -> 1237 | G17: =[4]일위대가목록!F3 -> 292 | H17: =TRUNC(G17*C17,0) -> 73 | I17: =[4]일위대가목록!G3 -> 4277 | J17: =TRUNC(I17*C17,0) -> 1069 | K17: =[4]일위대가목록!H3 -> 381 | L17: =TRUNC(K17*C17,0) -> 95 | P17: 10 | R17: N1070 | T17: F
A18: 잔토처리 | B18: BH 0.6M3 | C18: 0.04 | D18: m3 | E18: =G18+I18+K18 -> 1561 | F18: =H18+J18+L18 -> 61 | G18: =[4]일위대가목록!F4 -> 278 | H18: =TRUNC(G18*C18,0) -> 11 | I18: =[4]일위대가목록!G4 -> 920 | J18: =TRUNC(I18*C18,0) -> 36 | K18: =[4]일위대가목록!H4 -> 363 | L18: =TRUNC(K18*C18,0) -> 14 | P18: 20 | R18: N0860 | T18: F
A19: 되메우기및다짐 | B19: BH 0.6M3, 램머, 인력10% | C19: 0.2 | D19: m3 | E19: =G19+I19+K19 -> 6988 | F19: =H19+J19+L19 -> 1397 | G19: =[4]일위대가목록!F5 -> 440 | H19: =TRUNC(G19*C19,0) -> 88 | I19: =[4]일위대가목록!G5 -> 6160 | J19: =TRUNC(I19*C19,0) -> 1232 | K19: =[4]일위대가목록!H5 -> 388 | L19: =TRUNC(K19*C19,0) -> 77 | P19: 30 | R19: N1010 | T19: F
A20: 혼합골재 | B20: 보조기층용 | C20: 0.042 | D20: m3 | E20: =G20+I20+K20 -> 24000 | F20: =H20+J20+L20 -> 1008 | G20: =[4]자재조서!E6 -> 24000 | H20: =TRUNC(G20*C20,0) -> 1008 | I20: 0 | K20: 0 | P20: 40 | R20: MB-4500
A21: 혼합골재부설 및 다짐 | B21: 기계:인력=8:2 | C21: 0.04 | D21: m3 | E21: =G21+I21+K21 -> 10702 | F21: =H21+J21+L21 -> 427 | G21: =[4]일위대가목록!F6 -> 1075 | H21: =TRUNC(G21*C21,0) -> 43 | I21: =[4]일위대가목록!G6 -> 8587 | J21: =TRUNC(I21*C21,0) -> 343 | K21: =[4]일위대가목록!H6 -> 1040 | L21: =TRUNC(K21*C21,0) -> 41 | P21: 50 | R21: N0300 | T21: F
A22: 메가플로 파이프 | B22: T40,W310 | C22: 1.05 | D22: m | E22: =G22+I22+K22 -> 22500 | F22: =H22+J22+L22 -> 23625 | G22: =[4]자재조서!E7 -> 22500 | H22: =TRUNC(G22*C22,0) -> 23625 | I22: 0 | K22: 0 | P22: 60 | R22: MW-502
A23: P.V.C관 접합 및 부설 | B23: 고무링접합,150m적용 | C23: 1 | D23: m | E23: =G23+I23+K23 -> 8220 | F23: =H23+J23+L23 -> 8220 | G23: =[4]일위대가목록!F10 -> 0 | H23: =TRUNC(G23*C23,0) -> 0 | I23: =[4]일위대가목록!G10 -> 8220 | J23: =TRUNC(I23*C23,0) -> 8220 | K23: =[4]일위대가목록!H10 -> 0 | L23: =TRUNC(K23*C23,0) -> 0 | P23: 70 | R23: SBC7101 | T23: T
A24: 낙찰율적용 | B24: 87.295% | F24: =H24+J24+L24 -> 31404 | H24: =TRUNC(H16*$B24) -> 21691 | J24: =TRUNC(J16*$B24) -> 9515 | L24: =TRUNC(L16*$B24) -> 198 | P24: 60
A26: No.4 P.V.C관 접합 및 부설 | B26: 고무링접합,150m적용 | C26: 1 | D26: m | F26: =H26+J26+L26 -> 8220 | H26: =TRUNC(H27+H28,0) -> 0 | J26: =TRUNC(J27+J28,0) -> 8220 | L26: =TRUNC(L27+L28,0) -> 0 | O26: SBC7101
A27: 배 관 공 | C27: 0.025 | D27: 인 | E27: =G27+I27+K27 -> 229482 | F27: =H27+J27+L27 -> 5737 | G27: 0 | I27: =[4]노임!D3 -> 229482 | J27: =TRUNC(I27*C27,0) -> 5737 | K27: 0 | N27: 56900017030 | P27: 5 | R27: L028
A28: 보통인부 | C28: 0.015 | D28: 인 | E28: =G28+I28+K28 -> 165545 | F28: =H28+J28+L28 -> 2483 | G28: 0 | I28: =[4]노임!D4 -> 165545 | J28: =TRUNC(I28*C28,0) -> 2483 | K28: 0 | N28: 56900017041 | P28: 10 | R28: L085
A29: 낙찰율적용 | B29: 87.295% | F29: =H29+J29+L29 -> 7175 | H29: =TRUNC(H26*$B29) -> 0 | J29: =TRUNC(J26*$B29) -> 7175 | L29: =TRUNC(L26*$B29) -> 0 | P29: 60
A31: No.5 가설방음벽(RPP) | B31: 방음벽3m+방진망1m | C31: 1 | D31: m | F31: =H31+J31+L31 -> 105262 | H31: =H32 -> 411 | J31: =J32 -> 41847 | L31: =L32 -> 63004 | O31: SBC7101
A32: 가설방음벽(RPP) | B32: H=4.0m(방음3m+방진1m) | C32: 1 | D32: m | E32: =G32+I32+K32 -> 105262 | F32: =H32+J32+L32 -> 105262 | G32: ='일위대가_산근 (신규)'!C208 -> 411 | H32: =TRUNC(G32*$C$32,0) -> 411 | I32: ='일위대가_산근 (신규)'!D208 -> 41847 | J32: =TRUNC(I32*$C$32,0) -> 41847 | K32: ='일위대가_산근 (신규)'!E208 -> 63004 | L32: =TRUNC(K32*$C$32,0) -> 63004
A33: 낙찰율적용 | B33: 87.295% | F33: =H33+J33+L33 -> 91887 | H33: =TRUNC(H31*$B$33,0) -> 358 | J33: =TRUNC(J31*$B$33,0) -> 36530 | L33: =TRUNC(L31*$B$33,0) -> 54999 | P33: 60

Sheet 일위대가_산근 (신규)
A1: 일위대가_산근
A2: 산 출 근 거 | B2: 합 계 | C2: 재 료 비 | D2: 노 무 비 | E2: 경 비 | F2: 비 고
AA3: ※ 노란색 셀을 수정하고 툴바에서 수식 > 시트계산을 하면
A4: #11 터파기 | BH 0.6M3, 인력10%|m3 | B4: =$B33 -> 4950 | C4: =$C33 -> 292 | D4: =$D33 -> 4277 | E4: =$E33 -> 381 | H4: N1070 | K4: 1 | Y4: =EXACT($Z4,$B33) -> FALSE | Z4: 4933 | AA4: 엑셀 수식이 적용됩니다. (단축키 F9 키)
I6: 30 | K6: F
A8: 터파기(백호우0.6M3 90%):M3 | K8: '터파기(백호우0.6M3 90%):M3 '
A10: =CONCATENATE(" q=",TEXT($AB10,"#,##0.0"),", K=",TEXT($AF10,"#,##0.00"),", E=",TEXT($AJ10,"#,##0.0")) -> q=0.6, K=0.90, E=0.6 | K10: =SUBSTITUTE(SUBSTITUTE(SUBSTITUTE(SUBSTITUTE(" q=0.6, K=0.90, E=0.6","0.6",TEXT($AB10,"#,##0.0"),1),"0.90",TEXT($AF10,"#,##0.00"),1),"0.6",TEXT($AJ10,"#,##0.0"),2),"_x001D_","'") -> q=0.6, K=0.90, E=0.6 | AA10: Q = | AB10: 0.6 | AC10: Q = | AD10: =$AB10 -> 0.6 | AE10: K = | AF10: 0.9 | AG10: K = | AH10: =$AF10 -> 0.9 | AI10: E = | AJ10: 0.6 | AK10: E = | AL10: =$AJ10 -> 0.6
A12: =CONCATENATE(" CM=",TEXT($AB12,"#,##0.00")," sec(90°) , F=",TEXT($AF12,"#,##0.0")) -> CM=18.00 sec(90°) , F=0.8 | K12: =SUBSTITUTE(SUBSTITUTE(SUBSTITUTE(" CM=18_x001D_sec(90°)_x001D_, F=0.8","18",TEXT($AB12,"#,##0"),1),"0.8",TEXT($AF12,"#,##0.0"),1),"_x001D_","'") -> CM=18'sec(90°)', F=0.8 | AA12: CM = | AB12: 18 | AC12: CM = | AD12: =$AB12 -> 18 | AE12: F = | AF12: 0.8 | AG12: F = | AH12: =$AF12 -> 0.8
A14: =CONCATENATE(" Q=(3600*",TEXT($AB14,"#,##0.00"),"*",TEXT($AF14,"#,##0.00"),"*",TEXT($AJ14,"#,##0.00"),"*",TEXT($AN14,"#,##0.00"),")/",TEXT($AR14,"#,##0.00"),"=",TEXT($AZ14,"#,##0.00")," M3/HR ") -> Q=(3600*0.60*0.90*0.80*0.60)/18.00=51.84 M3/HR | B14: =SUM($C14,$D14,$E14) -> 0 | K14: Q=(3600*{q}*{K}*{F}*{E})/{CM}=?'M3/HR' | AA14: 14_1_1+ = | AB14: =$AD10 -> 0.6 | AC14: 14_1_1 = | AD14: =$AB14 -> 0.6 | AE14: 14_1_2+ = | AF14: =$AH10 -> 0.9 | AG14: 14_1_2 = | AH14: =$AF14 -> 0.9 | AI14: 14_1_3+ = | AJ14: =$AH12 -> 0.8 | AK14: 14_1_3 = | AL14: =$AJ14 -> 0.8 | AM14: 14_1_4+ = | AN14: =$AL10 -> 0.6 | AO14: 14_1_4 = | AP14: =$AN14 -> 0.6 | AQ14: 14_1_5+ = | AR14: =$AD12 -> 18 | AS14: 14_1_5 = | AT14: =$AR14 -> 18 | AU14: Q+ = | AV14: =ROUND((3600*$AD14*$AH14*$AL14*$AP14)/$AT14,2) -> 51.84 | AW14: Q = | AX14: =$AV14 -> 51.84 | AY14: 14_1_6+ = | AZ14: =ROUND((3600*$AD14*$AH14*$AL14*$AP14)/$AT14,2) -> 51.84 | BA14: 14_1_6 = | BB14: =$AZ14 -> 51.84
A17: =CONCATENATE(" 재 료 비 : ",TEXT($AB17,"#,##0.00"),"/",TEXT($AF17,"#,##0.00"),"*0.9 =",TEXT($AJ17,"#,##0.00")) -> 재 료 비 : 16,824.00/51.84*0.9 =292.00 | B17: =SUM($C17,$D17,$E17) -> 292 | C17: =$AJ17 -> 292 | K17: '재 료 비 : '~E0002010060.M~/{Q}*0.9 =?MA+ | AA17: 17_1_1+ = | AB17: =[4]중기사용료목록!E3 -> 16824 | AC17: 17_1_1 = | AD17: =$AB17 -> 16824 | AE17: 17_1_2+ = | AF17: =$AX14 -> 51.84 | AG17: 17_1_2 = | AH17: =$AF17 -> 51.84 | AI17: MA+ = | AJ17: =TRUNC($AD17/$AH17*0.9,0) -> 292 | AK17: MA = | AL17: =$AJ17 -> 292
A19: =CONCATENATE(" 노 무 비 : ",TEXT($AB19,"#,##0.00"),"/",TEXT($AF19,"#,##0.00"),"*0.9 =",TEXT($AJ19,"#,##0.00")) -> 노 무 비 : 55,700.00/51.84*0.9 =967.00 | B19: =SUM($C19,$D19,$E19) -> 967 | D19: =$AJ19 -> 967 | K19: '노 무 비 : '~E0002010060.L~/{Q}*0.9 =?LA+ | AA19: 19_1_1+ = | AB19: =[4]중기사용료목록!F3 -> 55700 | AC19: 19_1_1 = | AD19: =$AB19 -> 55700 | AE19: 19_1_2+ = | AF19: =$AX14 -> 51.84 | AG19: 19_1_2 = | AH19: =$AF19 -> 51.84 | AI19: LA+ = | AJ19: =TRUNC($AD19/$AH19*0.9,0) -> 967 | AK19: LA = | AL19: =$AJ19 -> 967
A21: =CONCATENATE(" 경 비 : ",TEXT($AB21,"#,##0.00"),"/",TEXT($AF21,"#,##0.00"),"*0.9 =",TEXT($AJ21,"#,##0.00")) -> 경 비 : 21,957.00/51.84*0.9 =381.00 | B21: =SUM($C21,$D21,$E21) -> 381 | E21: =$AJ21 -> 381 | K21: '경 비 : '~E0002010060.E~/{Q}*0.9 =?EQ+ | AA21: 21_1_1+ = | AB21: =[4]중기사용료목록!G3 -> 21957 | AC21: 21_1_1 = | AD21: =$AB21 -> 21957 | AE21: 21_1_2+ = | AF21: =$AX14 -> 51.84 | AG21: 21_1_2 = | AH21: =$AF21 -> 51.84 | AI21: EQ+ = | AJ21: =TRUNC($AD21/$AH21*0.9,0) -> 381 | AK21: EQ = | AL21: =$AJ21 -> 381
A23: 소계 : | B23: =SUM($C23,$D23,$E23) -> 1640 | C23: =$AB23 -> 292 | D23: =$AD23 -> 967 | E23: =$AF23 -> 381 | K23: > ' 소계 : ' | AA23: >MA = | AB23: =$AL17 -> 292 | AC23: >LA = | AD23: =$AL19 -> 967 | AE23: >EQ = | AF23: =$AL21 -> 381
A25: 터파기(인력10%):M3 | K25: '터파기(인력10%):M3 '
A27: =CONCATENATE(" 노 무 비 : ",TEXT($AB27,"#,##0.00"),"*0.2*0.1 =",TEXT($AF27,"#,##0.00")) -> 노 무 비 : 165,545.00*0.2*0.1 =3,310.00 | B27: =SUM($C27,$D27,$E27) -> 3310 | D27: =$AF27 -> 3310 | K27: '노 무 비 : '~L085~*0.2*0.1 =?LA+ | AA27: 27_1_1+ = | AB27: =([4]노임!D4*[4]전역변수!C34) -> 165545 | AC27: 27_1_1 = | AD27: =$AB27 -> 165545 | AE27: LA+ = | AF27: =TRUNC($AD27*0.2*0.1,0) -> 3310 | AG27: LA = | AH27: =$AL19+$AF27 -> 4277
A29: 소계 : | B29: =SUM($C29,$D29,$E29) -> 3310 | C29: =$AB29 -> 0 | D29: =$AD29 -> 3310 | E29: =$AF29 -> 0 | K29: > ' 소계 : ' | AA29: >MA = | AB29: =$AL17-$AL17 -> 0 | AC29: >LA = | AD29: =$AH27-$AL19 -> 3310 | AE29: >EQ = | AF29: =$AL21-$AL21 -> 0
A31: 합계 : | B31: =SUM($C31,$D31,$E31) -> 4950 | C31: =$AB31 -> 292 | D31: =$AD31 -> 4277 | E31: =$AF31 -> 381 | K31: >> ' 합계 : ' | AA31: >>MA = | AB31: =$AL17 -> 292 | AC31: >>LA = | AD31: =$AH27 -> 4277 | AE31: >>EQ = | AF31: =$AL21 -> 381
A33: 전체 합계 | B33: =SUM($C33,$D33,$E33) -> 4950 | C33: =TRUNC(SUM($AL17),0) -> 292 | D33: =TRUNC(SUM($AH27),0) -> 4277 | E33: =TRUNC(SUM($AL21),0) -> 381
A35: #12 잔토처리 | BH 0.6M3|m3 | B35: =$B58 -> 1561 | C35: =$C58 -> 278 | D35: =$D58 -> 920 | E35: =$E58 -> 363 | H35: N0860 | K35: 1 | Y35: =EXACT($Z35,$B58) -> FALSE | Z35: 1544
I37: 10 | K37: F
A38: ◈ 잔토처리(잔토) (굴삭기0.6㎥,덤프15T)/M3 | K38: ' ◈ 잔토처리(잔토) (굴삭기0.6㎥,덤프15T)/M3'
A40: 1) 상 차 (굴삭기 0.6㎥) | K40: 1) 상 차 (굴삭기 0.6㎥)
A42: =CONCATENATE(" q=",TEXT($AB42,"#,##0.0"),", K=",TEXT($AF42,"#,##0.0"),", L=",TEXT($AJ42,"#,##0.00")) -> q=0.6, K=0.9, L=1.25 | K42: =SUBSTITUTE(SUBSTITUTE(SUBSTITUTE(SUBSTITUTE(" q = 0.6, K = 0.9, L = 1.25","0.6",TEXT($AB42,"#,##0.0"),1),"0.9",TEXT($AF42,"#,##0.0"),1),"1.25",TEXT($AJ42,"#,##0.00"),1),"_x001D_","'") -> q = 0.6, K = 0.9, L = 1.25 | AA42: Q = | AB42: 0.6 | AC42: Q = | AD42: =$AB42 -> 0.6 | AE42: K = | AF42: 0.9 | AG42: K = | AH42: =$AF42 -> 0.9 | AI42: L = | AJ42: 1.25 | AK42: L = | AL42: =$AJ42 -> 1.25
A44: =CONCATENATE(" f = 1/",TEXT($AB44,"#,##0.00")," = "," , E1=",TEXT($AN44,"#,##0.0"),", Cm=",TEXT($AR44,"#,##0.00")," sec(135°) ") -> f = 1/1.25 = , E1=0.7, Cm=18.00 sec(135°) | B44: =SUM($C44,$D44,$E44) -> 0 | K44: =SUBSTITUTE(SUBSTITUTE(SUBSTITUTE(" f = 1/{L} = ? , E1 = 0.7, Cm = 18_x001D_sec(135°)_x001D_","0.7",TEXT($AN44,"#,##0.0"),1),"18",TEXT($AR44,"#,##0"),1),"_x001D_","'") -> f = 1/{L} = ? , E1 = 0.7, Cm = 18'sec(135°)' | AA44: 44_1_1+ = | AB44: =$AL42 -> 1.25 | AC44: 44_1_1 = | AD44: =$AB44 -> 1.25 | AE44: F+ = | AF44: =ROUND(1/$AD44,2) -> 0.8 | AG44: F = | AH44: =$AF44 -> 0.8 | AI44: 44_1_2+ = | AJ44: =ROUND(1/$AD44,2) -> 0.8 | AK44: 44_1_2 = | AL44: =$AJ44 -> 0.8 | AM44: E1 = | AN44: 0.7 | AO44: E1 = | AP44: =$AN44 -> 0.7 | AQ44: CM = | AR44: 18 | AS44: CM = | AT44: =$AR44 -> 18
A46: =CONCATENATE(" Q = 3600 * q * K * f * E1 / Cm = ",TEXT($AF46,"#,##0.00")," M3/HR") -> Q = 3600 * q * K * f * E1 / Cm = 6,096.38 M3/HR | B46: =SUM($C46,$D46,$E46) -> 0 | K46: Q = 3600 * q * K * f * E1 / Cm = {?}'M3/HR' | AA46: Q+ = | AB46: =ROUND(3600*$AD42*$AH42*$AH44*$AP44/$AT44,2) -> 60.48 | AC46: Q = | AD46: =$AB46 -> 60.48 | AE46: 46_1_1+ = | AF46: =ROUND(3600*$AD46*$AH42*$AH44*$AP44/$AT44,2) -> 6096.38 | AG46: 46_1_1 = | AH46: =$AF46 -> 6096.38
A48: =CONCATENATE(" 재 료 비 : ",TEXT($AB48,"#,##0.00"),"/",TEXT($AF48,"#,##0.00")," =",TEXT($AJ48,"#,##0.00")) -> 재 료 비 : 16,824.00/60.48 =278.00 | B48: =SUM($C48,$D48,$E48) -> 278 | C48: =$AJ48 -> 278 | K48: '재 료 비 : '~E0002010060.M~/{Q} =?MA+ | AA48: 48_1_1+ = | AB48: =[4]중기사용료목록!E3 -> 16824 | AC48: 48_1_1 = | AD48: =$AB48 -> 16824 | AE48: 48_1_2+ = | AF48: =$AD46 -> 60.48 | AG48: 48_1_2 = | AH48: =$AF48 -> 60.48 | AI48: MA+ = | AJ48: =TRUNC($AD48/$AH48,0) -> 278 | AK48: MA = | AL48: =$AJ48 -> 278
A50: =CONCATENATE(" 노 무 비 : ",TEXT($AB50,"#,##0.00"),"/",TEXT($AF50,"#,##0.00")," =",TEXT($AJ50,"#,##0.00")) -> 노 무 비 : 55,700.00/60.48 =920.00 | B50: =SUM($C50,$D50,$E50) -> 920 | D50: =$AJ50 -> 920 | K50: '노 무 비 : '~E0002010060.L~/{Q} =?LA+ | AA50: 50_1_1+ = | AB50: =[4]중기사용료목록!F3 -> 55700 | AC50: 50_1_1 = | AD50: =$AB50 -> 55700 | AE50: 50_1_2+ = | AF50: =$AD46 -> 60.48 | AG50: 50_1_2 = | AH50: =$AF50 -> 60.48 | AI50: LA+ = | AJ50: =TRUNC($AD50/$AH50,0) -> 920 | AK50: LA = | AL50: =$AJ50 -> 920
A52: =CONCATENATE(" 경 비 : ",TEXT($AB52,"#,##0.00"),"/",TEXT($AF52,"#,##0.00")," =",TEXT($AJ52,"#,##0.00")) -> 경 비 : 21,957.00/60.48 =363.00 | B52: =SUM($C52,$D52,$E52) -> 363 | E52: =$AJ52 -> 363 | K52: '경 비 : '~E0002010060.E~/{Q} =?EQ+ | AA52: 52_1_1+ = | AB52: =[4]중기사용료목록!G3 -> 21957 | AC52: 52_1_1 = | AD52: =$AB52 -> 21957 | AE52: 52_1_2+ = | AF52: =$AD46 -> 60.48 | AG52: 52_1_2 = | AH52: =$AF52 -> 60.48 | AI52: EQ+ = | AJ52: =TRUNC($AD52/$AH52,0) -> 363 | AK52: EQ = | AL52: =$AJ52 -> 363
A56: 합계 : | B56: =SUM($C56,$D56,$E56) -> 1561 | C56: =$AB56 -> 278 | D56: =$AD56 -> 920 | E56: =$AF56 -> 363 | K56: >> ' 합계 : ' | AA56: >>MA = | AB56: =$AL48 -> 278 | AC56: >>LA = | AD56: =$AL50 -> 920 | AE56: >>EQ = | AF56: =$AL52 -> 363
A58: 전체 합계 | B58: =SUM($C58,$D58,$E58) -> 1561 | C58: =TRUNC(SUM($AL48),0) -> 278 | D58: =TRUNC(SUM($AL50),0) -> 920 | E58: =TRUNC(SUM($AL52),0) -> 363
A60: #13 되메우기및다짐 | BH 0.6M3, P.C 1.5ton, 인력10%|m3 | B60: =$B91 -> 6988 | C60: =$C91 -> 440 | D60: =$D91 -> 6160 | E60: =$E91 -> 388 | H60: N1010 | K60: 1 | Y60: =EXACT($Z60,$B91) -> FALSE | Z60: 6926
I62: 10 | K62: F
A63: 1. 되메우기(기계 90%, 인력 10%) | K63: 1. 되메우기(기계 90%, 인력 10%)
A65: 가. 기계(백호우 0.6㎥, 90%) | K65: 가. 기계(백호우 0.6㎥, 90%)
A66: =CONCATENATE(" q=",TEXT($AB66,"#,##0.0"),", K=",TEXT($AF66,"#,##0.0"),", f = 0.875/1.25 = ",TEXT($AN66,"#,##0.00")) -> q=0.6, K=1.1, f = 0.875/1.25 = 0.70 | B66: =SUM($C66,$D66,$E66) -> 0 | K66: =SUBSTITUTE(SUBSTITUTE(SUBSTITUTE(" q = 0.6, K = 1.1, f = 0.875/1.25 = ?","0.6",TEXT($AB66,"#,##0.0"),1),"1.1",TEXT($AF66,"#,##0.0"),1),"_x001D_","'") -> q = 0.6, K = 1.1, f = 0.875/1.25 = ? | AA66: Q = | AB66: 0.6 | AC66: Q = | AD66: =$AB66 -> 0.6 | AE66: K = | AF66: 1.1 | AG66: K = | AH66: =$AF66 -> 1.1 | AI66: F+ = | AJ66: =ROUND(0.875/1.25,2) -> 0.7 | AK66: F = | AL66: =$AJ66 -> 0.7 | AM66: 66_3_1+ = | AN66: =ROUND(0.875/1.25,2) -> 0.7 | AO66: 66_3_1 = | AP66: =$AN66 -> 0.7
A67: =CONCATENATE(" Cm=",TEXT($AB67,"#,##0.00")," (90°) ,E=",TEXT($AF67,"#,##0.00")) -> Cm=18.00 (90°) ,E=0.70 | K67: =SUBSTITUTE(SUBSTITUTE(SUBSTITUTE(" Cm = 18_x001D_(90°)_x001D_,E = 0.70","18",TEXT($AB67,"#,##0"),1),"0.70",TEXT($AF67,"#,##0.00"),1),"_x001D_","'") -> Cm = 18'(90°)',E = 0.70 | AA67: CM = | AB67: 18 | AC67: CM = | AD67: =$AB67 -> 18 | AE67: E = | AF67: 0.7 | AG67: E = | AH67: =$AF67 -> 0.7
A68: =CONCATENATE(" Q = 3600 * q * f * K * E / Cm = ",TEXT($AF68,"#,##0.00")) -> Q = 3600 * q * f * K * E / Cm = 6,972.50 | B68: =SUM($C68,$D68,$E68) -> 0 | K68: Q = 3600 * q * f * K * E / Cm = ? | AA68: Q+ = | AB68: =ROUND(3600*$AD66*$AL66*$AH66*$AH67/$AD67,2) -> 64.68 | AC68: Q = | AD68: =$AB68 -> 64.68 | AE68: 68_1_1+ = | AF68: =ROUND(3600*$AD68*$AL66*$AH66*$AH67/$AD67,2) -> 6972.5 | AG68: 68_1_1 = | AH68: =$AF68 -> 6972.5
A69: =CONCATENATE(" 노무비 : ",TEXT($AB69,"#,##0.00")," / Q * 0.9 = ",TEXT($AF69,"#,##0.00")) -> 노무비 : 55,700.00 / Q * 0.9 = 775.00 | B69: =SUM($C69,$D69,$E69) -> 775 | D69: =$AF69 -> 775 | K69: ' 노무비 :'~E0002010060.L~ / Q * 0.9 = ?LA+ | AA69: 69_1_1+ = | AB69: =[4]중기사용료목록!F3 -> 55700 | AC69: 69_1_1 = | AD69: =$AB69 -> 55700 | AE69: LA+ = | AF69: =TRUNC($AD69/$AD68*0.9,0) -> 775 | AG69: LA = | AH69: =$AF69 -> 775
A70: =CONCATENATE(" 재료비 : ",TEXT($AB70,"#,##0.00")," / Q * 0.9 = ",TEXT($AF70,"#,##0.00")) -> 재료비 : 16,824.00 / Q * 0.9 = 234.00 | B70: =SUM($C70,$D70,$E70) -> 234 | C70: =$AF70 -> 234 | K70: ' 재료비 :'~E0002010060.M~ / Q * 0.9 = ?MA+ | AA70: 70_1_1+ = | AB70: =[4]중기사용료목록!E3 -> 16824 | AC70: 70_1_1 = | AD70: =$AB70 -> 16824 | AE70: MA+ = | AF70: =TRUNC($AD70/$AD68*0.9,0) -> 234 | AG70: MA = | AH70: =$AF70 -> 234
A71: =CONCATENATE(" 경 비 : ",TEXT($AB71,"#,##0.00")," / Q * 0.9 = ",TEXT($AF71,"#,##0.00")) -> 경 비 : 21,957.00 / Q * 0.9 = 305.00 | B71: =SUM($C71,$D71,$E71) -> 305 | E71: =$AF71 -> 305 | K71: ' 경 비 :'~E0002010060.E~ / Q * 0.9 = ?EQ+ | AA71: 71_1_1+ = | AB71: =[4]중기사용료목록!G3 -> 21957 | AC71: 71_1_1 = | AD71: =$AB71 -> 21957 | AE71: EQ+ = | AF71: =TRUNC($AD71/$AD68*0.9,0) -> 305 | AG71: EQ = | AH71: =$AF71 -> 305
...

Sheet 중기사용료목록 (신규)
A1: 중기사용료목록
A2: 공 종 명 | B2: 규 격 | C2: 수 량 | D2: 단 위 | E2: 재 료 비 | F2: 노 무 비 | G2: 경 비 | H2: 합 계 | I2: 비 고
A3: 굴삭기(무한궤도) | B3: 0.6 M3 | C3: 1 | D3: HR | E3: =[4]중기사용료!G10 -> 16824 | F3: =[4]중기사용료!G12 -> 55700 | G3: =[4]중기사용료!G7 -> 21957 | H3: =E3+F3+G3 -> 94481 | K3: E0002010060
A4: 진동 롤러 (핸드가이드식) | B4: 0.7 톤 | C4: 1 | D4: HR | E4: =[4]중기사용료!G22 -> 3361 | F4: =[4]중기사용료!G24 -> 33571 | G4: =[4]중기사용료!G19 -> 1846 | H4: =E4+F4+G4 -> 38778 | K4: E0013050007
A5: 플레이트 콤팩터 | B5: 1.5 TON | C5: 1 | D5: HR | E5: =[4]중기사용료!G34 -> 1862 | F5: =[4]중기사용료!G36 -> 33571 | G5: =[4]중기사용료!G31 -> 750 | H5: =E5+F5+G5 -> 36183 | K5: E0017300015

Sheet 중기사용료 (신규)
A1: 중기사용료
A3: 중 기 명 | B3: 굴삭기(무한궤도) 0.6 M3 | J3: E0002010060
A4: 중기가격 | B4: 105,310 천원
A5: 명 칭 | C5: 규 격 | D5: 수 량 | E5: 단 위 | F5: 단 가 | G5: 금 액 | H5: 비 고
A6: 경 비 | B6: 굴삭기(무한궤도) | C6: 0.6 M3 | D6: =(900 + 700 + 485)*10^-4 -> 0.2085 | E6: 천원 | F6: =[4]중기기초자료!F3 -> 105310 | G6: =TRUNC(F6*D6, 1) -> 21957.1 | K6: 10 | M6: G02010060 | N6: .sang=900, jung=700, kwan=485
B7: 소 계 | G7: =TRUNC(G6, 0) -> 21957
A8: 재 료 비 | B8: 경 유 | D8: 10.2 | E8: L | F8: =[4]중기기초자료!D9 -> 1352 | G8: =TRUNC(F8*D8, 1) -> 13790.4 | K8: 40 | M8: M9366005
B9: 잡 품 | D9: 22 | E9: % | F9: 0 | G9: =TRUNC((G8) * D9/100, 1) -> 3033.8 | K9: 50 | M9: F/M1
B10: 소 계 | G10: =TRUNC(G8+G9, 0) -> 16824
A11: 노 무 비 | B11: 건설기계운전사 | C11: 구)건설기계운전기사 | D11: 1 | E11: 인 | F11: =TRUNC([4]중기기초자료!E6 * [4]중기전역변수!C18, 1) -> 55700 | G11: =TRUNC(F11*D11, 1) -> 55700 | K11: 15 | M11: L086
B12: 소 계 | G12: =TRUNC(G11, 0) -> 55700
B13: 총 계 | G13: =TRUNC(G7+G10+G12, 0) -> 94481
A15: 중 기 명 | B15: 진동 롤러 (핸드가이드식) 0.7 톤 | J15: E0013050007
A16: 중기가격 | B16: 6,537 천원
A17: 명 칭 | C17: 규 격 | D17: 수 량 | E17: 단 위 | F17: 단 가 | G17: 금 액 | H17: 비 고
A18: 경 비 | B18: 진동 롤러 (핸드가이드식) | C18: 0.7 톤 | D18: =(1286 + 857 + 682)*10^-4 -> 0.2825 | E18: 천원 | F18: =[4]중기기초자료!F4 -> 6537 | G18: =TRUNC(F18*D18, 1) -> 1846.7 | K18: 10 | M18: G13050007 | N18: .sang=1286,jung=857,kwan=682
B19: 소 계 | G19: =TRUNC(G18, 0) -> 1846
A20: 재 료 비 | B20: 경 유 | D20: 2.2 | E20: L | F20: =[4]중기기초자료!D9 -> 1352 | G20: =TRUNC(F20*D20, 1) -> 2974.4 | K20: 40 | M20: M9366005
B21: 잡 품 | D21: 13 | E21: % | F21: 0 | G21: =TRUNC((G20) * D21/100, 1) -> 386.6 | K21: 50 | M21: F/M1
B22: 소 계 | G22: =TRUNC(G20+G21, 0) -> 3361
A23: 노 무 비 | B23: 일반기계운전사 | C23: 일반공사 직종 | D23: 1 | E23: 인 | F23: =TRUNC([4]중기기초자료!E7 * [4]중기전역변수!C18, 1) -> 33571.2 | G23: =TRUNC(F23*D23, 1) -> 33571.2 | I23: 56900017058 | K23: 15 | M23: L088
B24: 소 계 | G24: =TRUNC(G23, 0) -> 33571
B25: 총 계 | G25: =TRUNC(G19+G22+G24, 0) -> 38778
A27: 중 기 명 | B27: 플레이트 콤팩터 1.5 TON | J27: E0017300015
A28: 중기가격 | B28: 1,570 $
A29: 명 칭 | C29: 규 격 | D29: 수 량 | E29: 단 위 | F29: 단 가 | G29: 금 액 | H29: 비 고
A30: 경 비 | B30: 플레이트 콤팩터 | C30: 1.5 TON | D30: =(1800 + 1200 + 708)*10^-4 -> 0.3708 | E30: 천원 | F30: =TRUNC([4]중기기초자료!F5 * [4]중기전역변수!C4/1000,0) -> 2023 | G30: =TRUNC(F30*D30, 1) -> 750.1 | K30: 10 | M30: G17300015 | N30: .sang=1800,jung=1200,kwan=708
B31: 소 계 | G31: =TRUNC(G30, 0) -> 750
A32: 재 료 비 | B32: 휘 발 유 | D32: 1 | E32: L | F32: =[4]중기기초자료!D8 -> 1552 | G32: =TRUNC(F32*D32, 1) -> 1552 | K32: 40 | M32: M9360003
B33: 잡 품 | D33: 20 | E33: % | F33: 0 | G33: =TRUNC((G32) * D33/100, 1) -> 310.4 | K33: 50 | M33: F/M1
B34: 소 계 | G34: =TRUNC(G32+G33, 0) -> 1862
A35: 노 무 비 | B35: 일반기계운전사 | C35: 구)운전사(기계) | D35: 1 | E35: 인 | F35: =TRUNC([4]중기기초자료!E7 * [4]중기전역변수!C18, 1) -> 33571.2 | G35: =TRUNC(F35*D35, 1) -> 33571.2 | K35: 15 | M35: L088
B36: 소 계 | G36: =TRUNC(G35, 0) -> 33571
B37: 총 계 | G37: =TRUNC(G31+G34+G36, 0) -> 36183

Sheet 중기기초자료 (신규)
A1: 중기기초자료
A2: 명 칭 | B2: 규 격 | C2: 단 위 | D2: 재 료 비 | E2: 노 무 비 | F2: 경 비 | G2: 합 계 | H2: 비 고
A3: 굴삭기(무한궤도) | B3: 0.6 M3 | C3: 천원 | D3: 0 | E3: 0 | F3: 105310 | G3: 105310 | J3: G02010060
A4: 진동 롤러 (핸드가이드식) | B4: 0.7 톤 | C4: 천원 | D4: 0 | E4: 0 | F4: 6537 | G4: 6537 | J4: G13050007
A5: 플레이트 콤팩터 | B5: 1.5 TON | C5: $ | D5: 0 | E5: 0 | F5: 1570 | G5: 1570 | J5: G17300015
A6: 건설기계운전사 | B6: 구)건설기계운전기사 | C6: 인 | D6: 0 | E6: 267360 | F6: 0 | G6: 267360 | I6: 56900017002 | J6: L086
A7: 일반기계운전사 | B7: 일반공사 직종 | C7: 인 | D7: 0 | E7: 161142 | F7: 0 | G7: 161142 | I7: 56900017058 | J7: L088
A8: 휘 발 유 | C8: L | D8: 1552 | E8: 0 | F8: 0 | G8: 1552 | J8: M9360003
A9: 경 유 | C9: L | D9: 1352 | E9: 0 | F9: 0 | G9: 1352 | J9: M9366005

Sheet 노임 (신규)
A1: 노임
A2: 명 칭 | B2: 규 격 | C2: 단 위 | D2: 단 가 | E2: 비 고
A3: 배 관 공 | C3: 인 | D3: 229482 | F3: 56900017030 | G3: L028 | H3: L028
A4: 보통인부 | C4: 인 | D4: 165545 | F4: 56900017041 | G4: L085 | H4: L085

Sheet 자재 (신규)
A1: 자재
A2: 명 칭 | B2: 규 격 | C2: 단 위 | D2: 단 가 | E2: 비 고
A3: 스틸그레이팅 | B3: 중하중 395*995*52 | C3: M2 | D3: =[4]자재조서!E4 -> 312000 | E3: 물자/1-182/ | G3: M1572002 | H3: M1572003
A4: PE관 | B4: Φ200mm | C4: M | D4: =[4]자재조서!E5 -> 19780 | E4: 물자/1-765/ | G4: M5380200 | H4: M5369809
A5: 혼합골재 | B5: 보조기층용 | C5: m3 | D5: =[4]자재조서!E6 -> 24000 | E5: 물자/62/ | G5: MB-4500
A6: 메가플로 파이프 | B6: T40,W310 | C6: m | D6: =[4]자재조서!E7 -> 22500 | E6: 물정/99/ | G6: MW-502
A7: 유공관 연결구 | B7: 410X450 | C7: 개소 | D7: =[4]자재조서!E8 -> 60000 | E7: 물정/99/ | G7: MW-503
A8: ='자재조서 (신규)'!B9 -> 가설방음판RPP | B8: ='자재조서 (신규)'!C9 -> 1980x500xx30T | C8: ='자재조서 (신규)'!D9 -> M | D8: ='자재조서 (신규)'!E9 -> 42000 | E8: ='자재조서 (신규)'!G9 -> 1-1054
A9: ='자재조서 (신규)'!B10 -> 가설방음벽(주주파이프) | B9: ='자재조서 (신규)'!C10 -> Φ48×2.3t | C9: ='자재조서 (신규)'!D10 -> m | D9: ='자재조서 (신규)'!E10 -> 5250 | E9: ='자재조서 (신규)'!G10 -> 1-105
A10: ='자재조서 (신규)'!B11 -> 가설방음벽(지주파이프) | B10: ='자재조서 (신규)'!C11 -> Φ48×2.3t×2m | C10: ='자재조서 (신규)'!D11 -> ea | D10: ='자재조서 (신규)'!E11 -> 10500 | E10: ='자재조서 (신규)'!G11 -> 1-105
A11: ='자재조서 (신규)'!B12 -> 가설방음벽(횡대파이프) | B11: ='자재조서 (신규)'!C12 -> Φ48×2.3t | C11: ='자재조서 (신규)'!D12 -> m | D11: ='자재조서 (신규)'!E12 -> 5250 | E11: ='자재조서 (신규)'!G12 -> 1-105
