Workbook
Name ______JHY1: 수목중량!______JHY1
Name ______JHY1: 폐기목중량!______JHY1
Name ______JHY1: [0]!______JHY1
Name ______JHY2: 수목중량!______JHY2
Name ______JHY2: 폐기목중량!______JHY2
Name ______JHY2: [0]!______JHY2
Name ______LKS1: 수목중량!______LKS1
Name ______LKS1: 폐기목중량!______LKS1
Name ______LKS1: [0]!______LKS1
Name ______LKS2: 수목중량!______LKS2
Name ______LKS2: 폐기목중량!______LKS2
Name ______LKS2: [0]!______LKS2
Name _____a10: 수목중량!_____a10
Name _____a10: 폐기목중량!_____a10
Name _____a10: [0]!_____a10
Name _____a11: 수목중량!_____a11
Name _____a11: 폐기목중량!_____a11
Name _____a11: [0]!_____a11
Name _____a12: 수목중량!_____a12
Name _____a12: 폐기목중량!_____a12
Name _____a12: [0]!_____a12
Name _____a13: 수목중량!_____a13
Name _____a13: 폐기목중량!_____a13
Name _____a13: [0]!_____a13
Name _____a14: 수목중량!_____a14
Name _____a14: 폐기목중량!_____a14
Name _____a14: [0]!_____a14
Name _____a15: 수목중량!_____a15
Name _____a15: 폐기목중량!_____a15
Name _____a15: [0]!_____a15
Name _____a16: 수목중량!_____a16
Name _____a16: 폐기목중량!_____a16
Name _____a16: [0]!_____a16
Name _____a17: 수목중량!_____a17
Name _____a17: 폐기목중량!_____a17
Name _____a17: [0]!_____a17
Name _____a2: 수목중량!_____a2
Name _____a2: 폐기목중량!_____a2
Name _____a2: [0]!_____a2
Name _____a3: 수목중량!_____a3
Name _____a3: 폐기목중량!_____a3
Name _____a3: [0]!_____a3
Name _____a4: 수목중량!_____a4
Name _____a4: 폐기목중량!_____a4
Name _____a4: [0]!_____a4
Name _____a5: 수목중량!_____a5
Name _____a5: 폐기목중량!_____a5
Name _____a5: [0]!_____a5
Name _____a6: 수목중량!_____a6
Name _____a6: 폐기목중량!_____a6
Name _____a6: [0]!_____a6
Name _____a7: 수목중량!_____a7
Name _____a7: 폐기목중량!_____a7
Name _____a7: [0]!_____a7
Name _____a8: 수목중량!_____a8
Name _____a8: 폐기목중량!_____a8
Name _____a8: [0]!_____a8
Name _____a9: 수목중량!_____a9
Name _____a9: 폐기목중량!_____a9
Name _____a9: [0]!_____a9

Sheet 관급자재총괄집계표
A1: ■관급자재 총괄집계표-1
A2: 공 종 명 | B2: 규 격 | C2: 단 위 | D2: 수 량 | E2: =시설공관급자재집계표1!E2 -> 파고라 | G2: =시설공관급자재집계표1!G2 -> 등의자 | I2: =시설공관급자재집계표1!I2 -> 목재데크(m2) | K2: =시설공관급자재집계표1!K2 -> 디자인형휀스 | O2: =시설공관급자재집계표1!O2 -> 볼라드 | Q2: 비 고
E3: =시설공관급자재집계표1!E3 -> 4000x3600xH2710 | G3: =시설공관급자재집계표1!G3 -> 1600x580xH700 | I3: =시설공관급자재집계표1!I3 -> 90xT21 | K3: =시설공관급자재집계표1!K3 -> W1500×H1200mm | O3: =시설공관급자재집계표1!O3 -> D110x850
E4: 단위수량 | F4: 합계수량 | G4: 단위수량 | H4: 합계수량 | I4: 단위수량 | J4: 합계수량 | K4: 단위수량 | L4: 합계수량 | M4: 단위수량 | N4: 합계수량 | O4: 단위수량 | P4: 합계수량
A5: 식재공 | C5: 식 | D5: 1 | H5: =D5*G5 -> 0 | J5: =D5*I5 -> 0 | L5: =D5*K5 -> 0 | N5: =D5*M5 -> 0 | P5: =D5*O5 -> 0
A6: 시설공 | C6: 식 | D6: 1 | E6: =시설공관급자재집계표1!E37 -> 3 | F6: =D6*E6 -> 3 | G6: =시설공관급자재집계표1!G37 -> 21 | H6: =D6*G6 -> 21 | I6: =시설공관급자재집계표1!I37 -> 139 | J6: =D6*I6 -> 139 | K6: =시설공관급자재집계표1!K37 -> 36 | L6: =D6*K6 -> 36 | M6: =시설공관급자재집계표1!M37 -> 0 | N6: =D6*M6 -> 0 | O6: =시설공관급자재집계표1!O37 -> 10 | P6: =D6*O6 -> 10
A7: 포장공 | C7: 식 | D7: 1 | H7: =D7*G7 -> 0 | J7: =D7*I7 -> 0 | L7: =D7*K7 -> 0 | N7: =D7*M7 -> 0 | O7: =포장공관급자재집계표!Q18 -> 0 | P7: =D7*O7 -> 0
A8: 합계 | F8: =SUM(F5:F7) -> 3 | H8: =SUM(H5:H7) -> 21 | J8: =SUM(J5:J7) -> 139 | L8: =SUM(L5:L7) -> 36 | N8: =SUM(N5:N7) -> 0 | P8: =SUM(P5:P7) -> 10
A10: 공 종 명 | B10: 규 격 | C10: 단 위 | D10: 수 량 | E10: =시설공관급자재집계표2!E2 -> 트윈트위스트 | G10: =시설공관급자재집계표2!G2 -> 바디싣업 | I10: =시설공관급자재집계표2!I2 -> 크로스컨트리 | K10: =시설공관급자재집계표2!K2 -> 레그프레스 | M10: =시설공관급자재집계표2!M2 -> 스트레칭롤러 | O10: =시설공관급자재집계표2!O2 -> 워밍암 | Q10: 비 고
E11: =시설공관급자재집계표2!E3 -> 1845x590x1917 | G11: =시설공관급자재집계표2!G3 -> 1433x1349x1917 | I11: =시설공관급자재집계표2!I3 -> 2602x610x1917 | K11: =시설공관급자재집계표2!K3 -> 2404x440x1917 | M11: =시설공관급자재집계표2!M3 -> 1647x780x1917 | O11: =시설공관급자재집계표2!O3 -> 1078x934x2007
E12: 단위수량 | F12: 합계수량 | G12: 단위수량 | H12: 합계수량 | I12: 단위수량 | J12: 합계수량 | K12: 단위수량 | L12: 합계수량 | M12: 단위수량 | N12: 합계수량 | O12: 단위수량 | P12: 합계수량
A13: 식재공 | C13: 식 | D13: 1 | F13: =D13*E13 -> 0 | H13: =D13*G13 -> 0 | J13: =D13*I13 -> 0 | L13: =D13*K13 -> 0 | N13: =D13*M13 -> 0 | P13: =D13*O13 -> 0
A14: 시설공 | C14: 식 | D14: 1 | E14: =시설공관급자재집계표2!E37 -> 1 | F14: =D14*E14 -> 1 | G14: =시설공관급자재집계표2!G36 -> 1 | H14: =D14*G14 -> 1 | I14: =시설공관급자재집계표2!I36 -> 1 | J14: =D14*I14 -> 1 | K14: =시설공관급자재집계표2!K36 -> 1 | L14: =D14*K14 -> 1 | M14: =시설공관급자재집계표2!M36 -> 1 | N14: =D14*M14 -> 1 | O14: =시설공관급자재집계표2!O36 -> 1 | P14: =D14*O14 -> 1
A15: 포장공 | C15: 식 | D15: 1 | F15: =D15*E15 -> 0 | H15: =D15*G15 -> 0 | J15: =D15*I15 -> 0 | L15: =D15*K15 -> 0 | M15: =포장공관급자재집계표!O26 -> 0 | N15: =D15*M15 -> 0 | O15: =포장공관급자재집계표!Q26 -> 0 | P15: =D15*O15 -> 0
A16: 합계 | F16: =SUM(F13:F15) -> 1 | H16: =SUM(H13:H15) -> 1 | J16: =SUM(J13:J15) -> 1 | L16: =SUM(L13:L15) -> 1 | N16: =SUM(N13:N15) -> 1 | P16: =SUM(P13:P15) -> 1
A18: 공 종 명 | B18: 규 격 | C18: 단 위 | D18: 수 량 | E18: =시설공관급자재집계표3!E2 -> 종합안내판 | G18: =시설공관급자재집계표3!G2 -> 공원이용안내판 | I18: =시설공관급자재집계표3!I2 -> 공원시설안내판 | K18: =시설공관급자재집계표3!K2 -> 방향안내판 | M18: =시설공관급자재집계표3!M2 -> 촉지안내판 | O18: =시설공관급자재집계표3!O2 -> 촉지도 | Q18: 비 고
E19: =시설공관급자재집계표3!E3 -> 2100x2100 | G19: =시설공관급자재집계표3!G3 -> 300x1500 | I19: =시설공관급자재집계표3!I3 -> 400x1800 | K19: =시설공관급자재집계표3!K3 -> 600x150 | M19: =시설공관급자재집계표3!M3 -> 600x1200 | O19: =시설공관급자재집계표3!O3 -> 550x450
E20: 단위수량 | F20: 합계수량 | G20: 단위수량 | H20: 합계수량 | I20: 단위수량 | J20: 합계수량 | K20: 단위수량 | L20: 합계수량 | M20: 단위수량 | N20: 합계수량 | O20: 단위수량 | P20: 합계수량
A21: 식재공 | C21: 식 | D21: 1 | F21: =D21*E21 -> 0 | H21: =D21*G21 -> 0 | J21: =D21*I21 -> 0 | L21: =D21*K21 -> 0 | N21: =D21*M21 -> 0 | P21: =D21*O21 -> 0
A22: 시설공 | C22: 식 | D22: 1 | E22: =시설공관급자재집계표3!E37 -> 1 | F22: =D22*E22 -> 1 | G22: =시설공관급자재집계표3!G37 -> 1 | H22: =D22*G22 -> 1 | I22: =시설공관급자재집계표3!I37 -> 5 | J22: =D22*I22 -> 5 | K22: =시설공관급자재집계표3!K37 -> 4 | L22: =D22*K22 -> 4 | M22: =시설공관급자재집계표3!M37 -> 1 | N22: =D22*M22 -> 1 | O22: =시설공관급자재집계표3!O37 -> 1 | P22: =D22*O22 -> 1
A23: 포장공 | C23: 식 | D23: 1 | F23: =D23*E23 -> 0 | H23: =D23*G23 -> 0 | J23: =D23*I23 -> 0 | L23: =D23*K23 -> 0 | M23: =포장공관급자재집계표!O34 -> 0 | N23: =D23*M23 -> 0 | O23: =포장공관급자재집계표!Q34 -> 0 | P23: =D23*O23 -> 0
A24: 합계 | F24: =SUM(F21:F23) -> 1 | H24: =SUM(H21:H23) -> 1 | J24: =SUM(J21:J23) -> 5 | L24: =SUM(L21:L23) -> 4 | N24: =SUM(N21:N23) -> 1 | P24: =SUM(P21:P23) -> 1
A26: 공 종 명 | B26: 규 격 | C26: 단 위 | D26: 수 량 | E26: 레미콘 | G26: 이형철근 | I26: =시설공관급자재집계표4!E2 -> 조경블록(마감) | K26: =시설공관급자재집계표4!G2 -> 조경블록(본체) | M26: =시설공관급자재집계표4!I2 -> 보강토연결핀 | Q26: 비 고
E27: 25-18-8 | G27: D13 | I27: =시설공관급자재집계표4!E3 -> T75 | K27: =시설공관급자재집계표4!G3 -> T150 | M27: =시설공관급자재집계표4!I3 -> 12.3x133
E28: 단위수량 | F28: 합계수량 | G28: 단위수량 | H28: 합계수량 | I28: 단위수량 | J28: 합계수량 | K28: 단위수량 | L28: 합계수량 | M28: 단위수량 | N28: 합계수량
A29: 식재공 | C29: 식 | D29: 1 | H29: =D29*G29 -> 0 | J29: =D29*I29 -> 0 | L29: =D29*K29 -> 0 | N29: =D29*M29 -> 0
A30: 시설공 | C30: 식 | D30: 1 | E30: =시설공관급자재집계표4!$K$37 -> 182 | F30: =D30*E30 -> 182 | G30: =시설공관급자재집계표4!$M$37 -> 4.083 | H30: =D30*G30 -> 4.083 | I30: =시설공관급자재집계표4!E37 -> 182 | J30: =D30*I30 -> 182 | K30: =시설공관급자재집계표4!G37 -> 212 | L30: =D30*K30 -> 212 | M30: =시설공관급자재집계표4!I37 -> 8362 | N30: =$D$30*M30 -> 8362
A31: 포장공 | C31: 식 | D31: 1 | E31: =포장공관급자재집계표!$M$18 -> 137 | F31: =D31*E31 -> 137 | H31: =D31*G31 -> 0 | J31: =D31*I31 -> 0 | L31: =D31*K31 -> 0 | N31: =F31*M31 -> 0
A32: 합계 | F32: =SUM(F29:F31) -> 319 | H32: =SUM(H29:H31) -> 4.083 | J32: =SUM(J29:J31) -> 182 | L32: =SUM(L29:L31) -> 212 | N32: =SUM(N29:N31) -> 8362
A34: ■관급자재 총괄집계표-2
A35: 공 종 명 | B35: 규 격 | C35: 단 위 | D35: 수 량 | E35: =포장공관급자재집계표!E2 -> 인조화강석블럭(m2) | G35: =포장공관급자재집계표!G2 -> 인조잔디포장 | I35: =포장공관급자재집계표!I2 -> 화강석경계석(직선,m) | K35: =포장공관급자재집계표!K2 -> 화강석경계석(곡선,m) | Q35: 비 고
E36: =포장공관급자재집계표!E3 -> 200x200xT60 | G36: =포장공관급자재집계표!G3 -> T19 | I36: =포장공관급자재집계표!I3 -> 150x150x1000 | K36: =포장공관급자재집계표!K3 -> 150x150x1000
E37: 단위수량 | F37: 합계수량 | G37: 단위수량 | H37: 합계수량 | I37: 단위수량 | J37: 합계수량 | K37: 단위수량 | L37: 합계수량
A38: 식재공 | C38: 식 | D38: 1 | F38: =D38*E38 -> 0 | H38: =D38*G38 -> 0 | J38: =F38*I38 -> 0 | L38: =D38*K38 -> 0
A39: 시설공 | C39: 식 | D39: 1 | F39: =D39*E39 -> 0 | H39: =D39*G39 -> 0 | J39: =F39*I39 -> 0 | L39: =D39*K39 -> 0
A40: 포장공 | C40: 식 | D40: 1 | E40: =포장공관급자재집계표!E18 -> 3588 | F40: =D40*E40 -> 3588 | G40: =포장공관급자재집계표!G18 -> 648 | H40: =D40*G40 -> 648 | I40: =포장공관급자재집계표!I18 -> 1541 | J40: =D40*I40 -> 1541 | K40: =포장공관급자재집계표!K18 -> 303 | L40: =D40*K40 -> 303
A41: 합계 | F41: =SUM(F38:F40) -> 3588 | H41: =SUM(H38:H40) -> 648 | J41: =SUM(J38:J40) -> 1541 | L41: =SUM(L38:L40) -> 303
A43: 공 종 명 | B43: 규 격 | C43: 단 위 | D43: 수 량 | E43: =식재공관급자재집계표!E2 -> 유기질비료 (20kg/포) | Q43: 비 고
E44: 20kg/포
E45: 단위수량 | F45: 합계수량
...

Sheet 하차총괄집계표
A1: ■하차 총괄집계표
A2: 공 종 명 | B2: 규 격 | C2: 단위 | D2: 수량 | E2: =포장공하차집계표!$E$2 -> 인조화강석블럭포장 | G2: =포장공하차집계표!$G$2 -> 화강석경계석(ton) | I2: 조경블록(마감) | K2: 조경블록(본체) | Q2: 비 고
E3: =포장공하차집계표!$E$3 -> 200x200xT60 | G3: =포장공하차집계표!$G$3 -> 150x150x1000 | I3: T75 | K3: T150
E4: 단위수량 | F4: 합계수량 | G4: 단위수량 | H4: 합계수량 | I4: 단위수량 | J4: 합계수량 | K4: 단위수량 | L4: 합계수량
A5: 시설공 | C5: 식 | D5: 1 | F5: =$D5*E5 -> 0 | H5: =$D5*G5 -> 0 | I5: =시설공하차집계표!E23 -> 10.659264 | J5: =$D5*I5 -> 10.659264 | K5: =시설공하차집계표!G23 -> 132.9741 | L5: =$D5*K5 -> 132.9741 | N5: =$D5*M5 -> 0 | P5: =$D5*O5 -> 0
A6: 포장공 | C6: 식 | D6: 1 | E6: =포장공하차집계표!E16 -> 621 | F6: =$D6*E6 -> 621 | G6: =포장공하차집계표!G16 -> 107 | H6: =$D6*G6 -> 107 | I6: =포장공하차집계표!I16 -> 0 | J6: =$D6*I6 -> 0
A12: 소계 | E12: =SUM(F5:F6) -> 621 | G12: =SUM(H5:H6) -> 107 | I12: =SUM(J5:J6) -> 10.659264 | K12: =SUM(L5:L6) -> 132.9741 | M12: =SUM(N5:N6) -> 0 | O12: =SUM(P5:P6) -> 0
A13: 합계 | E13: =E12+G12+I12+K12 -> 871.63336 | M13: =SUM(N6:N7) -> 0 | O13: =SUM(P6:P7) -> 0

Sheet 자재운반총괄집계표
A1: ■자재운반 총괄집계표
A2: 공 종 명 | B2: 규 격 | C2: 단 위 | D2: 수 량 | E2: 양중(ton) | G2: 지게운반 | M2: 비 고
G3: 230M | I3: 190M | K3: 70M
E4: 단위중량 | F4: 합계 | G4: 단위중량 | H4: 합계 | I4: 단위중량 | J4: 합계 | K4: 단위중량 | L4: 합계
A5: 식재공 | C5: 식 | D5: 1 | E5: =식재공운반집계표!F34*0.001 -> #REF! | F5: =D5*E5 -> #REF! | G5: =식재공운반집계표!J34 -> #REF! | H5: =$D5*G5 -> #REF! | J5: =$D5*I5 -> 0 | K5: =식재공운반집계표!L34 -> #REF! | L5: =$D5*K5 -> #REF!
A6: 시설공 | C6: 식 | D6: 1 | E6: =시설공운반집계표!F27*0.001 -> 51.658 | F6: =D6*E6 -> 51.658 | H6: =$D6*G6 -> 0 | I6: =시설공운반집계표!H27 -> 0 | J6: =$D6*I6 -> 0 | K6: =시설공운반집계표!L27 -> 0 | L6: =$D6*K6 -> 0
A7: 포장공 | C7: 식 | D7: 1 | E7: =포장공운반집계표!F19*0.001 -> #REF! | F7: =D7*E7 -> #REF! | H7: =$D7*G7 -> 0 | I7: =포장공운반집계표!J19 -> #REF! | J7: =$D7*I7 -> #REF! | L7: =$D7*K7 -> 0
A8: 설비공 | C8: 식 | D8: 1
A9: 합계(kg) | E9: =ROUNDUP(SUM(F5:F8),-1) -> #REF! | G9: =ROUNDUP(SUM(H5:H8),-1) -> #REF! | I9: =ROUNDUP(SUM(J5:J8),-1) -> #REF! | K9: =ROUNDUP(SUM(L5:L8),-1) -> #REF!

Sheet 토공 총괄집계표
A1: ■토공 총괄집계표
A2: 포 장 명 | B2: 규 격 | C2: 단 위 | D2: 수 량 | E2: 터파기/토사(m3) | G2: 잔토처리/토사(m3) | I2: 되메우기(m3) | K2: 성토 | M2: 절토 | O2: 비 고
E3: 기계 | G3: 기계 | I3: 기계
A4: 철거공 | C4: 식 | D4: 1 | F4: =D4*E4 -> 0 | H4: =D4*G4 -> 0 | J4: =D4*I4 -> 0
A5: 식재공 | C5: 식 | D5: 1 | F5: =D5*E5 -> 0 | H5: =D5*G5 -> 0 | J5: =D5*I5 -> 0
A6: 시설공 | C6: 식 | D6: 1 | E6: =시설공토공집계표!E21 -> 340.61 | F6: =D6*E6 -> 340.61 | G6: =시설공토공집계표!G21 -> 264.52 | H6: =D6*G6 -> 264.52 | I6: =시설공토공집계표!I21 -> 83.23 | J6: =D6*I6 -> 83.23
A7: 포장공 | C7: 식 | D7: 1 | E7: =포장공토공집계표!E16 -> 2002.9 | F7: =D7*E7 -> 2002.9 | G7: =포장공토공집계표!I16 -> 1806 | H7: =D7*G7 -> 1806 | I7: =포장공토공집계표!M16 -> 196.9 | J7: =D7*I7 -> 196.9
A12: 합계 | E12: =SUM(F4:F11) -> 2343.51 | G12: =SUM(H4:H11) -> 2070.52 | I12: =SUM(J4:J11) -> 280.13
A13: 사토처리(토목이기) | E13: =G12 -> 2070.52

Sheet 토공
G8: 토공

Sheet 토적표
A1: ■토적표
A2: 측점 | D2: 거리(m) | E2: 절토량 | G2: 성토량 | I2: 사토량 | J2: 비 고
E3: A(m2) | F3: V(m3) | G3: A(m2) | H3: V(m3) | I3: V(m3)
A4: 1 | B4: +
A5: 2 | B5: +
A6: 2 | B6: +
A7: 3 | B7: +
A8: 3 | B8: +
A9: 소계 | E9: =SUM(F5:F8) -> 0 | G9: =SUM(H5:H8) -> 0 | I9: =E9-G9 -> 0
A11: 4 | B11: +
A12: 4 | B12: +
A13: 4 | B13: +
A14: 소계 | E14: =SUM(F11:F13) -> 0 | G14: =SUM(H11:H13) -> 0 | I14: =E14-G14 -> 0
A16: 5 | B16: +
A17: 5 | B17: +
A18: 5 | B18: +
A19: 5 | B19: +
A20: 5 | B20: +
A21: 5 | B21: +
A22: 소계 | E22: =SUM(F16:F21) -> 0 | G22: =SUM(H16:H21) -> 0 | I22: =E22-G22 -> 0
A24: 합계 | E24: =E9+E14+E22 -> 0 | G24: =G9+G14+G22 -> 0 | I24: =I9+I14+I22 -> 0
A25: 사토처리(토목이기) | E25: =E24-G24 -> 0

Sheet 철거공
G8: 철거공

Sheet 철거공수량집계표
A1: ■철거공수량집계표
A2: 시 설 명 | B2: 규 격 | C2: 단 위 | D2: 수 량 | E2: 비 고
A4: 소나무 | B4: H8.0xW3.0xR8 | C4: 주 | D4: 3
A5: 소나무 | B5: H5.0xW3.0xR25 | C5: 주 | D5: 1
A6: 스트로브잣나무 | B6: H10.0xR30 | C6: 주 | D6: 2
A7: 스트로브잣나무 | B7: H8.0xR18 | C7: 주 | D7: 18
A8: 스트로브잣나무 | B8: H7.0xR24 | C8: 주 | D8: 7
A9: 스트로브잣나무 | B9: H7.0xR22 | C9: 주 | D9: 12
A10: 스트로브잣나무 | B10: H7.0xR20 | C10: 주 | D10: 4
A11: 스트로브잣나무 | B11: H7.0xR15 | C11: 주 | D11: 15
A12: 스트로브잣나무 | B12: H6.0xR18 | C12: 주 | D12: 33
A13: 스트로브잣나무 | B13: H4.0xR15 | C13: 주 | D13: 11
A14: 전나무 | B14: H7.0xW2.0 | C14: 주 | D14: 4
A15: 전나무 | B15: H7.0xR18 | C15: 주 | D15: 10
... A50: 참나무 | B50: H6.0xR20 | C50: 주 | D50: 3

Sheet 철거공폐기물집계표
A1: ■철거공폐기물집계표
A2: 시 설 명 | B2: 규 격 | C2: 단위 | D2: 수 량 | E2: 폐콘크리트 | G2: 혼합폐기물 | I2: 폐목재 | K2: 폐기물운반 | L2: 비 고
E3: 단위수량 | F3: 소계 | G3: 단위수량 | H3: 소계 | I3: 단위수량 | J3: 소계
A4: =철거공수량집계표!#REF! -> #REF! | B4: =철거공수량집계표!#REF! -> #REF! | C4: =철거공수량집계표!#REF! -> #REF! | D4: =철거공수량집계표!#REF! -> #REF! | E4: =철거공수량산출서!F20 -> 0.1325 | F4: =D4*E4 -> #REF! | H4: =D4*G4 -> #REF! | J4: =D4*I4 -> #REF! | K4: =F4+H4+J4 -> #REF!
A7: 합계(ton) | E7: =SUM(F4:F6) -> #REF! | G7: =SUM(H5:H5) -> 0 | I7: =SUM(J5:J5) -> 0 | K7: =SUM(K4:K6) -> #REF!

Sheet 철거공수량산출서
A1: ■ | B1: =철거공수량집계표!#REF! -> #REF! | C1: =철거공수량집계표!#REF! -> #REF! | E1: =철거공수량집계표!#REF! -> #REF! | F1: 1
A2: NO | B2: 공 종 명 | C2: 규 격 | D2: 산 출 근 거 | E2: 단위 | F2: 수 량 | G2: 비 고
A18: 1 | B18: 무근콘크리트깨기 | D18: (0.35*0.4*1)-(0.3*0.3*1) | E18: m3 | F18: =(0.35*0.4*1)-(0.3*0.3*1) -> 0.05
A19: 2 | B19: 페기물 집적 및 상차 | C19: 폐콘크리트 | D19: (0.35*0.4*1)-(0.3*0.3*1) | E19: m3 | F19: =(0.35*0.4*1)-(0.3*0.3*1) -> 0.05
A20: 3 | B20: 폐기물 처리 | C20: 폐콘크리트 | D20: 0.05*2.65(단위중량) | E20: TON | F20: =0.05*2.65 -> 0.1325

Sheet 철거공임목폐기물집계표
A1: ■철거공임목폐기물집계표
A2: 수종명 | B2: 규 격 | C2: 단 위 | D2: 수량 | E2: 임목폐기물운반,처리 | G2: 임목폐기물상차 | I2: 비 고
E3: 단위중량(kg) | F3: 소계 | G3: 단위체적(m3) | H3: 소계
A4: =철거공수량집계표!A4 -> 소나무 | B4: =철거공수량집계표!B4 -> H8.0xW3.0xR8 | C4: =철거공수량집계표!C4 -> 주 | D4: =철거공수량집계표!D4 -> 3 | E4: ='폐기목 중량환산표1'!$F$6 -> 11.764706 | F4: =D4*E4 -> 35.294118 | G4: ='폐기목 중량환산표1'!$F$7 -> 0.01 | H4: =D4*G4 -> 0.03
A5: =철거공수량집계표!A5 -> 소나무 | B5: =철거공수량집계표!B5 -> H5.0xW3.0xR25 | C5: =철거공수량집계표!C5 -> 주 | D5: =철거공수량집계표!D5 -> 1 | E5: ='폐기목 중량환산표1'!$F$16 -> 230.9 | F5: =D5*E5 -> 230.9 | G5: ='폐기목 중량환산표1'!$F$17 -> 0.201 | H5: =D5*G5 -> 0.201
A6: =철거공수량집계표!A6 -> 스트로브잣나무 | B6: =철거공수량집계표!B6 -> H10.0xR30 | C6: =철거공수량집계표!C6 -> 주 | D6: =철거공수량집계표!D6 -> 2 | E6: ='폐기목 중량환산표1'!$K$16 -> 332.5 | F6: =D6*E6 -> 665 | G6: ='폐기목 중량환산표1'!$K$17 -> 0.289 | H6: =D6*G6 -> 0.578
A7: =철거공수량집계표!A7 -> 스트로브잣나무 | B7: =철거공수량집계표!B7 -> H8.0xR18 | C7: =철거공수량집계표!C7 -> 주 | D7: =철거공수량집계표!D7 -> 18 | E7: ='폐기목 중량환산표1'!$P$6 -> 95.764706 | F7: =D7*E7 -> 1723.7647 | G7: ='폐기목 중량환산표1'!$P$7 -> 0.084 | H7: =D7*G7 -> 1.512
A8: =철거공수량집계표!A8 -> 스트로브잣나무 | B8: =철거공수량집계표!B8 -> H7.0xR24 | C8: =철거공수량집계표!C8 -> 주 | D8: =철거공수량집계표!D8 -> 7 | E8: ='폐기목 중량환산표1'!$E$16 -> 191.5 | F8: =D8*E8 -> 1340.5 | G8: ='폐기목 중량환산표1'!$E$17 -> 0.167 | H8: =D8*G8 -> 1.169
A9: =철거공수량집계표!A9 -> 스트로브잣나무 | B9: =철거공수량집계표!B9 -> H7.0xR22 | C9: =철거공수량집계표!C9 -> 주 | D9: =철거공수량집계표!D9 -> 12 | E9: ='폐기목 중량환산표1'!$C$16 -> 160.9 | F9: =D9*E9 -> 1930.8 | G9: ='폐기목 중량환산표1'!$C$17 -> 0.14 | H9: =D9*G9 -> 1.68
A10: =철거공수량집계표!A10 -> 스트로브잣나무 | B10: =철거공수량집계표!B10 -> H7.0xR20 | C10: =철거공수량집계표!C10 -> 주 | D10: =철거공수량집계표!D10 -> 4 | E10: ='폐기목 중량환산표1'!$R$6 -> 118.23529 | F10: =D10*E10 -> 472.94118 | G10: ='폐기목 중량환산표1'!$R$7 -> 0.103 | H10: =D10*G10 -> 0.412
A11: =철거공수량집계표!A11 -> 스트로브잣나무 | B11: =철거공수량집계표!B11 -> H7.0xR15 | C11: =철거공수량집계표!C11 -> 주 | D11: =철거공수량집계표!D11 -> 15 | E11: ='폐기목 중량환산표1'!$M$6 -> 58.235294 | F11: =D11*E11 -> 873.52941 | G11: ='폐기목 중량환산표1'!$M$7 -> 0.051 | H11: =D11*G11 -> 0.765
A12: =철거공수량집계표!A12 -> 스트로브잣나무 | B12: =철거공수량집계표!B12 -> H6.0xR18 | C12: =철거공수량집계표!C12 -> 주 | D12: =철거공수량집계표!D12 -> 33 | E12: ='폐기목 중량환산표1'!$P$6 -> 95.764706 | F12: =D12*E12 -> 3160.2353 | G12: ='폐기목 중량환산표1'!$P$7 -> 0.084 | H12: =D12*G12 -> 2.772
A13: =철거공수량집계표!A13 -> 스트로브잣나무 | B13: =철거공수량집계표!B13 -> H4.0xR15 | C13: =철거공수량집계표!C13 -> 주 | D13: =철거공수량집계표!D13 -> 11 | E13: ='폐기목 중량환산표1'!$M$6 -> 58.235294 | F13: =D13*E13 -> 640.58824 | G13: ='폐기목 중량환산표1'!$M$7 -> 0.051 | H13: =D13*G13 -> 0.561
A14: =철거공수량집계표!A14 -> 전나무 | B14: =철거공수량집계표!B14 -> H7.0xW2.0 | C14: =철거공수량집계표!C14 -> 주 | D14: =철거공수량집계표!D14 -> 4 | E14: ='폐기목 중량환산표2'!$F$6 -> 912.35294 | F14: =D14*E14 -> 3649.4118 | G14: ='폐기목 중량환산표2'!$F$7 -> 0.792 | H14: =D14*G14 -> 3.168
A15: =철거공수량집계표!A15 -> 전나무 | B15: =철거공수량집계표!B15 -> H7.0xR18 | C15: =철거공수량집계표!C15 -> 주 | D15: =철거공수량집계표!D15 -> 10 | E15: ='폐기목 중량환산표1'!$P$6 -> 95.764706 | F15: =D15*E15 -> 957.64706 | G15: ='폐기목 중량환산표1'!$P$7 -> 0.084 | H15: =D15*G15 -> 0.84
A16: =철거공수량집계표!A16 -> 전나무 | B16: =철거공수량집계표!B16 -> H5.5xW3.0 | C16: =철거공수량집계표!C16 -> 주 | D16: =철거공수량집계표!D16 -> 3 | E16: ='폐기목 중량환산표1'!$P$16 -> 497.8 | F16: =D16*E16 -> 1493.4 | G16: ='폐기목 중량환산표1'!$P$17 -> 0.432 | H16: =D16*G16 -> 1.296
A17: =철거공수량집계표!A17 -> 전나무 | B17: =철거공수량집계표!B17 -> H5.0xR20 | C17: =철거공수량집계표!C17 -> 주 | D17: =철거공수량집계표!D17 -> 3 | E17: ='폐기목 중량환산표1'!$R$6 -> 118.23529 | F17: =D17*E17 -> 354.70588 | G17: ='폐기목 중량환산표1'!$R$7 -> 0.103 | H17: =D17*G17 -> 0.309
A18: =철거공수량집계표!A18 -> 전나무 | B18: =철거공수량집계표!B18 -> H3.5xW1.8 | C18: =철거공수량집계표!C18 -> 주 | D18: =철거공수량집계표!D18 -> 6 | E18: ='폐기목 중량환산표1'!$N$6 -> 66.235294 | F18: =D18*E18 -> 397.41176 | G18: ='폐기목 중량환산표1'!$N$7 -> 0.058 | H18: =D18*G18 -> 0.348
A19: =철거공수량집계표!A19 -> 전나무 | B19: =철거공수량집계표!B19 -> H3.0xW1.5 | C19: =철거공수량집계표!C19 -> 주 | D19: =철거공수량집계표!D19 -> 11 | E19: ='폐기목 중량환산표1'!$J$6 -> 31.882353 | F19: =D19*E19 -> 350.70588 | G19: ='폐기목 중량환산표1'!$J$7 -> 0.028 | H19: =D19*G19 -> 0.308
A20: =철거공수량집계표!A20 -> 주목 | B20: =철거공수량집계표!B20 -> H2.5xW2.0 | C20: =철거공수량집계표!C20 -> 주 | D20: =철거공수량집계표!D20 -> 3 | E20: ='폐기목 중량환산표1'!$G$6 -> 14.941176 | F20: =D20*E20 -> 44.823529 | G20: ='폐기목 중량환산표1'!$G$7 -> 0.014 | H20: =D20*G20 -> 0.042
A21: =철거공수량집계표!A21 -> 주목 | B21: =철거공수량집계표!B21 -> H2.5xW1.2 | C21: =철거공수량집계표!C21 -> 주 | D21: =철거공수량집계표!D21 -> 2 | E21: ='폐기목 중량환산표1'!$E$6 -> 9.0588235 | F21: =D21*E21 -> 18.117647 | G21: ='폐기목 중량환산표1'!$E$7 -> 0.009 | H21: =D21*G21 -> 0.018
A22: =철거공수량집계표!A22 -> 소나무묘목 | B22: =철거공수량집계표!B22 -> H0.8xR3 | C22: =철거공수량집계표!C22 -> 주 | D22: =철거공수량집계표!D22 -> 100 | E22: ='폐기목 중량환산표1'!$B$6 -> 2.3529412 | F22: =D22*E22 -> 235.29412 | G22: ='폐기목 중량환산표1'!$B$7 -> 0.003 | H22: =D22*G22 -> 0.3
A23: =철거공수량집계표!A23 -> 가중나무 | B23: =철거공수량집계표!B23 -> H3.5xB6 | C23: =철거공수량집계표!C23 -> 주 | D23: =철거공수량집계표!D23 -> 9 | E23: ='폐기목 중량환산표1'!$F$6 -> 11.764706 | F23: =D23*E23 -> 105.88235 | G23: ='폐기목 중량환산표1'!$F$7 -> 0.01 | H23: =D23*G23 -> 0.09
A24: =철거공수량집계표!A24 -> 감나무 | B24: =철거공수량집계표!B24 -> H2.0xR4 | C24: =철거공수량집계표!C24 -> 주 | D24: =철거공수량집계표!D24 -> 2 | E24: ='폐기목 중량환산표1'!$B$6 -> 2.3529412 | F24: =D24*E24 -> 4.7058824 | G24: ='폐기목 중량환산표1'!$B$7 -> 0.003 | H24: =D24*G24 -> 0.006
A25: =철거공수량집계표!A25 -> 단풍나무 | B25: =철거공수량집계표!B25 -> H5.0xR20 | C25: =철거공수량집계표!C25 -> 주 | D25: =철거공수량집계표!D25 -> 3 | E25: ='폐기목 중량환산표1'!$R$6 -> 118.23529 | F25: =D25*E25 -> 354.70588 | G25: ='폐기목 중량환산표1'!$R$7 -> 0.103 | H25: =D25*G25 -> 0.309
A26: =철거공수량집계표!A26 -> 당단풍 | B26: =철거공수량집계표!B26 -> H3.0xR13 | C26: =철거공수량집계표!C26 -> 주 | D26: =철거공수량집계표!D26 -> 1 | E26: ='폐기목 중량환산표1'!$K$6 -> 37.411765 | F26: =D26*E26 -> 37.411765 | G26: ='폐기목 중량환산표1'!$K$7 -> 0.033 | H26: =D26*G26 -> 0.033
A27: =철거공수량집계표!A27 -> 대추나무 | B27: =철거공수량집계표!B27 -> H2.0xR4 | C27: =철거공수량집계표!C27 -> 주 | D27: =철거공수량집계표!D27 -> 13 | E27: ='폐기목 중량환산표1'!$B$6 -> 2.3529412 | F27: =D27*E27 -> 30.588235 | G27: ='폐기목 중량환산표1'!$B$7 -> 0.003 | H27: =D27*G27 -> 0.039
A28: =철거공수량집계표!A28 -> 백목련 | B28: =철거공수량집계표!B28 -> H3.5xR15 | C28: =철거공수량집계표!C28 -> 주 | D28: =철거공수량집계표!D28 -> 3 | E28: ='폐기목 중량환산표1'!$M$6 -> 58.235294 | F28: =D28*E28 -> 174.70588 | G28: ='폐기목 중량환산표1'!$M$7 -> 0.051 | H28: =D28*G28 -> 0.153
A29: =철거공수량집계표!A29 -> 버드나무 | B29: =철거공수량집계표!B29 -> H14.0xR69 | C29: =철거공수량집계표!C29 -> 주 | D29: =철거공수량집계표!D29 -> 1 | E29: ='폐기목 중량환산표2'!$P$16 -> 4221.1 | F29: =D29*E29 -> 4221.1 | G29: ='폐기목 중량환산표2'!$P$17 -> 3.663 | H29: =D29*G29 -> 3.663
A30: =철거공수량집계표!A30 -> 버드나무 | B30: =철거공수량집계표!B30 -> H13.0xR36 | C30: =철거공수량집계표!C30 -> 주 | D30: =철거공수량집계표!D30 -> 1 | E30: ='폐기목 중량환산표1'!$Q$16 -> 574.5 | F30: =D30*E30 -> 574.5 | G30: ='폐기목 중량환산표1'!$Q$17 -> 0.499 | H30: =D30*G30 -> 0.499
A31: =철거공수량집계표!A31 -> 버드나무 | B31: =철거공수량집계표!B31 -> H12.0xR22 | C31: =철거공수량집계표!C31 -> 주 | D31: =철거공수량집계표!D31 -> 6 | E31: ='폐기목 중량환산표1'!$C$16 -> 160.9 | F31: =D31*E31 -> 965.4 | G31: ='폐기목 중량환산표1'!$C$17 -> 0.14 | H31: =D31*G31 -> 0.84
A32: =철거공수량집계표!A32 -> 버드나무 | B32: =철거공수량집계표!B32 -> H10.0xR36 | C32: =철거공수량집계표!C32 -> 주 | D32: =철거공수량집계표!D32 -> 1 | E32: ='폐기목 중량환산표1'!$Q$16 -> 574.5 | F32: =D32*E32 -> 574.5 | G32: ='폐기목 중량환산표1'!$Q$17 -> 0.499 | H32: =D32*G32 -> 0.499
A33: =철거공수량집계표!A33 -> 버드나무 | B33: =철거공수량집계표!B33 -> H8.0xR16 | C33: =철거공수량집계표!C33 -> 주 | D33: =철거공수량집계표!D33 -> 5 | E33: ='폐기목 중량환산표1'!$N$6 -> 66.235294 | F33: =D33*E33 -> 331.17647 | G33: ='폐기목 중량환산표1'!$N$7 -> 0.058 | H33: =D33*G33 -> 0.29
A34: =철거공수량집계표!A34 -> 버드나무 | B34: =철거공수량집계표!B34 -> H7.0xR22 | C34: =철거공수량집계표!C34 -> 주 | D34: =철거공수량집계표!D34 -> 2 | E34: ='폐기목 중량환산표1'!$C$16 -> 160.9 | F34: =D34*E34 -> 321.8 | G34: ='폐기목 중량환산표1'!$C$17 -> 0.14 | H34: =D34*G34 -> 0.28
A35: =철거공수량집계표!A35 -> 버드나무 | B35: =철거공수량집계표!B35 -> H5.0xR10 | C35: =철거공수량집계표!C35 -> 주 | D35: =철거공수량집계표!D35 -> 9 | E35: ='폐기목 중량환산표1'!$K$6 -> 37.411765 | F35: =D35*E35 -> 336.70588 | G35: ='폐기목 중량환산표1'!$K$7 -> 0.033 | H35: =D35*G35 -> 0.297
A36: =철거공수량집계표!A36 -> 버드나무 | B36: =철거공수량집계표!B36 -> H14.0xW6.0xR44 | C36: =철거공수량집계표!C36 -> 주 | D36: =철거공수량집계표!D36 -> 1 | E36: ='폐기목 중량환산표2'!$H$6 -> 1001.2941 | F36: =D36*E36 -> 1001.2941 | G36: ='폐기목 중량환산표2'!$H$7 -> 0.869 | H36: =D36*G36 -> 0.869
A37: =철거공수량집계표!A37 -> 버드나무 | B37: =철거공수량집계표!B37 -> H5.0xW2.0xR10 | C37: =철거공수량집계표!C37 -> 주 | D37: =철거공수량집계표!D37 -> 5 | E37: ='폐기목 중량환산표1'!$K$6 -> 37.411765 | F37: =D37*E37 -> 187.05882 | G37: ='폐기목 중량환산표1'!$K$7 -> 0.033 | H37: =D37*G37 -> 0.165
A38: =철거공수량집계표!A38 -> 산수유 | B38: =철거공수량집계표!B38 -> H3.0xR12 | C38: =철거공수량집계표!C38 -> 주 | D38: =철거공수량집계표!D38 -> 1 | E38: ='폐기목 중량환산표1'!$J$6 -> 31.882353 | F38: =D38*E38 -> 31.882353 | G38: ='폐기목 중량환산표1'!$J$7 -> 0.028 | H38: =D38*G38 -> 0.028
A39: =철거공수량집계표!A39 -> 신갈나무 | B39: =철거공수량집계표!B39 -> H13.0xW6.0xR32 | C39: =철거공수량집계표!C39 -> 주 | D39: =철거공수량집계표!D39 -> 1 | E39: ='폐기목 중량환산표1'!$M$16 -> 416.1 | F39: =D39*E39 -> 416.1 | G39: ='폐기목 중량환산표1'!$M$17 -> 0.361 | H39: =D39*G39 -> 0.361
A40: =철거공수량집계표!A40 -> 아까시나무 | B40: =철거공수량집계표!B40 -> H7.0xR25 | C40: =철거공수량집계표!C40 -> 주 | D40: =철거공수량집계표!D40 -> 2 | E40: ='폐기목 중량환산표1'!$F$16 -> 230.9 | F40: =D40*E40 -> 461.8 | G40: ='폐기목 중량환산표1'!$F$17 -> 0.201 | H40: =D40*G40 -> 0.402
...

Sheet 폐기목중량
A1: ■ 임목폐기물 중량계산 | P1: 주1) 조경공사적산기준(2020) 4.3.2. 수목운반 참조 | R1: 조경공사적산기준 | T1: 접시분(천근성) | U1: 보통분 | V1: 조개분(심근성) | W1: (산림청)
B2: * 지상부 중량 W1 (kg) = K x 3.14 x (B/2)2 x H x W x (1+p) [ W : 수간의 단위체적중량 1,200(kg/m3), P : 지엽에 과다에 의한 보합률(0.2) ] | R2: 뿌리분 형태 | S2: 뿌리분 체적(m3) | T2: 0.3927 | U2: 0.4581 | V2: 0.5236 | W2: 가로수 조성관리 매뉴얼
B3: * 지하부(뿌리분) 체적 V (m3) = 3.14 x (D/2)2 x (D/2) + 3.14 x (D/2)2 x (D') x (1/3) [ D' : 뿌리분형상, 접시분(0), 보통분(D/4), 조개(팽이)분(D/2) ]
B4: * 지하부(뿌리분) 중량 W2 (kg) = V x W' [ V : 뿌리분체적(m3), W' : 뿌리분단위중량, 1300(kg/m3) ]
B5: * 벌근부 중량 W2' (kg) = W2 x 20 (%, 실제 계측수량 비율)
A7: 구 분 | C7: K | D7: B | F7: H | G7: W | H7: P | I7: W1 | J7: D | L7: W' | M7: W2 | N7: W2' | O7: W1+W2' | P7: 비고
C8: 수간 형상 계수 | D8: 흉고 직경 (cm) | E8: 흉고 (m) | F8: 수고 (m) | G8: 단위 중량 (kg) | H8: 보합률 | I8: 지상부 중량 (kg) | J8: 근원 직경 (R,cm) | K8: D=4R (m) | L8: 뿌리분 단위중량(kg) | M8: 지하부 중량(kg) | N8: 벌근부 중량(kg) | O8: 임목폐기물 중량(kg)
A9: 교 목 | B9: 소나무/ 참나무류 | C9: 0.5 | D9: =J9/1.2 -> 20.833333 | E9: =D9*0.01 -> 0.20833333 | F9: 7 | G9: 1200 | H9: 0.2 | I9: =TRUNC((C9*3.14*((E9/2)^2)*F9*G9*(1+H9)),3) -> 171.718 | J9: 25 | K9: =J9*4*0.01 -> 1 | L9: 1300 | M9: =$U$2*K9^3*1300 -> 595.53 | N9: =M9*0.2 -> 119.106 | O9: =I9+N9 -> 290.824
A11: 관 목

Sheet 폐기목 중량환산표1
A1: ■ 폐기목 중량 환산표 1
A2: 구분 | B2: 수목규격
A3: 근원직경R(cm) | B3: =수목제원표1!B3 -> 4 | C3: =수목제원표1!C3 -> 5 | D3: =수목제원표1!D3 -> 6 | E3: =수목제원표1!E3 -> 7 | F3: =수목제원표1!F3 -> 8 | G3: =수목제원표1!G3 -> 9 | H3: =수목제원표1!H3 -> 10 | I3: =수목제원표1!I3 -> 11 | ... R3: =수목제원표1!R3 -> 20
A4: 흉고직경B(cm) | B4: =수목제원표1!B4 -> 3.2 | C4: =수목제원표1!C4 -> 4 | D4: =수목제원표1!D4 -> 4.8 | E4: =수목제원표1!E4 -> 5.6 | F4: =수목제원표1!F4 -> 6.4 | G4: =수목제원표1!G4 -> 7.2 | H4: =수목제원표1!H4 -> 8 | I4: =수목제원표1!I4 -> 8.8 | ... R4: =수목제원표1!R4 -> 16
A5: 수고H(m) | B5: =수목제원표1!B5 -> 2 | C5: =수목제원표1!C5 -> 2 | D5: =수목제원표1!D5 -> 2 | E5: =수목제원표1!E5 -> 2.5 | F5: =수목제원표1!F5 -> 2.5 | G5: =수목제원표1!G5 -> 2.5 | H5: =수목제원표1!H5 -> 2.5 | I5: =수목제원표1!I5 -> 3 | ... R5: =수목제원표1!R5 -> 4
A6: 폐기목 전체중량 | B6: =B8/$C23 -> 2.3529412 | C6: =C8/$C23 -> 3.6470588 | D6: =D8/$C23 -> 5.2941176 | E6: =E8/$C23 -> 9.0588235 | F6: =F8/$C23 -> 11.764706 | G6: =G8/$C23 -> 14.941176 | H6: =H8/$C23 -> 18.470588 | I6: =I8/$C23 -> 26.823529 | ... R6: =R8/$C23 -> 118.23529
A7: 폐기목 전체제적 | B7: =B9+B11 -> 0.003 | C7: =C9+C11 -> 0.004 | D7: =D9+D11 -> 0.005 | E7: =E9+E11 -> 0.009 | F7: =F9+F11 -> 0.01 | G7: =G9+G11 -> 0.014 | H7: =H9+H11 -> 0.017 | I7: =I9+I11 -> 0.024 | ... R7: =R9+R11 -> 0.103
A8: 지상부 중량(kg) | B8: =수목제원표1!B10 -> 2 | C8: =수목제원표1!C10 -> 3.1 | D8: =수목제원표1!D10 -> 4.5 | E8: =수목제원표1!E10 -> 7.7 | F8: =수목제원표1!F10 -> 10 | G8: =수목제원표1!G10 -> 12.7 | H8: =수목제원표1!H10 -> 15.7 | I8: =수목제원표1!I10 -> 22.8 | ... R8: =수목제원표1!R10 -> 100.5
A9: 지상부 제적(㎥) | B9: =수목제원표1!B11 -> 0.002 | C9: =수목제원표1!C11 -> 0.003 | D9: =수목제원표1!D11 -> 0.004 | E9: =수목제원표1!E11 -> 0.007 | F9: =수목제원표1!F11 -> 0.008 | G9: =수목제원표1!G11 -> 0.011 | H9: =수목제원표1!H11 -> 0.013 | I9: =수목제원표1!I11 -> 0.019 | ... R9: =수목제원표1!R11 -> 0.081
A10: 지하부 중량(kg) | B10: =ROUND(B6*$C24,1) -> 0.4 | C10: =ROUND(C6*$C24,1) -> 0.5 | D10: =ROUND(D6*$C24,1) -> 0.8 | E10: =ROUND(E6*$C24,1) -> 1.4 | F10: =ROUND(F6*$C24,1) -> 1.8 | G10: =ROUND(G6*$C24,1) -> 2.2 | H10: =ROUND(H6*$C24,1) -> 2.8 | I10: =ROUND(I6*$C24,1) -> 4 | ... R10: =ROUND(R6*$C24,1) -> 17.7
A11: 지하부 제적(㎥) | B11: =ROUND(B10/800,3) -> 0.001 | C11: =ROUND(C10/800,3) -> 0.001 | D11: =ROUND(D10/800,3) -> 0.001 | E11: =ROUND(E10/800,3) -> 0.002 | F11: =ROUND(F10/800,3) -> 0.002 | G11: =ROUND(G10/800,3) -> 0.003 | H11: =ROUND(H10/800,3) -> 0.004 | I11: =ROUND(I10/800,3) -> 0.005 | ... R11: =ROUND(R10/800,3) -> 0.022
A12: 구분 | B12: 수목규격
A13: 근원직경R(cm) | B13: =수목제원표1!B22 -> 21 | C13: ='[211]수목 제원표1'!C22 -> 22 | D13: ='[211]수목 제원표1'!D22 -> 23 | E13: ='[211]수목 제원표1'!E22 -> 24 | F13: ='[211]수목 제원표1'!F22 -> 25 | G13: ='[211]수목 제원표1'!G22 -> 26 | H13: ='[211]수목 제원표1'!H22 -> 27 | I13: ='[211]수목 제원표1'!I22 -> 28 | J13: ='[211]수목 제원표1'!J22 -> 29 | ... R13: ='[211]수목 제원표1'!R22 -> 37
A14: 흉고직경B(cm) | B14: =수목제원표1!B23 -> 16.8 | C14: =C13*0.8 -> 17.6 | D14: =D13*0.8 -> 18.4 | E14: =E13*0.8 -> 19.2 | F14: =F13*0.8 -> 20 | G14: =G13*0.8 -> 20.8 | H14: =H13*0.8 -> 21.6 | I14: =I13*0.8 -> 22.4 | J14: =J13*0.8 -> 23.2 | ... R14: =R13*0.8 -> 29.6
A15: 수고H(m) | B15: =수목제원표1!B24 -> 4.5 | C15: ='[211]수목 제원표1'!C24 -> 4.5 | D15: ='[211]수목 제원표1'!D24 -> 4.5 | E15: ='[211]수목 제원표1'!E24 -> 4.5 | F15: ='[211]수목 제원표1'!F24 -> 5 | G15: ='[211]수목 제원표1'!G24 -> 5 | H15: ='[211]수목 제원표1'!H24 -> 5 | I15: ='[211]수목 제원표1'!I24 -> 5 | J15: ='[211]수목 제원표1'!J24 -> 5 | ... R15: ='[211]수목 제원표1'!R24 -> 6
A16: 폐기목 전체중량 | B16: =ROUND(B18/$C23,1) -> 146.6 | C16: =ROUND(C18/$C23,1) -> 160.9 | D16: =ROUND(D18/$C23,1) -> 175.9 | E16: =ROUND(E18/$C23,1) -> 191.5 | F16: =ROUND(F18/$C23,1) -> 230.9 | G16: =ROUND(G18/$C23,1) -> 249.8 | H16: =ROUND(H18/$C23,1) -> 269.3 | I16: =ROUND(I18/$C23,1) -> 289.6 | ... R16: =ROUND(R18/$C23,1) -> 606.8
A17: 폐기목 전체제적 | B17: =B19+B21 -> 0.128 | C17: =C19+C21 -> 0.14 | D17: =D19+D21 -> 0.153 | E17: =E19+E21 -> 0.167 | F17: =F19+F21 -> 0.201 | G17: =G19+G21 -> 0.217 | H17: =H19+H21 -> 0.235 | I17: =I19+I21 -> 0.251 | ... R17: =R19+R21 -> 0.527
A18: 지상부 중량(kg) | B18: =수목제원표1!B29 -> 124.6 | C18: =수목제원표1!C29 -> 136.8 | D18: =수목제원표1!D29 -> 149.5 | E18: =수목제원표1!E29 -> 162.8 | F18: =수목제원표1!F29 -> 196.3 | G18: =수목제원표1!G29 -> 212.3 | H18: =수목제원표1!H29 -> 228.9 | I18: =수목제원표1!I29 -> 246.2 | ... R18: =수목제원표1!R29 -> 515.8
A19: 지상부 제적(㎥) | B19: =수목제원표1!B30 -> 0.1 | C19: =수목제원표1!C30 -> 0.11 | D19: =수목제원표1!D30 -> 0.12 | E19: =수목제원표1!E30 -> 0.131 | F19: =수목제원표1!F30 -> 0.158 | G19: =수목제원표1!G30 -> 0.17 | H19: =수목제원표1!H30 -> 0.184 | I19: =수목제원표1!I30 -> 0.197 | ... R19: =수목제원표1!R30 -> 0.413
A20: 지하부 중량(kg) | B20: =ROUND(B16*$C24,1) -> 22 | C20: =ROUND(C16*$C24,1) -> 24.1 | D20: =ROUND(D16*$C24,1) -> 26.4 | E20: =ROUND(E16*$C24,1) -> 28.7 | F20: =ROUND(F16*$C24,1) -> 34.6 | G20: =ROUND(G16*$C24,1) -> 37.5 | H20: =ROUND(H16*$C24,1) -> 40.4 | I20: =ROUND(I16*$C24,1) -> 43.4 | ... R20: =ROUND(R16*$C24,1) -> 91
A21: 지하부 제적(㎥) | B21: =ROUND(B20/800,3) -> 0.028 | C21: =ROUND(C20/800,3) -> 0.03 | D21: =ROUND(D20/800,3) -> 0.033 | E21: =ROUND(E20/800,3) -> 0.036 | F21: =ROUND(F20/800,3) -> 0.043 | G21: =ROUND(G20/800,3) -> 0.047 | H21: =ROUND(H20/800,3) -> 0.051 | I21: =ROUND(I20/800,3) -> 0.054 | ... R21: =ROUND(R20/800,3) -> 0.114
A22: * 각 부분 분배비 (참고: 산림생태학_이경준외 4인)
A23: 지상부중량 | B23: : | C23: =G23+G24+G25 -> 0.85 | E23: 줄기 | F23: : | G23: 0.45
A24: 지하부중량 | B24: : | C24: =G26 -> 0.15 | E24: 가지 | F24: : | G24: 0.15
A25: 전체중량 | B25: : | C25: =C23+C24 -> 1 | E25: 잎 | F25: : | G25: 0.25
E26: 뿌리분 | F26: : | G26: 0.15

Sheet 폐기목 중량환산표2
A1: ■ 폐기목 중량 환산표 2
A2: 구분 | B2: 수목규격
A3: 근원직경R(cm) | B3: =수목제원표2!B3 -> 38 | C3: =수목제원표2!C3 -> 39 | D3: =수목제원표2!D3 -> 40 | E3: =수목제원표2!E3 -> 41 | F3: =수목제원표2!F3 -> 42 | G3: =수목제원표2!G3 -> 43 | H3: =수목제원표2!H3 -> 44 | I3: =수목제원표2!I3 -> 45 | ... R3: =수목제원표2!R3 -> 54
A4: 흉고직경B(cm) | B4: =수목제원표2!B4 -> 30.4 | C4: =수목제원표2!C4 -> 31.2 | D4: =수목제원표2!D4 -> 32 | E4: =수목제원표2!E4 -> 32.8 | F4: =수목제원표2!F4 -> 33.6 | G4: =수목제원표2!G4 -> 34.4 | H4: =수목제원표2!H4 -> 35.2 | I4: =수목제원표2!I4 -> 36 | ... R4: =수목제원표2!R4 -> 43.2
A5: 수고H(m) | B5: =수목제원표2!B5 -> 6 | C5: =수목제원표2!C5 -> 6 | D5: =수목제원표2!D5 -> 7 | E5: =수목제원표2!E5 -> 7 | F5: =수목제원표2!F5 -> 7 | G5: =수목제원표2!G5 -> 7 | H5: =수목제원표2!H5 -> 7 | I5: =수목제원표2!I5 -> 8 | ... R5: =수목제원표2!R5 -> 9
A6: 폐기목 전체중량 | B6: =B8/$C23 -> 640.11765 | C6: =C8/$C23 -> 674.23529 | D6: =D8/$C23 -> 827.52941 | E6: =E8/$C23 -> 869.41176 | F6: =F8/$C23 -> 912.35294 | G6: =G8/$C23 -> 956.23529 | H6: =H8/$C23 -> 1001.2941 | I6: =I8/$C23 -> 1196.9412 | ... R6: =R8/$C23 -> 1938.9412
A7: 폐기목 전체제적 | B7: =B9+B11 -> 0.556 | C7: =C9+C11 -> 0.585 | D7: =D9+D11 -> 0.718 | E7: =E9+E11 -> 0.755 | F7: =F9+F11 -> 0.792 | G7: =G9+G11 -> 0.83 | H7: =H9+H11 -> 0.869 | I7: =I9+I11 -> 1.038 | ... R7: =R9+R11 -> 1.683
A8: 지상부 중량(kg) | B8: =수목제원표2!B10 -> 544.1 | C8: =수목제원표2!C10 -> 573.1 | D8: =수목제원표2!D10 -> 703.4 | E8: =수목제원표2!E10 -> 739 | F8: =수목제원표2!F10 -> 775.5 | G8: =수목제원표2!G10 -> 812.8 | H8: =수목제원표2!H10 -> 851.1 | I8: =수목제원표2!I10 -> 1017.4 | ... R8: =수목제원표2!R10 -> 1648.1
A9: 지상부 제적(㎥) | B9: =수목제원표2!B11 -> 0.436 | C9: =수목제원표2!C11 -> 0.459 | D9: =수목제원표2!D11 -> 0.563 | E9: =수목제원표2!E11 -> 0.592 | F9: =수목제원표2!F11 -> 0.621 | G9: =수목제원표2!G11 -> 0.651 | H9: =수목제원표2!H11 -> 0.681 | I9: =수목제원표2!I11 -> 0.814 | ... R9: =수목제원표2!R11 -> 1.319
A10: 지하부 중량(kg) | B10: =ROUND(B6*$C24,1) -> 96 | C10: =ROUND(C6*$C24,1) -> 101.1 | D10: =ROUND(D6*$C24,1) -> 124.1 | E10: =ROUND(E6*$C24,1) -> 130.4 | F10: =ROUND(F6*$C24,1) -> 136.9 | G10: =ROUND(G6*$C24,1) -> 143.4 | H10: =ROUND(H6*$C24,1) -> 150.2 | I10: =ROUND(I6*$C24,1) -> 179.5 | ... R10: =ROUND(R6*$C24,1) -> 290.8
A11: 지하부 제적(㎥) | B11: =ROUND(B10/800,3) -> 0.12 | C11: =ROUND(C10/800,3) -> 0.126 | D11: =ROUND(D10/800,3) -> 0.155 | E11: =ROUND(E10/800,3) -> 0.163 | F11: =ROUND(F10/800,3) -> 0.171 | G11: =ROUND(G10/800,3) -> 0.179 | H11: =ROUND(H10/800,3) -> 0.188 | I11: =ROUND(I10/800,3) -> 0.224 | ... R11: =ROUND(R10/800,3) -> 0.364
A12: 구분 | B12: 수목규격
A13: 근원직경R(cm) | B13: =수목제원표2!B22 -> 55 | C13: ='[211]수목 제원표2'!C22 -> 56 | D13: ='[211]수목 제원표2'!D22 -> 57 | E13: ='[211]수목 제원표2'!E22 -> 58 | F13: ='[211]수목 제원표2'!F22 -> 59 | G13: ='[211]수목 제원표2'!G22 -> 60 | H13: ='[211]수목 제원표2'!H22 -> 61 | I13: ='[211]수목 제원표2'!I22 -> 62 | J13: ='[211]수목 제원표2'!J22 -> 63 | ... R13: ='[211]수목 제원표2'!R22 -> 71
A14: 흉고직경B(cm) | B14: =수목제원표2!B23 -> 44 | C14: =C13*0.8 -> 44.8 | D14: =D13*0.8 -> 45.6 | E14: =E13*0.8 -> 46.4 | F14: =F13*0.8 -> 47.2 | G14: =G13*0.8 -> 48 | H14: =H13*0.8 -> 48.8 | I14: =I13*0.8 -> 49.6 | J14: =J13*0.8 -> 50.4 | ... R14: =R13*0.8 -> 56.8
A15: 수고H(m) | B15: =수목제원표2!B24 -> 10 | C15: ='[211]수목 제원표2'!C24 -> 10 | D15: ='[211]수목 제원표2'!D24 -> 10 | E15: ='[211]수목 제원표2'!E24 -> 10 | F15: ='[211]수목 제원표2'!F24 -> 10 | G15: ='[211]수목 제원표2'!G24 -> 11 | H15: ='[211]수목 제원표2'!H24 -> 11 | I15: ='[211]수목 제원표2'!I24 -> 11 | J15: ='[211]수목 제원표2'!J24 -> 11 | ... R15: ='[211]수목 제원표2'!R24 -> 13
A16: 폐기목 전체중량 | B16: =ROUND(B18/$C23,1) -> 2234.9 | C16: =ROUND(C18/$C23,1) -> 2316.9 | D16: =ROUND(D18/$C23,1) -> 2400.5 | E16: =ROUND(E18/$C23,1) -> 2485.4 | F16: =ROUND(F18/$C23,1) -> 2571.9 | G16: =ROUND(G18/$C23,1) -> 2925.8 | H16: =ROUND(H18/$C23,1) -> 3024.1 | I16: =ROUND(I18/$C23,1) -> 3124 | ... R16: =ROUND(R18/$C23,1) -> 4841.8
A17: 폐기목 전체제적 | B17: =B19+B21 -> 1.939 | C17: =C19+C21 -> 2.01 | D17: =D19+D21 -> 2.083 | E17: =E19+E21 -> 2.157 | F17: =F19+F21 -> 2.231 | G17: =G19+G21 -> 2.539 | H17: =H19+H21 -> 2.624 | I17: =I19+I21 -> 2.711 | ... R17: =R19+R21 -> 4.201
A18: 지상부 중량(kg) | B18: =수목제원표2!B29 -> 1899.7 | C18: =수목제원표2!C29 -> 1969.4 | D18: =수목제원표2!D29 -> 2040.4 | E18: =수목제원표2!E29 -> 2112.6 | F18: =수목제원표2!F29 -> 2186.1 | G18: =수목제원표2!G29 -> 2486.9 | H18: =수목제원표2!H29 -> 2570.5 | I18: =수목제원표2!I29 -> 2655.4 | ... R18: =수목제원표2!R29 -> 4115.5
A19: 지상부 제적(㎥) | B19: =수목제원표2!B30 -> 1.52 | C19: =수목제원표2!C30 -> 1.576 | D19: =수목제원표2!D30 -> 1.633 | E19: =수목제원표2!E30 -> 1.691 | F19: =수목제원표2!F30 -> 1.749 | G19: =수목제원표2!G30 -> 1.99 | H19: =수목제원표2!H30 -> 2.057 | I19: =수목제원표2!I30 -> 2.125 | ... R19: =수목제원표2!R30 -> 3.293
A20: 지하부 중량(kg) | B20: =ROUND(B16*$C24,1) -> 335.2 | C20: =ROUND(C16*$C24,1) -> 347.5 | D20: =ROUND(D16*$C24,1) -> 360.1 | E20: =ROUND(E16*$C24,1) -> 372.8 | F20: =ROUND(F16*$C24,1) -> 385.8 | G20: =ROUND(G16*$C24,1) -> 438.9 | H20: =ROUND(H16*$C24,1) -> 453.6 | I20: =ROUND(I16*$C24,1) -> 468.6 | ... R20: =ROUND(R16*$C24,1) -> 726.3
A21: 지하부 제적(㎥) | B21: =ROUND(B20/800,3) -> 0.419 | C21: =ROUND(C20/800,3) -> 0.434 | D21: =ROUND(D20/800,3) -> 0.45 | E21: =ROUND(E20/800,3) -> 0.466 | F21: =ROUND(F20/800,3) -> 0.482 | G21: =ROUND(G20/800,3) -> 0.549 | H21: =ROUND(H20/800,3) -> 0.567 | I21: =ROUND(I20/800,3) -> 0.586 | ... R21: =ROUND(R20/800,3) -> 0.908
A22: * 각 부분 분배비 (참고: 산림생태학_이경준외 4인)
A23: 지상부중량 | B23: : | C23: =G23+G24+G25 -> 0.85 | E23: 줄기 | F23: : | G23: 0.45
A24: 지하부중량 | B24: : | C24: =G26 -> 0.15 | E24: 가지 | F24: : | G24: 0.15
A25: 전체중량 | B25: : | C25: =C23+C24 -> 1 | E25: 잎 | F25: : | G25: 0.25
E26: 뿌리분 | F26: : | G26: 0.15

Sheet 수목제원표1
A1: 수목 제원표 1
A2: 구분 | B2: 수목규격
A3: 근원직경R(cm) | B3: 4 | C3: 5 | D3: 6 | E3: 7 | F3: 8 | G3: 9 | H3: 10 | I3: 11 | J3: 12 | K3: 13 | L3: 14 | M3: 15 | N3: 16 | O3: 17 | P3: 18 | Q3: 19 | R3: 20
A4: 흉고직경B(cm) | B4: =B3*0.8 -> 3.2 | C4: =C3*0.8 -> 4 | D4: =D3*0.8 -> 4.8 | E4: =E3*0.8 -> 5.6 | F4: =F3*0.8 -> 6.4 | G4: =G3*0.8 -> 7.2 | H4: =H3*0.8 -> 8 | I4: =I3*0.8 -> 8.8 | ... R4: =R3*0.8 -> 16
A5: 수고H(m) | B5: 2 | C5: 2 | D5: 2 | E5: 2.5 | F5: 2.5 | G5: 2.5 | H5: 2.5 | I5: 3 | J5: 3 | K5: 3 | L5: 3 | M5: 3.5 | N5: 3.5 | O5: 3.5 | P5: 4 | Q5: 4 | R5: 4
A6: 수간형상계수(k) | B6: 0.5 | C6: 0.5 | D6: 0.5 | E6: 0.5 | F6: 0.5 | G6: 0.5 | H6: 0.5 | I6: 0.5 | J6: 0.5 | K6: 0.5 | L6: 0.5 | M6: 0.5 | N6: 0.5 | O6: 0.5 | P6: 0.5 | Q6: 0.5 | R6: 0.5
A7: 원 주 율(π) | B7: 3.14 | C7: 3.14 | D7: 3.14 | E7: 3.14 | F7: 3.14 | G7: 3.14 | H7: 3.14 | I7: 3.14 | J7: 3.14 | K7: 3.14 | L7: 3.14 | M7: 3.14 | N7: 3.14 | O7: 3.14 | P7: 3.14 | Q7: 3.14 | R7: 3.14
A8: 수목생체단위중량(w1, kg/㎥) | B8: 1250 | C8: 1250 | D8: 1250 | E8: 1250 | F8: 1250 | G8: 1250 | H8: 1250 | I8: 1250 | J8: 1250 | K8: 1250 | L8: 1250 | M8: 1250 | N8: 1250 | O8: 1250 | P8: 1250 | Q8: 1250 | R8: 1250
A9: 보합률(P,고립) | B9: 1 | C9: 1 | D9: 1 | E9: 1 | F9: 1 | G9: 1 | H9: 1 | I9: 1 | J9: 1 | K9: 1 | L9: 1 | M9: 1 | N9: 1 | O9: 1 | P9: 1 | Q9: 1 | R9: 1
A10: 지상부 중량(kg) | B10: =ROUND(B6*B7*(B4/2)^2*B5*B8*(1+B9)/10000,1) -> 2 | C10: =ROUND(C6*C7*(C4/2)^2*C5*C8*(1+C9)/10000,1) -> 3.1 | D10: =ROUND(D6*D7*(D4/2)^2*D5*D8*(1+D9)/10000,1) -> 4.5 | E10: =ROUND(E6*E7*(E4/2)^2*E5*E8*(1+E9)/10000,1) -> 7.7 | F10: =ROUND(F6*F7*(F4/2)^2*F5*F8*(1+F9)/10000,1) -> 10 | G10: =ROUND(G6*G7*(G4/2)^2*G5*G8*(1+G9)/10000,1) -> 12.7 | H10: =ROUND(H6*H7*(H4/2)^2*H5*H8*(1+H9)/10000,1) -> 15.7 | I10: =ROUND(I6*I7*(I4/2)^2*I5*I8*(1+I9)/10000,1) -> 22.8 | ... R10: =ROUND(R6*R7*(R4/2)^2*R5*R8*(1+R9)/10000,1) -> 100.5
A11: 지상부 제적(㎥) | B11: =ROUNDUP(B10/B8,3) -> 0.002 | C11: =ROUNDUP(C10/C8,3) -> 0.003 | D11: =ROUNDUP(D10/D8,3) -> 0.004 | E11: =ROUNDUP(E10/E8,3) -> 0.007 | F11: =ROUNDUP(F10/F8,3) -> 0.008 | G11: =ROUNDUP(G10/G8,3) -> 0.011 | H11: =ROUNDUP(H10/H8,3) -> 0.013 | I11: =ROUNDUP(I10/I8,3) -> 0.019 | ... R11: =ROUNDUP(R10/R8,3) -> 0.081
A12: 뿌리분직경(D,cm,5배분) | B12: =B3*5 -> 20 | C12: =C3*5 -> 25 | D12: =D3*5 -> 30 | E12: =E3*5 -> 35 | F12: =F3*5 -> 40 | G12: =G3*5 -> 45 | H12: =H3*5 -> 50 | I12: =I3*5 -> 55 | ... R12: =R3*5 -> 100
A13: 분체적(V, ㎥) | B13: =ROUND(7/48*B7*(B12/100)^3,4) -> 0.0037 | C13: =ROUND(7/48*C7*(C12/100)^3,4) -> 0.0072 | D13: =ROUND(7/48*D7*(D12/100)^3,4) -> 0.0124 | E13: =ROUND(7/48*E7*(E12/100)^3,4) -> 0.0196 | F13: =ROUND(7/48*F7*(F12/100)^3,4) -> 0.0293 | G13: =ROUND(7/48*G7*(G12/100)^3,4) -> 0.0417 | H13: =ROUND(7/48*H7*(H12/100)^3,4) -> 0.0572 | I13: =ROUND(7/48*I7*(I12/100)^3,4) -> 0.0762 | ... R13: =ROUND(7/48*R7*(R12/100)^3,4) -> 0.4579
A14: 뿌리분단위당중량(t/㎥) | B14: 1.3 | C14: 1.3 | D14: 1.3 | E14: 1.3 | F14: 1.3 | G14: 1.3 | H14: 1.3 | I14: 1.3 | J14: 1.3 | K14: 1.3 | L14: 1.3 | M14: 1.3 | N14: 1.3 | O14: 1.3 | P14: 1.3 | Q14: 1.3 | R14: 1.3
A15: 수목의 지하부 중량(kg) | B15: =ROUND(B13*B14*1000,1) -> 4.8 | C15: =ROUND(C13*C14*1000,1) -> 9.4 | D15: =ROUND(D13*D14*1000,1) -> 16.1 | E15: =ROUND(E13*E14*1000,1) -> 25.5 | F15: =ROUND(F13*F14*1000,1) -> 38.1 | G15: =ROUND(G13*G14*1000,1) -> 54.2 | H15: =ROUND(H13*H14*1000,1) -> 74.4 | I15: =ROUND(I13*I14*1000,1) -> 99.1 | ... R15: =ROUND(R13*R14*1000,1) -> 595.3
A16: 전제 중량(kg) | B16: =B10+B15 -> 6.8 | C16: =C10+C15 -> 12.5 | D16: =D10+D15 -> 20.6 | E16: =E10+E15 -> 33.2 | F16: =F10+F15 -> 48.1 | G16: =G10+G15 -> 66.9 | H16: =H10+H15 -> 90.1 | I16: =I10+I15 -> 121.9 | ... R16: =R10+R15 -> 695.8
A17: 전체 부피(㎥) | B17: =B11+B13 -> 0.0057 | C17: =C11+C13 -> 0.0102 | D17: =D11+D13 -> 0.0164 | E17: =E11+E13 -> 0.0266 | F17: =F11+F13 -> 0.0373 | G17: =G11+G13 -> 0.0527 | H17: =H11+H13 -> 0.0702 | I17: =I11+I13 -> 0.0952 | ... R17: =R11+R13 -> 0.5389
A18: 수목 면적(㎡) | B18: =ROUND(3.14*(B5*0.8/2*B5*0.8/2),2) -> 2.01 | C18: =ROUND(3.14*(C5*0.8/2*C5*0.8/2),2) -> 2.01 | D18: =ROUND(3.14*(D5*0.8/2*D5*0.8/2),2) -> 2.01 | E18: =ROUND(3.14*(E5*0.8/2*E5*0.8/2),2) -> 3.14 | F18: =ROUND(3.14*(F5*0.8/2*F5*0.8/2),2) -> 3.14 | G18: =ROUND(3.14*(G5*0.8/2*G5*0.8/2),2) -> 3.14 | H18: =ROUND(3.14*(H5*0.8/2*H5*0.8/2),2) -> 3.14 | I18: =ROUND(3.14*(I5*0.8/2*I5*0.8/2),2) -> 4.52 | ... R18: =ROUND(3.14*(R5*0.8/2*R5*0.8/2),2) -> 8.04
A19: 전정잔재물 (지상부x30%)(Kg) | B19: =ROUND(B10*30%,2) -> 0.6 | C19: =ROUND(C10*30%,2) -> 0.93 | D19: =ROUND(D10*30%,2) -> 1.35 | E19: =ROUND(E10*30%,2) -> 2.31 | F19: =ROUND(F10*30%,2) -> 3 | G19: =ROUND(G10*30%,2) -> 3.81 | H19: =ROUND(H10*30%,2) -> 4.71 | I19: =ROUND(I10*30%,2) -> 6.84 | ... R19: =ROUND(R10*30%,2) -> 30.15
A20: 전정부피- 적사(M3) | B20: =ROUND(B19/1000/0.5,3) -> 0.001 | C20: =ROUND(C19/1000/0.5,3) -> 0.002 | D20: =ROUND(D19/1000/0.5,3) -> 0.003 | E20: =ROUND(E19/1000/0.5,3) -> 0.005 | F20: =ROUND(F19/1000/0.5,3) -> 0.006 | G20: =ROUND(G19/1000/0.5,3) -> 0.008 | H20: =ROUND(H19/1000/0.5,3) -> 0.009 | I20: =ROUND(I19/1000/0.5,3) -> 0.014 | ... R20: =ROUND(R19/1000/0.5,3) -> 0.06
A21: 구분 | B21: 수목규격
A22: 근원직경R(cm) | B22: 21 | C22: 22 | D22: 23 | E22: 24 | F22: 25 | G22: 26 | H22: 27 | I22: 28 | J22: 29 | K22: 30 | L22: 31 | M22: 32 | N22: 33 | O22: 34 | P22: 35 | Q22: 36 | R22: 37
A23: 흉고직경B(cm) | B23: =B22*0.8 -> 16.8 | C23: =C22*0.8 -> 17.6 | D23: =D22*0.8 -> 18.4 | E23: =E22*0.8 -> 19.2 | F23: =F22*0.8 -> 20 | G23: =G22*0.8 -> 20.8 | H23: =H22*0.8 -> 21.6 | I23: =I22*0.8 -> 22.4 | ... R23: =R22*0.8 -> 29.6
A24: 수고H(m) | B24: 4.5 | C24: 4.5 | D24: 4.5 | E24: 4.5 | F24: 5 | G24: 5 | H24: 5 | I24: 5 | J24: 5 | K24: 5 | L24: 5.5 | M24: 5.5 | N24: 5.5 | O24: 5.5 | P24: 5.5 | Q24: 6 | R24: 6
A25: 수간형상계수(f) | B25: 0.5 | C25: 0.5 | D25: 0.5 | E25: 0.5 | F25: 0.5 | G25: 0.5 | H25: 0.5 | I25: 0.5 | J25: 0.5 | K25: 0.5 | L25: 0.5 | M25: 0.5 | N25: 0.5 | O25: 0.5 | P25: 0.5 | Q25: 0.5 | R25: 0.5
A26: 원 주 율(π) | B26: 3.14 | C26: 3.14 | D26: 3.14 | E26: 3.14 | F26: 3.14 | G26: 3.14 | H26: 3.14 | I26: 3.14 | J26: 3.14 | K26: 3.14 | L26: 3.14 | M26: 3.14 | N26: 3.14 | O26: 3.14 | P26: 3.14 | Q26: 3.14 | R26: 3.14
A27: 수목생체단위중량(w1, kg/㎥) | B27: 1250 | C27: 1250 | D27: 1250 | E27: 1250 | F27: 1250 | G27: 1250 | H27: 1250 | I27: 1250 | J27: 1250 | K27: 1250 | L27: 1250 | M27: 1250 | N27: 1250 | O27: 1250 | P27: 1250 | Q27: 1250 | R27: 1250
A28: 보합률(P,고립) | B28: 1 | C28: 1 | D28: 1 | E28: 1 | F28: 1 | G28: 1 | H28: 1 | I28: 1 | J28: 1 | K28: 1 | L28: 1 | M28: 1 | N28: 1 | O28: 1 | P28: 1 | Q28: 1 | R28: 1
A29: 지상부 중량(kg) | B29: =ROUND(B25*B26*(B23/2)^2*B24*B27*(1+B28)/10000,1) -> 124.6 | C29: =ROUND(C25*C26*(C23/2)^2*C24*C27*(1+C28)/10000,1) -> 136.8 | D29: =ROUND(D25*D26*(D23/2)^2*D24*D27*(1+D28)/10000,1) -> 149.5 | E29: =ROUND(E25*E26*(E23/2)^2*E24*E27*(1+E28)/10000,1) -> 162.8 | F29: =ROUND(F25*F26*(F23/2)^2*F24*F27*(1+F28)/10000,1) -> 196.3 | G29: =ROUND(G25*G26*(G23/2)^2*G24*G27*(1+G28)/10000,1) -> 212.3 | H29: =ROUND(H25*H26*(H23/2)^2*H24*H27*(1+H28)/10000,1) -> 228.9 | I29: =ROUND(I25*I26*(I23/2)^2*I24*I27*(1+I28)/10000,1) -> 246.2 | ... R29: =ROUND(R25*R26*(R23/2)^2*R24*R27*(1+R28)/10000,1) -> 515.8
A30: 지상부 제적(㎥) | B30: =ROUNDUP(B29/B27,3) -> 0.1 | C30: =ROUNDUP(C29/C27,3) -> 0.11 | D30: =ROUNDUP(D29/D27,3) -> 0.12 | E30: =ROUNDUP(E29/E27,3) -> 0.131 | F30: =ROUNDUP(F29/F27,3) -> 0.158 | G30: =ROUNDUP(G29/G27,3) -> 0.17 | H30: =ROUNDUP(H29/H27,3) -> 0.184 | I30: =ROUNDUP(I29/I27,3) -> 0.197 | ... R30: =ROUNDUP(R29/R27,3) -> 0.413
A31: 뿌리분직경(D,cm,5배분) | B31: =B22*5 -> 105 | C31: =C22*5 -> 110 | D31: =D22*5 -> 115 | E31: =E22*5 -> 120 | F31: =F22*5 -> 125 | G31: =G22*5 -> 130 | H31: =H22*5 -> 135 | I31: =I22*5 -> 140 | ... R31: =R22*5 -> 185
A32: 분체적(V, ㎥) | B32: =ROUND(7/48*B26*(B31/100)^3,4) -> 0.5301 | C32: =ROUND(7/48*C26*(C31/100)^3,4) -> 0.6095 | D32: =ROUND(7/48*D26*(D31/100)^3,4) -> 0.6964 | E32: =ROUND(7/48*E26*(E31/100)^3,4) -> 0.7913 | F32: =ROUND(7/48*F26*(F31/100)^3,4) -> 0.8944 | G32: =ROUND(7/48*G26*(G31/100)^3,4) -> 1.006 | H32: =ROUND(7/48*H26*(H31/100)^3,4) -> 1.1266 | I32: =ROUND(7/48*I26*(I31/100)^3,4) -> 1.2565 | ... R32: =ROUND(7/48*R26*(R31/100)^3,4) -> 2.8994
A33: 뿌리분단위당중량(t/㎥) | B33: 1.3 | C33: 1.3 | D33: 1.3 | E33: 1.3 | F33: 1.3 | G33: 1.3 | H33: 1.3 | I33: 1.3 | J33: 1.3 | K33: 1.3 | L33: 1.3 | M33: 1.3 | N33: 1.3 | O33: 1.3 | P33: 1.3 | Q33: 1.3 | R33: 1.3
A34: 수목의 지하부 중량(kg) | B34: =ROUND(B32*B33*1000,1) -> 689.1 | C34: =ROUND(C32*C33*1000,1) -> 792.4 | D34: =ROUND(D32*D33*1000,1) -> 905.3 | E34: =ROUND(E32*E33*1000,1) -> 1028.7 | F34: =ROUND(F32*F33*1000,1) -> 1162.7 | G34: =ROUND(G32*G33*1000,1) -> 1307.8 | H34: =ROUND(H32*H33*1000,1) -> 1464.6 | I34: =ROUND(I32*I33*1000,1) -> 1633.5 | ... R34: =ROUND(R32*R33*1000,1) -> 3769.2
A35: 전제 중량(kg) | B35: =B29+B34 -> 813.7 | C35: =C29+C34 -> 929.2 | D35: =D29+D34 -> 1054.8 | E35: =E29+E34 -> 1191.5 | F35: =F29+F34 -> 1359 | G35: =G29+G34 -> 1520.1 | H35: =H29+H34 -> 1693.5 | I35: =I29+I34 -> 1879.7 | ... R35: =R29+R34 -> 4285
A36: 전체 부피(㎥) | B36: =B30+B32 -> 0.6301 | C36: =C30+C32 -> 0.7195 | D36: =D30+D32 -> 0.8164 | E36: =E30+E32 -> 0.9223 | F36: =F30+F32 -> 1.0524 | G36: =G30+G32 -> 1.176 | H36: =H30+H32 -> 1.3106 | I36: =I30+I32 -> 1.4535 | ... R36: =R30+R32 -> 3.3124
A37: 수목 면적(㎡) | B37: =ROUND(3.14*(B24*0.8/2*B24*0.8/2),2) -> 10.17 | C37: =ROUND(3.14*(C24*0.8/2*C24*0.8/2),2) -> 10.17 | D37: =ROUND(3.14*(D24*0.8/2*D24*0.8/2),2) -> 10.17 | E37: =ROUND(3.14*(E24*0.8/2*E24*0.8/2),2) -> 10.17 | F37: =ROUND(3.14*(F24*0.8/2*F24*0.8/2),2) -> 12.56 | G37: =ROUND(3.14*(G24*0.8/2*G24*0.8/2),2) -> 12.56 | H37: =ROUND(3.14*(H24*0.8/2*H24*0.8/2),2) -> 12.56 | I37: =ROUND(3.14*(I24*0.8/2*I24*0.8/2),2) -> 12.56 | ... R37: =ROUND(3.14*(R24*0.8/2*R24*0.8/2),2) -> 18.09
A38: 전정잔재물 (지상부x30%)(Kg) | B38: =ROUND(B29*30%,2) -> 37.38 | C38: =ROUND(C29*30%,2) -> 41.04 | D38: =ROUND(D29*30%,2) -> 44.85 | E38: =ROUND(E29*30%,2) -> 48.84 | F38: =ROUND(F29*30%,2) -> 58.89 | G38: =ROUND(G29*30%,2) -> 63.69 | H38: =ROUND(H29*30%,2) -> 68.67 | I38: =ROUND(I29*30%,2) -> 73.86 | ... R38: =ROUND(R29*30%,2) -> 154.74
A39: 전정부피- 적사(M3) | B39: =ROUND(B38/1000/0.5,3) -> 0.075 | C39: =ROUND(C38/1000/0.5,3) -> 0.082 | D39: =ROUND(D38/1000/0.5,3) -> 0.09 | E39: =ROUND(E38/1000/0.5,3) -> 0.098 | F39: =ROUND(F38/1000/0.5,3) -> 0.118 | G39: =ROUND(G38/1000/0.5,3) -> 0.127 | H39: =ROUND(H38/1000/0.5,3) -> 0.137 | I39: =ROUND(I38/1000/0.5,3) -> 0.148 | ... R39: =ROUND(R38/1000/0.5,3) -> 0.309
A40: ※지상부 중량 산출근거: | B40: k*3.14*(B/2)^2*h*w1*(1+p) | H40: ※지하부 중량 산출근거: | J40: 분체적*단위중량
...

Sheet 수목제원표2
A1: 수목 제원표 2
A2: 구분 | B2: 수목규격
A3: 근원직경R(cm) | B3: 38 | C3: 39 | D3: 40 | E3: 41 | F3: 42 | G3: 43 | H3: 44 | I3: 45 | J3: 46 | K3: 47 | L3: 48 | M3: 49 | N3: 50 | O3: 51 | P3: 52 | Q3: 53 | R3: 54
A4: 흉고직경B(cm) | B4: =B3*0.8 -> 30.4 | C4: =C3*0.8 -> 31.2 | D4: =D3*0.8 -> 32 | E4: =E3*0.8 -> 32.8 | F4: =F3*0.8 -> 33.6 | G4: =G3*0.8 -> 34.4 | H4: =H3*0.8 -> 35.2 | I4: =I3*0.8 -> 36 | ... R4: =R3*0.8 -> 43.2
A5: 수고H(m) | B5: 6 | C5: 6 | D5: 7 | E5: 7 | F5: 7 | G5: 7 | H5: 7 | I5: 8 | J5: 8 | K5: 8 | L5: 8 | M5: 8 | N5: 9 | O5: 9 | P5: 9 | Q5: 9 | R5: 9
A6: 수간형상계수(k) | B6: 0.5 | C6: 0.5 | D6: 0.5 | E6: 0.5 | F6: 0.5 | G6: 0.5 | H6: 0.5 | I6: 0.5 | J6: 0.5 | K6: 0.5 | L6: 0.5 | M6: 0.5 | N6: 0.5 | O6: 0.5 | P6: 0.5 | Q6: 0.5 | R6: 0.5
A7: 원 주 율(π) | B7: 3.14 | C7: 3.14 | D7: 3.14 | E7: 3.14 | F7: 3.14 | G7: 3.14 | H7: 3.14 | I7: 3.14 | J7: 3.14 | K7: 3.14 | L7: 3.14 | M7: 3.14 | N7: 3.14 | O7: 3.14 | P7: 3.14 | Q7: 3.14 | R7: 3.14
A8: 수목생체단위중량(w1, kg/㎥) | B8: 1250 | C8: 1250 | D8: 1250 | E8: 1250 | F8: 1250 | G8: 1250 | H8: 1250 | I8: 1250 | J8: 1250 | K8: 1250 | L8: 1250 | M8: 1250 | N8: 1250 | O8: 1250 | P8: 1250 | Q8: 1250 | R8: 1250
A9: 보합률(P,고립) | B9: 1 | C9: 1 | D9: 1 | E9: 1 | F9: 1 | G9: 1 | H9: 1 | I9: 1 | J9: 1 | K9: 1 | L9: 1 | M9: 1 | N9: 1 | O9: 1 | P9: 1 | Q9: 1 | R9: 1
A10: 지상부 중량(kg) | B10: =ROUND(B6*B7*(B4/2)^2*B5*B8*(1+B9)/10000,1) -> 544.1 | C10: =ROUND(C6*C7*(C4/2)^2*C5*C8*(1+C9)/10000,1) -> 573.1 | D10: =ROUND(D6*D7*(D4/2)^2*D5*D8*(1+D9)/10000,1) -> 703.4 | E10: =ROUND(E6*E7*(E4/2)^2*E5*E8*(1+E9)/10000,1) -> 739 | F10: =ROUND(F6*F7*(F4/2)^2*F5*F8*(1+F9)/10000,1) -> 775.5 | G10: =ROUND(G6*G7*(G4/2)^2*G5*G8*(1+G9)/10000,1) -> 812.8 | H10: =ROUND(H6*H7*(H4/2)^2*H5*H8*(1+H9)/10000,1) -> 851.1 | I10: =ROUND(I6*I7*(I4/2)^2*I5*I8*(1+I9)/10000,1) -> 1017.4 | ... R10: =ROUND(R6*R7*(R4/2)^2*R5*R8*(1+R9)/10000,1) -> 1648.1
A11: 지상부 제적(㎥) | B11: =ROUNDUP(B10/B8,3) -> 0.436 | C11: =ROUNDUP(C10/C8,3) -> 0.459 | D11: =ROUNDUP(D10/D8,3) -> 0.563 | E11: =ROUNDUP(E10/E8,3) -> 0.592 | F11: =ROUNDUP(F10/F8,3) -> 0.621 | G11: =ROUNDUP(G10/G8,3) -> 0.651 | H11: =ROUNDUP(H10/H8,3) -> 0.681 | I11: =ROUNDUP(I10/I8,3) -> 0.814 | ... R11: =ROUNDUP(R10/R8,3) -> 1.319
A12: 뿌리분직경(D,cm,5배분) | B12: =B3*5 -> 190 | C12: =C3*5 -> 195 | D12: =D3*5 -> 200 | E12: =E3*5 -> 205 | F12: =F3*5 -> 210 | G12: =G3*5 -> 215 | H12: =H3*5 -> 220 | I12: =I3*5 -> 225 | ... R12: =R3*5 -> 270
A13: 분체적(V, ㎥) | B13: =ROUND(7/48*B7*(B12/100)^3,4) -> 3.1409 | C13: =ROUND(7/48*C7*(C12/100)^3,4) -> 3.3954 | D13: =ROUND(7/48*D7*(D12/100)^3,4) -> 3.6633 | E13: =ROUND(7/48*E7*(E12/100)^3,4) -> 3.945 | F13: =ROUND(7/48*F7*(F12/100)^3,4) -> 4.2408 | G13: =ROUND(7/48*G7*(G12/100)^3,4) -> 4.5509 | H13: =ROUND(7/48*H7*(H12/100)^3,4) -> 4.8759 | I13: =ROUND(7/48*I7*(I12/100)^3,4) -> 5.216 | ... R13: =ROUND(7/48*R7*(R12/100)^3,4) -> 9.0132
A14: 뿌리분단위당중량(t/㎥) | B14: 1.3 | C14: 1.3 | D14: 1.3 | E14: 1.3 | F14: 1.3 | G14: 1.3 | H14: 1.3 | I14: 1.3 | J14: 1.3 | K14: 1.3 | L14: 1.3 | M14: 1.3 | N14: 1.3 | O14: 1.3 | P14: 1.3 | Q14: 1.3 | R14: 1.3
A15: 수목의 지하부 중량(kg) | B15: =ROUND(B13*B14*1000,1) -> 4083.2 | C15: =ROUND(C13*C14*1000,1) -> 4414 | D15: =ROUND(D13*D14*1000,1) -> 4762.3 | E15: =ROUND(E13*E14*1000,1) -> 5128.5 | F15: =ROUND(F13*F14*1000,1) -> 5513 | G15: =ROUND(G13*G14*1000,1) -> 5916.2 | H15: =ROUND(H13*H14*1000,1) -> 6338.7 | I15: =ROUND(I13*I14*1000,1) -> 6780.8 | ... R15: =ROUND(R13*R14*1000,1) -> 11717.2
A16: 전제 중량(kg) | B16: =B10+B15 -> 4627.3 | C16: =C10+C15 -> 4987.1 | D16: =D10+D15 -> 5465.7 | E16: =E10+E15 -> 5867.5 | F16: =F10+F15 -> 6288.5 | G16: =G10+G15 -> 6729 | H16: =H10+H15 -> 7189.8 | I16: =I10+I15 -> 7798.2 | ... R16: =R10+R15 -> 13365.3
A17: 전체 부피(㎥) | B17: =B11+B13 -> 3.5769 | C17: =C11+C13 -> 3.8544 | D17: =D11+D13 -> 4.2263 | E17: =E11+E13 -> 4.537 | F17: =F11+F13 -> 4.8618 | G17: =G11+G13 -> 5.2019 | H17: =H11+H13 -> 5.5569 | I17: =I11+I13 -> 6.03 | ... R17: =R11+R13 -> 10.3322
A18: 수목 면적(㎡) | B18: =ROUND(3.14*(B5*0.8/2*B5*0.8/2),2) -> 18.09 | C18: =ROUND(3.14*(C5*0.8/2*C5*0.8/2),2) -> 18.09 | D18: =ROUND(3.14*(D5*0.8/2*D5*0.8/2),2) -> 24.62 | E18: =ROUND(3.14*(E5*0.8/2*E5*0.8/2),2) -> 24.62 | F18: =ROUND(3.14*(F5*0.8/2*F5*0.8/2),2) -> 24.62 | G18: =ROUND(3.14*(G5*0.8/2*G5*0.8/2),2) -> 24.62 | H18: =ROUND(3.14*(H5*0.8/2*H5*0.8/2),2) -> 24.62 | I18: =ROUND(3.14*(I5*0.8/2*I5*0.8/2),2) -> 32.15 | ... R18: =ROUND(3.14*(R5*0.8/2*R5*0.8/2),2) -> 40.69
A19: 전정잔재물 (지상부x30%)(Kg) | B19: =ROUND(B10*30%,2) -> 163.23 | C19: =ROUND(C10*30%,2) -> 171.93 | D19: =ROUND(D10*30%,2) -> 211.02 | E19: =ROUND(E10*30%,2) -> 221.7 | F19: =ROUND(F10*30%,2) -> 232.65 | G19: =ROUND(G10*30%,2) -> 243.84 | H19: =ROUND(H10*30%,2) -> 255.33 | I19: =ROUND(I10*30%,2) -> 305.22 | ... R19: =ROUND(R10*30%,2) -> 494.43
A20: 전정부피- 적사(M3) | B20: =ROUND(B19/1000/0.5,3) -> 0.326 | C20: =ROUND(C19/1000/0.5,3) -> 0.344 | D20: =ROUND(D19/1000/0.5,3) -> 0.422 | E20: =ROUND(E19/1000/0.5,3) -> 0.443 | F20: =ROUND(F19/1000/0.5,3) -> 0.465 | G20: =ROUND(G19/1000/0.5,3) -> 0.488 | H20: =ROUND(H19/1000/0.5,3) -> 0.511 | I20: =ROUND(I19/1000/0.5,3) -> 0.61 | ... R20: =ROUND(R19/1000/0.5,3) -> 0.989
A21: 구분 | B21: 수목규격
A22: 근원직경R(cm) | B22: 55 | C22: 56 | D22: 57 | E22: 58 | F22: 59 | G22: 60 | H22: 61 | I22: 62 | J22: 63 | K22: 64 | L22: 65 | M22: 66 | N22: 67 | O22: 68 | P22: 69 | Q22: 70 | R22: 71
A23: 흉고직경B(cm) | B23: =B22*0.8 -> 44 | C23: =C22*0.8 -> 44.8 | D23: =D22*0.8 -> 45.6 | E23: =E22*0.8 -> 46.4 | F23: =F22*0.8 -> 47.2 | G23: =G22*0.8 -> 48 | H23: =H22*0.8 -> 48.8 | I23: =I22*0.8 -> 49.6 | ... R23: =R22*0.8 -> 56.8
A24: 수고H(m) | B24: 10 | C24: 10 | D24: 10 | E24: 10 | F24: 10 | G24: 11 | H24: 11 | I24: 11 | J24: 11 | K24: 11 | L24: 12 | M24: 12 | N24: 12 | O24: 12 | P24: 12 | Q24: 13 | R24: 13
A25: 수간형상계수(f) | B25: 0.5 | C25: 0.5 | D25: 0.5 | E25: 0.5 | F25: 0.5 | G25: 0.5 | H25: 0.5 | I25: 0.5 | J25: 0.5 | K25: 0.5 | L25: 0.5 | M25: 0.5 | N25: 0.5 | O25: 0.5 | P25: 0.5 | Q25: 0.5 | R25: 0.5
A26: 원 주 율(π) | B26: 3.14 | C26: 3.14 | D26: 3.14 | E26: 3.14 | F26: 3.14 | G26: 3.14 | H26: 3.14 | I26: 3.14 | J26: 3.14 | K26: 3.14 | L26: 3.14 | M26: 3.14 | N26: 3.14 | O26: 3.14 | P26: 3.14 | Q26: 3.14 | R26: 3.14
A27: 수목생체단위중량(w1, kg/㎥) | B27: 1250 | C27: 1250 | D27: 1250 | E27: 1250 | F27: 1250 | G27: 1250 | H27: 1250 | I27: 1250 | J27: 1250 | K27: 1250 | L27: 1250 | M27: 1250 | N27: 1250 | O27: 1250 | P27: 1250 | Q27: 1250 | R27: 1250
A28: 보합률(P,고립) | B28: 1 | C28: 1 | D28: 1 | E28: 1 | F28: 1 | G28: 1 | H28: 1 | I28: 1 | J28: 1 | K28: 1 | L28: 1 | M28: 1 | N28: 1 | O28: 1 | P28: 1 | Q28: 1 | R28: 1
A29: 지상부 중량(kg) | B29: =ROUND(B25*B26*(B23/2)^2*B24*B27*(1+B28)/10000,1) -> 1899.7 | C29: =ROUND(C25*C26*(C23/2)^2*C24*C27*(1+C28)/10000,1) -> 1969.4 | D29: =ROUND(D25*D26*(D23/2)^2*D24*D27*(1+D28)/10000,1) -> 2040.4 | E29: =ROUND(E25*E26*(E23/2)^2*E24*E27*(1+E28)/10000,1) -> 2112.6 | F29: =ROUND(F25*F26*(F23/2)^2*F24*F27*(1+F28)/10000,1) -> 2186.1 | G29: =ROUND(G25*G26*(G23/2)^2*G24*G27*(1+G28)/10000,1) -> 2486.9 | H29: =ROUND(H25*H26*(H23/2)^2*H24*H27*(1+H28)/10000,1) -> 2570.5 | I29: =ROUND(I25*I26*(I23/2)^2*I24*I27*(1+I28)/10000,1) -> 2655.4 | ... R29: =ROUND(R25*R26*(R23/2)^2*R24*R27*(1+R28)/10000,1) -> 4115.5
A30: 지상부 제적(㎥) | B30: =ROUNDUP(B29/B27,3) -> 1.52 | C30: =ROUNDUP(C29/C27,3) -> 1.576 | D30: =ROUNDUP(D29/D27,3) -> 1.633 | E30: =ROUNDUP(E29/E27,3) -> 1.691 | F30: =ROUNDUP(F29/F27,3) -> 1.749 | G30: =ROUNDUP(G29/G27,3) -> 1.99 | H30: =ROUNDUP(H29/H27,3) -> 2.057 | I30: =ROUNDUP(I29/I27,3) -> 2.125 | ... R30: =ROUNDUP(R29/R27,3) -> 3.293
A31: 뿌리분직경(D,cm,5배분) | B31: =B22*5 -> 275 | C31: =C22*5 -> 280 | D31: =D22*5 -> 285 | E31: =E22*5 -> 290 | F31: =F22*5 -> 295 | G31: =G22*5 -> 300 | H31: =H22*5 -> 305 | I31: =I22*5 -> 310 | ... R31: =R22*5 -> 355
A32: 분체적(V, ㎥) | B32: =ROUND(7/48*B26*(B31/100)^3,4) -> 9.5232 | C32: =ROUND(7/48*C26*(C31/100)^3,4) -> 10.0522 | D32: =ROUND(7/48*D26*(D31/100)^3,4) -> 10.6004 | E32: =ROUND(7/48*E26*(E31/100)^3,4) -> 11.1681 | F32: =ROUND(7/48*F26*(F31/100)^3,4) -> 11.7558 | G32: =ROUND(7/48*G26*(G31/100)^3,4) -> 12.3638 | H32: =ROUND(7/48*H26*(H31/100)^3,4) -> 12.9923 | I32: =ROUND(7/48*I26*(I31/100)^3,4) -> 13.6418 | ... R32: =ROUND(7/48*R26*(R31/100)^3,4) -> 20.4867
A33: 뿌리분단위당중량(t/㎥) | B33: 1.3 | C33: 1.3 | D33: 1.3 | E33: 1.3 | F33: 1.3 | G33: 1.3 | H33: 1.3 | I33: 1.3 | J33: 1.3 | K33: 1.3 | L33: 1.3 | M33: 1.3 | N33: 1.3 | O33: 1.3 | P33: 1.3 | Q33: 1.3 | R33: 1.3
A34: 수목의 지하부 중량(kg) | B34: =ROUND(B32*B33*1000,1) -> 12380.2 | C34: =ROUND(C32*C33*1000,1) -> 13067.9 | D34: =ROUND(D32*D33*1000,1) -> 13780.5 | E34: =ROUND(E32*E33*1000,1) -> 14518.5 | F34: =ROUND(F32*F33*1000,1) -> 15282.5 | G34: =ROUND(G32*G33*1000,1) -> 16072.9 | H34: =ROUND(H32*H33*1000,1) -> 16890 | I34: =ROUND(I32*I33*1000,1) -> 17734.3 | ... R34: =ROUND(R32*R33*1000,1) -> 26632.7
A35: 전제 중량(kg) | B35: =B29+B34 -> 14279.9 | C35: =C29+C34 -> 15037.3 | D35: =D29+D34 -> 15820.9 | E35: =E29+E34 -> 16631.1 | F35: =F29+F34 -> 17468.6 | G35: =G29+G34 -> 18559.8 | H35: =H29+H34 -> 19460.5 | I35: =I29+I34 -> 20389.7 | ... R35: =R29+R34 -> 30748.2
A36: 전체 부피(㎥) | B36: =B30+B32 -> 11.0432 | C36: =C30+C32 -> 11.6282 | D36: =D30+D32 -> 12.2334 | E36: =E30+E32 -> 12.8591 | F36: =F30+F32 -> 13.5048 | G36: =G30+G32 -> 14.3538 | H36: =H30+H32 -> 15.0493 | I36: =I30+I32 -> 15.7668 | ... R36: =R30+R32 -> 23.7797
A37: 수목 면적(㎡) | B37: =ROUND(3.14*(B24*0.8/2*B24*0.8/2),2) -> 50.24 | C37: =ROUND(3.14*(C24*0.8/2*C24*0.8/2),2) -> 50.24 | D37: =ROUND(3.14*(D24*0.8/2*D24*0.8/2),2) -> 50.24 | E37: =ROUND(3.14*(E24*0.8/2*E24*0.8/2),2) -> 50.24 | F37: =ROUND(3.14*(F24*0.8/2*F24*0.8/2),2) -> 50.24 | G37: =ROUND(3.14*(G24*0.8/2*G24*0.8/2),2) -> 60.79 | H37: =ROUND(3.14*(H24*0.8/2*H24*0.8/2),2) -> 60.79 | I37: =ROUND(3.14*(I24*0.8/2*I24*0.8/2),2) -> 60.79 | ... R37: =ROUND(3.14*(R24*0.8/2*R24*0.8/2),2) -> 84.91
A38: 전정잔재물 (지상부x30%)(Kg) | B38: =ROUND(B29*30%,2) -> 569.91 | C38: =ROUND(C29*30%,2) -> 590.82 | D38: =ROUND(D29*30%,2) -> 612.12 | E38: =ROUND(E29*30%,2) -> 633.78 | F38: =ROUND(F29*30%,2) -> 655.83 | G38: =ROUND(G29*30%,2) -> 746.07 | H38: =ROUND(H29*30%,2) -> 771.15 | I38: =ROUND(I29*30%,2) -> 796.62 | ... R38: =ROUND(R29*30%,2) -> 1234.65
A39: 전정부피- 적사(M3) | B39: =ROUND(B38/1000/0.5,3) -> 1.14 | C39: =ROUND(C38/1000/0.5,3) -> 1.182 | D39: =ROUND(D38/1000/0.5,3) -> 1.224 | E39: =ROUND(E38/1000/0.5,3) -> 1.268 | F39: =ROUND(F38/1000/0.5,3) -> 1.312 | G39: =ROUND(G38/1000/0.5,3) -> 1.492 | H39: =ROUND(H38/1000/0.5,3) -> 1.542 | I39: =ROUND(I38/1000/0.5,3) -> 1.593 | ... R39: =ROUND(R38/1000/0.5,3) -> 2.469
A40: ※지상부 중량 산출근거: | B40: k*3.14*(B/2)^2*h*w1*(1+p) | H40: ※지하부 중량 산출근거: | J40: 분체적*단위중량
...

Sheet 식재공
G8: 식재공

Sheet 식재공수량집계
A1: ■식재공수량집계표
A2: 품 명 | B2: 규 격 | C2: 단위 | D2: 수량(주) | E2: 단위중량(kg) | F2: 수목중량(kg) | G2: 비 고
A4: 1)이식 | E4: =수목중량!N9 -> 3290.4653 | F4: =D4*E4 -> 0
A5: 금송 | B5: H8.0xR25 | C5: 주 | D5: 2 | E5: =수목중량!N10 -> 55.33852 | F5: =D5*E5 -> 110.67704
A6: 금송 | B6: H7.0xW3.5 | C6: 주 | D6: 3 | E6: =수목중량!N11 -> 29.840522 | F6: =D6*E6 -> 89.521567
A7: 금송 | B7: H5.0xW2.5 | C7: 주 | D7: 2 | E7: =수목중량!N12 -> 1352.84 | F7: =D7*E7 -> 2705.6801
A8: 소나무 | B8: H14.0xR40 | C8: 주 | D8: 5
A9: 소나무 | B9: H10.0xW5.0xR36 | C9: 주 | D9: 6 | E9: =수목중량!N13 -> 182.35188 | F9: =D9*E9 -> 1094.1113
A10: 소나무 | B10: H10.0xW4.0xR28 | C10: 주 | D10: 10
A11: 소나무 | B11: H5.5xW2.5xR25 | C11: 주 | D11: 2
A12: 소나무 | B12: H3.5xR20 | C12: 주 | D12: 39
A13: 소나무 | B13: H2.5xR10 | C13: 주 | D13: 3
A14: 스트로브잣나무 | B14: H10.0xR26 | C14: 주 | D14: 2
A15: 스트로브잣나무 | B15: H8.0xR18 | C15: 주 | D15: 7
A16: 스트로브잣나무 | B16: H7.0xR22 | C16: 주 | D16: 12
A17: 스트로브잣나무 | B17: H6.0xR18 | C17: 주 | D17: 36
A18: 전나무 | B18: H16.0xW6.0xR44 | C18: 주 | D18: 8
A19: 전나무 | B19: H16.0xW5.0xR58 | C19: 주 | D19: 2
A20: 전나무 | B20: H16.0xR46 | C20: 주 | D20: 2
A21: 주목 | B21: H3.0xW2.0 | C21: 주 | D21: 4
... A74: 칠엽수 | B74: H5.0xW3.5xR12 | C74: 주 | D74: 3
A75: 2)교목식재 | E75: =수목중량!N14 -> 29.840522 | F75: =D75*E75 -> 0
A76: 계수나무 | B76: H4.5xR15 | C76: 주 | D76: 29
A77: 꽃사과 | B77: H3.0xR8 | C77: 주 | D77: 36
A78: 느티나무 | B78: H5.0xR30 | C78: 주 | D78: 3
A79: 때죽나무 | B79: H3.5xR10 | C79: 주 | D79: 19
A80: 매화나무 | B80: H3.5xR10 | C80: 주 | D80: 6
A81: 산딸나무 | B81: H3.5xR12 | C81: 주 | D81: 41
A82: 산수유 | B82: H3.5xR15 | C82: 주 | D82: 17
A83: 왕벚나무 | B83: H4.0xB12 | C83: 주 | D83: 20
A84: 참나무 | B84: H5.0xR25 | C84: 주 | D84: 10
A85: 청단풍 | B85: H3.5xR15 | C85: 주 | D85: 20
A86: 팥배나무 | B86: H4.0xR12 | C86: 주 | D86: 10
A87: 팽나무 | B87: H6.0xR30 | C87: 주 | D87: 1
A88: 팽나무 | B88: H5.0xR20 | C88: 주 | D88: 5
A89: 3)관목식재 | E89: =수목중량!N39 -> 0 | F89: =D89*E89 -> 0
A90: 남천 | B90: H1.0x3가지 | C90: 주 | D90: 400
A91: 피라칸사스 | B91: H1.0xW0.3 | C91: 주 | D91: 700
A92: 회양목 | B92: H0.3xW0.3 | C92: 주 | D92: 700
A93: 낙상홍 | B93: H1.0xW0.4 | C93: 주 | D93: 200
...

Sheet 수목중량
A1: ■ 수목 중량계산 | Q1: 주1) 조경공사적산기준(2020) 4.3.2. 수목운반 참조 | S1: 조경공사적산기준 | U1: 접시분(천근성) | V1: 보통분 | W1: 조개분(심근성) | X1: (산림청)
B2: * 지상부 중량 W1 (kg) = K x 3.14 x (B/2)2 x H x W x (1+p) [ W : 수간의 단위체적중량 1,200(kg/m3), P : 지엽에 과다에 의한 보합률(0.2) ] | S2: 뿌리분 형태 | T2: 뿌리분 체적(m3) | U2: 0.3927 | V2: 0.4581 | W2: 0.5236 | X2: 가로수 조성관리 매뉴얼
B3: * 지하부(뿌리분) 체적 V (m3) = 3.14 x (D/2)2 x (D/2) + 3.14 x (D/2)2 x (D') x (1/3) [ D' : 뿌리분형상, 접시분(0), 보통분(D/4), 조개(팽이)분(D/2) ]
B4: * 지하부(뿌리분) 중량 W2 (kg) = V x W' [ V : 뿌리분체적(m3), W' : 뿌리분단위중량, 1300(kg/m3) ]
B5: * 벌근부 중량 W2' (kg) = W2 x 20 (%, 실제 계측수량 비율)
A7: 구 분 | C7: K | D7: B | F7: H | G7: W | H7: P | I7: W1 | J7: D | L7: W' | M7: W2 | N7: W1+W2 | O7: W2' | P7: W1+W2' | Q7: 비고
C8: 수간 형상 계수 | D8: 흉고 직경 (cm) | E8: 흉고 (m) | F8: 수고 (m) | G8: 단위 중량 (kg) | H8: 보합률 | I8: 지상부 중량 (kg) | J8: 근원 직경 (R,cm) | K8: D=4R (m) | L8: 뿌리분 단위중량(kg) | M8: 지하부 중량(kg) | N8: 수목중량 (kg) | O8: 벌근부 중량(kg) | P8: 임목폐기물 중량(kg)
A9: 교 목 | B9: =식재공수량집계!A4 -> 1)이식 | C9: 0.5 | D9: =J9/1.2 -> 33.333333 | E9: =D9*0.01 -> 0.33333333 | F9: 8 | G9: 1200 | H9: 0.2 | I9: =TRUNC((C9*3.14*((E9/2)^2)*F9*G9*(1+H9)),3) -> 502.4 | J9: 40 | K9: =J9*4*0.01 -> 1.6 | L9: 1300 | M9: =$W$2*K9^3*1300 -> 2788.0653 | N9: =I9+M9 -> 3290.4653 | O9: =M9*0.2 -> 557.61306 | P9: =I9+O9 -> 1060.0131
B10: =식재공수량집계!A5 -> 금송 | C10: 0.5 | D10: =J10/1.2 -> 8.3333333 | E10: =D10*0.01 -> 0.083333333 | F10: 3 | G10: 1200 | H10: 0.2 | I10: =TRUNC((C10*3.14*((E10/2)^2)*F10*G10*(1+H10)),3) -> 11.775 | J10: 10 | K10: =J10*4*0.01 -> 0.4 | L10: 1300 | M10: =$W$2*K10^3*1300 -> 43.56352 | N10: =I10+M10 -> 55.33852 | O10: =M10*0.2 -> 8.712704 | P10: =I10+O10 -> 20.487704
B11: =식재공수량집계!A6 -> 금송 | C11: 0.5 | D11: =J11/1.2 -> 6.6666667 | E11: =D11*0.01 -> 0.066666667 | F11: 3 | G11: 1200 | H11: 0.2 | I11: =TRUNC((C11*3.14*((E11/2)^2)*F11*G11*(1+H11)),3) -> 7.536 | J11: 8 | K11: =J11*4*0.01 -> 0.32 | L11: 1300 | M11: =$W$2*K11^3*1300 -> 22.304522 | N11: =I11+M11 -> 29.840522 | O11: =M11*0.2 -> 4.4609044 | P11: =I11+O11 -> 11.996904
