Workbook

Sheet ★확인요망★
C7: - 고용보험(65세이상, 보수월액X0.9%(요율))
C8: - 연금보험(60세이하, 8일이상, 보수월액X4.5%(요율), 상한액 5,530,000원 이상 시 248,850원 적용 )
B9: 2025.01.01 | C9: - 연금보험(60세이하, 8일이상, 보수월액X4.5%(요율), 상한액 6,170,000원 이상 시 277,650원 적용 )
C10: 신규채용자 한해서 1일자로 근무한 근로자는 해당. 1일 이후 근무자는 비해당.
C11: - 건강보험(8일이상, 보수월액X3.545%(요율))
C12: - 장기요양보험(요율 12.95%)
C13: - 2000년생 확인 및 신규채용자 후 체크요망.
C14: - 갑근세 단가 15만원이상

Sheet 요율
B1: 2026년 상반기 (1월 ~ 6월 적용)
B2: 구 분 | C2: 요율1 | D2: 요율2 | E2: 비과세 기준액 | G2: 명칭변경 시 수정
B3: 소 득 세 | C3: 6 | D3: 45 | E3: 150000 | G3: 소 득 세 | H3: 갑 근 세 | I3: 소 득 세
B4: 건강보험 | C4: 3.595 | D4: 2026년 1월 1일부터 적용 | G4: 지방소득세 | H4: 주 민 세 | I4: 지방소득세
B5: 노인장기 | C5: 13.14 | D5: 2026년 1월 1일부터 적용 | F5: 0.1314 | G5: ㈜아 산
B6: 국민연금(2025.07.01~2026.06.30) | C6: 4.75 | D6: 8 | E6: 2200000 | G6: 고색2지구 공원 및 공공공지 조성공사 | H6: 선 택
C7: 312640 | D7: =C7*C6% -> 14850.4 | E7: 하한액 | G7: 연금·건강보험 적용 | H7: ○
C8: 4964220 | D8: =C8*C6% -> 235800.45 | E8: 상한액 | G8: 고용보험 만 65세이상 적용 | H8: X
B9: 고용보험 | C9: 0.9 | D9: 2026년 1월 1일부터 적용 | G9: 고용보험 외국인 적용 | H9: X
B11: 2026년 하반기 (7월 ~ 9월 적용)
B12: 구 분 | C12: 요율1 | D12: 요율2 | E12: 비과세 기준액
B13: 소 득 세 | C13: 6 | D13: 45 | E13: 150000
B14: 건강보험 | C14: 3.595 | D14: 2026년 1월 1일부터 적용
B15: 노인장기 | C15: 13.14 | D15: 2026년 1월 1일부터 적용 | F15: 0.1314
B16: 국민연금(2025.07.01~2025.09.30) | C16: 4.5 | D16: 8 | E16: 2200000
C17: 312640 | D17: 14850 | E17: 하한액
C18: 4964220 | D18: 235800 | E18: 상한액
B19: 고용보험 | C19: 0.9 | D19: 2026년 07월 1일부터 적용
B21: 2026년 하반기 (10월 ~ 12월 적용)
B22: 구 분 | C22: 요율1 | D22: 요율2 | E22: 비과세 기준액
B23: 소 득 세 | C23: 6 | D23: 45 | E23: 150000
B24: 건강보험 | C24: 3.595 | D24: 2026년 1월 1일부터 적용
B25: 노인장기 | C25: 13.14 | D25: 2026년 1월 1일부터 적용 | F25: 0.1314
B26: 국민연금(2025.10.01~2025.12.31) | C26: 4.75 | D26: 8 | E26: 2200000
C27: 312640 | D27: =C27*C26% -> 14850.4 | E27: 하한액
C28: 4964220 | D28: =C28*C26% -> 235800.45 | E28: 상한액
B29: 고용보험 | C29: 0.9 | D29: 2026년 07월 1일부터 적용

Sheet 청구서
A2: 공사근로자 노무비 청구서(2023년 01월)
A3: 1. | C3: 공 사 명 | F3: : | G3: =요율!G6 -> 고색2지구 공원 및 공공공지 조성공사
A4: 2. | C4: 계 약 금 액 | F4: : | G4: ="일금" & TEXT(L4, "[dbnum4] g/표준") & "원정" -> 일금 일십팔억칠천육백칠십팔만칠천원정 | K4: ( | L4: 1876787000 | M4: )
A5: 3. | C5: 계 약 년 월 일 | F5: : | G5: 44197
A6: 4. | C6: 착 공 년 월 일 | F6: : | G6: 44198 | Q6: 661526622 | R6: =Q6*0.1 -> 66152662 | S6: =Q6+R6 -> 7.2767928e+08
A7: 5. | C7: 준 공 년 월 일 | F7: : | G7: 44199 | Q7: =P7/1.1 -> 0 | R7: =Q7*0.1 -> 0 | S7: =SUM(Q7:R7) -> 0
A8: 6. | C8: 노무비총액 | F8: : | G8: ="일금 " & NUMBERSTRING(L8, 1) & "원정" -> 일금 칠억이천칠백육십칠만구천이백팔십사원정 | K8: ( | L8: =S6 -> 7.2767928e+08 | M8: )
A9: 7. | C9: 기지급금액 | F9: : | G9: ="일금 " & NUMBERSTRING(L9, 1) & "원정" -> 일금 영원정 | K9: ( | L9: =집계표!G18 -> 0 | M9: ) | O9: 직불금 | P9: 합계 | Q9: 공급액 | R9: 부가세 | S9: 합계
A10: 8. | C10: 금회청구액 | F10: : | G10: ="일금 " & NUMBERSTRING(L10, 1) & "원정" -> 일금 영원정 | K10: ( | L10: =L11+L13+L15+L17+L19 -> 0 | M10: ) | P10: =L10 -> 0 | Q10: =TRUNC(P10/1.1) -> 0 | R10: =P10-Q10 -> 0 | S10: =Q10+R10 -> 0
C11: (계약상대자) | F11: : | G11: ="일금 " & NUMBERSTRING(L11, 1) & "원정" -> 일금 영원정 | K11: ( | L11: =집계표!H7 -> 0 | M11: ) | O11: 원도급 | P11: =L11 -> 0 | Q11: =TRUNC(P11/1.1) -> 0 | R11: =P11-Q11 -> 0 | S11: =Q11+R11 -> 0
C12: 부강종합건설㈜
C13: (직불하도급사) | F13: : | G13: ="일금 " & NUMBERSTRING(L13, 1) & "원정" -> 일금 영원정 | K13: ( | L13: =집계표!H14 -> 0 | M13: ) | O13: =C14 -> 00건설㈜ | P13: =L13 -> 0 | Q13: =TRUNC(P13/1.1) -> 0 | R13: =P13-Q13 -> 0 | S13: =Q13+R13 -> 0
C14: 00건설㈜
C15: (직불하도급사) | F15: : | G15: ="일금 " & NUMBERSTRING(L15, 1) & "원정" -> 일금 영원정 | K15: ( | L15: =집계표!H13 -> 0 | M15: ) | O15: =C16 -> ㈜00기업 | P15: =L15 -> 0 | Q15: =TRUNC(P15/1.1) -> 0 | R15: =P15-Q15 -> 0 | S15: =Q15+R15 -> 0
C16: ㈜00기업
C17: (직불하도급사) | F17: : | G17: ="일금 " & NUMBERSTRING(L17, 1) & "원정" -> 일금 영원정 | K17: ( | L17: =집계표!H14 -> 0 | M17: ) | O17: =C18 -> ㈜000개발 | P17: =L17 -> 0 | Q17: =TRUNC(P17/1.1) -> 0 | R17: =P17-Q17 -> 0 | S17: =Q17+R17 -> 0
C18: ㈜000개발
C19: (직불하도급사) | F19: : | G19: ="일금 " & NUMBERSTRING(L19, 1) & "원정" -> 일금 영원정 | K19: ( | L19: =집계표!H16 -> 0 | M19: ) | O19: =C20 -> 주식회사 00 | P19: =L19 -> 0 | Q19: =TRUNC(P19/1.1) -> 0 | R19: =P19-Q19 -> 0 | S19: =Q19+R19 -> 0
C20: 주식회사 00
A21: 9. | C21: 잔여금액 | F21: : | G21: ="일금 " & NUMBERSTRING(L21, 1) & "원정" -> 일금 칠억이천칠백육십칠만구천이백팔십사원정 | K21: ( | L21: =L8-L10-L9 -> 7.2767928e+08 | M21: ) | O21: 선지급금 | P21: 합계 | Q21: 공급액 | R21: 부가세 | S21: 합계
A22: 위 금액을 2023 년 01월 노무비(1회)로 청구하오니 아래와 같이 지급하여 주시기 바랍니다.
B23: 구분 | D23: 업 체 명 | H23: 은행명 | I23: 계좌번호(노무비) | J23: 청구액
B24: 계약상대자 | D24: =C12 -> 부강종합건설㈜ | H24: 농협은행 | I24: 355-0062-3586-33 | J24: =L11 -> 0
B25: 직불하도급사 | D25: =C14 -> 00건설㈜
B26: 직불하도급사 | D26: =C16 -> ㈜00기업
B27: 직불하도급사 | D27: =C18 -> ㈜000개발
A29: 붙 임 : 1. 노무자 명부 및 당월 개인별 노무비 청구(지급) 내역서 각 1부.
A32: 2023 년 02 월 일
E35: 계약상대자 : | H35: 회사명 | I35: =O35 -> 부강종합건설㈜ | O35: =D24 -> 부강종합건설㈜
H36: 주소 | I36: =O36 -> 경남 합천군 | O36: 경남 합천군
H37: 대표자 | I37: =O37& " (인)" -> 김 0 0 (인) | O37: 김 0 0
E38: 직불하도급사 : | H38: 회사명 | I38: =O38 -> 00건설㈜ | O38: =C14 -> 00건설㈜
H39: 주소 | I39: =O39 -> 경남 남해군 | O39: 경남 남해군
H40: 대표자 | I40: =O40& " (인)" -> 강 0 0 (인) | O40: 강 0 0
E41: 직불하도급사 : | H41: 회사명 | I41: =O41 -> ㈜00기업 | O41: =C16 -> ㈜00기업
H42: 주소 | I42: =O42 -> 대구광역시 수성구 | O42: 대구광역시 수성구
H43: 대표자 | I43: =O43& " (인)" -> 김 0 0 (인) | O43: 김 0 0
E44: 직불하도급사 : | H44: 회사명 | I44: =O44 -> ㈜000개발 | O44: =C18 -> ㈜000개발
H45: 주소 | I45: =O45 -> 경남 김해시 | O45: 경남 김해시
H46: 대표자 | I46: =O46& " (인)" -> 박 0 0 (인) | O46: 박 0 0
...

Sheet 집계표
A2: 공사근로자 노무비 청구 내역 집계표(2023 년 01 월)
A3: =내역서!A3:D3 -> ○ 공 사 명 : | C3: =청구서!G3 -> 고색2지구 공원 및 공공공지 조성공사
A4: ○ 노무비 금액： | C4: ="일금 " & NUMBERSTRING(I4, 1) & "원정" -> 일금 칠억이천칠백육십칠만구천이백팔십사원정 | H4: ( | I4: =청구서!L8 -> 7.2767928e+08 | K4: )
A5: ○ 금월 청구금액： | C5: ="일금 " & NUMBERSTRING(I5, 1) & "원정" -> 일금 영원정 | H5: ( | I5: =H18 -> 0 | K5: )
A6: 구 분 | B6: 공 종 | D6: 업 체 명 | E6: 전용계좌번호 | F6: 노무비 금액 | G6: 전월까지 금액 | H6: 금월 청구금액 | J6: 누계 금액
A7: 도급사 | B7: 건축공사 | D7: =청구서!D24 -> 부강종합건설㈜ | E7: 355-0062-3586-33 농협은행(노무비) | F7: =L7-L11 -> 7.2767928e+08 | H7: =내역서!D30 -> 0 | J7: =G7+H7 -> 0 | L7: =청구서!L8 -> 7.2767928e+08
J8: =G8+H8 -> 0 | L8: 0
J9: =G9+H9 -> 0 | L9: 0
A10: 소 계(A) | F10: =SUM(F7:F9) -> 7.2767928e+08 | G10: =SUM(G7:G9) -> 0 | H10: =SUM(H7:I9) -> 0 | J10: =G10+H10 -> 0
A11: 직불 하도 급사 | J11: =G11+H11 -> 0
J12: =G12+H12 -> 0 | L12: 0
J13: =G13+H13 -> 0 | L13: 0
J14: =G14+H14 -> 0 | L14: =F14-G14 -> 0
J15: =G15+H15 -> 0 | L15: 0
G16: 0 | J16: =G16+H16 -> 0 | L16: 0
A17: 소 계(B) | F17: =SUM(F11:F16) -> 0 | G17: =SUM(G14:G16) -> 0 | H17: =SUM(H11:I16) -> 0 | J17: =G17+H17 -> 0 | L17: 0
A18: 합 계(A+B) | F18: =F10+F17 -> 7.2767928e+08 | G18: =G10+G17 -> 0 | H18: =H10+H17 -> 0 | J18: =G18+H18 -> 0 | L18: 20570000

Sheet 내역서
A1: 공사근로자 노무비 청구 내역서(2023 년 01월)
A3: ○ 공 사 명 : | B3: =청구서!G3 -> 고색2지구 공원 및 공공공지 조성공사
A4: 계약상대자 | B4: 직종 | C4: 근로자성명 | D4: 청구금액 | E4: 은행명 | F4: 계좌번호 | G4: 휴대폰번호
A5: =청구서!O35 -> 부강종합건설㈜ | B5: =IFERROR(VLOOKUP(C5,주소록!$A$4:$L$305,2,0)," ") -> 작업반장 | C5: =주소록!A4 -> 오부택 | D5: =IFERROR(VLOOKUP(C5,급여!$A$3:$M$127,6,0)," ") | E5: =IFERROR(VLOOKUP(C5,주소록!$A$4:$L$305,7,0)," ") -> 농협중앙회 | F5: =IFERROR(VLOOKUP(C5,주소록!$A$4:$L$305,8,0)," ") -> 204030-56-159309 | G5: =IFERROR(VLOOKUP(C5,주소록!$A$4:$L$305,5,0)," ") -> 010-8783-1657 | H5: 주소록 탭 기재 후 청구내역서 상 근로자 이름만 적으면 데이터 자동 연결됩니다.
B6: =IFERROR(VLOOKUP(C6,주소록!$A$4:$L$305,2,0)," ") -> 조경공 | C6: =주소록!A5 -> 하해군 | D6: =IFERROR(VLOOKUP(C6,급여!$A$3:$M$127,6,0)," ") | E6: =IFERROR(VLOOKUP(C6,주소록!$A$4:$L$305,7,0)," ") -> 농협중앙회 | F6: =IFERROR(VLOOKUP(C6,주소록!$A$4:$L$305,8,0)," ") -> 352-0964-6051-63 | G6: =IFERROR(VLOOKUP(C6,주소록!$A$4:$L$305,5,0)," ") -> 010-4993-9423
B7: =IFERROR(VLOOKUP(C7,주소록!$A$4:$L$305,2,0)," ") -> 조경공 | C7: =주소록!A6 -> 유수진 | D7: =IFERROR(VLOOKUP(C7,급여!$A$3:$M$127,6,0)," ") | E7: =IFERROR(VLOOKUP(C7,주소록!$A$4:$L$305,7,0)," ") -> 국민은행 | F7: =IFERROR(VLOOKUP(C7,주소록!$A$4:$L$305,8,0)," ") -> 352601-01-213053 | G7: =IFERROR(VLOOKUP(C7,주소록!$A$4:$L$305,5,0)," ") -> 010-3124-2716
B8: =IFERROR(VLOOKUP(C8,주소록!$A$4:$L$305,2,0)," ") | C8: C | D8: =IFERROR(VLOOKUP(C8,급여!$A$3:$M$127,6,0)," ") | E8: =IFERROR(VLOOKUP(C8,주소록!$A$4:$L$305,7,0)," ") | F8: =IFERROR(VLOOKUP(C8,주소록!$A$4:$L$305,8,0)," ") | G8: =IFERROR(VLOOKUP(C8,주소록!$A$4:$L$305,5,0)," ")
B9: =IFERROR(VLOOKUP(C9,주소록!$A$4:$L$305,2,0)," ") -> 조경공 | C9: =주소록!A8 -> 유광열 | D9: =IFERROR(VLOOKUP(C9,급여!$A$3:$M$127,6,0)," ") | E9: =IFERROR(VLOOKUP(C9,주소록!$A$4:$L$305,7,0)," ") -> 국민은행 | F9: =IFERROR(VLOOKUP(C9,주소록!$A$4:$L$305,8,0)," ") -> 420802-01-297649 | G9: =IFERROR(VLOOKUP(C9,주소록!$A$4:$L$305,5,0)," ") -> 010-8750-3852
B10: =IFERROR(VLOOKUP(C10,주소록!$A$4:$L$305,2,0)," ") -> 조경공 | C10: =주소록!A9 -> 현영석 | D10: =IFERROR(VLOOKUP(C10,급여!$A$3:$M$127,6,0)," ") | E10: =IFERROR(VLOOKUP(C10,주소록!$A$4:$L$305,7,0)," ") -> 우리은행 | F10: =IFERROR(VLOOKUP(C10,주소록!$A$4:$L$305,8,0)," ") -> 1002-209-949780 | G10: =IFERROR(VLOOKUP(C10,주소록!$A$4:$L$305,5,0)," ") -> 010-5335-3740
B11: =IFERROR(VLOOKUP(C11,주소록!$A$4:$L$305,2,0)," ") -> 조경공 | C11: =주소록!A10 -> 김성배 | D11: =IFERROR(VLOOKUP(C11,급여!$A$3:$M$127,6,0)," ") | E11: =IFERROR(VLOOKUP(C11,주소록!$A$4:$L$305,7,0)," ") -> 기업은행 | F11: =IFERROR(VLOOKUP(C11,주소록!$A$4:$L$305,8,0)," ") -> 139-018946-02-039 | G11: =IFERROR(VLOOKUP(C11,주소록!$A$4:$L$305,5,0)," ") -> 010-2084-1165
B12: =IFERROR(VLOOKUP(C12,주소록!$A$4:$L$305,2,0)," ") -> 조경공 | C12: =주소록!A11 -> 민경식 | D12: =IFERROR(VLOOKUP(C12,급여!$A$3:$M$127,6,0)," ") | E12: =IFERROR(VLOOKUP(C12,주소록!$A$4:$L$305,7,0)," ") -> 신한은행 | F12: =IFERROR(VLOOKUP(C12,주소록!$A$4:$L$305,8,0)," ") -> 110-065-529493 | G12: =IFERROR(VLOOKUP(C12,주소록!$A$4:$L$305,5,0)," ") -> 010-4253-6883
B13: =IFERROR(VLOOKUP(C13,주소록!$A$4:$L$305,2,0)," ") -> 보통인부 | C13: =주소록!A12 -> 문순철 | D13: =IFERROR(VLOOKUP(C13,급여!$A$3:$M$127,6,0)," ") | E13: =IFERROR(VLOOKUP(C13,주소록!$A$4:$L$305,7,0)," ") -> 농협중앙회 | F13: =IFERROR(VLOOKUP(C13,주소록!$A$4:$L$305,8,0)," ") -> 302-1775-7802-51 | G13: =IFERROR(VLOOKUP(C13,주소록!$A$4:$L$305,5,0)," ") -> 010-7963-6888
B14: =IFERROR(VLOOKUP(C14,주소록!$A$4:$L$305,2,0)," ") -> 조경공 | C14: =주소록!A13 -> 김기윤 | D14: =IFERROR(VLOOKUP(C14,급여!$A$3:$M$127,6,0)," ") | E14: =IFERROR(VLOOKUP(C14,주소록!$A$4:$L$305,7,0)," ") -> 국민은행 | F14: =IFERROR(VLOOKUP(C14,주소록!$A$4:$L$305,8,0)," ") -> 833-21-0509-800 | G14: =IFERROR(VLOOKUP(C14,주소록!$A$4:$L$305,5,0)," ") -> 010-5358-5893
B15: =IFERROR(VLOOKUP(C15,주소록!$A$4:$L$305,2,0)," ") -> 조경공 | C15: =주소록!A14 -> 김수석 | D15: =IFERROR(VLOOKUP(C15,급여!$A$3:$M$127,6,0)," ") | E15: =IFERROR(VLOOKUP(C15,주소록!$A$4:$L$305,7,0)," ") -> 농협중앙회 | F15: =IFERROR(VLOOKUP(C15,주소록!$A$4:$L$305,8,0)," ") -> 204040-56-201577 | G15: =IFERROR(VLOOKUP(C15,주소록!$A$4:$L$305,5,0)," ") -> 010-9185-0935
B16: =IFERROR(VLOOKUP(C16,주소록!$A$4:$L$305,2,0)," ") -> 조경공 | C16: =주소록!A15 -> 권오훈 | D16: =IFERROR(VLOOKUP(C16,급여!$A$3:$M$127,6,0)," ") | E16: =IFERROR(VLOOKUP(C16,주소록!$A$4:$L$305,7,0)," ") -> 농협중앙회 | F16: =IFERROR(VLOOKUP(C16,주소록!$A$4:$L$305,8,0)," ") -> 172080-52-090513 | G16: =IFERROR(VLOOKUP(C16,주소록!$A$4:$L$305,5,0)," ") -> 010-3433-9377
B17: =IFERROR(VLOOKUP(C17,주소록!$A$4:$L$305,2,0)," ") -> 조경공 | C17: =주소록!A16 -> 윤종현 | D17: =IFERROR(VLOOKUP(C17,급여!$A$3:$M$127,6,0)," ") | E17: =IFERROR(VLOOKUP(C17,주소록!$A$4:$L$305,7,0)," ") -> 국민은행 | F17: =IFERROR(VLOOKUP(C17,주소록!$A$4:$L$305,8,0)," ") -> 035802-04-481610 | G17: =IFERROR(VLOOKUP(C17,주소록!$A$4:$L$305,5,0)," ") -> 010-8716-9947
B18: =IFERROR(VLOOKUP(C18,주소록!$A$4:$L$305,2,0)," ") -> 보통인부 | C18: =주소록!A17 -> 김원태 | D18: =IFERROR(VLOOKUP(C18,급여!$A$3:$M$127,6,0)," ") | E18: =IFERROR(VLOOKUP(C18,주소록!$A$4:$L$305,7,0)," ") -> KEB하나은행 | F18: =IFERROR(VLOOKUP(C18,주소록!$A$4:$L$305,8,0)," ") -> 580-910278-79407 | G18: =IFERROR(VLOOKUP(C18,주소록!$A$4:$L$305,5,0)," ") -> 010-5540-5904
B19: =IFERROR(VLOOKUP(C19,주소록!$A$4:$L$305,2,0)," ") -> 조경공 | C19: =주소록!A18 -> 정재우 | D19: =IFERROR(VLOOKUP(C19,급여!$A$3:$M$127,6,0)," ") | E19: =IFERROR(VLOOKUP(C19,주소록!$A$4:$L$305,7,0)," ") -> 우체국 | F19: =IFERROR(VLOOKUP(C19,주소록!$A$4:$L$305,8,0)," ") -> 102822-02-132334 | G19: =IFERROR(VLOOKUP(C19,주소록!$A$4:$L$305,5,0)," ") -> 010-7767-5506
B20: =IFERROR(VLOOKUP(C20,주소록!$A$4:$L$305,2,0)," ") -> 조경공 | C20: =주소록!A19 -> 김웅탄 | D20: =IFERROR(VLOOKUP(C20,급여!$A$3:$M$127,6,0)," ") | E20: =IFERROR(VLOOKUP(C20,주소록!$A$4:$L$305,7,0)," ") -> 신한은행 | F20: =IFERROR(VLOOKUP(C20,주소록!$A$4:$L$305,8,0)," ") -> 110-414-437990 | G20: =IFERROR(VLOOKUP(C20,주소록!$A$4:$L$305,5,0)," ") -> 010-4890-8284
... B27: =IFERROR(VLOOKUP(C27,주소록!$A$4:$L$305,2,0)," ") -> 조경공 | C27: =주소록!A26 -> 이병대 | D27: =IFERROR(VLOOKUP(C27,급여!$A$3:$M$127,6,0)," ") | E27: =IFERROR(VLOOKUP(C27,주소록!$A$4:$L$305,7,0)," ") -> 신한은행 | F27: =IFERROR(VLOOKUP(C27,주소록!$A$4:$L$305,8,0)," ") -> 110-412-527148 | G27: =IFERROR(VLOOKUP(C27,주소록!$A$4:$L$305,5,0)," ") -> 010-8736-9866
A28: [소계1] | D28: =SUM(D5:D27) -> 0
A29: 부가세 | D29: =D28*0.1 -> 0
A30: 청구금액 | D30: =D28+D29 -> 0
A31: 직불하도급사 | B31: 직종 | C31: 근로자성명 | D31: 청구액 | E31: 은행명 | F31: 계좌번호 | G31: 휴대폰번호
B32: =IFERROR(VLOOKUP(C32,주소록!$A$4:$L$305,2,0)," ") -> 조경공 | C32: =주소록!A31 -> 조태휘 | D32: =IFERROR(VLOOKUP(C32,급여!$A$3:$M$127,6,0)," ") | E32: =IFERROR(VLOOKUP(C32,주소록!$A$4:$L$305,7,0)," ") -> 신한은행 | F32: =IFERROR(VLOOKUP(C32,주소록!$A$4:$L$305,8,0)," ") -> 110-479-254923
B33: =IFERROR(VLOOKUP(C33,주소록!$A$4:$L$305,2,0)," ") -> 조경공 | C33: =주소록!A32 -> 차용수 | D33: =IFERROR(VLOOKUP(C33,급여!$A$3:$M$127,6,0)," ") | E33: =IFERROR(VLOOKUP(C33,주소록!$A$4:$L$305,7,0)," ") -> 농협중앙회 | F33: =IFERROR(VLOOKUP(C33,주소록!$A$4:$L$305,8,0)," ") -> 216011-52-042985
B34: =IFERROR(VLOOKUP(C34,주소록!$A$4:$L$305,2,0)," ") -> 조경공 | C34: =주소록!A33 -> 한정수 | D34: =IFERROR(VLOOKUP(C34,급여!$A$3:$M$127,6,0)," ") | E34: =IFERROR(VLOOKUP(C34,주소록!$A$4:$L$305,7,0)," ") -> 신협중앙회 | F34: =IFERROR(VLOOKUP(C34,주소록!$A$4:$L$305,8,0)," ") -> 132-069-090029
B35: =IFERROR(VLOOKUP(C35,주소록!$A$4:$L$305,2,0)," ") -> 조경공 | C35: =주소록!A34 -> 김윤자 | D35: =IFERROR(VLOOKUP(C35,급여!$A$3:$M$127,6,0)," ") | E35: =IFERROR(VLOOKUP(C35,주소록!$A$4:$L$305,7,0)," ") -> 신한은행 | F35: =IFERROR(VLOOKUP(C35,주소록!$A$4:$L$305,8,0)," ") -> 110-118-001184
B36: =IFERROR(VLOOKUP(C36,주소록!$A$4:$L$305,2,0)," ") -> 조경공 | C36: =주소록!A35 -> 이명분 | D36: =IFERROR(VLOOKUP(C36,급여!$A$3:$M$127,6,0)," ") | E36: =IFERROR(VLOOKUP(C36,주소록!$A$4:$L$305,7,0)," ") -> 농협중앙회 | F36: =IFERROR(VLOOKUP(C36,주소록!$A$4:$L$305,8,0)," ") -> 301-0021-1505-41
B37: =IFERROR(VLOOKUP(C37,주소록!$A$4:$L$305,2,0)," ") -> 조경공 | C37: =주소록!A36 -> 이인애 | D37: =IFERROR(VLOOKUP(C37,급여!$A$3:$M$127,6,0)," ") | E37: =IFERROR(VLOOKUP(C37,주소록!$A$4:$L$305,7,0)," ") -> 새마을금고 | F37: =IFERROR(VLOOKUP(C37,주소록!$A$4:$L$305,8,0)," ") -> 9002-1804-7397-0
B38: =IFERROR(VLOOKUP(C38,주소록!$A$4:$L$305,2,0)," ") -> 조경공 | C38: =주소록!A37 -> 이정주 | D38: =IFERROR(VLOOKUP(C38,급여!$A$3:$M$127,6,0)," ") | E38: =IFERROR(VLOOKUP(C38,주소록!$A$4:$L$305,7,0)," ") -> 농협중앙회 | F38: =IFERROR(VLOOKUP(C38,주소록!$A$4:$L$305,8,0)," ") -> 170671-52-086183
B39: =IFERROR(VLOOKUP(C39,주소록!$A$4:$L$305,2,0)," ") -> 조경공 | C39: =주소록!A38 -> 이현자 | D39: =IFERROR(VLOOKUP(C39,급여!$A$3:$M$127,6,0)," ") | E39: =IFERROR(VLOOKUP(C39,주소록!$A$4:$L$305,7,0)," ") -> 국민은행 | F39: =IFERROR(VLOOKUP(C39,주소록!$A$4:$L$305,8,0)," ") -> 224601-04-129755
B40: =IFERROR(VLOOKUP(C40,주소록!$A$4:$L$305,2,0)," ") -> 조경공 | C40: =주소록!A39 -> 유군희 | D40: =IFERROR(VLOOKUP(C40,급여!$A$3:$M$127,6,0)," ") | E40: =IFERROR(VLOOKUP(C40,주소록!$A$4:$L$305,7,0)," ") -> 우리은행 | F40: =IFERROR(VLOOKUP(C40,주소록!$A$4:$L$305,8,0)," ") -> 1002-539-484383
B41: =IFERROR(VLOOKUP(C41,주소록!$A$4:$L$305,2,0)," ") -> 조경공 | C41: =주소록!A40 -> 류시현 | D41: =IFERROR(VLOOKUP(C41,급여!$A$3:$M$127,6,0)," ") | E41: =IFERROR(VLOOKUP(C41,주소록!$A$4:$L$305,7,0)," ") -> 제일은행 | F41: =IFERROR(VLOOKUP(C41,주소록!$A$4:$L$305,8,0)," ") -> 580-20-374487
A45: [소계2] | D45: =SUM(D32:D44) -> 0
A46: 부가세 | D46: =D45*0.1 -> 0
A47: 청구금액 | D47: =D45+D46 -> 0
A48: [합 계] | D48: =D28+D45 -> 0
A49: 부가세 | D49: =D48*0.1 -> 0
A50: 청구금액 | D50: =D48+D49 -> 0
...

Sheet 주소록
A2: 1 | B2: =A2+1 -> 2 | C2: =B2+1 -> 3 | D2: =C2+1 -> 4 | E2: =D2+1 -> 5 | F2: =E2+1 -> 6 | G2: =F2+1 -> 7 | H2: =G2+1 -> 8 | I2: =H2+1 -> 9 | ... K2: =J2+1 -> 11 | L2: 오늘기준 | M2: 은행명 아래 표 참고해서 통일 시켜주세요~ | N2: ="오류 : "&COUNTIF($P$4:$P$480,"X") -> 오류 : 0
A3: 성명 | B3: 직종 | C3: 주민등록번호 | D3: 주소 | E3: 연락처 | F3: 은행코드 | G3: 은행 | H3: 계좌번호 | I3: 예금주 | J3: 국적코드 | K3: 체류자격코드 | L3: 나이 (만) | N3: 주민번호 체크 | P3: 은행명 | S3: CPU시험사
A4: 오부택 | B4: 작업반장 | C4: 651015-1333111 | D4: 경기도 남양주시 도농동 291-34 19/4 | E4: 010-8783-1657 | F4: 0011 | G4: 농협중앙회 | H4: 204030-56-159309 | I4: 오부택 | L4: =IFERROR(IF(OR(MID(C4,8,1)<"3",AND(MID(C4,8,1)>="5",MID(C4,8,1)<="6")),INT(TEXT(TODAY(),"yyyy.mmdd")-TEXT(TEXT(LEFT(C4,6),"1900-00-00"),"yyyy.mmdd")),INT(TEXT(TODAY(),"yyyy.mmdd")-TEXT(TEXT(LEFT(C4,6),"2000-00-00"),"yyyy.mmdd"))),"") -> 60 | N4: =IFERROR(IF(MID(C4,8,1)>="5",IF(RIGHT(C4,1)=(RIGHT(13-MOD(MID(C4,1,1)*2+MID(C4,2,1)*3+MID(C4,3,1)*4+MID(C4,4,1)*5+MID(C4,5,1)*6+MID(C4,6,1)*7+MID(C4,8,1)*8+MID(C4,9,1)*9+MID(C4,10,1)*2+MID(C4,11,1)*3+MID(C4,12,1)*4+MID(C4,13,1)*5,11),1)),"O","X"),IF(RIGHT(C4,1)=(RIGHT(11-MOD(MID(C4,1,1)*2+MID(C4,2,1)*3+MID(C4,3,1)*4+MID(C4,4,1)*5+MID(C4,5,1)*6+MID(C4,6,1)*7+MID(C4,8,1)*8+MID(C4,9,1)*9+MID(C4,10,1)*2+MID(C4,11,1)*3+MID(C4,12,1)*4+MID(C4,13,1)*5,11),1)),"O","X")),"") -> O | P4: KEB하나은행 | Q4: 0081 | S4: H/W설치사
A5: 하해군 | B5: 조경공 | C5: 630816-1221210 | D5: 경기도 남양주시 진건읍 사릉로용정1길 11 | E5: 010-4993-9423 | F5: 0011 | G5: 농협중앙회 | H5: 352-0964-6051-63 | I5: 하진욱 | L5: =IFERROR(IF(OR(MID(C5,8,1)<"3",AND(MID(C5,8,1)>="5",MID(C5,8,1)<="6")),INT(TEXT(TODAY(),"yyyy.mmdd")-TEXT(TEXT(LEFT(C5,6),"1900-00-00"),"yyyy.mmdd")),INT(TEXT(TODAY(),"yyyy.mmdd")-TEXT(TEXT(LEFT(C5,6),"2000-00-00"),"yyyy.mmdd"))),"") -> 62 | N5: =IFERROR(IF(MID(C5,8,1)>="5",IF(RIGHT(C5,1)=(RIGHT(13-MOD(MID(C5,1,1)*2+MID(C5,2,1)*3+MID(C5,3,1)*4+MID(C5,4,1)*5+MID(C5,5,1)*6+MID(C5,6,1)*7+MID(C5,8,1)*8+MID(C5,9,1)*9+MID(C5,10,1)*2+MID(C5,11,1)*3+MID(C5,12,1)*4+MID(C5,13,1)*5,11),1)),"O","X"),IF(RIGHT(C5,1)=(RIGHT(11-MOD(MID(C5,1,1)*2+MID(C5,2,1)*3+MID(C5,3,1)*4+MID(C5,4,1)*5+MID(C5,5,1)*6+MID(C5,6,1)*7+MID(C5,8,1)*8+MID(C5,9,1)*9+MID(C5,10,1)*2+MID(C5,11,1)*3+MID(C5,12,1)*4+MID(C5,13,1)*5,11),1)),"O","X")),"") -> O | P5: 경남은행 | Q5: 0039 | S5: H/W시험사
A6: 유수진 | B6: 조경공 | C6: 701126-1241813 | D6: 경기도 포천군 영북면 운천리 528 | E6: 010-3124-2716 | F6: 0004 | G6: 국민은행 | H6: 352601-01-213053 | I6: 유수진 | L6: =IFERROR(IF(OR(MID(C6,8,1)<"3",AND(MID(C6,8,1)>="5",MID(C6,8,1)<="6")),INT(TEXT(TODAY(),"yyyy.mmdd")-TEXT(TEXT(LEFT(C6,6),"1900-00-00"),"yyyy.mmdd")),INT(TEXT(TODAY(),"yyyy.mmdd")-TEXT(TEXT(LEFT(C6,6),"2000-00-00"),"yyyy.mmdd"))),"") -> 55 | N6: =IFERROR(IF(MID(C6,8,1)>="5",IF(RIGHT(C6,1)=(RIGHT(13-MOD(MID(C6,1,1)*2+MID(C6,2,1)*3+MID(C6,3,1)*4+MID(C6,4,1)*5+MID(C6,5,1)*6+MID(C6,6,1)*7+MID(C6,8,1)*8+MID(C6,9,1)*9+MID(C6,10,1)*2+MID(C6,11,1)*3+MID(C6,12,1)*4+MID(C6,13,1)*5,11),1)),"O","X"),IF(RIGHT(C6,1)=(RIGHT(11-MOD(MID(C6,1,1)*2+MID(C6,2,1)*3+MID(C6,3,1)*4+MID(C6,4,1)*5+MID(C6,5,1)*6+MID(C6,6,1)*7+MID(C6,8,1)*8+MID(C6,9,1)*9+MID(C6,10,1)*2+MID(C6,11,1)*3+MID(C6,12,1)*4+MID(C6,13,1)*5,11),1)),"O","X")),"") -> O | P6: 광주은행 | Q6: 0034 | S6: H/W시험사
A7: 김방수 | B7: 조경공 | C7: 650604-1622312 | D7: 경기도 남양주시 경춘로859번길26, B동 204호(금곡동,동익빌라) | E7: 010-9342-8092 | F7: 0011 | G7: 농협중앙회 | H7: 204074-51-050436 | I7: 김방수 | L7: =IFERROR(IF(OR(MID(C7,8,1)<"3",AND(MID(C7,8,1)>="5",MID(C7,8,1)<="6")),INT(TEXT(TODAY(),"yyyy.mmdd")-TEXT(TEXT(LEFT(C7,6),"1900-00-00"),"yyyy.mmdd")),INT(TEXT(TODAY(),"yyyy.mmdd")-TEXT(TEXT(LEFT(C7,6),"2000-00-00"),"yyyy.mmdd"))),"") -> 60 | N7: =IFERROR(IF(MID(C7,8,1)>="5",IF(RIGHT(C7,1)=(RIGHT(13-MOD(MID(C7,1,1)*2+MID(C7,2,1)*3+MID(C7,3,1)*4+MID(C7,4,1)*5+MID(C7,5,1)*6+MID(C7,6,1)*7+MID(C7,8,1)*8+MID(C7,9,1)*9+MID(C7,10,1)*2+MID(C7,11,1)*3+MID(C7,12,1)*4+MID(C7,13,1)*5,11),1)),"O","X"),IF(RIGHT(C7,1)=(RIGHT(11-MOD(MID(C7,1,1)*2+MID(C7,2,1)*3+MID(C7,3,1)*4+MID(C7,4,1)*5+MID(C7,5,1)*6+MID(C7,6,1)*7+MID(C7,8,1)*8+MID(C7,9,1)*9+MID(C7,10,1)*2+MID(C7,11,1)*3+MID(C7,12,1)*4+MID(C7,13,1)*5,11),1)),"O","X")),"") -> O | P7: 국민은행 | Q7: 0004 | S7: P.C설치공
A8: 유광열 | B8: 조경공 | C8: 600815-1650411 | D8: 서울시 동대문구 제기로21길 63-4 | E8: 010-8750-3852 | F8: 0004 | G8: 국민은행 | H8: 420802-01-297649 | I8: 유광열 | L8: =IFERROR(IF(OR(MID(C8,8,1)<"3",AND(MID(C8,8,1)>="5",MID(C8,8,1)<="6")),INT(TEXT(TODAY(),"yyyy.mmdd")-TEXT(TEXT(LEFT(C8,6),"1900-00-00"),"yyyy.mmdd")),INT(TEXT(TODAY(),"yyyy.mmdd")-TEXT(TEXT(LEFT(C8,6),"2000-00-00"),"yyyy.mmdd"))),"") -> 65 | N8: =IFERROR(IF(MID(C8,8,1)>="5",IF(RIGHT(C8,1)=(RIGHT(13-MOD(MID(C8,1,1)*2+MID(C8,2,1)*3+MID(C8,3,1)*4+MID(C8,4,1)*5+MID(C8,5,1)*6+MID(C8,6,1)*7+MID(C8,8,1)*8+MID(C8,9,1)*9+MID(C8,10,1)*2+MID(C8,11,1)*3+MID(C8,12,1)*4+MID(C8,13,1)*5,11),1)),"O","X"),IF(RIGHT(C8,1)=(RIGHT(11-MOD(MID(C8,1,1)*2+MID(C8,2,1)*3+MID(C8,3,1)*4+MID(C8,4,1)*5+MID(C8,5,1)*6+MID(C8,6,1)*7+MID(C8,8,1)*8+MID(C8,9,1)*9+MID(C8,10,1)*2+MID(C8,11,1)*3+MID(C8,12,1)*4+MID(C8,13,1)*5,11),1)),"O","X")),"") -> O | P8: 기업은행 | Q8: 0003 | S8: P.C제작공
A9: 현영석 | B9: 조경공 | C9: 591020-1037016 | D9: 서울시 서대문구 세무서길 50-1 | E9: 010-5335-3740 | F9: 0020 | G9: 우리은행 | H9: 1002-209-949780 | I9: 현영석 | L9: =IFERROR(IF(OR(MID(C9,8,1)<"3",AND(MID(C9,8,1)>="5",MID(C9,8,1)<="6")),INT(TEXT(TODAY(),"yyyy.mmdd")-TEXT(TEXT(LEFT(C9,6),"1900-00-00"),"yyyy.mmdd")),INT(TEXT(TODAY(),"yyyy.mmdd")-TEXT(TEXT(LEFT(C9,6),"2000-00-00"),"yyyy.mmdd"))),"") -> 66 | N9: =IFERROR(IF(MID(C9,8,1)>="5",IF(RIGHT(C9,1)=(RIGHT(13-MOD(MID(C9,1,1)*2+MID(C9,2,1)*3+MID(C9,3,1)*4+MID(C9,4,1)*5+MID(C9,5,1)*6+MID(C9,6,1)*7+MID(C9,8,1)*8+MID(C9,9,1)*9+MID(C9,10,1)*2+MID(C9,11,1)*3+MID(C9,12,1)*4+MID(C9,13,1)*5,11),1)),"O","X"),IF(RIGHT(C9,1)=(RIGHT(11-MOD(MID(C9,1,1)*2+MID(C9,2,1)*3+MID(C9,3,1)*4+MID(C9,4,1)*5+MID(C9,5,1)*6+MID(C9,6,1)*7+MID(C9,8,1)*8+MID(C9,9,1)*9+MID(C9,10,1)*2+MID(C9,11,1)*3+MID(C9,12,1)*4+MID(C9,13,1)*5,11),1)),"O","X")),"") -> O | P9: 농협중앙회 | Q9: 0011 | S9: P.S공
A10: 김성배 | B10: 조경공 | C10: 540910-1041520 | D10: 서울시 은평구 녹번동 4-262 | E10: 010-2084-1165 | F10: 0003 | G10: 기업은행 | H10: 139-018946-02-039 | I10: 김성배 | L10: =IFERROR(IF(OR(MID(C10,8,1)<"3",AND(MID(C10,8,1)>="5",MID(C10,8,1)<="6")),INT(TEXT(TODAY(),"yyyy.mmdd")-TEXT(TEXT(LEFT(C10,6),"1900-00-00"),"yyyy.mmdd")),INT(TEXT(TODAY(),"yyyy.mmdd")-TEXT(TEXT(LEFT(C10,6),"2000-00-00"),"yyyy.mmdd"))),"") -> 71 | N10: =IFERROR(IF(MID(C10,8,1)>="5",IF(RIGHT(C10,1)=(RIGHT(13-MOD(MID(C10,1,1)*2+MID(C10,2,1)*3+MID(C10,3,1)*4+MID(C10,4,1)*5+MID(C10,5,1)*6+MID(C10,6,1)*7+MID(C10,8,1)*8+MID(C10,9,1)*9+MID(C10,10,1)*2+MID(C10,11,1)*3+MID(C10,12,1)*4+MID(C10,13,1)*5,11),1)),"O","X"),IF(RIGHT(C10,1)=(RIGHT(11-MOD(MID(C10,1,1)*2+MID(C10,2,1)*3+MID(C10,3,1)*4+MID(C10,4,1)*5+MID(C10,5,1)*6+MID(C10,6,1)*7+MID(C10,8,1)*8+MID(C10,9,1)*9+MID(C10,10,1)*2+MID(C10,11,1)*3+MID(C10,12,1)*4+MID(C10,13,1)*5,11),1)),"O","X")),"") -> O | P10: 농협회원조합 | Q10: 0012 | S10: P.S공
A11: 민경식 | B11: 조경공 | C11: 720302-1037116 | D11: 서울특별시 은평구 녹번동 44-26 B02호 | E11: 010-4253-6883 | F11: 0088 | G11: 신한은행 | H11: 110-065-529493 | I11: 민경식 | L11: =IFERROR(IF(OR(MID(C11,8,1)<"3",AND(MID(C11,8,1)>="5",MID(C11,8,1)<="6")),INT(TEXT(TODAY(),"yyyy.mmdd")-TEXT(TEXT(LEFT(C11,6),"1900-00-00"),"yyyy.mmdd")),INT(TEXT(TODAY(),"yyyy.mmdd")-TEXT(TEXT(LEFT(C11,6),"2000-00-00"),"yyyy.mmdd"))),"") -> 54 | N11: =IFERROR(IF(MID(C11,8,1)>="5",IF(RIGHT(C11,1)=(RIGHT(13-MOD(MID(C11,1,1)*2+MID(C11,2,1)*3+MID(C11,3,1)*4+MID(C11,4,1)*5+MID(C11,5,1)*6+MID(C11,6,1)*7+MID(C11,8,1)*8+MID(C11,9,1)*9+MID(C11,10,1)*2+MID(C11,11,1)*3+MID(C11,12,1)*4+MID(C11,13,1)*5,11),1)),"O","X"),IF(RIGHT(C11,1)=(RIGHT(11-MOD(MID(C11,1,1)*2+MID(C11,2,1)*3+MID(C11,3,1)*4+MID(C11,4,1)*5+MID(C11,5,1)*6+MID(C11,6,1)*7+MID(C11,8,1)*8+MID(C11,9,1)*9+MID(C11,10,1)*2+MID(C11,11,1)*3+MID(C11,12,1)*4+MID(C11,13,1)*5,11),1)),"O","X")),"") -> O | P11: 대구은행 | Q11: 0031 | S11: S/W시험사
A12: 문순철 | B12: 보통인부 | C12: 580706-5860194 | D12: 서울특별시 은평구 연소로 35길7 101 | E12: 010-7963-6888 | F12: 0011 | G12: 농협중앙회 | H12: 302-1775-7802-51 | I12: WEN SHUNZHE | L12: =IFERROR(IF(OR(MID(C12,8,1)<"3",AND(MID(C12,8,1)>="5",MID(C12,8,1)<="6")),INT(TEXT(TODAY(),"yyyy.mmdd")-TEXT(TEXT(LEFT(C12,6),"1900-00-00"),"yyyy.mmdd")),INT(TEXT(TODAY(),"yyyy.mmdd")-TEXT(TEXT(LEFT(C12,6),"2000-00-00"),"yyyy.mmdd"))),"") -> 67 | N12: =IFERROR(IF(MID(C12,8,1)>="5",IF(RIGHT(C12,1)=(RIGHT(13-MOD(MID(C12,1,1)*2+MID(C12,2,1)*3+MID(C12,3,1)*4+MID(C12,4,1)*5+MID(C12,5,1)*6+MID(C12,6,1)*7+MID(C12,8,1)*8+MID(C12,9,1)*9+MID(C12,10,1)*2+MID(C12,11,1)*3+MID(C12,12,1)*4+MID(C12,13,1)*5,11),1)),"O","X"),IF(RIGHT(C12,1)=(RIGHT(11-MOD(MID(C12,1,1)*2+MID(C12,2,1)*3+MID(C12,3,1)*4+MID(C12,4,1)*5+MID(C12,5,1)*6+MID(C12,6,1)*7+MID(C12,8,1)*8+MID(C12,9,1)*9+MID(C12,10,1)*2+MID(C12,11,1)*3+MID(C12,12,1)*4+MID(C12,13,1)*5,11),1)),"O","X")),"") -> O | P12: 부산은행 | Q12: 0032 | S12: 가구공
A13: 김기윤 | B13: 조경공 | C13: 620811-1538913 | D13: 서울특별시 은평구 갈현로31길3, 302호(갈현동, 장성케이씨빌) | E13: 010-5358-5893 | F13: 0004 | G13: 국민은행 | H13: 833-21-0509-800 | I13: 김기윤 | L13: =IFERROR(IF(OR(MID(C13,8,1)<"3",AND(MID(C13,8,1)>="5",MID(C13,8,1)<="6")),INT(TEXT(TODAY(),"yyyy.mmdd")-TEXT(TEXT(LEFT(C13,6),"1900-00-00"),"yyyy.mmdd")),INT(TEXT(TODAY(),"yyyy.mmdd")-TEXT(TEXT(LEFT(C13,6),"2000-00-00"),"yyyy.mmdd"))),"") -> 63 | N13: =IFERROR(IF(MID(C13,8,1)>="5",IF(RIGHT(C13,1)=(RIGHT(13-MOD(MID(C13,1,1)*2+MID(C13,2,1)*3+MID(C13,3,1)*4+MID(C13,4,1)*5+MID(C13,5,1)*6+MID(C13,6,1)*7+MID(C13,8,1)*8+MID(C13,9,1)*9+MID(C13,10,1)*2+MID(C13,11,1)*3+MID(C13,12,1)*4+MID(C13,13,1)*5,11),1)),"O","X"),IF(RIGHT(C13,1)=(RIGHT(11-MOD(MID(C13,1,1)*2+MID(C13,2,1)*3+MID(C13,3,1)*4+MID(C13,4,1)*5+MID(C13,5,1)*6+MID(C13,6,1)*7+MID(C13,8,1)*8+MID(C13,9,1)*9+MID(C13,10,1)*2+MID(C13,11,1)*3+MID(C13,12,1)*4+MID(C13,13,1)*5,11),1)),"O","X")),"") -> O | P13: 산림조합중앙회 | Q13: 0064 | S13: 가구공
A14: 김수석 | B14: 조경공 | C14: 650502-1810529 | D14: 경기도 남양주시 와부읍 덕소로67-20, 105동 505호 | E14: 010-9185-0935 | F14: 0011 | G14: 농협중앙회 | H14: 204040-56-201577 | I14: 김수석 | L14: =IFERROR(IF(OR(MID(C14,8,1)<"3",AND(MID(C14,8,1)>="5",MID(C14,8,1)<="6")),INT(TEXT(TODAY(),"yyyy.mmdd")-TEXT(TEXT(LEFT(C14,6),"1900-00-00"),"yyyy.mmdd")),INT(TEXT(TODAY(),"yyyy.mmdd")-TEXT(TEXT(LEFT(C14,6),"2000-00-00"),"yyyy.mmdd"))),"") -> 61 | N14: =IFERROR(IF(MID(C14,8,1)>="5",IF(RIGHT(C14,1)=(RIGHT(13-MOD(MID(C14,1,1)*2+MID(C14,2,1)*3+MID(C14,3,1)*4+MID(C14,4,1)*5+MID(C14,5,1)*6+MID(C14,6,1)*7+MID(C14,8,1)*8+MID(C14,9,1)*9+MID(C14,10,1)*2+MID(C14,11,1)*3+MID(C14,12,1)*4+MID(C14,13,1)*5,11),1)),"O","X"),IF(RIGHT(C14,1)=(RIGHT(11-MOD(MID(C14,1,1)*2+MID(C14,2,1)*3+MID(C14,3,1)*4+MID(C14,4,1)*5+MID(C14,5,1)*6+MID(C14,6,1)*7+MID(C14,8,1)*8+MID(C14,9,1)*9+MID(C14,10,1)*2+MID(C14,11,1)*3+MID(C14,12,1)*4+MID(C14,13,1)*5,11),1)),"O","X")),"") -> O | P14: 산업은행 | Q14: 0002 | S14: 가구목공
A15: 권오훈 | B15: 조경공 | C15: 640920-1814621 | D15: 경기도 남양주시 와부읍 수레로1번길 28-3, 203호(장미연립) | E15: 010-3433-9377 | F15: 0011 | G15: 농협중앙회 | H15: 172080-52-090513 | I15: 권오훈 | L15: =IFERROR(IF(OR(MID(C15,8,1)<"3",AND(MID(C15,8,1)>="5",MID(C15,8,1)<="6")),INT(TEXT(TODAY(),"yyyy.mmdd")-TEXT(TEXT(LEFT(C15,6),"1900-00-00"),"yyyy.mmdd")),INT(TEXT(TODAY(),"yyyy.mmdd")-TEXT(TEXT(LEFT(C15,6),"2000-00-00"),"yyyy.mmdd"))),"") -> 61 | N15: =IFERROR(IF(MID(C15,8,1)>="5",IF(RIGHT(C15,1)=(RIGHT(13-MOD(MID(C15,1,1)*2+MID(C15,2,1)*3+MID(C15,3,1)*4+MID(C15,4,1)*5+MID(C15,5,1)*6+MID(C15,6,1)*7+MID(C15,8,1)*8+MID(C15,9,1)*9+MID(C15,10,1)*2+MID(C15,11,1)*3+MID(C15,12,1)*4+MID(C15,13,1)*5,11),1)),"O","X"),IF(RIGHT(C15,1)=(RIGHT(11-MOD(MID(C15,1,1)*2+MID(C15,2,1)*3+MID(C15,3,1)*4+MID(C15,4,1)*5+MID(C15,5,1)*6+MID(C15,6,1)*7+MID(C15,8,1)*8+MID(C15,9,1)*9+MID(C15,10,1)*2+MID(C15,11,1)*3+MID(C15,12,1)*4+MID(C15,13,1)*5,11),1)),"O","X")),"") -> O | P15: 새마을금고 | Q15: 0045 | S15: 가스용접공
... A26: 이병대 | B26: 조경공 | C26: 610316-1543716 | D26: 서울 강동구 천호동 211-12 | E26: 010-8736-9866 | F26: 0088 | G26: 신한은행 | H26: 110-412-527148 | I26: 이병대 | L26: =IFERROR(IF(OR(MID(C26,8,1)<"3",AND(MID(C26,8,1)>="5",MID(C26,8,1)<="6")),INT(TEXT(TODAY(),"yyyy.mmdd")-TEXT(TEXT(LEFT(C26,6),"1900-00-00"),"yyyy.mmdd")),INT(TEXT(TODAY(),"yyyy.mmdd")-TEXT(TEXT(LEFT(C26,6),"2000-00-00"),"yyyy.mmdd"))),"") -> 65 | N26: =IFERROR(IF(MID(C26,8,1)>="5",IF(RIGHT(C26,1)=(RIGHT(13-MOD(MID(C26,1,1)*2+MID(C26,2,1)*3+MID(C26,3,1)*4+MID(C26,4,1)*5+MID(C26,5,1)*6+MID(C26,6,1)*7+MID(C26,8,1)*8+MID(C26,9,1)*9+MID(C26,10,1)*2+MID(C26,11,1)*3+MID(C26,12,1)*4+MID(C26,13,1)*5,11),1)),"O","X"),IF(RIGHT(C26,1)=(RIGHT(11-MOD(MID(C26,1,1)*2+MID(C26,2,1)*3+MID(C26,3,1)*4+MID(C26,4,1)*5+MID(C26,5,1)*6+MID(C26,6,1)*7+MID(C26,8,1)*8+MID(C26,9,1)*9+MID(C26,10,1)*2+MID(C26,11,1)*3+MID(C26,12,1)*4+MID(C26,13,1)*5,11),1)),"O","X")),"") -> O | P26: 한국시티은행 | Q26: 0027 | S26: 건설안전공
A27: 이병인 | B27: 조경공 | C27: 500709-1063529 | D27: 인천 연수구 예술로 22번길 20, 401호 | E27: 010-2010-0909 | F27: 0011 | G27: 농협중앙회 | H27: 352-1702-4909-03 | I27: 이병인 | L27: =IFERROR(IF(OR(MID(C27,8,1)<"3",AND(MID(C27,8,1)>="5",MID(C27,8,1)<="6")),INT(TEXT(TODAY(),"yyyy.mmdd")-TEXT(TEXT(LEFT(C27,6),"1900-00-00"),"yyyy.mmdd")),INT(TEXT(TODAY(),"yyyy.mmdd")-TEXT(TEXT(LEFT(C27,6),"2000-00-00"),"yyyy.mmdd"))),"") -> 75 | N27: =IFERROR(IF(MID(C27,8,1)>="5",IF(RIGHT(C27,1)=(RIGHT(13-MOD(MID(C27,1,1)*2+MID(C27,2,1)*3+MID(C27,3,1)*4+MID(C27,4,1)*5+MID(C27,5,1)*6+MID(C27,6,1)*7+MID(C27,8,1)*8+MID(C27,9,1)*9+MID(C27,10,1)*2+MID(C27,11,1)*3+MID(C27,12,1)*4+MID(C27,13,1)*5,11),1)),"O","X"),IF(RIGHT(C27,1)=(RIGHT(11-MOD(MID(C27,1,1)*2+MID(C27,2,1)*3+MID(C27,3,1)*4+MID(C27,4,1)*5+MID(C27,5,1)*6+MID(C27,6,1)*7+MID(C27,8,1)*8+MID(C27,9,1)*9+MID(C27,10,1)*2+MID(C27,11,1)*3+MID(C27,12,1)*4+MID(C27,13,1)*5,11),1)),"O","X")),"") -> O | S27: 건축목공
A28: 이우정 | B28: 조경공 | C28: 560418-1327011 | D28: 인천 남구 소성로 211, 3동 303호 학익동 신동아아파트 | E28: 010-8639-4427 | F28: 0011 | G28: 농협중앙회 | H28: 133-12-125675 | I28: 이우정 | L28: =IFERROR(IF(OR(MID(C28,8,1)<"3",AND(MID(C28,8,1)>="5",MID(C28,8,1)<="6")),INT(TEXT(TODAY(),"yyyy.mmdd")-TEXT(TEXT(LEFT(C28,6),"1900-00-00"),"yyyy.mmdd")),INT(TEXT(TODAY(),"yyyy.mmdd")-TEXT(TEXT(LEFT(C28,6),"2000-00-00"),"yyyy.mmdd"))),"") -> 70 | N28: =IFERROR(IF(MID(C28,8,1)>="5",IF(RIGHT(C28,1)=(RIGHT(13-MOD(MID(C28,1,1)*2+MID(C28,2,1)*3+MID(C28,3,1)*4+MID(C28,4,1)*5+MID(C28,5,1)*6+MID(C28,6,1)*7+MID(C28,8,1)*8+MID(C28,9,1)*9+MID(C28,10,1)*2+MID(C28,11,1)*3+MID(C28,12,1)*4+MID(C28,13,1)*5,11),1)),"O","X"),IF(RIGHT(C28,1)=(RIGHT(11-MOD(MID(C28,1,1)*2+MID(C28,2,1)*3+MID(C28,3,1)*4+MID(C28,4,1)*5+MID(C28,5,1)*6+MID(C28,6,1)*7+MID(C28,8,1)*8+MID(C28,9,1)*9+MID(C28,10,1)*2+MID(C28,11,1)*3+MID(C28,12,1)*4+MID(C28,13,1)*5,11),1)),"O","X")),"") -> O | S28: 견출공
A29: 정원봉 | B29: 조경공 | C29: 490711-1652917 | D29: 인천 연수구 선학동 347 선학시영아파트 115동 206호 | E29: 010-7732-5769 | F29: 0088 | G29: 신한은행 | H29: 110-300-559320 | I29: 정원봉 | L29: =IFERROR(IF(OR(MID(C29,8,1)<"3",AND(MID(C29,8,1)>="5",MID(C29,8,1)<="6")),INT(TEXT(TODAY(),"yyyy.mmdd")-TEXT(TEXT(LEFT(C29,6),"1900-00-00"),"yyyy.mmdd")),INT(TEXT(TODAY(),"yyyy.mmdd")-TEXT(TEXT(LEFT(C29,6),"2000-00-00"),"yyyy.mmdd"))),"") -> 76 | N29: =IFERROR(IF(MID(C29,8,1)>="5",IF(RIGHT(C29,1)=(RIGHT(13-MOD(MID(C29,1,1)*2+MID(C29,2,1)*3+MID(C29,3,1)*4+MID(C29,4,1)*5+MID(C29,5,1)*6+MID(C29,6,1)*7+MID(C29,8,1)*8+MID(C29,9,1)*9+MID(C29,10,1)*2+MID(C29,11,1)*3+MID(C29,12,1)*4+MID(C29,13,1)*5,11),1)),"O","X"),IF(RIGHT(C29,1)=(RIGHT(11-MOD(MID(C29,1,1)*2+MID(C29,2,1)*3+MID(C29,3,1)*4+MID(C29,4,1)*5+MID(C29,5,1)*6+MID(C29,6,1)*7+MID(C29,8,1)*8+MID(C29,9,1)*9+MID(C29,10,1)*2+MID(C29,11,1)*3+MID(C29,12,1)*4+MID(C29,13,1)*5,11),1)),"O","X")),"") -> O | S29: 경량기포공
A30: 정형기 | B30: 조경공 | C30: 440320-1472111 | D30: 인천 부평구 백범로 340번길 6 십정동 | E30: 010-3705-2432 | F30: 0048 | G30: 신협중앙회 | H30: 132-132-096895 | I30: 정형기 | L30: =IFERROR(IF(OR(MID(C30,8,1)<"3",AND(MID(C30,8,1)>="5",MID(C30,8,1)<="6")),INT(TEXT(TODAY(),"yyyy.mmdd")-TEXT(TEXT(LEFT(C30,6),"1900-00-00"),"yyyy.mmdd")),INT(TEXT(TODAY(),"yyyy.mmdd")-TEXT(TEXT(LEFT(C30,6),"2000-00-00"),"yyyy.mmdd"))),"") -> 82 | N30: =IFERROR(IF(MID(C30,8,1)>="5",IF(RIGHT(C30,1)=(RIGHT(13-MOD(MID(C30,1,1)*2+MID(C30,2,1)*3+MID(C30,3,1)*4+MID(C30,4,1)*5+MID(C30,5,1)*6+MID(C30,6,1)*7+MID(C30,8,1)*8+MID(C30,9,1)*9+MID(C30,10,1)*2+MID(C30,11,1)*3+MID(C30,12,1)*4+MID(C30,13,1)*5,11),1)),"O","X"),IF(RIGHT(C30,1)=(RIGHT(11-MOD(MID(C30,1,1)*2+MID(C30,2,1)*3+MID(C30,3,1)*4+MID(C30,4,1)*5+MID(C30,5,1)*6+MID(C30,6,1)*7+MID(C30,8,1)*8+MID(C30,9,1)*9+MID(C30,10,1)*2+MID(C30,11,1)*3+MID(C30,12,1)*4+MID(C30,13,1)*5,11),1)),"O","X")),"") -> O | S30: 경량기포공
A31: 조태휘 | B31: 조경공 | C31: 461015-1148113 | D31: 인천 남구 관교동 13-8 풍림아파트 102동 303호 | E31: 010-7799-6342 | F31: 0088 | G31: 신한은행 | H31: 110-479-254923 | I31: 조태휘 | L31: =IFERROR(IF(OR(MID(C31,8,1)<"3",AND(MID(C31,8,1)>="5",MID(C31,8,1)<="6")),INT(TEXT(TODAY(),"yyyy.mmdd")-TEXT(TEXT(LEFT(C31,6),"1900-00-00"),"yyyy.mmdd")),INT(TEXT(TODAY(),"yyyy.mmdd")-TEXT(TEXT(LEFT(C31,6),"2000-00-00"),"yyyy.mmdd"))),"") -> 79 | N31: =IFERROR(IF(MID(C31,8,1)>="5",IF(RIGHT(C31,1)=(RIGHT(13-MOD(MID(C31,1,1)*2+MID(C31,2,1)*3+MID(C31,3,1)*4+MID(C31,4,1)*5+MID(C31,5,1)*6+MID(C31,6,1)*7+MID(C31,8,1)*8+MID(C31,9,1)*9+MID(C31,10,1)*2+MID(C31,11,1)*3+MID(C31,12,1)*4+MID(C31,13,1)*5,11),1)),"O","X"),IF(RIGHT(C31,1)=(RIGHT(11-MOD(MID(C31,1,1)*2+MID(C31,2,1)*3+MID(C31,3,1)*4+MID(C31,4,1)*5+MID(C31,5,1)*6+MID(C31,6,1)*7+MID(C31,8,1)*8+MID(C31,9,1)*9+MID(C31,10,1)*2+MID(C31,11,1)*3+MID(C31,12,1)*4+MID(C31,13,1)*5,11),1)),"O","X")),"") -> O | S31: 경량철골공
A32: 차용수 | B32: 조경공 | C32: 430320-1141011 | D32: 경기도 부천시원미구 상동 1832-504 반달마을1832동504호 | E32: 010-2820-7710 | F32: 0011 | G32: 농협중앙회 | H32: 216011-52-042985 | I32: 차용수 | L32: =IFERROR(IF(OR(MID(C32,8,1)<"3",AND(MID(C32,8,1)>="5",MID(C32,8,1)<="6")),INT(TEXT(TODAY(),"yyyy.mmdd")-TEXT(TEXT(LEFT(C32,6),"1900-00-00"),"yyyy.mmdd")),INT(TEXT(TODAY(),"yyyy.mmdd")-TEXT(TEXT(LEFT(C32,6),"2000-00-00"),"yyyy.mmdd"))),"") -> 83 | N32: =IFERROR(IF(MID(C32,8,1)>="5",IF(RIGHT(C32,1)=(RIGHT(13-MOD(MID(C32,1,1)*2+MID(C32,2,1)*3+MID(C32,3,1)*4+MID(C32,4,1)*5+MID(C32,5,1)*6+MID(C32,6,1)*7+MID(C32,8,1)*8+MID(C32,9,1)*9+MID(C32,10,1)*2+MID(C32,11,1)*3+MID(C32,12,1)*4+MID(C32,13,1)*5,11),1)),"O","X"),IF(RIGHT(C32,1)=(RIGHT(11-MOD(MID(C32,1,1)*2+MID(C32,2,1)*3+MID(C32,3,1)*4+MID(C32,4,1)*5+MID(C32,5,1)*6+MID(C32,6,1)*7+MID(C32,8,1)*8+MID(C32,9,1)*9+MID(C32,10,1)*2+MID(C32,11,1)*3+MID(C32,12,1)*4+MID(C32,13,1)*5,11),1)),"O","X")),"") -> O | S32: 경비
A33: 한정수 | B33: 조경공 | C33: 560904-1245511 | D33: 인천 남동구 만수동 1049 담방마을아파트 101동 1102호 | E33: 010-2375-8518 | F33: 0048 | G33: 신협중앙회 | H33: 132-069-090029 | I33: 한정수 | L33: =IFERROR(IF(OR(MID(C33,8,1)<"3",AND(MID(C33,8,1)>="5",MID(C33,8,1)<="6")),INT(TEXT(TODAY(),"yyyy.mmdd")-TEXT(TEXT(LEFT(C33,6),"1900-00-00"),"yyyy.mmdd")),INT(TEXT(TODAY(),"yyyy.mmdd")-TEXT(TEXT(LEFT(C33,6),"2000-00-00"),"yyyy.mmdd"))),"") -> 69 | N33: =IFERROR(IF(MID(C33,8,1)>="5",IF(RIGHT(C33,1)=(RIGHT(13-MOD(MID(C33,1,1)*2+MID(C33,2,1)*3+MID(C33,3,1)*4+MID(C33,4,1)*5+MID(C33,5,1)*6+MID(C33,6,1)*7+MID(C33,8,1)*8+MID(C33,9,1)*9+MID(C33,10,1)*2+MID(C33,11,1)*3+MID(C33,12,1)*4+MID(C33,13,1)*5,11),1)),"O","X"),IF(RIGHT(C33,1)=(RIGHT(11-MOD(MID(C33,1,1)*2+MID(C33,2,1)*3+MID(C33,3,1)*4+MID(C33,4,1)*5+MID(C33,5,1)*6+MID(C33,6,1)*7+MID(C33,8,1)*8+MID(C33,9,1)*9+MID(C33,10,1)*2+MID(C33,11,1)*3+MID(C33,12,1)*4+MID(C33,13,1)*5,11),1)),"O","X")),"") -> O | S33: 계령공
A34: 김윤자 | B34: 조경공 | C34: 470310-2011417 | D34: 인천광역시 남구 주안동 421-53 | E34: 010-4847-3572 | F34: 0088 | G34: 신한은행 | H34: 110-118-001184 | I34: 김윤자 | L34: =IFERROR(IF(OR(MID(C34,8,1)<"3",AND(MID(C34,8,1)>="5",MID(C34,8,1)<="6")),INT(TEXT(TODAY(),"yyyy.mmdd")-TEXT(TEXT(LEFT(C34,6),"1900-00-00"),"yyyy.mmdd")),INT(TEXT(TODAY(),"yyyy.mmdd")-TEXT(TEXT(LEFT(C34,6),"2000-00-00"),"yyyy.mmdd"))),"") -> 79 | N34: =IFERROR(IF(MID(C34,8,1)>="5",IF(RIGHT(C34,1)=(RIGHT(13-MOD(MID(C34,1,1)*2+MID(C34,2,1)*3+MID(C34,3,1)*4+MID(C34,4,1)*5+MID(C34,5,1)*6+MID(C34,6,1)*7+MID(C34,8,1)*8+MID(C34,9,1)*9+MID(C34,10,1)*2+MID(C34,11,1)*3+MID(C34,12,1)*4+MID(C34,13,1)*5,11),1)),"O","X"),IF(RIGHT(C34,1)=(RIGHT(11-MOD(MID(C34,1,1)*2+MID(C34,2,1)*3+MID(C34,3,1)*4+MID(C34,4,1)*5+MID(C34,5,1)*6+MID(C34,6,1)*7+MID(C34,8,1)*8+MID(C34,9,1)*9+MID(C34,10,1)*2+MID(C34,11,1)*3+MID(C34,12,1)*4+MID(C34,13,1)*5,11),1)),"O","X")),"") -> O | S34: 계장공
A35: 이명분 | B35: 조경공 | C35: 491128-2149618 | D35: 인천광역시 남구 주안동 1434-19 | E35: 010-5758-9519 | F35: 0011 | G35: 농협중앙회 | H35: 301-0021-1505-41 | I35: 이명분 | L35: =IFERROR(IF(OR(MID(C35,8,1)<"3",AND(MID(C35,8,1)>="5",MID(C35,8,1)<="6")),INT(TEXT(TODAY(),"yyyy.mmdd")-TEXT(TEXT(LEFT(C35,6),"1900-00-00"),"yyyy.mmdd")),INT(TEXT(TODAY(),"yyyy.mmdd")-TEXT(TEXT(LEFT(C35,6),"2000-00-00"),"yyyy.mmdd"))),"") -> 76 | N35: =IFERROR(IF(MID(C35,8,1)>="5",IF(RIGHT(C35,1)=(RIGHT(13-MOD(MID(C35,1,1)*2+MID(C35,2,1)*3+MID(C35,3,1)*4+MID(C35,4,1)*5+MID(C35,5,1)*6+MID(C35,6,1)*7+MID(C35,8,1)*8+MID(C35,9,1)*9+MID(C35,10,1)*2+MID(C35,11,1)*3+MID(C35,12,1)*4+MID(C35,13,1)*5,11),1)),"O","X"),IF(RIGHT(C35,1)=(RIGHT(11-MOD(MID(C35,1,1)*2+MID(C35,2,1)*3+MID(C35,3,1)*4+MID(C35,4,1)*5+MID(C35,5,1)*6+MID(C35,6,1)*7+MID(C35,8,1)*8+MID(C35,9,1)*9+MID(C35,10,1)*2+MID(C35,11,1)*3+MID(C35,12,1)*4+MID(C35,13,1)*5,11),1)),"O","X")),"") -> O | S35: 계측공
A36: 이인애 | B36: 조경공 | C36: 491119-2141011 | D36: 인천 남구 주안동 668-6 남승빌라 202호 | E36: 010-4326-7710 | F36: 0045 | G36: 새마을금고 | H36: 9002-1804-7397-0 | I36: 이인애 | L36: =IFERROR(IF(OR(MID(C36,8,1)<"3",AND(MID(C36,8,1)>="5",MID(C36,8,1)<="6")),INT(TEXT(TODAY(),"yyyy.mmdd")-TEXT(TEXT(LEFT(C36,6),"1900-00-00"),"yyyy.mmdd")),INT(TEXT(TODAY(),"yyyy.mmdd")-TEXT(TEXT(LEFT(C36,6),"2000-00-00"),"yyyy.mmdd"))),"") -> 76 | N36: =IFERROR(IF(MID(C36,8,1)>="5",IF(RIGHT(C36,1)=(RIGHT(13-MOD(MID(C36,1,1)*2+MID(C36,2,1)*3+MID(C36,3,1)*4+MID(C36,4,1)*5+MID(C36,5,1)*6+MID(C36,6,1)*7+MID(C36,8,1)*8+MID(C36,9,1)*9+MID(C36,10,1)*2+MID(C36,11,1)*3+MID(C36,12,1)*4+MID(C36,13,1)*5,11),1)),"O","X"),IF(RIGHT(C36,1)=(RIGHT(11-MOD(MID(C36,1,1)*2+MID(C36,2,1)*3+MID(C36,3,1)*4+MID(C36,4,1)*5+MID(C36,5,1)*6+MID(C36,6,1)*7+MID(C36,8,1)*8+MID(C36,9,1)*9+MID(C36,10,1)*2+MID(C36,11,1)*3+MID(C36,12,1)*4+MID(C36,13,1)*5,11),1)),"O","X")),"") -> O | S36: 계측공
A37: 이정주 | B37: 조경공 | C37: 461024-2143612 | D37: 인천 남구 인하로 198번지 13 주안동 | E37: 010-2375-9442 | F37: 0011 | G37: 농협중앙회 | H37: 170671-52-086183 | I37: 이정주 | L37: =IFERROR(IF(OR(MID(C37,8,1)<"3",AND(MID(C37,8,1)>="5",MID(C37,8,1)<="6")),INT(TEXT(TODAY(),"yyyy.mmdd")-TEXT(TEXT(LEFT(C37,6),"1900-00-00"),"yyyy.mmdd")),INT(TEXT(TODAY(),"yyyy.mmdd")-TEXT(TEXT(LEFT(C37,6),"2000-00-00"),"yyyy.mmdd"))),"") -> 79 | N37: =IFERROR(IF(MID(C37,8,1)>="5",IF(RIGHT(C37,1)=(RIGHT(13-MOD(MID(C37,1,1)*2+MID(C37,2,1)*3+MID(C37,3,1)*4+MID(C37,4,1)*5+MID(C37,5,1)*6+MID(C37,6,1)*7+MID(C37,8,1)*8+MID(C37,9,1)*9+MID(C37,10,1)*2+MID(C37,11,1)*3+MID(C37,12,1)*4+MID(C37,13,1)*5,11),1)),"O","X"),IF(RIGHT(C37,1)=(RIGHT(11-MOD(MID(C37,1,1)*2+MID(C37,2,1)*3+MID(C37,3,1)*4+MID(C37,4,1)*5+MID(C37,5,1)*6+MID(C37,6,1)*7+MID(C37,8,1)*8+MID(C37,9,1)*9+MID(C37,10,1)*2+MID(C37,11,1)*3+MID(C37,12,1)*4+MID(C37,13,1)*5,11),1)),"O","X")),"") -> O | S37: 고압케이블전공
A38: 이현자 | B38: 조경공 | C38: 550519-2543711 | D38: 인천 남동구 간석동 1157-1 우신아파트 다동 301호 | E38: 010-3105-5988 | F38: 0004 | G38: 국민은행 | H38: 224601-04-129755 | I38: 이현자(외향산) | L38: =IFERROR(IF(OR(MID(C38,8,1)<"3",AND(MID(C38,8,1)>="5",MID(C38,8,1)<="6")),INT(TEXT(TODAY(),"yyyy.mmdd")-TEXT(TEXT(LEFT(C38,6),"1900-00-00"),"yyyy.mmdd")),INT(TEXT(TODAY(),"yyyy.mmdd")-TEXT(TEXT(LEFT(C38,6),"2000-00-00"),"yyyy.mmdd"))),"") -> 71 | N38: =IFERROR(IF(MID(C38,8,1)>="5",IF(RIGHT(C38,1)=(RIGHT(13-MOD(MID(C38,1,1)*2+MID(C38,2,1)*3+MID(C38,3,1)*4+MID(C38,4,1)*5+MID(C38,5,1)*6+MID(C38,6,1)*7+MID(C38,8,1)*8+MID(C38,9,1)*9+MID(C38,10,1)*2+MID(C38,11,1)*3+MID(C38,12,1)*4+MID(C38,13,1)*5,11),1)),"O","X"),IF(RIGHT(C38,1)=(RIGHT(11-MOD(MID(C38,1,1)*2+MID(C38,2,1)*3+MID(C38,3,1)*4+MID(C38,4,1)*5+MID(C38,5,1)*6+MID(C38,6,1)*7+MID(C38,8,1)*8+MID(C38,9,1)*9+MID(C38,10,1)*2+MID(C38,11,1)*3+MID(C38,12,1)*4+MID(C38,13,1)*5,11),1)),"O","X")),"") -> O | S38: 골재쇄석공
... A55: 진순금 | B55: 조경공 | C55: 540913-2394217 | D55: 인천 남동구 논현동 635-1 논현휴먼시아 하늘마을 316동 704호 | E55: 010-5361-8975 | F55: 0011 | G55: 농협중앙회 | H55: 351-0314-5156-53 | I55: 진순금 | L55: =IFERROR(IF(OR(MID(C55,8,1)<"3",AND(MID(C55,8,1)>="5",MID(C55,8,1)<="6")),INT(TEXT(TODAY(),"yyyy.mmdd")-TEXT(TEXT(LEFT(C55,6),"1900-00-00"),"yyyy.mmdd")),INT(TEXT(TODAY(),"yyyy.mmdd")-TEXT(TEXT(LEFT(C55,6),"2000-00-00"),"yyyy.mmdd"))),"") -> 71 | N55: =IFERROR(IF(MID(C55,8,1)>="5",IF(RIGHT(C55,1)=(RIGHT(13-MOD(MID(C55,1,1)*2+MID(C55,2,1)*3+MID(C55,3,1)*4+MID(C55,4,1)*5+MID(C55,5,1)*6+MID(C55,6,1)*7+MID(C55,8,1)*8+MID(C55,9,1)*9+MID(C55,10,1)*2+MID(C55,11,1)*3+MID(C55,12,1)*4+MID(C55,13,1)*5,11),1)),"O","X"),IF(RIGHT(C55,1)=(RIGHT(11-MOD(MID(C55,1,1)*2+MID(C55,2,1)*3+MID(C55,3,1)*4+MID(C55,4,1)*5+MID(C55,5,1)*6+MID(C55,6,1)*7+MID(C55,8,1)*8+MID(C55,9,1)*9+MID(C55,10,1)*2+MID(C55,11,1)*3+MID(C55,12,1)*4+MID(C55,13,1)*5,11),1)),"O","X")),"") -> O | S55: 기관선원
L56: =IFERROR(IF(OR(MID(C56,8,1)<"3",AND(MID(C56,8,1)>="5",MID(C56,8,1)<="6")),INT(TEXT(TODAY(),"yyyy.mmdd")-TEXT(TEXT(LEFT(C56,6),"1900-00-00"),"yyyy.mmdd")),INT(TEXT(TODAY(),"yyyy.mmdd")-TEXT(TEXT(LEFT(C56,6),"2000-00-00"),"yyyy.mmdd"))),"") | N56: =IFERROR(IF(MID(C56,8,1)>="5",IF(RIGHT(C56,1)=(RIGHT(13-MOD(MID(C56,1,1)*2+MID(C56,2,1)*3+MID(C56,3,1)*4+MID(C56,4,1)*5+MID(C56,5,1)*6+MID(C56,6,1)*7+MID(C56,8,1)*8+MID(C56,9,1)*9+MID(C56,10,1)*2+MID(C56,11,1)*3+MID(C56,12,1)*4+MID(C56,13,1)*5,11),1)),"O","X"),IF(RIGHT(C56,1)=(RIGHT(11-MOD(MID(C56,1,1)*2+MID(C56,2,1)*3+MID(C56,3,1)*4+MID(C56,4,1)*5+MID(C56,5,1)*6+MID(C56,6,1)*7+MID(C56,8,1)*8+MID(C56,9,1)*9+MID(C56,10,1)*2+MID(C56,11,1)*3+MID(C56,12,1)*4+MID(C56,13,1)*5,11),1)),"O","X")),"") | S56: 기관장
A57: 이병호 | B57: 조경공 | C57: 590724-1321219 | D57: 경기도 용인시 처인구 김량장 159-22 | E57: 010-3797-7304 | F57: 0011 | G57: 농협중앙회 | H57: 235020-52-083554 | I57: 이병호 | L57: =IFERROR(IF(OR(MID(C57,8,1)<"3",AND(MID(C57,8,1)>="5",MID(C57,8,1)<="6")),INT(TEXT(TODAY(),"yyyy.mmdd")-TEXT(TEXT(LEFT(C57,6),"1900-00-00"),"yyyy.mmdd")),INT(TEXT(TODAY(),"yyyy.mmdd")-TEXT(TEXT(LEFT(C57,6),"2000-00-00"),"yyyy.mmdd"))),"") -> 66 | N57: =IFERROR(IF(MID(C57,8,1)>="5",IF(RIGHT(C57,1)=(RIGHT(13-MOD(MID(C57,1,1)*2+MID(C57,2,1)*3+MID(C57,3,1)*4+MID(C57,4,1)*5+MID(C57,5,1)*6+MID(C57,6,1)*7+MID(C57,8,1)*8+MID(C57,9,1)*9+MID(C57,10,1)*2+MID(C57,11,1)*3+MID(C57,12,1)*4+MID(C57,13,1)*5,11),1)),"O","X"),IF(RIGHT(C57,1)=(RIGHT(11-MOD(MID(C57,1,1)*2+MID(C57,2,1)*3+MID(C57,3,1)*4+MID(C57,4,1)*5+MID(C57,5,1)*6+MID(C57,6,1)*7+MID(C57,8,1)*8+MID(C57,9,1)*9+MID(C57,10,1)*2+MID(C57,11,1)*3+MID(C57,12,1)*4+MID(C57,13,1)*5,11),1)),"O","X")),"") -> O | S57: 기술보조
A58: 이병묵 | B58: 조경공 | C58: 630504-1321213 | D58: 경기도 수원시 장안구 장안로 211 | E58: 010-9050-5294 | F58: 0011 | G58: 농협중앙회 | H58: 356-1148-2295-63 | I58: 이병묵 | L58: =IFERROR(IF(OR(MID(C58,8,1)<"3",AND(MID(C58,8,1)>="5",MID(C58,8,1)<="6")),INT(TEXT(TODAY(),"yyyy.mmdd")-TEXT(TEXT(LEFT(C58,6),"1900-00-00"),"yyyy.mmdd")),INT(TEXT(TODAY(),"yyyy.mmdd")-TEXT(TEXT(LEFT(C58,6),"2000-00-00"),"yyyy.mmdd"))),"") -> 63 | N58: =IFERROR(IF(MID(C58,8,1)>="5",IF(RIGHT(C58,1)=(RIGHT(13-MOD(MID(C58,1,1)*2+MID(C58,2,1)*3+MID(C58,3,1)*4+MID(C58,4,1)*5+MID(C58,5,1)*6+MID(C58,6,1)*7+MID(C58,8,1)*8+MID(C58,9,1)*9+MID(C58,10,1)*2+MID(C58,11,1)*3+MID(C58,12,1)*4+MID(C58,13,1)*5,11),1)),"O","X"),IF(RIGHT(C58,1)=(RIGHT(11-MOD(MID(C58,1,1)*2+MID(C58,2,1)*3+MID(C58,3,1)*4+MID(C58,4,1)*5+MID(C58,5,1)*6+MID(C58,6,1)*7+MID(C58,8,1)*8+MID(C58,9,1)*9+MID(C58,10,1)*2+MID(C58,11,1)*3+MID(C58,12,1)*4+MID(C58,13,1)*5,11),1)),"O","X")),"") -> O | S58: 기와공
A59: 이춘식 | B59: 조경공 | C59: 610213-1229113 | D59: 경기도 용인시 처인구 유방동 93 | E59: 010-9014-4004 | F59: 0011 | G59: 농협중앙회 | H59: 235010-56-164581 | I59: 이춘식 | L59: =IFERROR(IF(OR(MID(C59,8,1)<"3",AND(MID(C59,8,1)>="5",MID(C59,8,1)<="6")),INT(TEXT(TODAY(),"yyyy.mmdd")-TEXT(TEXT(LEFT(C59,6),"1900-00-00"),"yyyy.mmdd")),INT(TEXT(TODAY(),"yyyy.mmdd")-TEXT(TEXT(LEFT(C59,6),"2000-00-00"),"yyyy.mmdd"))),"") -> 65 | N59: =IFERROR(IF(MID(C59,8,1)>="5",IF(RIGHT(C59,1)=(RIGHT(13-MOD(MID(C59,1,1)*2+MID(C59,2,1)*3+MID(C59,3,1)*4+MID(C59,4,1)*5+MID(C59,5,1)*6+MID(C59,6,1)*7+MID(C59,8,1)*8+MID(C59,9,1)*9+MID(C59,10,1)*2+MID(C59,11,1)*3+MID(C59,12,1)*4+MID(C59,13,1)*5,11),1)),"O","X"),IF(RIGHT(C59,1)=(RIGHT(11-MOD(MID(C59,1,1)*2+MID(C59,2,1)*3+MID(C59,3,1)*4+MID(C59,4,1)*5+MID(C59,5,1)*6+MID(C59,6,1)*7+MID(C59,8,1)*8+MID(C59,9,1)*9+MID(C59,10,1)*2+MID(C59,11,1)*3+MID(C59,12,1)*4+MID(C59,13,1)*5,11),1)),"O","X")),"") -> O | S59: 기중기선원
A60: CUI SONGZHE | B60: 조경공 | C60: 630418-5101795 | D60: 경기도 용인시 처인구 금령로 93번길 12-6 | E60: 010-5755-8878 | F60: 0011 | G60: 농협중앙회 | H60: 302-0699-9766-61 | I60: CUI SONGZHE | L60: =IFERROR(IF(OR(MID(C60,8,1)<"3",AND(MID(C60,8,1)>="5",MID(C60,8,1)<="6")),INT(TEXT(TODAY(),"yyyy.mmdd")-TEXT(TEXT(LEFT(C60,6),"1900-00-00"),"yyyy.mmdd")),INT(TEXT(TODAY(),"yyyy.mmdd")-TEXT(TEXT(LEFT(C60,6),"2000-00-00"),"yyyy.mmdd"))),"") -> 63 | N60: =IFERROR(IF(MID(C60,8,1)>="5",IF(RIGHT(C60,1)=(RIGHT(13-MOD(MID(C60,1,1)*2+MID(C60,2,1)*3+MID(C60,3,1)*4+MID(C60,4,1)*5+MID(C60,5,1)*6+MID(C60,6,1)*7+MID(C60,8,1)*8+MID(C60,9,1)*9+MID(C60,10,1)*2+MID(C60,11,1)*3+MID(C60,12,1)*4+MID(C60,13,1)*5,11),1)),"O","X"),IF(RIGHT(C60,1)=(RIGHT(11-MOD(MID(C60,1,1)*2+MID(C60,2,1)*3+MID(C60,3,1)*4+MID(C60,4,1)*5+MID(C60,5,1)*6+MID(C60,6,1)*7+MID(C60,8,1)*8+MID(C60,9,1)*9+MID(C60,10,1)*2+MID(C60,11,1)*3+MID(C60,12,1)*4+MID(C60,13,1)*5,11),1)),"O","X")),"") -> O | S60: 내선전공
A61: LI GUANGSHAN | B61: 조경공 | C61: 741015-5761090 | D61: 경기도 용인시 처인구 학산로 69 | E61: 010-8689-6778 | F61: 0011 | G61: 농협중앙회 | H61: 351-0394-9779-43 | I61: LI GUANGSHAN | L61: =IFERROR(IF(OR(MID(C61,8,1)<"3",AND(MID(C61,8,1)>="5",MID(C61,8,1)<="6")),INT(TEXT(TODAY(),"yyyy.mmdd")-TEXT(TEXT(LEFT(C61,6),"1900-00-00"),"yyyy.mmdd")),INT(TEXT(TODAY(),"yyyy.mmdd")-TEXT(TEXT(LEFT(C61,6),"2000-00-00"),"yyyy.mmdd"))),"") -> 51 | N61: =IFERROR(IF(MID(C61,8,1)>="5",IF(RIGHT(C61,1)=(RIGHT(13-MOD(MID(C61,1,1)*2+MID(C61,2,1)*3+MID(C61,3,1)*4+MID(C61,4,1)*5+MID(C61,5,1)*6+MID(C61,6,1)*7+MID(C61,8,1)*8+MID(C61,9,1)*9+MID(C61,10,1)*2+MID(C61,11,1)*3+MID(C61,12,1)*4+MID(C61,13,1)*5,11),1)),"O","X"),IF(RIGHT(C61,1)=(RIGHT(11-MOD(MID(C61,1,1)*2+MID(C61,2,1)*3+MID(C61,3,1)*4+MID(C61,4,1)*5+MID(C61,5,1)*6+MID(C61,6,1)*7+MID(C61,8,1)*8+MID(C61,9,1)*9+MID(C61,10,1)*2+MID(C61,11,1)*3+MID(C61,12,1)*4+MID(C61,13,1)*5,11),1)),"O","X")),"") -> O | S61: 내장공
A62: QUAN GUANGSHI | B62: 조경공 | C62: 550312-5300299 | D62: 경기도 용인시 처인구 금학로 383번길 | E62: 010-3115-9188 | F62: 0045 | G62: 새마을금고 | H62: 9003-2802-2730-1 | I62: QUAN GUANGSHI | L62: =IFERROR(IF(OR(MID(C62,8,1)<"3",AND(MID(C62,8,1)>="5",MID(C62,8,1)<="6")),INT(TEXT(TODAY(),"yyyy.mmdd")-TEXT(TEXT(LEFT(C62,6),"1900-00-00"),"yyyy.mmdd")),INT(TEXT(TODAY(),"yyyy.mmdd")-TEXT(TEXT(LEFT(C62,6),"2000-00-00"),"yyyy.mmdd"))),"") -> 71 | N62: =IFERROR(IF(MID(C62,8,1)>="5",IF(RIGHT(C62,1)=(RIGHT(13-MOD(MID(C62,1,1)*2+MID(C62,2,1)*3+MID(C62,3,1)*4+MID(C62,4,1)*5+MID(C62,5,1)*6+MID(C62,6,1)*7+MID(C62,8,1)*8+MID(C62,9,1)*9+MID(C62,10,1)*2+MID(C62,11,1)*3+MID(C62,12,1)*4+MID(C62,13,1)*5,11),1)),"O","X"),IF(RIGHT(C62,1)=(RIGHT(11-MOD(MID(C62,1,1)*2+MID(C62,2,1)*3+MID(C62,3,1)*4+MID(C62,4,1)*5+MID(C62,5,1)*6+MID(C62,6,1)*7+MID(C62,8,1)*8+MID(C62,9,1)*9+MID(C62,10,1)*2+MID(C62,11,1)*3+MID(C62,12,1)*4+MID(C62,13,1)*5,11),1)),"O","X")),"") -> O | S62: 내장목공
A63: 이성회 | B63: 조경공 | C63: 730117-1821011 | D63: 경상남도 창원시 마산합포구 장장군로 3 | E63: 010-5495-9645 | F63: 0081 | G63: KEB하나은행 | H63: 346-910740-02107 | I63: 이성회 | L63: =IFERROR(IF(OR(MID(C63,8,1)<"3",AND(MID(C63,8,1)>="5",MID(C63,8,1)<="6")),INT(TEXT(TODAY(),"yyyy.mmdd")-TEXT(TEXT(LEFT(C63,6),"1900-00-00"),"yyyy.mmdd")),INT(TEXT(TODAY(),"yyyy.mmdd")-TEXT(TEXT(LEFT(C63,6),"2000-00-00"),"yyyy.mmdd"))),"") -> 53 | N63: =IFERROR(IF(MID(C63,8,1)>="5",IF(RIGHT(C63,1)=(RIGHT(13-MOD(MID(C63,1,1)*2+MID(C63,2,1)*3+MID(C63,3,1)*4+MID(C63,4,1)*5+MID(C63,5,1)*6+MID(C63,6,1)*7+MID(C63,8,1)*8+MID(C63,9,1)*9+MID(C63,10,1)*2+MID(C63,11,1)*3+MID(C63,12,1)*4+MID(C63,13,1)*5,11),1)),"O","X"),IF(RIGHT(C63,1)=(RIGHT(11-MOD(MID(C63,1,1)*2+MID(C63,2,1)*3+MID(C63,3,1)*4+MID(C63,4,1)*5+MID(C63,5,1)*6+MID(C63,6,1)*7+MID(C63,8,1)*8+MID(C63,9,1)*9+MID(C63,10,1)*2+MID(C63,11,1)*3+MID(C63,12,1)*4+MID(C63,13,1)*5,11),1)),"O","X")),"") -> O | S63: 내화벽돌공
A64: 김우용 | B64: 조경공 | C64: 550713-1249716 | D64: 경기도 용인시 처인구 포곡읍 포곡로 108번길 | E64: 010-7215-4530 | F64: 0045 | G64: 새마을금고 | H64: 9003-2360-9222-2 | I64: 김우용 | L64: =IFERROR(IF(OR(MID(C64,8,1)<"3",AND(MID(C64,8,1)>="5",MID(C64,8,1)<="6")),INT(TEXT(TODAY(),"yyyy.mmdd")-TEXT(TEXT(LEFT(C64,6),"1900-00-00"),"yyyy.mmdd")),INT(TEXT(TODAY(),"yyyy.mmdd")-TEXT(TEXT(LEFT(C64,6),"2000-00-00"),"yyyy.mmdd"))),"") -> 70 | N64: =IFERROR(IF(MID(C64,8,1)>="5",IF(RIGHT(C64,1)=(RIGHT(13-MOD(MID(C64,1,1)*2+MID(C64,2,1)*3+MID(C64,3,1)*4+MID(C64,4,1)*5+MID(C64,5,1)*6+MID(C64,6,1)*7+MID(C64,8,1)*8+MID(C64,9,1)*9+MID(C64,10,1)*2+MID(C64,11,1)*3+MID(C64,12,1)*4+MID(C64,13,1)*5,11),1)),"O","X"),IF(RIGHT(C64,1)=(RIGHT(11-MOD(MID(C64,1,1)*2+MID(C64,2,1)*3+MID(C64,3,1)*4+MID(C64,4,1)*5+MID(C64,5,1)*6+MID(C64,6,1)*7+MID(C64,8,1)*8+MID(C64,9,1)*9+MID(C64,10,1)*2+MID(C64,11,1)*3+MID(C64,12,1)*4+MID(C64,13,1)*5,11),1)),"O","X")),"") -> O | S64: 내화벽돌공
A65: 조왕행 | B65: 조경공 | C65: 470518-1329213 | D65: 경기도 용인시 처인구 금령로 106번길 | E65: 010-8780-8916 | F65: 0011 | G65: 농협중앙회 | H65: 356-1489-0156-23 | I65: 조왕행 | L65: =IFERROR(IF(OR(MID(C65,8,1)<"3",AND(MID(C65,8,1)>="5",MID(C65,8,1)<="6")),INT(TEXT(TODAY(),"yyyy.mmdd")-TEXT(TEXT(LEFT(C65,6),"1900-00-00"),"yyyy.mmdd")),INT(TEXT(TODAY(),"yyyy.mmdd")-TEXT(TEXT(LEFT(C65,6),"2000-00-00"),"yyyy.mmdd"))),"") -> 79 | N65: =IFERROR(IF(MID(C65,8,1)>="5",IF(RIGHT(C65,1)=(RIGHT(13-MOD(MID(C65,1,1)*2+MID(C65,2,1)*3+MID(C65,3,1)*4+MID(C65,4,1)*5+MID(C65,5,1)*6+MID(C65,6,1)*7+MID(C65,8,1)*8+MID(C65,9,1)*9+MID(C65,10,1)*2+MID(C65,11,1)*3+MID(C65,12,1)*4+MID(C65,13,1)*5,11),1)),"O","X"),IF(RIGHT(C65,1)=(RIGHT(11-MOD(MID(C65,1,1)*2+MID(C65,2,1)*3+MID(C65,3,1)*4+MID(C65,4,1)*5+MID(C65,5,1)*6+MID(C65,6,1)*7+MID(C65,8,1)*8+MID(C65,9,1)*9+MID(C65,10,1)*2+MID(C65,11,1)*3+MID(C65,12,1)*4+MID(C65,13,1)*5,11),1)),"O","X")),"") -> O | S65: 냉동수리공
A66: 이미정 | B66: 신호수 | C66: 700520-2909022 | D66: 경기도 용인시 기흥구 동백8로 131번길 20 | E66: 010-5527-0633 | F66: 0088 | G66: 신한은행 | H66: 110-240-521583 | I66: 이미정 | L66: =IFERROR(IF(OR(MID(C66,8,1)<"3",AND(MID(C66,8,1)>="5",MID(C66,8,1)<="6")),INT(TEXT(TODAY(),"yyyy.mmdd")-TEXT(TEXT(LEFT(C66,6),"1900-00-00"),"yyyy.mmdd")),INT(TEXT(TODAY(),"yyyy.mmdd")-TEXT(TEXT(LEFT(C66,6),"2000-00-00"),"yyyy.mmdd"))),"") -> 56 | N66: =IFERROR(IF(MID(C66,8,1)>="5",IF(RIGHT(C66,1)=(RIGHT(13-MOD(MID(C66,1,1)*2+MID(C66,2,1)*3+MID(C66,3,1)*4+MID(C66,4,1)*5+MID(C66,5,1)*6+MID(C66,6,1)*7+MID(C66,8,1)*8+MID(C66,9,1)*9+MID(C66,10,1)*2+MID(C66,11,1)*3+MID(C66,12,1)*4+MID(C66,13,1)*5,11),1)),"O","X"),IF(RIGHT(C66,1)=(RIGHT(11-MOD(MID(C66,1,1)*2+MID(C66,2,1)*3+MID(C66,3,1)*4+MID(C66,4,1)*5+MID(C66,5,1)*6+MID(C66,6,1)*7+MID(C66,8,1)*8+MID(C66,9,1)*9+MID(C66,10,1)*2+MID(C66,11,1)*3+MID(C66,12,1)*4+MID(C66,13,1)*5,11),1)),"O","X")),"") -> O | S66: 노즐공
A67: 김명선 | B67: 조경공 | C67: 570219-1526525 | D67: 서울시 영등포구 신길 2176 | E67: 010-5217-1834 | F67: 0088 | G67: 신한은행 | H67: 110-059-759360 | I67: 김명선 | L67: =IFERROR(IF(OR(MID(C67,8,1)<"3",AND(MID(C67,8,1)>="5",MID(C67,8,1)<="6")),INT(TEXT(TODAY(),"yyyy.mmdd")-TEXT(TEXT(LEFT(C67,6),"1900-00-00"),"yyyy.mmdd")),INT(TEXT(TODAY(),"yyyy.mmdd")-TEXT(TEXT(LEFT(C67,6),"2000-00-00"),"yyyy.mmdd"))),"") -> 69 | N67: =IFERROR(IF(MID(C67,8,1)>="5",IF(RIGHT(C67,1)=(RIGHT(13-MOD(MID(C67,1,1)*2+MID(C67,2,1)*3+MID(C67,3,1)*4+MID(C67,4,1)*5+MID(C67,5,1)*6+MID(C67,6,1)*7+MID(C67,8,1)*8+MID(C67,9,1)*9+MID(C67,10,1)*2+MID(C67,11,1)*3+MID(C67,12,1)*4+MID(C67,13,1)*5,11),1)),"O","X"),IF(RIGHT(C67,1)=(RIGHT(11-MOD(MID(C67,1,1)*2+MID(C67,2,1)*3+MID(C67,3,1)*4+MID(C67,4,1)*5+MID(C67,5,1)*6+MID(C67,6,1)*7+MID(C67,8,1)*8+MID(C67,9,1)*9+MID(C67,10,1)*2+MID(C67,11,1)*3+MID(C67,12,1)*4+MID(C67,13,1)*5,11),1)),"O","X")),"") -> O | S67: 대리석공
...

Sheet 위임장
A1: 위 임 장
A3: 수 임 인
A4: 성 명 | I4: 주 민 번 호 | L4: =IF(ISERROR(VLOOKUP(D4,주소록!$A$3:$K$523,5,0)),"",VLOOKUP(D4,주소록!$A$3:$K$523,5,0))
A5: 주 소 | D5: =IF(ISERROR(VLOOKUP(D4,주소록!$A$3:$K$523,6,0)),"",VLOOKUP(D4,주소록!$A$3:$K$523,6,0))
A6: 연 락 처 | D6: =IF(ISERROR(VLOOKUP(D4,주소록!$A$3:$K$523,7,0)),"",VLOOKUP(D4,주소록!$A$3:$K$523,7,0)) | I6: 계 좌 번 호 | L6: =IF(ISERROR(VLOOKUP(D4,주소록!$A$3:$K$523,9,0)),"",VLOOKUP(D4,주소록!$A$3:$K$523,9,0)) | N6: =IF(ISERROR(VLOOKUP(D4,주소록!$A$3:$K$523,10,0)),"",VLOOKUP(D4,주소록!$A$3:$K$523,10,0))
A8: =" 상기인을 본인의 대리인으로 정하여 ["&V8&"] 「"&V9&"」 하수급인 「"&V10&"」의" -> 상기인을 본인의 대리인으로 정하여 [고색2지구 공원 및 공공공지 조성공사] 「부강종합건설㈜」 하수급인 「(주)하도급 회사」의 | U8: 공사명 | V8: =요율!G6 -> 고색2지구 공원 및 공공공지 조성공사
A9: =" 근로자로서 「"&V10&"」이(가) 지급하여야할 ["&V11&" "&W11&"] 노무비를 원수급자인 「"&V9&"」와(과) 하수급인" -> 근로자로서 「(주)하도급 회사」이(가) 지급하여야할 [2023년 1월] 노무비를 원수급자인 「부강종합건설㈜」와(과) 하수급인 | U9: 원도급 회사 | V9: 부강종합건설㈜
A10: =" 「"&V10&"」로부터 수령할 노무비와 기타 모든 사항을 수임인에게 일체의 권한을 위임하고 위임후에 따른" -> 「(주)하도급 회사」로부터 수령할 노무비와 기타 모든 사항을 수임인에게 일체의 권한을 위임하고 위임후에 따른 | U10: 하도급 회사 | V10: (주)하도급 회사
A11: 분실,휭령,공문서 위조등을 포함한 모든 책임을 본인이 감수하며 민,형사상 처벌을 감수할것이며 어떠한 법률적 | U11: 청구 월 | V11: 2023년 | W11: 1월
A12: 책임도 이의를 제기치 않을 것을 서명 날인 합니다
A14: 성 명 | C14: 주 민 번 호 | G14: 주 소 | M14: 청구금액 | P14: 서 명
M15: =IFERROR(VLOOKUP(A15,INDIRECT(#REF!&"!$B$7:$BA$93"),33,FALSE),"")
M16: =IFERROR(VLOOKUP(A16,INDIRECT(#REF!&"!$B$7:$BA$93"),33,FALSE),"")
M17: =IFERROR(VLOOKUP(A17,INDIRECT(#REF!&"!$B$7:$BA$93"),33,FALSE),"")
M18: =IFERROR(VLOOKUP(A18,INDIRECT(#REF!&"!$B$7:$BA$93"),33,FALSE),"")
M19: =IFERROR(VLOOKUP(A19,INDIRECT(#REF!&"!$B$7:$BA$93"),33,FALSE),"")
C20: =IF(ISERROR(VLOOKUP(A20,주소록!$A$3:$K$523,5,0)),"",VLOOKUP(A20,주소록!$A$3:$K$523,5,0)) | G20: =IF(ISERROR(VLOOKUP(A20,주소록!$A$3:$K$523,6,0)),"",VLOOKUP(A20,주소록!$A$3:$K$523,4,0)) | M20: =IFERROR(VLOOKUP(A20,INDIRECT(#REF!&"!$B$7:$BA$93"),33,FALSE),"")
C21: =IF(ISERROR(VLOOKUP(A21,주소록!$A$3:$K$523,5,0)),"",VLOOKUP(A21,주소록!$A$3:$K$523,5,0)) | G21: =IF(ISERROR(VLOOKUP(A21,주소록!$A$3:$K$523,6,0)),"",VLOOKUP(A21,주소록!$A$3:$K$523,4,0)) | M21: =IFERROR(VLOOKUP(A21,INDIRECT(#REF!&"!$B$7:$BA$93"),33,FALSE),"")
C22: =IF(ISERROR(VLOOKUP(A22,주소록!$A$3:$K$523,5,0)),"",VLOOKUP(A22,주소록!$A$3:$K$523,5,0)) | G22: =IF(ISERROR(VLOOKUP(A22,주소록!$A$3:$K$523,6,0)),"",VLOOKUP(A22,주소록!$A$3:$K$523,4,0)) | M22: =IFERROR(VLOOKUP(A22,INDIRECT(#REF!&"!$B$7:$BA$93"),33,FALSE),"")
C23: =IF(ISERROR(VLOOKUP(A23,주소록!$A$3:$K$523,5,0)),"",VLOOKUP(A23,주소록!$A$3:$K$523,5,0)) | G23: =IF(ISERROR(VLOOKUP(A23,주소록!$A$3:$K$523,6,0)),"",VLOOKUP(A23,주소록!$A$3:$K$523,4,0)) | M23: =IFERROR(VLOOKUP(A23,INDIRECT(#REF!&"!$B$7:$BA$93"),33,FALSE),"")
C24: =IF(ISERROR(VLOOKUP(A24,주소록!$A$3:$K$523,5,0)),"",VLOOKUP(A24,주소록!$A$3:$K$523,5,0)) | G24: =IF(ISERROR(VLOOKUP(A24,주소록!$A$3:$K$523,6,0)),"",VLOOKUP(A24,주소록!$A$3:$K$523,4,0)) | M24: =IFERROR(VLOOKUP(A24,INDIRECT(#REF!&"!$B$7:$BA$93"),33,FALSE),"")
C25: =IF(ISERROR(VLOOKUP(A25,주소록!$A$3:$K$523,5,0)),"",VLOOKUP(A25,주소록!$A$3:$K$523,5,0)) | G25: =IF(ISERROR(VLOOKUP(A25,주소록!$A$3:$K$523,6,0)),"",VLOOKUP(A25,주소록!$A$3:$K$523,4,0)) | M25: =IFERROR(VLOOKUP(A25,INDIRECT(#REF!&"!$B$7:$BA$93"),33,FALSE),"")
C26: =IF(ISERROR(VLOOKUP(A26,주소록!$A$3:$K$523,5,0)),"",VLOOKUP(A26,주소록!$A$3:$K$523,5,0)) | G26: =IF(ISERROR(VLOOKUP(A26,주소록!$A$3:$K$523,6,0)),"",VLOOKUP(A26,주소록!$A$3:$K$523,4,0)) | M26: =IFERROR(VLOOKUP(A26,INDIRECT(#REF!&"!$B$7:$BA$93"),33,FALSE),"")
C27: =IF(ISERROR(VLOOKUP(A27,주소록!$A$3:$K$523,5,0)),"",VLOOKUP(A27,주소록!$A$3:$K$523,5,0)) | G27: =IF(ISERROR(VLOOKUP(A27,주소록!$A$3:$K$523,6,0)),"",VLOOKUP(A27,주소록!$A$3:$K$523,4,0)) | M27: =IFERROR(VLOOKUP(A27,INDIRECT(#REF!&"!$B$7:$BA$93"),33,FALSE),"")
C28: =IF(ISERROR(VLOOKUP(A28,주소록!$A$3:$K$523,5,0)),"",VLOOKUP(A28,주소록!$A$3:$K$523,5,0)) | G28: =IF(ISERROR(VLOOKUP(A28,주소록!$A$3:$K$523,6,0)),"",VLOOKUP(A28,주소록!$A$3:$K$523,4,0)) | M28: =IFERROR(VLOOKUP(A28,INDIRECT(#REF!&"!$B$7:$BA$93"),33,FALSE),"")
C29: =IF(ISERROR(VLOOKUP(A29,주소록!$A$3:$K$523,5,0)),"",VLOOKUP(A29,주소록!$A$3:$K$523,5,0)) | G29: =IF(ISERROR(VLOOKUP(A29,주소록!$A$3:$K$523,6,0)),"",VLOOKUP(A29,주소록!$A$3:$K$523,4,0)) | M29: =IFERROR(VLOOKUP(A29,INDIRECT(#REF!&"!$B$7:$BA$93"),33,FALSE),"")
C30: =IF(ISERROR(VLOOKUP(A30,주소록!$A$3:$K$523,5,0)),"",VLOOKUP(A30,주소록!$A$3:$K$523,5,0)) | G30: =IF(ISERROR(VLOOKUP(A30,주소록!$A$3:$K$523,6,0)),"",VLOOKUP(A30,주소록!$A$3:$K$523,4,0)) | M30: =IFERROR(VLOOKUP(A30,INDIRECT(#REF!&"!$B$7:$BA$93"),33,FALSE),"")
C31: =IF(ISERROR(VLOOKUP(A31,주소록!$A$3:$K$523,5,0)),"",VLOOKUP(A31,주소록!$A$3:$K$523,5,0)) | G31: =IF(ISERROR(VLOOKUP(A31,주소록!$A$3:$K$523,6,0)),"",VLOOKUP(A31,주소록!$A$3:$K$523,4,0)) | M31: =IFERROR(VLOOKUP(A31,INDIRECT(#REF!&"!$B$7:$BA$93"),33,FALSE),"")
... C34: =IF(ISERROR(VLOOKUP(A34,주소록!$A$3:$K$523,5,0)),"",VLOOKUP(A34,주소록!$A$3:$K$523,5,0)) | G34: =IF(ISERROR(VLOOKUP(A34,주소록!$A$3:$K$523,6,0)),"",VLOOKUP(A34,주소록!$A$3:$K$523,4,0)) | M34: =IFERROR(VLOOKUP(A34,INDIRECT(#REF!&"!$B$7:$BA$93"),33,FALSE),"")

Sheet 4월
A1: 일용 노무비 지급 명세서 | BA1: =Y2&"03" -> 202603
A2: 공 사 명 | C2: =요율!G6 -> 고색2지구 공원 및 공공공지 조성공사 | O2: 기 간 | Y2: 2026 | AC2: 4 | AH2: 청 구 금 액 | AK2: =AK5&" "&AK6 -> 소 득 세 지방소득세 | AN2: 건강보험 노인장기 | AQ2: 국민연금 고용보험 | AT2: 공제계 | AW2: 실 지급액 | BA2: =RIGHT(Y2,2)&"-03" -> 26-03 | BG2: 기준날짜
A3: 회 사 명 | C3: =요율!G5 -> ㈜아 산 | O3: =DATE($Y$2,$AC$2,1) -> 46113 | R3: ~ | S3: =DATE($Y$2,$AC$2+1,0) -> 46142 | AH3: =AH153 -> 33425000 | AK3: =SUM(AK7:AM152) -> 262930 | AN3: =SUM(AN7:AP152) -> 1198200 | AQ3: =SUM(AQ7:AS152) -> 574560 | AT3: =SUM(AT7:AV152) -> 2035690 | AW3: =SUM(AW7:AY152) -> 31389310 | BA3: =Y2&"03" -> 202603 | BG3: =O3 -> 46113
A5: 번 호 | B5: 성 명 | C5: 주 민 번 호 | G5: 주 소 | O5: =O3 -> 46113 | P5: =O5+1 -> 46114 | Q5: =P5+1 -> 46115 | R5: =Q5+1 -> 46116 | S5: =R5+1 -> 46117 | T5: =S5+1 -> 46118 | U5: =T5+1 -> 46119 | V5: =U5+1 -> 46120 | W5: =V5+1 -> 46121 | ... AC5: =AB5+1 -> 46127 | AE5: 출력일수 | AG5: 일급 | AH5: 지 급 총 액 | AK5: =요율!$G$3 -> 소 득 세 | AN5: 건강보험 | AQ5: 국민연금 | AT5: 공제소계 | AW5: 차감 지급액 | AZ5: 영수인 | BA5: 직 종 | BC5: 번 호 | BD5: 생년월일 | BG5: 나 이 | BJ5: 건강연금 | BM5: 1 | BN5: 2 | BO5: 3 | BP5: 4 | BQ5: 5 | BR5: 6 | BS5: 7 | BT5: 8 | BU5: 9 | BV5: 10 | BW5: 11 | BX5: 12 | BY5: 13 | BZ5: 14 | CA5: 15 | CD5: 예금주검증
C6: 연 락 처 | G6: 은 행 명 | J6: 계 좌 번 호 | O6: =O5+15 -> 46128 | P6: =O6+1 -> 46129 | Q6: =P6+1 -> 46130 | R6: =Q6+1 -> 46131 | S6: =R6+1 -> 46132 | T6: =S6+1 -> 46133 | U6: =T6+1 -> 46134 | V6: =U6+1 -> 46135 | W6: =V6+1 -> 46136 | ... AA6: =Z6+1 -> 46140 | AB6: =IFERROR(IF(DAY(DATE($Y$2,$AC$2+1,0))<COLUMNS($O$6:AB$6)+15,"",AA6+1),"") -> 46141 | AC6: =IFERROR(IF(DAY(DATE($Y$2,$AC$2+1,0))<COLUMNS($O$6:AC$6)+15,"",AB6+1),"") -> 46142 | AD6: =IFERROR(IF(DAY(DATE($Y$2,$AC$2+1,0))<COLUMNS($O$6:AD$6)+15,"",AC6+1),"") | AE6: 출력공수 | AK6: =요율!$G$4 -> 지방소득세 | AN6: 노인장기 | AQ6: 고용보험 | AT6: 기타 | BA6: 팀 명 | BD6: 성 명 | BG6: =AK5 -> 소 득 세 | BJ6: 일수 | BK6: 금액 | BL6: 확정 | BM6: 16 | BN6: 17 | BO6: 18 | BP6: 19 | BQ6: 20 | BR6: 21 | BS6: 22 | BT6: 23 | BU6: 24 | BV6: 25 | BW6: 26 | BX6: 27 | BY6: 28 | BZ6: 29 | CA6: 30 | CB6: 31
