Workbook

Sheet 표지
F6: 2025년도
D16: 국도46호선 | AC16: 호평IC교(상) | BE16: 등 | BL16: 포장 | BW16: 및 | CC16: 시설물 | CS16: 보수공사
AR33: 의정부국토관리사무소

Sheet 갑지(도급)
A2: 계 약 내 역 서
E6: 공사명 | K6: : | L6: 국도46호선 호평ic교(상) 등 포장 및 시설물 보수공사
E8: 전체계약금액 | K8: : | L8: 일금 오억칠천일백이만이천칠백원정 | AD8: ( | AE8: \ | AF8: 571022700 | AM8: )
E11: 공사개요 | K11: : | L11: 호평 ic교(상) : 아스팔트 포장 절삭 후 덧씌우기, 국도46호선 신구운교 외 5개소 : 단면보수
J14: 위 공사에 대하여 붙임과 같이 계약내역서를 제출합니다.
X16: 2026년 03 월 27 일
T18: 상호 | X18: : | Y18: 주식회사 아 산 | AI18: 대표자 | AM18: : | AN18: 진 익 주 | AS18: ( 인 )
T19: 주소 | X19: : | Y19: 경기도 남양주시 다산중앙로146번길 70-123, 2층
D20: 의정부국토관리사무소장 귀하

Sheet 원가계산서
B1: 원가계산서
B3: 비 목 | E3: 구분 | F3: 금 액 | G3: 요율 | H3: 산 출 근 거
C4: 재 | D4: 직 접 재 료 비 | E4: 1
C5: 료 | D5: 간 접 재 료 비 | E5: 2 | F5: =도급계약내역서!K182 -> 107,322,412
C6: 비 | D6: 작업설.부산물등(△) | E6: 3
D7: 소 계 | E7: A | F7: =TRUNC((F4+F5+F6),0) -> 107322412 | H7: (1 + 2 + 3 )
C8: 노 | D8: 직 접 노 무 비 | E8: 4 | F8: =도급계약내역서!I182 -> 187,495,739
B9: 순 | C9: 무 | D9: 간 접 노 무 비 | E9: 5 | F9: =TRUNC(F8*0.165,0) -> 30936796 | G9: 16.5% | H9: 4 × 0.165
C10: 비 | D10: 소 계 | E10: B | F10: =TRUNC((F8+F9),0) -> 218432535 | H10: ( 4 + 5 )
B11: 공 | D11: 산 출 경 비 | E11: 6 | F11: =도급계약내역서!M182 -> 27,944,371
D12: 산 재 보 험 료 | E12: 7 | F12: =TRUNC(F10*0.0356,0) -> 7776198 | G12: 3.56% | H12: B × 0.0356
B13: 사 | D13: 고 용 보 험 료 | E13: 8 | F13: =TRUNC(F10*0.0101,0) -> 2206168 | G13: 1.01% | H13: B × 0.0101
C14: 경 | D14: 건 강 보 험 료 | E14: 9 | F14: =TRUNC(F8*0.03595,0) -> 6740471 | G14: 3.595% | H14: 4 × 0.03595
B15: 원 | D15: 연 금 보 험 료 | E15: 10 | F15: =TRUNC(F8*0.0475,0) -> 8906047 | G15: 4.75% | H15: 4 × 0.0475
D16: 노인장기요양 보 험 료 | E16: 11 | F16: =TRUNC(F14*0.1314,0) -> 885697 | G16: 13.14% | H16: 9 × 0.1314
B17: 가 | D17: 퇴 직 공 제 부 금 비 | E17: 12 | F17: =TRUNC(F8*0.023,0) -> 4312401 | G17: 2.3% | H17: 4 × 0.023
D18: 건설기계대여금지급보증서발급액 | E18: 13 | F18: =TRUNC((F7+F8+F11)*0.004,0) -> 1291050 | G18: 0.4% | H18: (A + 4 + 6) × 0.004
D19: 산 업 안 전 보건관리비 | E19: 14 | F19: =TRUNC(((F7+F8+F33/1.1)*0.0253)+3300000,0) -> 11625999 | G19: 2.53% | H19: ((A + 4 + L/1.1) × 0.0253) + 3,300,000
D20: 환 경 보 전 비 | E20: 15 | F20: =TRUNC((F7+F8+F11)*0.009,0) -> 2904862 | G20: 0.9% | H20: (A + 4 + 6) ×0.009
D21: 공 사 이 행 보증수수료 | E21: 16
C22: 비 | D22: 하도급대금지급보증수수료 | E22: 17 | F22: =TRUNC((F7+F8+F11)*0.00081,0) -> 261437 | G22: 0.081% | H22: (A + 4 + 6) ×0.00081
D23: 기 타 경 비 | E23: 18 | F23: =TRUNC((F7+F10)*0.052,0) -> 16939257 | G23: 5.2% | H23: (A + B) × 0.052
D24: 소 계 | E24: C | F24: =TRUNC((F11+F12+F13+F14+F15+F16+F17+F18+F19+F20+F21+F22+F23),0) -> 91793958 | H24: (6:18)
D25: 순 공 사 원 가 | E25: D | F25: =TRUNC((F7+F10+F24),0) -> 417548905 | H25: (A + B + C)
D26: 일 반 관 리 비 | E26: E | F26: =TRUNC(F25*0.08,0) -> 33403912 | G26: 8% | H26: D × 0.08
D27: 이 윤 | E27: F | F27: =TRUNC((F10+F24+F26)*0.1488,0)-18214 -> 51113990 | G27: 14.88% | H27: (B + C + E) ×0.1488
D28: 안전 관리 계획서 작성 | E28: G | F28: =도급계약내역서!G203 -> 17884603 | L28: =도급계약내역서!G203 -> 17884603
D29: 폐 기 물 처 리 비 | E29: H | F29: =도급계약내역서!G207 -> 454308 | L29: =도급계약내역서!G207 -> 454308
D30: 총 원 가 | E30: I | F30: =TRUNC((F25+F26+F27+F28+F29),0) -> 520405718 | H30: (D + E + F + G + H)
D31: 부 가 가 치 세 | E31: J | F31: =IF(L52<> "0.9",TRUNC(F30*0.1,0),TRUNC(F30*0.1,0)+1) -> 52040571 | G31: 10% | H31: I × 0.1
D32: 도 급 예 정 액 | E32: K | F32: =TRUNC((F30+F31),5) -> 572446289 | H32: (I + J)
D33: 관 급 자 재 대 | E33: L | F33: =도급계약내역서!G212 -> 37700000 | L33: =도급계약내역서!G212 -> 37700000
D34: 총 공 사 비 | E34: M | F34: =TRUNC((F32+F33),0) -> 610146289 | H34: (K + L)
L52: =RIGHT(F30*0.1,3) -> 1.8

Sheet 내역서총괄표(도급)
A1: 내역서총괄표
A2: 공사명 : 국도46호선 호평ic교(상) 등 포장 및 시설물 보수공사
A3: 공종 | B3: 품 명 | C3: 규 격 | D3: 수 량 | E3: 단위 | F3: 도 급 금 액 | G3: 노무비 | H3: 재료비 | I3: 경 비 | J3: 비 고
A4: 1. | B4: 국도46호선 호평IC교(상) | F4: 181183936 | G4: 110,285,258 | H4: 64,798,890 | I4: 6,099,788
A5: 2. | B5: 국도46호선 신구운교 등 | F5: 141578586 | G5: 77,210,481 | H5: 42,523,522 | I5: 21,844,583
B6: 순 공 사 비 | F6: 322762522 | G6: 187,495,739 | H6: 107,322,412 | I6: 27,944,371
B7: 간접노무비 | D7: 1 | E7: 식 | F7: 30939448 | G7: 30939448
B8: 산재보험료 | D8: 1 | E8: 식 | F8: 7776864 | I8: 7776864
B9: 고용보험료 | D9: 1 | E9: 식 | F9: 2206356 | I9: 2206356
B10: 건강보험료 | D10: 1 | E10: 식 | F10: 7437746 | I10: 7437746
B11: 연금보험료 | D11: 1 | E11: 식 | F11: 9827342 | I11: 9827342
B12: 노인장기요양보험료 | D12: 1 | E12: 식 | F12: 977319 | I12: 977319
B13: 퇴직공제부금비 | D13: 1 | E13: 식 | F13: 4758502 | I13: 4758502
B14: 건설기계대여금지급보증서발급액 | D14: 1 | E14: 식 | F14: 1291049 | I14: 1291049
B15: 산업안전보건관리비 | D15: 1 | E15: 식 | F15: 12397587 | I15: 12397587
B16: 환경보전비 | D16: 1 | E16: 식 | F16: 2904862 | I16: 2904862
B17: 하도급대금지급보증수수료 | D17: 1 | E17: 식 | F17: 261437 | I17: 261437
B18: 기타경비 | D18: 1 | E18: 식 | F18: 16940698 | I18: 16940698
B19: 순공사원가 | D19: 1 | E19: 식 | F19: 420481732 | G19: 218435187 | H19: 107322412 | I19: 94724133
B20: 일반관리비 | D20: 1 | E20: 식 | F20: 33638537 | I20: 33638537
B21: 이윤 | D21: 1 | E21: 식 | F21: 46652366 | I21: 46652366
B22: 안전관리계획서 작성 | F22: 17884603 | I22: 17884603
B23: 폐기물처리비 | F23: 454308 | I23: 454308
B24: 총원가 | F24: 519111546 | G24: 218435187 | H24: 107322412 | I24: 193353947
B25: 부가가치세 | D25: 10 | E25: % | F25: 51911154 | I25: 51911154
B26: 도급예정액 | F26: 571022700 | G26: 218435187 | H26: 107322412 | I26: 245265101
B27: 관급자재대 | F27: 37700000 | H27: 37,700,000
B28: 총공사비 | F28: 608722700 | G28: 218435187 | H28: 145022412 | I28: 245265101

Sheet 도급계약내역서
A1: 계약내역서
A3: 공종 | B3: 품 명 | C3: 규 격 | D3: 수 량 | E3: 단위 | F3: 도 급 금 액 | H3: 노 무 비 | J3: 재 료 비 | L3: 경 비 | N3: 비 고 | O3: 투찰율 | P3: 0.90627
F4: 단 가 | G4: 금 액 | H4: 단 가 | I4: 금 액 | J4: 단 가 | K4: 금 액 | L4: 단 가 | M4: 금 액
A5: 1. | B5: 국도46호선 호평IC교(상) | F5: 0 | G5: 181183936 | I5: 110,285,258 | K5: 64,798,890 | M5: 6,099,788 | P5: 187495739
A6: 1-1 | B6: 호평 IC교 (상) | F6: 0 | G6: 181183936 | I6: 110,285,258 | K6: 64,798,890 | M6: 6,099,788
A7: 1-1-1 | B7: 아스팔트 포장 절삭 후 덧씌우기 | F7: 0 | G7: 173186989 | I7: 108,354,908 | K7: 61,266,379 | M7: 3,565,702
B8: 아스팔트 포장 절삭후 아스팔트 덧씌우기 | C8: A-Type (1회절삭,2회포장)-야간작업 | D8: 1969 | E8: ㎡ | F8: 6368 | G8: 12538592 | H8: 3674 | I8: 7234106 | J8: 1208 | K8: 2378552 | L8: 1486 | M8: 2925934 | N8: 0.90627 | Q8: 187495739
B9: 교면방수 | C9: JJ 시트식 복합 교면방수 (야간) | D9: 1969 | E9: ㎡ | F9: 80540 | G9: 158583260 | H9: 51208 | I9: 100828552 | J9: 29010 | K9: 57120690 | L9: 322 | M9: 634018 | N9: 0.90627
B10: 교면물빼기 유공관 | C10: Φ15mm,그물망형, 야간 | D10: 125 | E10: M | F10: 11301 | G10: 1412625 | H10: 2338 | I10: 292250 | J10: 8917 | K10: 1114625 | L10: 46 | M10: 5750 | N10: 0.90627
B11: 아스팔트유제 | C11: RSC-4 | D11: 4 | E11: D/M | F11: 163128 | G11: 652512 | H11: 0 | I11: 0 | J11: 163128 | K11: 652512 | L11: 0 | M11: 0 | N11: 0.90627
A12: 1-1-3 | B12: 부대공 | F12: 0 | G12: 7996947 | H12: 0 | I12: 1,930,350 | J12: 0 | K12: 3,532,511 | L12: 0 | M12: 2,534,086
B13: 차선도색(융착식,일반형)-운행도로,차량부분통제 | C13: 수동식,백색실선 | D13: 65 | E13: ㎡ | F13: 24905 | G13: 1618825 | H13: 2886 | I13: 187590 | J13: 21671 | K13: 1408615 | L13: 348 | M13: 22620 | N13: 0.90627
B14: 차선도색(융착식,일반형)-운행도로,차량부분통제 | C14: 수동식,백색파선 | D14: 5 | E14: ㎡ | F14: 29457 | G14: 147285 | H14: 5773 | I14: 28865 | J14: 22987 | K14: 114935 | L14: 697 | M14: 3485 | N14: 0.90627
B15: 차선도색(융착식,일반형)-운행도로,차량부분통제 | C15: 수동식,문자.기호 | D15: 72 | E15: ㎡ | F15: 41739 | G15: 3005208 | H15: 16039 | I15: 1154808 | J15: 23760 | K15: 1710720 | L15: 1940 | M15: 139680 | N15: 0.90627
B16: 교통안전관리비 | C16: 야간 | D16: 1 | E16: 일 | F16: 882668 | G16: 882668 | H16: 501653 | I16: 501653 | J16: 221662 | K16: 221662 | L16: 159353 | M16: 159353 | N16: 0.90627
B17: 로봇신호수 설치 및 철거 | C17: 야간 | D17: 1 | E17: 조 | F17: 134013 | G17: 134013 | H17: 57434 | I17: 57434 | J17: 76579 | K17: 76579 | L17: 0 | M17: 0 | N17: 0.90627
B18: 중기운반 | C18: 아스콘포장 | D18: 1 | E18: 식 | F18: 1996896 | G18: 1996896 | H18: 0 | I18: 0 | J18: 0 | K18: 0 | L18: 1996896 | M18: 1996896 | N18: 0.90627
B19: 품질시험비 | C19: 연성포장 | D19: 1 | E19: 식 | F19: 212052 | G19: 212052 | H19: 0 | I19: 0 | J19: 0 | K19: 0 | L19: 212052 | M19: 212052
F20: 0 | G20: 0 | H20: 0 | J20: 0 | L20: 0
A21: 2. | B21: 국도46호선 신구운교 등 | F21: 0 | G21: 141578586 | H21: 0 | I21: 77,210,481 | J21: 0 | K21: 42,523,522 | L21: 0 | M21: 21,844,583
A22: 2-1 | B22: 신구운교(춘천) | F22: 0 | G22: 6196197 | H22: 0 | I22: 2,999,433 | J22: 0 | K22: 1,482,225 | L22: 0 | M22: 1,714,539
A23: 2-1-1 | B23: 보수공 | F23: 0 | G23: 2794732 | H23: 0 | I23: 1,703,281 | J23: 0 | K23: 1,063,453 | L23: 0 | M23: 27,998
B24: 방호벽 및 중분대 | F24: 0 | G24: 805140 | H24: 0 | I24: 279,280 | J24: 0 | K24: 519,510 | L24: 0 | M24: 6,350
B25: 철근방청단면보수(SSR공법) | C25: 벽체T=50mm (야간) | D25: 2 | E25: ㎡ | F25: 402570 | G25: 805140 | H25: 139640 | I25: 279280 | J25: 259755 | K25: 519510 | L25: 3175 | M25: 6350 | N25: 0.90627
B26: 바닥판 하면 | F26: 0 | G26: 1027981 | H26: 0 | I26: 791,502 | J26: 0 | K26: 225,394 | L26: 0 | M26: 11,085
B27: 표면보수(SSR공법) | C27: 천정 (야간) | D27: 10 | E27: ㎡ | F27: 91558 | G27: 915580 | H27: 70059 | I27: 700590 | J27: 20572 | K27: 205720 | L27: 927 | M27: 9270 | N27: 0.90627
B28: 콘크리트 균열보수(야간) | C28: 주입공법 | D28: 3 | E28: m | F28: 37467 | G28: 112401 | H28: 30304 | I28: 90912 | J28: 6558 | K28: 19674 | L28: 605 | M28: 1815 | N28: 0.90627
B29: 교대 | F29: 0 | G29: 76993 | H29: 0 | I29: 57,403 | J29: 0 | K29: 18,714 | L29: 0 | M29: 876
B30: 표면보수(SSR공법) | C30: 벽체 (야간) | D30: 1 | E30: ㎡ | F30: 76993 | G30: 76993 | H30: 57403 | I30: 57403 | J30: 18714 | K30: 18714 | L30: 876 | M30: 876 | N30: 0.90627
B31: 교각 | F31: 0 | G31: 884618 | H31: 0 | I31: 575,096 | J31: 0 | K31: 299,835 | L31: 0 | M31: 9,687
B32: 표면보수(SSR공법) | C32: 벽체 (야간) | D32: 8 | E32: ㎡ | F32: 76993 | G32: 615944 | H32: 57403 | I32: 459224 | J32: 18714 | K32: 149712 | L32: 876 | M32: 7008 | N32: 0.90627
B33: 단면보수(SSR공법) | C33: 벽체T=30mm (야간) | D33: 1 | E33: ㎡ | F33: 268674 | G33: 268674 | H33: 115872 | I33: 115872 | J33: 150123 | K33: 150123 | L33: 2679 | M33: 2679 | N33: 0.90627
A34: 2-1-2 | B34: 부대공 | F34: 0 | G34: 3401465 | H34: 0 | I34: 1,296,152 | J34: 0 | K34: 418,772 | L34: 0 | M34: 1,686,541
B35: 굴절차 | C35: 22M (야간) | D35: 1 | E35: 일 | F35: 2380766 | G35: 2380766 | H35: 734763 | I35: 734763 | J35: 119772 | K35: 119772 | L35: 1526231 | M35: 1526231 | N35: 0.90627
B36: 교통안전관리비 | C36: 야간 | D36: 1 | E36: 일 | F36: 882668 | G36: 882668 | H36: 501653 | I36: 501653 | J36: 221662 | K36: 221662 | L36: 159353 | M36: 159353 | N36: 0.90627
B37: 로봇신호수 설치 및 철거 | C37: 야간 | D37: 1 | E37: 조 | F37: 134013 | G37: 134013 | H37: 57434 | I37: 57434 | J37: 76579 | K37: 76579 | L37: 0 | M37: 0 | N37: 0.90627
B38: 폐기물상차 | C38: 백호0.7㎥ | D38: 1 | E38: ㎥ | F38: 4018 | G38: 4018 | H38: 2302 | I38: 2302 | J38: 759 | K38: 759 | L38: 957 | M38: 957 | N38: 0.90627
F39: 0 | G39: 0 | H39: 0 | J39: 0 | L39: 0
A40: 2-2 | B40: 조종교 | F40: 0 | G40: 22033531 | H40: 0 | I40: 13,034,608 | J40: 0 | K40: 5,467,202 | L40: 0 | M40: 3,531,721
A41: 2-2-1 | B41: 보수공 | F41: 0 | G41: 15368632 | H41: 0 | I41: 10,502,040 | J41: 0 | K41: 4,706,996 | L41: 0 | M41: 159,596
...

Sheet 제경비산출서(전체)
A1: 제 경 비 산 출 내 역 서
A2: 공사명 : 국도46호선 호평ic교(상) 등 포장 및 시설물 보수공사
A3: 공 종 명 | B3: 설계금액 | C3: 도급금액 | D3: 산 출 근 거 | O3: 비 고
A4: 가. 직접공사비 | B4: 356120488 | C4: 322762522
A5: 1.간 접 노 무 비 | B5: 34137084 | C5: 30939448 | D5: ( | E5: 322762522 | F5: ÷ | G5: 356120488 | H5: ) | I5: × | J5: 34137084 | K5: = | L5: 30939448 | M5: ≒ | N5: 30939448 | R5: 0.09585824
A6: 2.산 재 보 험 료 | B6: 8580614 | C6: 7776864 | D6: ( | E6: 322762522 | F6: ÷ | G6: 356120488 | H6: ) | I6: × | J6: 8580614 | K6: = | L6: 7776864 | M6: ≒ | N6: 7776864 | R6: 0.02409469
A7: 3.고 용 보 험 료 | B7: 2434387 | C7: 2206356 | D7: ( | E7: 322762522 | F7: ÷ | G7: 356120488 | H7: ) | I7: × | J7: 2434387 | K7: = | L7: 2206356 | M7: ≒ | N7: 2206356 | R7: 0.00683584
A8: 4.건 강 보 험 료 | B8: 7437746 | C8: 7437746 | D8: 설계가 반영 | M8: ≒ | N8: 7437746 | R8: 0.02304401
A9: 5.연 금 보 험 료 | B9: 9827342 | C9: 9827342 | D9: 설계가 반영 | M9: ≒ | N9: 9827342 | R9: 0.03044759
A10: 6.노인장기요양보험료 | B10: 977319 | C10: 977319 | D10: 설계가 반영 | M10: ≒ | N10: 977319 | R10: 0.00302798
A11: 7.퇴직공제부금비 | B11: 4758502 | C11: 4758502 | D11: 설계가 반영 | M11: ≒ | N11: 4758502 | R11: 0.01474304
A12: 8.건설기계대여대금 | B12: 1424481 | C12: 1291049 | D12: ( | E12: 322762522 | F12: ÷ | G12: 356120488 | H12: ) | I12: × | J12: 1424481 | K12: = | L12: 1291049 | M12: ≒ | N12: 1291049 | R12: 0.00399999
A13: 9.산 업 안 전 보 건 관 리 비 | B13: 12397587 | C13: 12397587 | D13: 설계가 반영 | M13: ≒ | N13: 12397587 | R13: 0.03841086
A14: 10.환 경 보 전 비 | B14: 3205084 | C14: 2904862 | D14: ( | E14: 322762522 | F14: ÷ | G14: 356120488 | H14: ) | I14: × | J14: 3205084 | K14: = | L14: 2904862 | M14: ≒ | N14: 2904862 | R14: 0.00899999
A15: 11.하도급대금지급보증수수료 | B15: 288457 | C15: 261437 | D15: ( | E15: 322762522 | F15: ÷ | G15: 356120488 | H15: ) | I15: × | J15: 288457 | K15: = | L15: 261437 | M15: ≒ | N15: 261437 | R15: 0.00080999
A16: 12.기 타 경 비 | B16: 18691544 | C16: 16940698 | D16: ( | E16: 322762522 | F16: ÷ | G16: 356120488 | H16: ) | I16: × | J16: 18691544 | K16: = | L16: 16940698 | M16: ≒ | N16: 16940698 | R16: 0.05248657
A17: 나. 소 계 | B17: 460280635 | C17: 420481732
A18: 13.일 반 관 리 비 | B18: 36822450 | C18: 33638537 | D18: ( | E18: 420481732 | F18: ÷ | G18: 460280635 | H18: ) | I18: × | J18: 36822450 | K18: = | L18: 33638537 | M18: ≒ | N18: 33638537 | R18: 0.07999999
A19: 14.이 윤 | B19: 56329192 | C19: 46652366 | D19: ( | E19: 420481732 | F19: ÷ | G19: 460280635 | H19: ) | I19: × | J19: 56329192 | K19: = | L19: 51458598 | M19: ≒ | N19: 46652366 | O19: 이윤조정 | Q19: 0 | R19: 0.1109498
A20: 15.안전관리계획서작성 | B20: 17884603 | C20: 17884603 | D20: 설계가 반영 | M20: ≒ | N20: 17884603
A21: 16.폐기물처리비 | B21: 501302 | C21: 454308
A22: 라. 공 급 가 액 | B22: 571818182 | C22: 519111546
A23: 17.부 가 가 치 세 | B23: 57181818 | C23: 51911154 | Q23: 0
A24: 마. 도 급 공 사 비 | B24: 629000000 | C24: 571022700 | Q24: 571022700
C26: 571022700
Q27: 0
C29: 571022700 | N29: 0
N31: 0

Sheet 적용제경비산출서
A1: 적 용 제 경 비 산 출 서
A3: 구 분 | B3: 도급금액 | C3: 산 출 근 거 | K3: 적용 제경비율 | N3: 비 고
A4: - 순공사비 = 직접공사비 | B4: 322762522
A5: 가. 간접노무비 | B5: 30939448 | D5: ( | E5: 30939448 | F5: ÷ | G5: 322762522 | H5: ) | I5: = | J5: 0.09585824 | K5: 순공사비 | L5: × | M5: 0.09585824 | P5: 0.09585824
A6: 나. 산재보험료 | B6: 7776864 | D6: ( | E6: 7776864 | F6: ÷ | G6: 322762522 | H6: ) | I6: = | J6: 0.02409469 | K6: 순공사비 | L6: × | M6: 0.02409469 | P6: 0.02409469
A7: 다. 고용보험료 | B7: 2206356 | D7: ( | E7: 2206356 | F7: ÷ | G7: 322762522 | H7: ) | I7: = | J7: 0.00683584 | K7: 순공사비 | L7: × | M7: 0.00683584 | P7: 0.00683584
A8: 라. 건강보험료 | B8: 7437746 | D8: ( | E8: 7437746 | F8: ÷ | G8: 322762522 | H8: ) | I8: = | J8: 0.02304401 | K8: 순공사비 | L8: × | M8: 0.02304401 | P8: 0.02304401
A9: 마. 연금보험료 | B9: 9827342 | D9: ( | E9: 9827342 | F9: ÷ | G9: 322762522 | H9: ) | I9: = | J9: 0.03044759 | K9: 순공사비 | L9: × | M9: 0.03044759 | P9: 0.03044759
A10: 바. 노인장기요양보험료 | B10: 977319 | D10: ( | E10: 977319 | F10: ÷ | G10: 322762522 | H10: ) | I10: = | J10: 0.00302798 | K10: 순공사비 | L10: × | M10: 0.00302798 | P10: 0.00302798
A11: 사. 퇴직공제부금비 | B11: 4758502 | D11: ( | E11: 4758502 | F11: ÷ | G11: 322762522 | H11: ) | I11: = | J11: 0.01474304 | K11: 순공사비 | L11: × | M11: 0.01474304 | P11: 0.01474304
A12: 아. 건설기계대여대금지급보증서 | B12: 1291049 | D12: ( | E12: 1291049 | F12: ÷ | G12: 322762522 | H12: ) | I12: = | J12: 0.00399999 | K12: 순공사비 | L12: × | M12: 0.00399999 | P12: 0.00399999
A13: 자. 산업안전보건관리비 | B13: 12397587 | D13: ( | E13: 12397587 | F13: ÷ | G13: 322762522 | H13: ) | I13: = | J13: 0.03841086 | K13: 순공사비 | L13: × | M13: 0.03841086 | P13: 0.03841086
A14: 차. 환경보전비 | B14: 2904862 | D14: ( | E14: 2904862 | F14: ÷ | G14: 322762522 | H14: ) | I14: = | J14: 0.00899999 | K14: 순공사비 | L14: × | M14: 0.00899999 | P14: 0.00899999
A15: 카. 하도급대금지급보증수수료 | B15: 261437 | D15: ( | E15: 261437 | F15: ÷ | G15: 322762522 | H15: ) | I15: = | J15: 0.00080999 | K15: 순공사비 | L15: × | M15: 0.00080999 | P15: 0.00080999
A16: 타. 기타경비 | B16: 16940698 | D16: ( | E16: 16940698 | F16: ÷ | G16: 322762522 | H16: ) | I16: = | J16: 0.05248657 | K16: 순공사비 | L16: × | M16: 0.05248657 | P16: 0.05248657
A17: 1. 순공사원가 | B17: 420481732
A18: 2. 일반관리비 | B18: 33638537 | D18: ( | E18: 33638537 | F18: ÷ | G18: 420481732 | H18: ) | I18: = | J18: 0.07999999 | K18: 순공사원가 | L18: × | M18: 0.07999999 | P18: 0.07999999
A19: 3. 이 윤 | B19: 46652366 | D19: ( | E19: 46652366 | F19: ÷ | G19: 420481732 | H19: ) | I19: = | J19: 0.1109498 | K19: 순공사원가 | L19: × | M19: 0.1109498 | P19: 0.1109498
A20: 4. 안전관리계획서작성 | B20: 17884603
A21: 5. 폐기물처리비 | B21: 454308
A22: 공 급 가 액 | B22: 519111546
A23: 6. 부가가치세 | B23: 51911154
A24: Ⅰ.도 급 액 | B24: 571022700

Sheet 설계내역서
B1: 설계내역서
B3: 공종 | C3: 품 명 | D3: 규 격 | E3: 수 량 | F3: 단위 | G3: 합 계 | I3: 노 무 비 | K3: 재 료 비 | M3: 경 비 | O3: 비 고
G4: 단 가 | H4: 금 액 | I4: 단 가 | J4: 금 액 | K4: 단 가 | L4: 금 액 | M4: 단 가 | N4: 금 액
B5: 1. | C5: 국도46호선 호평IC교(상) | G5: 0 | H5: 199908313 | J5: 121,695,188 | L5: 71,502,290 | N5: 6,710,835 | Q5: 30804793
B6: 1-1 | C6: 호평 IC교 (상) | G6: 0 | H6: 199908313 | J6: 121,695,188 | L6: 71,502,290 | N6: 6,710,835 | Q6: 118424276
B7: 1-1-1 | C7: 아스팔트 포장 절삭 후 덧씌우기 | G7: 0 | H7: 191105975 | J7: 119,565,140 | L7: 67,604,336 | N7: 3,936,499
C8: 아스팔트 포장 절삭후 아스팔트 덧씌우기 | D8: A-Type (1회절삭,2회포장)-야간작업 | E8: 1969 | F8: ㎡ | G8: 7028 | H8: 13838132 | I8: 4,055 | J8: 7984295 | K8: 1,333 | L8: 2624677 | M8: 1,640 | N8: 3229160 | O8: 단산1참조
C9: 교면방수 | D9: JJ 시트식 복합 교면방수 (야간) | E9: 1969 | F9: ㎡ | G9: 88872 | H9: 174988968 | I9: 56505 | J9: 111258345 | K9: 32011 | L9: 63029659 | M9: 356 | N9: 700964 | O9: 일위1참조
C10: 교면물빼기 유공관 | D10: Φ15mm,그물망형, 야간 | E10: 125 | F10: M | G10: 12471 | H10: 1558875 | I10: 2580 | J10: 322500 | K10: 9840 | L10: 1230000 | M10: 51 | N10: 6375 | O10: 일위5참조
C11: 아스팔트유제 | D11: RSC-4 | E11: 4 | F11: D/M | G11: 180000 | H11: 720000 | I11: 0 | J11: 0 | K11: 180000 | L11: 720000 | M11: 0 | N11: 0
B12: 1-1-3 | C12: 부대공 | G12: 0 | H12: 8802338 | J12: 2,130,048 | L12: 3,897,954 | N12: 2,774,336
C13: 차선도색(융착식,일반형)-운행도로,차량부분통제 | D13: 수동식,백색실선 | E13: 65 | F13: ㎡ | G13: 27483 | H13: 1786395 | I13: 3,185 | J13: 207025 | K13: 23,913 | L13: 1554345 | M13: 385 | N13: 25025 | O13: 단산2참조
C14: 차선도색(융착식,일반형)-운행도로,차량부분통제 | D14: 수동식,백색파선 | E14: 5 | F14: ㎡ | G14: 32506 | H14: 162530 | I14: 6,371 | J14: 31855 | K14: 25,365 | L14: 126825 | M14: 770 | N14: 3850 | O14: 단산3참조
C15: 차선도색(융착식,일반형)-운행도로,차량부분통제 | D15: 수동식,문자.기호 | E15: 72 | F15: ㎡ | G15: 46057 | H15: 3316104 | I15: 17,698 | J15: 1274256 | K15: 26,218 | L15: 1887696 | M15: 2,141 | N15: 154152 | O15: 단산4참조
C16: 교통안전관리비 | D16: 야간 | E16: 1 | F16: 일 | G16: 973959 | H16: 973959 | I16: 553537 | J16: 553537 | K16: 244588 | L16: 244588 | M16: 175834 | N16: 175834 | O16: 일위7참조
C17: 로봇신호수 설치 및 철거 | D17: 야간 | E17: 1 | F17: 조 | G17: 147875 | H17: 147875 | I17: 63375 | J17: 63375 | K17: 84500 | L17: 84500 | M17: 0 | N17: 0 | O17: 일위8참조
C18: 중기운반 | D18: 아스콘포장 | E18: 1 | F18: 식 | G18: 2203423 | H18: 2203423 | J18: 0 | L18: 0 | M18: 2203423 | N18: 2203423 | O18: 단산7참조
C19: 품질시험비 | D19: 연성포장 | E19: 1 | F19: 식 | G19: 212052 | H19: 212052 | I19: 0 | J19: 0 | K19: 0 | L19: 0 | M19: 212052 | N19: 212052 | O19: 일위9참조
G20: 0 | H20: 0
B21: 2. | C21: 국도46호선 신구운교 등 | G21: 0 | H21: 156212175 | J21: 85,196,231 | L21: 46,921,986 | N21: 24,093,958
B22: 2-1 | C22: 신구운교(춘천) | G22: 0 | H22: 6837069 | J22: 3,309,659 | L22: 1,635,537 | N22: 1,891,873
B23: 2-1-1 | C23: 보수공 | G23: 0 | H23: 3083803 | J23: 1,879,450 | L23: 1,173,451 | N23: 30,902
C24: 방호벽 및 중분대 | G24: 0 | H24: 888414 | J24: 308,166 | L24: 573,240 | N24: 7,008
C25: 철근방청단면보수(SSR공법) | D25: 벽체T=50mm (야간) | E25: 2 | F25: ㎡ | G25: 444207 | H25: 888414 | I25: 154083 | J25: 308166 | K25: 286620 | L25: 573240 | M25: 3504 | N25: 7008 | O25: 일위10참조
C26: 바닥판 하면 | G26: 0 | H26: 1134312 | J26: 873,367 | L26: 248,711 | N26: 12,234
C27: 표면보수(SSR공법) | D27: 천정 (야간) | E27: 10 | F27: ㎡ | G27: 101028 | H27: 1010280 | I27: 77305 | J27: 773050 | K27: 22700 | L27: 227000 | M27: 1023 | N27: 10230 | O27: 일위17참조
C28: 콘크리트 균열보수(야간) | D28: 주입공법 | E28: 3 | F28: m | G28: 41344 | H28: 124032 | I28: 33439 | J28: 100317 | K28: 7237 | L28: 21711 | M28: 668 | N28: 2004 | O28: 일위20참조
C29: 교대 | G29: 0 | H29: 84957 | J29: 63,340 | L29: 20,650 | N29: 967
C30: 표면보수(SSR공법) | D30: 벽체 (야간) | E30: 1 | F30: ㎡ | G30: 84957 | H30: 84957 | I30: 63340 | J30: 63340 | K30: 20650 | L30: 20650 | M30: 967 | N30: 967 | O30: 일위22참조
C31: 교각 | G31: 0 | H31: 976120 | J31: 634,577 | L31: 330,850 | N31: 10,693
C32: 표면보수(SSR공법) | D32: 벽체 (야간) | E32: 8 | F32: ㎡ | G32: 84957 | H32: 679656 | I32: 63340 | J32: 506720 | K32: 20650 | L32: 165200 | M32: 967 | N32: 7736 | O32: 일위22참조
C33: 단면보수(SSR공법) | D33: 벽체T=30mm (야간) | E33: 1 | F33: ㎡ | G33: 296464 | H33: 296464 | I33: 127857 | J33: 127857 | K33: 165650 | L33: 165650 | M33: 2957 | N33: 2957 | O33: 일위23참조
B34: 2-1-2 | C34: 부대공 | G34: 0 | H34: 3753266 | J34: 1,430,209 | L34: 462,086 | N34: 1,860,971
C35: 굴절차 | D35: 22M (야간) | E35: 1 | F35: 일 | G35: 2626996 | H35: 2626996 | I35: 810,756 | J35: 810756 | K35: 132,160 | L35: 132160 | M35: 1,684,080 | N35: 1684080 | O35: 단산9참조
C36: 교통안전관리비 | D36: 야간 | E36: 1 | F36: 일 | G36: 973959 | H36: 973959 | I36: 553537 | J36: 553537 | K36: 244588 | L36: 244588 | M36: 175834 | N36: 175834 | O36: 일위7참조
C37: 로봇신호수 설치 및 철거 | D37: 야간 | E37: 1 | F37: 조 | G37: 147875 | H37: 147875 | I37: 63375 | J37: 63375 | K37: 84500 | L37: 84500 | M37: 0 | N37: 0 | O37: 일위8참조
C38: 폐기물상차 | D38: 백호0.7㎥ | E38: 1 | F38: ㎥ | G38: 4436 | H38: 4436 | I38: 2,541 | J38: 2541 | K38: 838 | L38: 838 | M38: 1,057 | N38: 1057 | O38: 단산10참조
G39: 0 | H39: 0
B40: 2-2 | C40: 조종교 | G40: 0 | H40: 24312504 | J40: 14,382,759 | L40: 6,032,719 | N40: 3,897,026
B41: 2-2-1 | C41: 보수공 | G41: 0 | H41: 16958283 | J41: 11,588,257 | L41: 5,193,885 | N41: 176,141
...

Sheet 일위대가총괄표
B1: 일위대가총괄표
B3: 호 표 | C3: 품 명 | D3: 규 격 | E3: 단위 | F3: 합 계 | G3: 노무비 | H3: 재료비 | I3: 경 비 | J3: 비 고 | Z3: 당초합계 | AA3: 당초노무비 | AB3: 당초재료비 | AC3: 당초경비
B4: 제1호표 | C4: 교면방수 | D4: JJ 시트식 복합 교면방수 (야간) | E4: ㎡ | F4: 88872 | G4: 56505 | H4: 32011 | I4: 356 | Z4: 88872 | AA4: 56505 | AB4: 32011 | AC4: 356
B5: 제2호표 | C5: 바탕처리 | E5: ㎡ | F5: 9268 | G5: 8912 | H5: 0 | I5: 356 | J5: 6-1-1바탕처리 | Z5: 9268 | AA5: 8912 | AC5: 356
B6: 제3호표 | C6: 프라이머 바름 | D6: Multy Coat B | E6: ㎡ | F6: 20629 | G6: 14293 | H6: 6336 | I6: 0 | Z6: 20629 | AA6: 14293 | AB6: 6336
B7: 제4호표 | C7: 도막방수제,시트 시공 | E7: ㎡ | F7: 40140 | G7: 14465 | H7: 25675 | I7: 0 | Z7: 40140 | AA7: 14465 | AB7: 25675
B8: 제5호표 | C8: 교면물빼기 유공관 | D8: Φ15mm,그물망형, 야간 | E8: M | F8: 12471 | G8: 2580 | H8: 9840 | I8: 51 | Z8: 12471 | AA8: 2580 | AB8: 9840 | AC8: 51
B9: 제6호표 | C9: 교면물빼기 유공관 | D9: Φ15mm,그물망형 | E9: M | F9: 11611 | G9: 1720 | H9: 9840 | I9: 51 | Z9: 11611 | AA9: 1720 | AB9: 9840 | AC9: 51
B10: 제7호표 | C10: 교통안전관리비 | D10: 야간 | E10: 일 | F10: 973959 | G10: 553537 | H10: 244588 | I10: 175834 | Z10: 973959 | AA10: 553537 | AB10: 244588 | AC10: 175834
B11: 제8호표 | C11: 로봇신호수 설치 및 철거 | D11: 야간 | E11: 조 | F11: 147875 | G11: 63375 | H11: 84500 | I11: 0 | Z11: 147875 | AA11: 63375 | AB11: 84500
B12: 제9호표 | C12: 품질시험비 | D12: 연성포장 | E12: 식 | F12: 212052 | G12: 0 | H12: 0 | I12: 212052 | Z12: 212052 | AC12: 212052
B13: 제10호표 | C13: 철근방청단면보수(SSR공법) | D13: 벽체T=50mm (야간) | E13: ㎡ | F13: 444207 | G13: 154083 | H13: 286620 | I13: 3504 | Z13: 444207 | AA13: 154083 | AB13: 286620 | AC13: 3504
B14: 제11호표 | C14: 콘크리트면처리(치핑) | E14: ㎡ | F14: 6158 | G14: 5702 | H14: 0 | I14: 456 | Z14: 6158 | AA14: 5702 | AC14: 456
B15: 제12호표 | C15: 고압물청소 | E15: ㎡ | F15: 4657 | G15: 4522 | H15: 0 | I15: 135 | Z15: 4657 | AA15: 4522 | AC15: 135
B16: 제13호표 | C16: 철근녹제거 | E16: ㎡ | F16: 3594 | G16: 3490 | H16: 0 | I16: 104 | Z16: 3594 | AA16: 3490 | AC16: 104
B17: 제14호표 | C17: 철근방청처리 | D17: 벽체 붗칠2회 | E17: ㎡ | F17: 5596 | G17: 2676 | H17: 2920 | I17: 0 | Z17: 5596 | AA17: 2676 | AB17: 2920
B18: 제15호표 | C18: 몰탈바르기 | E18: ㎡ | F18: 1231145 | G18: 1131819 | H18: 55012 | I18: 44314 | Z18: 1231145 | AA18: 1131819 | AB18: 55012 | AC18: 44314
B19: 제16호표 | C19: 마감재도포 | D19: 벽체 | E19: ㎡ | F19: 48786 | G19: 29742 | H19: 18450 | I19: 594 | Z19: 48786 | AA19: 29742 | AB19: 18450 | AC19: 594
B20: 제17호표 | C20: 표면보수(SSR공법) | D20: 천정 (야간) | E20: ㎡ | F20: 101028 | G20: 77305 | H20: 22700 | I20: 1023 | Z20: 101028 | AA20: 77305 | AB20: 22700 | AC20: 1023
B21: 제18호표 | C21: 단면처리 | E21: ㎡ | F21: 8201 | G21: 7963 | H21: 0 | I21: 238 | Z21: 8201 | AA21: 7963 | AC21: 238
B22: 제19호표 | C22: 마감재도포 | D22: 천정 | E22: ㎡ | F22: 60202 | G22: 39052 | H22: 20500 | I22: 650 | Z22: 60202 | AA22: 39052 | AB22: 20500 | AC22: 650
B23: 제20호표 | C23: 콘크리트 균열보수(야간) | D23: 주입공법 | E23: m | F23: 41344 | G23: 33439 | H23: 7237 | I23: 668 | Z23: 41344 | AA23: 33439 | AB23: 7237 | AC23: 668
B24: 제21호표 | C24: 콘크리트 균열보수 | D24: 주입공법, 주간 | E24: m | F24: 30198 | G24: 22293 | H24: 7237 | I24: 668 | Z24: 30198 | AA24: 22293 | AB24: 7237 | AC24: 668
B25: 제22호표 | C25: 표면보수(SSR공법) | D25: 벽체 (야간) | E25: ㎡ | F25: 84957 | G25: 63340 | H25: 20650 | I25: 967 | Z25: 84957 | AA25: 63340 | AB25: 20650 | AC25: 967
B26: 제23호표 | C26: 단면보수(SSR공법) | D26: 벽체T=30mm (야간) | E26: ㎡ | F26: 296464 | G26: 127857 | H26: 165650 | I26: 2957 | Z26: 296464 | AA26: 127857 | AB26: 165650 | AC26: 2957
B27: 제24호표 | C27: 단면보수(SSR공법) | D27: 천정T=10mm (야간) | E27: ㎡ | F27: 166125 | G27: 90891 | H27: 73550 | I27: 1684 | Z27: 166125 | AA27: 90891 | AB27: 73550 | AC27: 1684
B28: 제25호표 | C28: 철근방청단면보수(SSR공법) | D28: 천정T=50mm (야간) | E28: ㎡ | F28: 461080 | G28: 168850 | H28: 288670 | I28: 3560 | Z28: 461080 | AA28: 168850 | AB28: 288670 | AC28: 3560
B29: 제26호표 | C29: 철근방청처리 | D29: 천정 붗칠2회 | E29: ㎡ | F29: 6131 | G29: 3211 | H29: 2920 | I29: 0 | Z29: 6131 | AA29: 3211 | AB29: 2920
B30: 제27호표 | C30: 단면보수(SSR공법) | D30: 벽체T=10mm (야간) | E30: ㎡ | F30: 147554 | G30: 76926 | H30: 69000 | I30: 1628 | Z30: 147554 | AA30: 76926 | AB30: 69000 | AC30: 1628
B31: 제28호표 | C31: 단면보수(SSR공법) | D31: 천정T=30mm (야간) | E31: ㎡ | F31: 317535 | G31: 141822 | H31: 172700 | I31: 3013 | Z31: 317535 | AA31: 141822 | AB31: 172700 | AC31: 3013
B32: 제29호표 | C32: 품질시험비 | D32: 압축강도, 부착강도 | E32: 식 | F32: 99000 | G32: 0 | H32: 0 | I32: 99000 | Z32: 99000 | AC32: 99000
B33: 제30호표 | C33: 표면보수(SSR공법) | D33: 벽체 | E33: ㎡ | F33: 63844 | G33: 42227 | H33: 20650 | I33: 967 | Z33: 63844 | AA33: 42227 | AB33: 20650 | AC33: 967
B34: 제31호표 | C34: 표면보수(SSR공법) | D34: 천정 | E34: ㎡ | F34: 75260 | G34: 51537 | H34: 22700 | I34: 1023 | Z34: 75260 | AA34: 51537 | AB34: 22700 | AC34: 1023
B35: 제32호표 | C35: 안전관리책임자 | D35: 공사기간(투입일 정산) | E35: 일 | F35: 235459 | G35: 235459 | H35: 0 | I35: 0 | Z35: 235459 | AA35: 235459
B36: 제33호표 | C36: 안전관리계획서작성비 | E36: 식 | F36: 3757063 | G36: 1491436 | H36: 0 | I36: 2265627 | Z36: 3757063 | AA36: 1491436 | AC36: 2265627

Sheet 일위대가
B1: 일위대가
B3: 호 표 | C3: 품 명 | D3: 규 격 | E3: 수 량 | F3: 단위 | G3: 합 계 | I3: 노 무 비 | K3: 재 료 비 | M3: 경 비 | O3: 비 고
G4: 단 가 | H4: 금 액 | I4: 단 가 | J4: 금 액 | K4: 단 가 | L4: 금 액 | M4: 단 가 | N4: 금 액
B5: 제1호표 | C5: 교면방수 | D5: JJ 시트식 복합 교면방수 (야간) | F5: ㎡ | H5: 88872 | J5: 56505 | L5: 32011 | N5: 356
C6: 바탕처리 | E6: 1 | F6: ㎡ | G6: 9268 | H6: 9268 | I6: 8912 | J6: 8912 | K6: 0 | L6: 0 | M6: 356 | N6: 356 | O6: 일위2참조
C7: 프라이머 바름 | D7: Multy Coat B | E7: 1 | F7: ㎡ | G7: 20629 | H7: 20629 | I7: 14293 | J7: 14293 | K7: 6336 | L7: 6336 | M7: 0 | N7: 0 | O7: 일위3참조
C8: 도막방수제,시트 시공 | E8: 1 | F8: ㎡ | G8: 40140 | H8: 40140 | I8: 14465 | J8: 14465 | K8: 25675 | L8: 25675 | M8: 0 | N8: 0 | O8: 일위4참조
C9: 야간할증 | D9: 노무비의 | E9: 50 | F9: % | G9: 37670 | H9: 18835 | I9: 37670 | J9: 18835 | L9: 0 | N9: 0
J10: 0 | L10: 0 | N10: 0
B11: 제2호표 | C11: 바탕처리 | F11: ㎡ | H11: 9268 | J11: 8912 | L11: 0 | N11: 356 | O11: 6-1-1바탕처리
C12: 방 수 공 | E12: 0.03 | F12: 인 | G12: 228286 | H12: 6848 | I12: 228286 | J12: 6848 | K12: 0 | L12: 0 | M12: 0 | N12: 0
C13: 보통인부 | E13: 0.012 | F13: 인 | G13: 172068 | H13: 2064 | I13: 172068 | J13: 2064 | K13: 0 | L13: 0 | M13: 0 | N13: 0
C14: 기계경비 | D14: 노무비의 | E14: 4 | F14: % | G14: 8912 | H14: 356 | J14: 0 | L14: 0 | M14: 8912 | N14: 356
J15: 0 | L15: 0 | N15: 0
B16: 제3호표 | C16: 프라이머 바름 | D16: Multy Coat B | F16: ㎡ | H16: 20629 | J16: 14293 | L16: 6336 | N16: 0
C17: 멀티코트B | D17: 아스팔트프라이머 | E17: 0.08 | F17: can | G17: 79200 | H17: 6336 | I17: 0 | J17: 0 | K17: 79200 | L17: 6336 | M17: 0 | N17: 0
C18: 방 수 공 | E18: 0.04 | F18: 인 | G18: 228286 | H18: 9131 | I18: 228286 | J18: 9131 | K18: 0 | L18: 0 | M18: 0 | N18: 0
C19: 보통인부 | E19: 0.03 | F19: 인 | G19: 172068 | H19: 5162 | I19: 172068 | J19: 5162 | K19: 0 | L19: 0 | M19: 0 | N19: 0
J20: 0 | L20: 0 | N20: 0
B21: 제4호표 | C21: 도막방수제,시트 시공 | F21: ㎡ | H21: 40140 | J21: 14465 | L21: 25675 | N21: 0
C22: 교면복합씰 | D22: JJ교면도막방수제 t=2.0mm | E22: 1.55 | F22: kg | G22: 6500 | H22: 10075 | I22: 0 | J22: 0 | K22: 6500 | L22: 10075 | M22: 0 | N22: 0
C23: 교면복합시트 | D23: JJ교면복합시트 T=0.5mm | E23: 1.95 | F23: ㎡ | G23: 8000 | H23: 15600 | I23: 0 | J23: 0 | K23: 8000 | L23: 15600 | M23: 0 | N23: 0
C24: 방 수 공 | E24: 0.04 | F24: 인 | G24: 228286 | H24: 9131 | I24: 228286 | J24: 9131 | K24: 0 | L24: 0 | M24: 0 | N24: 0
C25: 보통인부 | E25: 0.031 | F25: 인 | G25: 172068 | H25: 5334 | I25: 172068 | J25: 5334 | K25: 0 | L25: 0 | M25: 0 | N25: 0
J26: 0 | L26: 0 | N26: 0
B27: 제5호표 | C27: 교면물빼기 유공관 | D27: Φ15mm,그물망형, 야간 | F27: M | H27: 12471 | J27: 2580 | L27: 9840 | N27: 51
C28: 교면물빼기 유공관 | D28: Φ15mm,그물망형 | E28: 1 | F28: M | G28: 11611 | H28: 11611 | I28: 1720 | J28: 1720 | K28: 9840 | L28: 9840 | M28: 51 | N28: 51 | O28: 일위6참조
C29: 야간할증 | D29: 노무비의 | E29: 50 | F29: % | G29: 1720 | H29: 860 | I29: 1720 | J29: 860 | L29: 0 | N29: 0
J30: 0 | L30: 0 | N30: 0
B31: 제6호표 | C31: 교면물빼기 유공관 | D31: Φ15mm,그물망형 | F31: M | H31: 11611 | J31: 1720 | L31: 9840 | N31: 51
C32: 유공관 | D32: Φ15mm, 그물망형 | E32: 1.05 | F32: M | G32: 9170 | H32: 9628 | I32: 0 | J32: 0 | K32: 9170 | L32: 9628 | M32: 0 | N32: 0
C33: 고정테이프 | D33: 30×5000 | E33: 2 | F33: EA | G33: 106 | H33: 212 | I33: 0 | J33: 0 | K33: 106 | L33: 212 | M33: 0 | N33: 0
C34: 보통인부 | E34: 0.01 | F34: 인 | G34: 172068 | H34: 1720 | I34: 172068 | J34: 1720 | K34: 0 | L34: 0 | M34: 0 | N34: 0
C35: 기구손료 | D35: 노무비의 | E35: 3 | F35: % | G35: 1720 | H35: 51 | J35: 0 | L35: 0 | M35: 1720 | N35: 51
J36: 0 | L36: 0 | N36: 0
B37: 제7호표 | C37: 교통안전관리비 | D37: 야간 | F37: 일 | H37: 973959 | J37: 553537 | L37: 244588 | N37: 175834
C38: 교통안전관리비 | D38: 주간 | E38: 1 | F38: 일 | G38: 789447 | H38: 789447 | I38: 369,025 | J38: 369025 | K38: 244,588 | L38: 244588 | M38: 175,834 | N38: 175834 | O38: 단산5참조
C39: 야간할증 | D39: 노무비의 | E39: 50 | F39: % | G39: 369025 | H39: 184512 | I39: 369025 | J39: 184512 | L39: 0 | N39: 0
J40: 0 | L40: 0 | N40: 0
B41: 제8호표 | C41: 로봇신호수 설치 및 철거 | D41: 야간 | F41: 조 | H41: 147875 | J41: 63375 | L41: 84500 | N41: 0
...

Sheet 단가산출총괄표
B1: 단가산출총괄표
B3: No | C3: 품 명 | D3: 규 격 | E3: 단위 | F3: 합 계 | G3: 노무비 | H3: 재료비 | I3: 경 비 | J3: 비 고 | Z3: 당초합계 | AA3: 당초노무비 | AB3: 당초재료비 | AC3: 당초경비
B4: 1 | C4: 아스팔트 포장 절삭후 아스팔트 덧씌우기 | D4: A-Type (1회절삭,2회포장)-야간작업 | E4: ㎡ | F4: =G4+H4+I4 -> 7028 | G4: =단가산출!CY4 -> 4,055 | H4: =단가산출!CZ4 -> 1,333 | I4: =단가산출!DA4 -> 1,640 | Z4: 7028 | AA4: 4055 | AB4: 1333 | AC4: 1640
B5: 2 | C5: 차선도색(융착식,일반형)-운행도로,차량부분통제 | D5: 수동식,백색실선 | E5: ㎡ | F5: =G5+H5+I5 -> 27483 | G5: =단가산출!CY111 -> 3,185 | H5: =단가산출!CZ111 -> 23,913 | I5: =단가산출!DA111 -> 385 | Z5: 27483 | AA5: 3185 | AB5: 23913 | AC5: 385
B6: 3 | C6: 차선도색(융착식,일반형)-운행도로,차량부분통제 | D6: 수동식,백색파선 | E6: ㎡ | F6: =G6+H6+I6 -> 32506 | G6: =단가산출!CY178 -> 6,371 | H6: =단가산출!CZ178 -> 25,365 | I6: =단가산출!DA178 -> 770 | Z6: 32506 | AA6: 6371 | AB6: 25365 | AC6: 770
B7: 4 | C7: 차선도색(융착식,일반형)-운행도로,차량부분통제 | D7: 수동식,문자.기호 | E7: ㎡ | F7: =G7+H7+I7 -> 46057 | G7: =단가산출!CY245 -> 17,698 | H7: =단가산출!CZ245 -> 26,218 | I7: =단가산출!DA245 -> 2,141 | Z7: 46057 | AA7: 17698 | AB7: 26218 | AC7: 2141
B8: 5 | C8: 교통안전관리비 | D8: 주간 | E8: 일 | F8: =G8+H8+I8 -> 789447 | G8: =단가산출!CY313 -> 369,025 | H8: =단가산출!CZ313 -> 244,588 | I8: =단가산출!DA313 -> 175,834 | Z8: 789447 | AA8: 369025 | AB8: 244588 | AC8: 175834
B9: 6 | C9: 로봇신호수 설치 및 철거 | D9: 한팔용 | E9: 조 | F9: =G9+H9+I9 -> 126750 | G9: =단가산출!CY355 -> 42,250 | H9: =단가산출!CZ355 -> 84,500 | I9: =단가산출!DA355 -> 0 | Z9: 126750 | AA9: 42250 | AB9: 84500
B10: 7 | C10: 중기운반 | D10: 아스콘포장 | E10: 식 | F10: =G10+H10+I10 -> 2203423 | G10: =단가산출!CY376 -> 1,341,644 | H10: =단가산출!CZ376 -> 422,721 | I10: =단가산출!DA376 -> 439,058 | J10: 경비성단가 | Z10: 2203423 | AA10: 1341644 | AB10: 422721 | AC10: 439058
B11: 8 | C11: 굴절차 | D11: 22M | E11: 일 | F11: =G11+H11+I11 -> 2356744 | G11: =단가산출!CY475 -> 540,504 | H11: =단가산출!CZ475 -> 132,160 | I11: =단가산출!DA475 -> 1,684,080 | Z11: 2356744 | AA11: 540504 | AB11: 132160 | AC11: 1684080
B12: 9 | C12: 굴절차 | D12: 22M (야간) | E12: 일 | F12: =G12+H12+I12 -> 2626996 | G12: =단가산출!CY493 -> 810,756 | H12: =단가산출!CZ493 -> 132,160 | I12: =단가산출!DA493 -> 1,684,080 | Z12: 2626996 | AA12: 810756 | AB12: 132160 | AC12: 1684080
B13: 10 | C13: 폐기물상차 | D13: 백호0.7㎥ | E13: ㎥ | F13: =G13+H13+I13 -> 4436 | G13: =단가산출!CY513 -> 2,541 | H13: =단가산출!CZ513 -> 838 | I13: =단가산출!DA513 -> 1,057 | Z13: 4436 | AA13: 2541 | AB13: 838 | AC13: 1057

Sheet 단가산출
B1: 단가산출
B3: 산 출 근 거 | C3: 합 계 | D3: 노무비 | E3: 재료비 | F3: 경 비 | CX3: 합 계 | CY3: 노무비 | CZ3: 재료비 | DA3: 경 비
B4: 1.아스팔트 포장 절삭후 아스팔트 덧씌우기 (A-Type (1회절삭,2회포장)-야간작업) [㎡] | CX4: =CX109 -> 7028 | CY4: =CY109 -> 4,055 | CZ4: =CZ109 -> 1,333 | DA4: =DA109 -> 1,640
E6: < 2024년 품셈신설. 유지보수 2-1-4 >
E9: ※ | H9: 야간 | M9: 노임 | R9: 150 | U9: %
E11: ※ | H11: 밀링깊이 | Q11: 100 | T11: mm | W11: 이하 | AB11: 1 | AC11: 회절삭후 | AK11: , | AM11: 2 | AN11: 회 | AQ11: 재포장하는 | BB11: 기준
H12: A | I12: - | J12: Type | O12: : | Q12: 고속도로 | Y12: , | AA12: 자동차전용도로 | AO12: , | AQ12: 평면교차로가 | BD12: 없는 | BI12: 일반도로 | BR12: 등과 | BW12: 같이
Q13: 시공구간이 | AB13: 연결되어있는 | AO13: 경우
E15: ※ | H15: 1 | I15: 일 | L15: 시공량 | S15: : | U15: Qd | X15: = | Z15: =TEXT(2600,"#,##0.#######") -> 2,600. | AE15: ㎡ | AG15: / | AH15: 일
H16: 시간당 | O16: 시공량 | V16: : | X16: Q | Z16: = | AB16: Qd | AE16: ÷ | AH16: =TEXT(8,"#,##0.#######") -> 8. | AI16: hr | AL16: = | AN16: =TEXT(Z15,"#,##0.#######") -> 2,600. | AT16: ÷ | AW16: =TEXT(AH16,"#,##0.#######") -> 8. | AY16: = | BB16: =TEXT(ROUND(Z15/AH16,2),"#,##0.#######") -> 325. | BH16: ㎡ | BJ16: / | BK16: hr
D18: 1. | G18: 배치인원
G20: 포 장 공 | R20: : | T20: =TEXT(노임단가!F4,"#,##0") -> 273,308 | AD20: × | AG20: =TEXT(4,"#,##0.#######") -> 4. | AJ20: 인 | AM20: × | AP20: =TEXT(150,"#,##0.#######") -> 150. | AS20: % | AV20: ÷ | AY20: Qd | BB20: = | BD20: =TEXT(T20,"#,##0.#######") -> 273,308. | BL20: × | BO20: =TEXT(AG20,"#,##0.#######") -> 4. | BQ20: × | BT20: =TEXT(AP20,"#,##0.#######") -> 150. | BY20: ÷ | CB20: =TEXT(Z15,"#,##0.#######") -> 2,600. | CH20: = | CJ20: =TEXT(TRUNC(T20*AG20*(AP20*(1/100))/Z15,1),"#,##0.#######") -> 630.7
G22: 보통인부 | R22: : | T22: =TEXT(노임단가!F5,"#,##0") -> 172,068 | AD22: × | AG22: =TEXT(2,"#,##0.#######") -> 2. | AJ22: 인 | AM22: × | AP22: =TEXT(150,"#,##0.#######") -> 150. | AS22: % | AU22: ÷ | AX22: Qd | BA22: = | BC22: =TEXT(T22,"#,##0.#######") -> 172,068. | BK22: × | BN22: =TEXT(AG22,"#,##0.#######") -> 2. | BP22: × | BS22: =TEXT(AP22,"#,##0.#######") -> 150. | BW22: ÷ | BZ22: =TEXT(Z15,"#,##0.#######") -> 2,600. | CF22: = | CH22: =TEXT(TRUNC(T22*AG22*(AP22*(1/100))/Z15,1),"#,##0.#######") -> 198.5
G24: 인부소계 | P24: : | R24: =TEXT(TRUNC(CJ20+CH22,1),"#,##0.#######") -> 829.2 | CY24: =R24 -> 829.2
D26: 2. | G26: 재료비 | N26: ( | O26: 팁 | Q26: ( | R26: 날 | T26: ) | V26: 소모량 | AB26: )
G28: 1 | H28: ㎥당 | M28: 0.69 | Q28: 개소모 | W28: , | Y28: 밀링깊이 | AH28: 100 | AK28: mm기준시 | AT28: 1 | AU28: ㎥는 | AZ28: 10 | BB28: ㎡임
G30: 팁(날) | O30: (노면파쇄기용) | AF30: =TEXT(자재단가!R5,"#,##0.#######") -> 6,000. | AN30: × | AQ30: =TEXT(0.69,"#,##0.#######") -> 0.69 | AU30: 개 | AX30: ÷ | BA30: =TEXT(10,"#,##0.#######") -> 10. | BC30: ㎡ | BF30: = | BH30: =TEXT(TRUNC(AF30*AQ30/BA30,1),"#,##0.#") -> 414. | CX30: =CY30+CZ30+DA30 -> 414 | CZ30: =BH30 -> 414.
D32: 3. | G32: 기계경비
E34: 가 | G34: . | I34: 노면파쇄기 | V34: (2.0m)
G36: 노무비 | N36: : | Q36: =TEXT(기계경비총괄표!G4,"#,##0") -> 59,020 | Z36: ÷ | AC36: =TEXT(BB16,"#,##0.#######") -> 325. | AI36: × | AK36: =TEXT(2,"#,##0.#######") -> 2. | AL36: 대 | AO36: × | AR36: =TEXT(150,"#,##0.#######") -> 150. | AU36: % | AX36: = | AZ36: =TEXT(TRUNC(Q36/BB16*AK36*(AR36*(1/100)),1),"#,##0.#") -> 544.8
G37: 재료비 | N37: : | Q37: =TEXT(기계경비총괄표!H4,"#,##0") -> 84,117 | Z37: ÷ | AC37: =TEXT(BB16,"#,##0.#######") -> 325. | AI37: × | AK37: =TEXT(2,"#,##0.#######") -> 2. | AL37: 대 | AO37: = | AQ37: =TEXT(TRUNC(Q37/BB16*AK37,1),"#,##0.#") -> 517.6
G38: 경 | K38: 비 | N38: : | P38: =TEXT(기계경비총괄표!I4,"#,##0") -> 176,745 | Z38: ÷ | AC38: =TEXT(BB16,"#,##0.#######") -> 325. | AI38: × | AK38: =TEXT(2,"#,##0.#######") -> 2. | AL38: 대 | AO38: = | AQ38: =TEXT(TRUNC(P38/BB16*AK38,1),"#,##0.#") -> 1,087.6
G39: 소 | K39: 계 | N39: : | AM39: =TEXT(AZ36+AQ37+AQ38,"#,##0.#######") -> 2,150. | CX39: =CY39+CZ39+DA39 -> 2150 | CY39: =TEXT(AZ36,"#,###.0") -> 544.8 | CZ39: =TEXT(AQ37,"#,###.0") -> 517.6 | DA39: =TEXT(AQ38,"#,###.0") -> 1,087.6
E41: 나 | G41: . | I41: 로우더(타이어)+소형노면파쇄기 | AN41: (0.95㎥)
G43: 노무비 | N43: : | P43: =TEXT(기계경비총괄표!G5,"#,##0") -> 59,020 | Y43: ÷ | AB43: =TEXT(BB16,"#,##0.#######") -> 325. | AH43: × | AK43: =TEXT(150,"#,##0.#######") -> 150. | AN43: % | AP43: = | AR43: =TEXT(TRUNC(P43/BB16*(AK43*(1/100)),1),"#,##0.#") -> 272.4
G44: 재료비 | N44: : | P44: =TEXT(기계경비총괄표!H5,"#,##0") -> 12,284 | Y44: ÷ | AB44: =TEXT(BB16,"#,##0.#######") -> 325. | AH44: = | AJ44: =TEXT(TRUNC(P44/BB16,1),"#,##0.#") -> 37.7
G45: 경 | K45: 비 | N45: : | P45: =TEXT(기계경비총괄표!I5,"#,##0") -> 21,504 | Y45: ÷ | AB45: =TEXT(BB16,"#,##0.#######") -> 325. | AH45: = | AJ45: =TEXT(TRUNC(P45/BB16,1),"#,##0.#") -> 66.1
G46: 소 | K46: 계 | N46: : | AE46: =TEXT(AR43+AJ44+AJ45,"#,##0.#######") -> 376.2 | CX46: =CY46+CZ46+DA46 -> 376.2 | CY46: =TEXT(AR43,"#,###.0") -> 272.4 | CZ46: =TEXT(AJ44,"#,###.0") -> 37.7 | DA46: =TEXT(AJ45,"#,###.0") -> 66.1
E48: 다 | G48: . | I48: 로우더(타이어) | Z48: (0.57㎥)
G50: 노무비 | N50: : | P50: =TEXT(기계경비총괄표!G6,"#,##0") -> 59,020 | Y50: ÷ | AB50: =TEXT(BB16,"#,##0.#######") -> 325. | AH50: × | AJ50: =TEXT(3,"#,##0.#######") -> 3. | AK50: 대 | AN50: × | AQ50: =TEXT(150,"#,##0.#######") -> 150. | AT50: % | AV50: = | AX50: =TEXT(TRUNC(P50/BB16*AJ50*(AQ50*(1/100)),1),"#,##0.#") -> 817.2
G51: 재료비 | N51: : | Q51: =TEXT(기계경비총괄표!H6,"#,##0") -> 6,935 | Y51: ÷ | AB51: =TEXT(BB16,"#,##0.#######") -> 325. | AH51: × | AJ51: =TEXT(3,"#,##0.#######") -> 3. | AK51: 대 | AN51: = | AQ51: =TEXT(TRUNC(Q51/BB16*AJ51,1),"#,##0.#") -> 64.
G52: 경 | K52: 비 | N52: : | Q52: =TEXT(기계경비총괄표!I6,"#,##0") -> 7,505 | Y52: ÷ | AB52: =TEXT(BB16,"#,##0.#######") -> 325. | AH52: × | AJ52: =TEXT(3,"#,##0.#######") -> 3. | AK52: 대 | AN52: = | AQ52: =TEXT(TRUNC(Q52/BB16*AJ52,1),"#,##0.#") -> 69.2
G53: 소 | K53: 계 | N53: : | AL53: =TEXT(AX50+AQ51+AQ52,"#,##0.#######") -> 950.4 | CX53: =CY53+CZ53+DA53 -> 950.4 | CY53: =TEXT(AX50,"#,###.0") -> 817.2 | CZ53: =TEXT(AQ51,"#,###.0") -> 64.0 | DA53: =TEXT(AQ52,"#,###.0") -> 69.2
E55: 라 | G55: . | I55: 아스팔트페이버(피니셔) | AH55: (3.0m)
G57: 노무비 | N57: : | P57: =TEXT(기계경비총괄표!G7,"#,##0") -> 59,020 | Y57: ÷ | AB57: =TEXT(BB16,"#,##0.#######") -> 325. | AH57: × | AK57: =TEXT(150,"#,##0.#######") -> 150. | AN57: % | AP57: = | AR57: =TEXT(TRUNC(P57/BB16*(AK57*(1/100)),1),"#,##0.#") -> 272.4
G58: 재료비 | N58: : | P58: =TEXT(기계경비총괄표!H7,"#,##0") -> 19,140 | Y58: ÷ | AB58: =TEXT(BB16,"#,##0.#######") -> 325. | AH58: = | AK58: =TEXT(TRUNC(P58/BB16,1),"#,##0.#") -> 58.8
G59: 경 | K59: 비 | N59: : | P59: =TEXT(기계경비총괄표!I7,"#,##0") -> 59,141 | Y59: ÷ | AB59: =TEXT(BB16,"#,##0.#######") -> 325. | AH59: = | AJ59: =TEXT(TRUNC(P59/BB16,1),"#,##0.#") -> 181.9
G60: 소 | K60: 계 | N60: : | AF60: =TEXT(AR57+AK58+AJ59,"#,##0.#######") -> 513.1 | CX60: =CY60+CZ60+DA60 -> 513.1 | CY60: =TEXT(AR57,"#,###.0") -> 272.4 | CZ60: =TEXT(AK58,"#,###.0") -> 58.8 | DA60: =TEXT(AJ59,"#,###.0") -> 181.9
E62: 마 | G62: . | I62: 머캐덤로울러(자주식) | AF62: (10~12Ton)
G64: 노무비 | N64: : | P64: =TEXT(기계경비총괄표!G8,"#,##0") -> 59,020 | Y64: ÷ | AB64: =TEXT(BB16,"#,##0.#######") -> 325. | AH64: × | AK64: =TEXT(150,"#,##0.#######") -> 150. | AN64: % | AP64: = | AR64: =TEXT(TRUNC(P64/BB16*(AK64*(1/100)),1),"#,##0.#") -> 272.4
...

Sheet 기계경비총괄표
B1: 기계경비총괄표
B3: No | C3: 품 명 | D3: 규 격 | E3: 단위 | F3: 합 계 | G3: 노무비 | H3: 재료비 | I3: 경 비 | Z3: 당초합계 | AA3: 당초노무비 | AB3: 당초재료비 | AC3: 당초경비
B4: 1 | C4: 노면파쇄기 | D4: 2.0m | E4: hr | F4: =G4+H4+I4 -> 319882 | G4: =기계경비!AA4 -> 59020 | H4: =기계경비!AB4 -> 84117 | I4: =기계경비!AC4 -> 176745 | Z4: 319882 | AA4: 59020 | AB4: 84117 | AC4: 176745
B5: 2 | C5: 로우더(타이어)+소형노면파쇄기 | D5: 0.95㎥ | E5: hr | F5: =G5+H5+I5 -> 92808 | G5: =기계경비!AA10 -> 59020 | H5: =기계경비!AB10 -> 12284 | I5: =기계경비!AC10 -> 21504 | Z5: 92808 | AA5: 59020 | AB5: 12284 | AC5: 21504
B6: 3 | C6: 로우더(타이어) | D6: 0.57㎥ | E6: hr | F6: =G6+H6+I6 -> 73460 | G6: =기계경비!AA17 -> 59020 | H6: =기계경비!AB17 -> 6935 | I6: =기계경비!AC17 -> 7505 | Z6: 73460 | AA6: 59020 | AB6: 6935 | AC6: 7505
B7: 4 | C7: 아스팔트페이버(피니셔) | D7: 3.0m | E7: hr | F7: =G7+H7+I7 -> 137301 | G7: =기계경비!AA23 -> 59020 | H7: =기계경비!AB23 -> 19140 | I7: =기계경비!AC23 -> 59141 | Z7: 137301 | AA7: 59020 | AB7: 19140 | AC7: 59141
B8: 5 | C8: 머캐덤 로울러(자주식) | D8: 10~12Ton | E8: hr | F8: =G8+H8+I8 -> 86977 | G8: =기계경비!AA29 -> 59020 | H8: =기계경비!AB29 -> 15100 | I8: =기계경비!AC29 -> 12857 | Z8: 86977 | AA8: 59020 | AB8: 15100 | AC8: 12857
B9: 6 | C9: 타이어 로울러(자주식) | D9: 8~15Ton | E9: hr | F9: =G9+H9+I9 -> 91695 | G9: =기계경비!AA35 -> 59020 | H9: =기계경비!AB35 -> 13539 | I9: =기계경비!AC35 -> 19136 | Z9: 91695 | AA9: 59020 | AB9: 13539 | AC9: 19136
B10: 7 | C10: 탠덤 로울러(자주식) | D10: 5~8Ton | E10: hr | F10: =G10+H10+I10 -> 76175 | G10: =기계경비!AA41 -> 59020 | H10: =기계경비!AB41 -> 8118 | I10: =기계경비!AC41 -> 9037 | Z10: 76175 | AA10: 59020 | AB10: 8118 | AC10: 9037
B11: 8 | C11: 아스팔트 디스트리뷰터 | D11: 3800ℓ | E11: hr | F11: =G11+H11+I11 -> 94238 | G11: =기계경비!AA47 -> 59020 | H11: =기계경비!AB47 -> 18748 | I11: =기계경비!AC47 -> 16470 | Z11: 94238 | AA11: 59020 | AB11: 18748 | AC11: 16470
B12: 9 | C12: 물탱크 | D12: 16000ℓ | E12: hr | F12: =G12+H12+I12 -> 92007 | G12: =기계경비!AA53 -> 49778 | H12: =기계경비!AB53 -> 23075 | I12: =기계경비!AC53 -> 19154 | Z12: 92007 | AA12: 49778 | AB12: 23075 | AC12: 19154
B13: 10 | C13: 덤프트럭 | D13: 4.5Ton | E13: hr | F13: =G13+H13+I13 -> 66885 | G13: =기계경비!AA59 -> 49778 | H13: =기계경비!AB59 -> 9494 | I13: =기계경비!AC59 -> 7613 | Z13: 66885 | AA13: 49778 | AB13: 9494 | AC13: 7613
B14: 11 | C14: 덤프트럭 | D14: 2.5Ton | E14: hr | F14: =G14+H14+I14 -> 61806 | G14: =기계경비!AA65 -> 49778 | H14: =기계경비!AB65 -> 5506 | I14: =기계경비!AC65 -> 6522 | Z14: 61806 | AA14: 49778 | AB14: 5506 | AC14: 6522
B15: 12 | C15: 싸인카 | D15: 자주식 | E15: hr | F15: =G15+H15+I15 -> 66591 | G15: =기계경비!AA71 -> 49778 | H15: =기계경비!AB71 -> 6274 | I15: =기계경비!AC71 -> 10539 | Z15: 66591 | AA15: 49778 | AB15: 6274 | AC15: 10539
B16: 13 | C16: 트럭트랙터및평판트레일러 | D16: 20Ton | E16: hr | F16: =G16+H16+I16 -> 107892 | G16: =기계경비!AA77 -> 59020 | H16: =기계경비!AB77 -> 31558 | I16: =기계경비!AC77 -> 17314 | Z16: 107892 | AA16: 59020 | AB16: 31558 | AC16: 17314
B17: 14 | C17: 모터 그레이더 | D17: 3.6m(일반용) | E17: hr | F17: =G17+H17+I17 -> 136855 | G17: =기계경비!AA83 -> 59020 | H17: =기계경비!AB83 -> 30984 | I17: =기계경비!AC83 -> 46851 | Z17: 136855 | AA17: 59020 | AB17: 30984 | AC17: 46851
B18: 15 | C18: 혼합.압송 일체형 뿜칠기계 | D18: 60Lmin(7.5KW) | E18: hr | F18: =G18+H18+I18 -> 43664 | G18: =기계경비!AA89 -> 36248 | H18: =기계경비!AB89 -> 0 | I18: =기계경비!AC89 -> 7416 | Z18: 43664 | AA18: 36248 | AC18: 7416
B19: 16 | C19: 발전기 | D19: 50kW | E19: hr | F19: =G19+H19+I19 -> 54971 | G19: =기계경비!AA93 -> 36248 | H19: =기계경비!AB93 -> 14477 | I19: =기계경비!AC93 -> 4246 | Z19: 54971 | AA19: 36248 | AB19: 14477 | AC19: 4246
B20: 17 | C20: 교량점검차 | D20: 자주식 | E20: hr | F20: =G20+H20+I20 -> 294593 | G20: =기계경비!AA99 -> 67563 | H20: =기계경비!AB99 -> 16520 | I20: =기계경비!AC99 -> 210510 | Z20: 294593 | AA20: 67563 | AB20: 16520 | AC20: 210510
B21: 18 | C21: 굴착기(무한궤도) | D21: 0.7㎥(발파) | E21: hr | F21: =G21+H21+I21 -> 106815 | G21: =기계경비!AA106 -> 59020 | H21: =기계경비!AB106 -> 19473 | I21: =기계경비!AC106 -> 28322 | Z21: 106815 | AA21: 59020 | AB21: 19473 | AC21: 28322
B22: 19 | C22: 굴삭기(무한궤도) | D22: 0.7㎥ | E22: hr | F22: =G22+H22+I22 -> 103047 | G22: =기계경비!AA112 -> 59020 | H22: =기계경비!AB112 -> 19473 | I22: =기계경비!AC112 -> 24554 | Z22: 103047 | AA22: 59020 | AB22: 19473 | AC22: 24554

Sheet 기계경비
B1: 기계경비
B3: 명 칭 | C3: 규 격 | D3: 산 출 근 거 | Z3: 합 계 | AA3: 노무비 | AB3: 재료비 | AC3: 경 비 | AD3: 비 고
B4: 1. 노면파쇄기 | C4: 2.0m | Z4: =AA4+AB4+AC4 -> 319882 | AA4: =TRUNC(AA5+AA6+AA7+AA8) -> 59020 | AB4: =TRUNC(AB5+AB6+AB7+AB8) -> 84117 | AC4: =TRUNC(AC5+AC6+AC7+AC8) -> 176745
B5: 손 료 | D5: 438356000 | I5: ￦× | K5: 4032 | N5: × | O5: 10(-7) | Z5: =AA5+AB5+AC5 -> 176745.1 | AC5: =TRUNC(D5*K5*0.0000001,1) -> 176745.1 | AD5: '26年 개정
B6: 주연료 | C6: 경유 | D6: 52.7 | H6: ℓ | I6: × | J6: =자재단가!R6 -> 1376 | Z6: =AA6+AB6+AC6 -> 72515.2 | AB6: =TRUNC(D6*J6,1) -> 72515.2
B7: 잡 품 | C7: 주연료의 | D7: 16 | H7: % | I7: × | J7: =AB6 -> 72515.2 | Z7: =AA7+AB7+AC7 -> 11602.4 | AB7: =TRUNC(D7/100*J7,1) -> 11602.4
B8: 건설기계운전사 | D8: 1 | G8: 인 | H8: × | I8: =노임단가!F6 -> 283297 | M8: × | N8: 1/8*16/12*25/20 | Z8: =AA8+AB8+AC8 -> 59020.2 | AA8: =TRUNC(D8*I8*기계경비적용기준!E21,1) -> 59020.2
B10: 2. 로우더(타이어)+소형노면파쇄기 | C10: 0.95㎥ | Z10: =AA10+AB10+AC10 -> 92808 | AA10: =TRUNC(AA11+AA12+AA13+AA14+AA15) -> 59020 | AB10: =TRUNC(AB11+AB12+AB13+AB14+AB15) -> 12284 | AC10: =TRUNC(AC11+AC12+AC13+AC14+AC15) -> 21504
B11: 로우더(0.95㎥) 손료 | D11: 46576000 | I11: ￦× | K11: 2085 | N11: × | O11: 10(-7) | Z11: =AA11+AB11+AC11 -> 9711 | AC11: =TRUNC(D11*K11*0.0000001,1) -> 9711 | AD11: '26年 개정
B12: 소형노면파쇄기(0.95㎥) 손료 | D12: 29250000 | I12: ￦× | K12: 4032 | N12: × | O12: 10(-7) | Z12: =AA12+AB12+AC12 -> 11793.6 | AC12: =TRUNC(D12*K12*0.0000001,1) -> 11793.6 | AD12: '26年 개정
B13: 주연료 | C13: 경유 | D13: 6.2 | H13: ℓ | I13: × | J13: =자재단가!R6 -> 1376 | Z13: =AA13+AB13+AC13 -> 8531.2 | AB13: =TRUNC(D13*J13,1) -> 8531.2
B14: 잡 품 | C14: 주연료의 | D14: 44 | H14: % | I14: × | J14: =AB13 -> 8531.2 | Z14: =AA14+AB14+AC14 -> 3753.7 | AB14: =TRUNC(D14/100*J14,1) -> 3753.7
B15: 건설기계운전사 | D15: 1 | G15: 인 | H15: × | I15: =노임단가!F6 -> 283297 | M15: × | N15: 1/8*16/12*25/20 | Z15: =AA15+AB15+AC15 -> 59020.2 | AA15: =TRUNC(D15*I15*기계경비적용기준!E21,1) -> 59020.2
B17: 3. 로우더(타이어) | C17: 0.57㎥ | Z17: =AA17+AB17+AC17 -> 73460 | AA17: =TRUNC(AA18+AA19+AA20+AA21) -> 59020 | AB17: =TRUNC(AB18+AB19+AB20+AB21) -> 6935 | AC17: =TRUNC(AC18+AC19+AC20+AC21) -> 7505
B18: 손 료 | D18: 35999000 | I18: ￦× | K18: 2085 | N18: × | O18: 10(-7) | Z18: =AA18+AB18+AC18 -> 7505.7 | AC18: =TRUNC(D18*K18*0.0000001,1) -> 7505.7 | AD18: '26年 개정
B19: 주연료 | C19: 경유 | D19: 3.5 | H19: ℓ | I19: × | J19: =자재단가!R6 -> 1376 | Z19: =AA19+AB19+AC19 -> 4816 | AB19: =TRUNC(D19*J19,1) -> 4816
B20: 잡 품 | C20: 주연료의 | D20: 44 | H20: % | I20: × | J20: =AB19 -> 4816 | Z20: =AA20+AB20+AC20 -> 2119 | AB20: =TRUNC(D20/100*J20,1) -> 2119
B21: 건설기계운전사 | D21: 1 | G21: 인 | H21: × | I21: =노임단가!F6 -> 283297 | M21: × | N21: 1/8*16/12*25/20 | Z21: =AA21+AB21+AC21 -> 59020.2 | AA21: =TRUNC(D21*I21*기계경비적용기준!E21,1) -> 59020.2
B23: 4. 아스팔트페이버(피니셔) | C23: 3.0m | Z23: =AA23+AB23+AC23 -> 137301 | AA23: =TRUNC(AA24+AA25+AA26+AA27) -> 59020 | AB23: =TRUNC(AB24+AB25+AB26+AB27) -> 19140 | AC23: =TRUNC(AC24+AC25+AC26+AC27) -> 59141
B24: 손 료 | D24: 250388000 | I24: ￦× | K24: 2362 | N24: × | O24: 10(-7) | Z24: =AA24+AB24+AC24 -> 59141.6 | AC24: =TRUNC(D24*K24*0.0000001,1) -> 59141.6 | AD24: '26年 개정
B25: 주연료 | C25: 경유 | D25: 13 | H25: ℓ | I25: × | J25: =자재단가!R6 -> 1376 | Z25: =AA25+AB25+AC25 -> 17888 | AB25: =TRUNC(D25*J25,1) -> 17888
B26: 잡 품 | C26: 주연료의 | D26: 7 | H26: % | I26: × | J26: =AB25 -> 17888 | Z26: =AA26+AB26+AC26 -> 1252.1 | AB26: =TRUNC(D26/100*J26,1) -> 1252.1
B27: 건설기계운전사 | D27: 1 | G27: 인 | H27: × | I27: =노임단가!F6 -> 283297 | M27: × | N27: 1/8*16/12*25/20 | Z27: =AA27+AB27+AC27 -> 59020.2 | AA27: =TRUNC(D27*I27*기계경비적용기준!E21,1) -> 59020.2
B29: 5. 머캐덤 로울러(자주식) | C29: 10~12Ton | Z29: =AA29+AB29+AC29 -> 86977 | AA29: =TRUNC(AA30+AA31+AA32+AA33) -> 59020 | AB29: =TRUNC(AB30+AB31+AB32+AB33) -> 15100 | AC29: =TRUNC(AC30+AC31+AC32+AC33) -> 12857
B30: 손 료 | D30: 71351000 | I30: ￦× | K30: 1802 | N30: × | O30: 10(-7) | Z30: =AA30+AB30+AC30 -> 12857.4 | AC30: =TRUNC(D30*K30*0.0000001,1) -> 12857.4 | AD30: '26年 개정
B31: 주연료 | C31: 경유 | D31: 9.3 | H31: ℓ | I31: × | J31: =자재단가!R6 -> 1376 | Z31: =AA31+AB31+AC31 -> 12796.8 | AB31: =TRUNC(D31*J31,1) -> 12796.8
B32: 잡 품 | C32: 주연료의 | D32: 18 | H32: % | I32: × | J32: =AB31 -> 12796.8 | Z32: =AA32+AB32+AC32 -> 2303.4 | AB32: =TRUNC(D32/100*J32,1) -> 2303.4
B33: 건설기계운전사 | D33: 1 | G33: 인 | H33: × | I33: =노임단가!F6 -> 283297 | M33: × | N33: 1/8*16/12*25/20 | Z33: =AA33+AB33+AC33 -> 59020.2 | AA33: =TRUNC(D33*I33*기계경비적용기준!E21,1) -> 59020.2
B35: 6. 타이어 로울러(자주식) | C35: 8~15Ton | Z35: =AA35+AB35+AC35 -> 91695 | AA35: =TRUNC(AA36+AA37+AA38+AA39) -> 59020 | AB35: =TRUNC(AB36+AB37+AB38+AB39) -> 13539 | AC35: =TRUNC(AC36+AC37+AC38+AC39) -> 19136
B36: 손 료 | D36: 98388000 | I36: ￦× | K36: 1945 | N36: × | O36: 10(-7) | Z36: =AA36+AB36+AC36 -> 19136.4 | AC36: =TRUNC(D36*K36*0.0000001,1) -> 19136.4 | AD36: '26年 개정
B37: 주연료 | C37: 경유 | D37: 8 | H37: ℓ | I37: × | J37: =자재단가!R6 -> 1376 | Z37: =AA37+AB37+AC37 -> 11008 | AB37: =TRUNC(D37*J37,1) -> 11008
B38: 잡 품 | C38: 주연료의 | D38: 23 | H38: % | I38: × | J38: =AB37 -> 11008 | Z38: =AA38+AB38+AC38 -> 2531.8 | AB38: =TRUNC(D38/100*J38,1) -> 2531.8
B39: 건설기계운전사 | D39: 1 | G39: 인 | H39: × | I39: =노임단가!F6 -> 283297 | M39: × | N39: 1/8*16/12*25/20 | Z39: =AA39+AB39+AC39 -> 59020.2 | AA39: =TRUNC(D39*I39*기계경비적용기준!E21,1) -> 59020.2
B41: 7. 탠덤 로울러(자주식) | C41: 5~8Ton | Z41: =AA41+AB41+AC41 -> 76175 | AA41: =TRUNC(AA42+AA43+AA44+AA45) -> 59020 | AB41: =TRUNC(AB42+AB43+AB44+AB45) -> 8118 | AC41: =TRUNC(AC42+AC43+AC44+AC45) -> 9037
B42: 손 료 | D42: 48513000 | I42: ￦× | K42: 1863 | N42: × | O42: 10(-7) | Z42: =AA42+AB42+AC42 -> 9037.9 | AC42: =TRUNC(D42*K42*0.0000001,1) -> 9037.9 | AD42: '26年 개정
B43: 주연료 | C43: 경유 | D43: 5 | H43: ℓ | I43: × | J43: =자재단가!R6 -> 1376 | Z43: =AA43+AB43+AC43 -> 6880 | AB43: =TRUNC(D43*J43,1) -> 6880
B44: 잡 품 | C44: 주연료의 | D44: 18 | H44: % | I44: × | J44: =AB43 -> 6880 | Z44: =AA44+AB44+AC44 -> 1238.4 | AB44: =TRUNC(D44/100*J44,1) -> 1238.4
B45: 건설기계운전사 | D45: 1 | G45: 인 | H45: × | I45: =노임단가!F6 -> 283297 | M45: × | N45: 1/8*16/12*25/20 | Z45: =AA45+AB45+AC45 -> 59020.2 | AA45: =TRUNC(D45*I45*기계경비적용기준!E21,1) -> 59020.2
B47: 8. 아스팔트 디스트리뷰터 | C47: 3800ℓ | Z47: =AA47+AB47+AC47 -> 94238 | AA47: =TRUNC(AA48+AA49+AA50+AA51) -> 59020 | AB47: =TRUNC(AB48+AB49+AB50+AB51) -> 18748 | AC47: =TRUNC(AC48+AC49+AC50+AC51) -> 16470
B48: 손 료 | D48: 64113000 | I48: ￦× | K48: 2569 | N48: × | O48: 10(-7) | Z48: =AA48+AB48+AC48 -> 16470.6 | AC48: =TRUNC(D48*K48*0.0000001,1) -> 16470.6 | AD48: '26年 개정
...

Sheet 기계경비적용기준
B1: 기계경비적용기준
C4: 환 율 (/￦) | G4: 기본재료비
C6: 화 폐 | D6: 환 율 | E6: 비 고 | G6: No | H6: 품 명 | I6: 규 격 | J6: 단위 | K6: 단 가
C7: 달러($) | D7: 1436.7 | E7: 2026.2.2. 매매기준율 | G7: 2 | H7: 경유 | J7: ℓ | K7: =자재단가!R6 -> 1376
C8: 엔(100￥) | D8: 924.01 | E8: 2026.2.2. 매매기준율
C9: 유로(E) | D9: 1701.2 | E9: 2026.2.2. 매매기준율
C10: 마르크(M)
C11: 파운드(L) | D11: 1963.18 | E11: 2026.2.2. 매매기준율
C18: 노임계수 | G18: 계산결과값 자리수
C20: No | D20: 노임계수 | E20: 계산값
C21: 1 | D21: 1/8*16/12*25/20 | E21: =1/8*16/12*25/20 -> 0.20833333
C22: 2 | D22: 1/8*16/12*25/20*24/15 | E22: =1/8*16/12*25/20*24/15 -> 0.33333333 | G22: 경 비 소수 1 미만 절하
C23: 3 | D23: 1/8*16/12*25/20*12/10 | E23: =1/8*16/12*25/20*12/10 -> 0.25
C24: 4 | D24: 1/8*16/12*25/20*14/12 | E24: =1/8*16/12*25/20*14/12 -> 0.24305556 | G24: 재료비 소수 1 미만 절하
C25: 5 | D25: 1/8*16/12*25/20*24/5 | E25: =1/8*16/12*25/20*24/5 -> 1
G26: 노무비 소수 1 미만 절하

Sheet 자재단가
B1: 자재단가
B3: No | C3: 품 명 | D3: 규 격 | E3: 단위 | F3: 가격정보 | H3: 물가자료 | J3: 유통물가 | L3: 물가정보 | N3: 거래가격 | P3: 견적가1 | R3: 적용단가 | S3: 비 고 | Z3: 당초합계 | AA3: 당초노무비 | AB3: 당초재료비 | AC3: 당초경비
F4: 단 가 | G4: page | H4: 단 가 | I4: page | J4: 단 가 | K4: page | L4: 단 가 | M4: page | N4: 단 가 | O4: page | P4: 단 가 | Q4: page
B5: 1 | C5: 팁(날) | D5: 노면파쇄기용 | E5: 개 | L5: 6000 | M5: 1035(23.10) | R5: =MIN(F5,H5,J5,L5,N5,P5) -> 6000 | Z5: 6000
B6: 2 | C6: 경유 | E6: ℓ | F6: 1376 | G6: 2026.1.6 | R6: =MIN(F6,H6,J6,L6,N6,P6) -> 1376 | S6: 조달청 | Z6: 1376
B7: 3 | C7: 멀티코트 B | D7: 아스팔트 프라이머 | E7: can | N7: 79200 | O7: 549(25.12) | R7: =MIN(F7,H7,J7,L7,N7,P7) -> 79200 | Z7: 79200
B8: 4 | C8: 교면복합씰 | D8: JJ교면도막방수제 t=2.0mm | E8: kg | P8: 6500 | R8: =MIN(F8,H8,J8,L8,N8,P8) -> 6500 | Z8: 6500
B9: 5 | C9: 교면복합시트 | D9: JJ교면복합시트 T=0.5mm | E9: ㎡ | P9: 8000 | R9: =MIN(F9,H9,J9,L9,N9,P9) -> 8000 | Z9: 8000
B10: 6 | C10: 유공관 | D10: Φ15mm, 그물망형 | E10: M | J10: 9170 | K10: 611(21.2) | N10: 9170 | O10: 792(21.2) | R10: =MIN(F10,H10,J10,L10,N10,P10) -> 9170 | Z10: 9170
B11: 7 | C11: 고정테이프 | D11: 30×5000 | E11: EA | H11: 200 | I11: 755(19.8) | J11: 200 | K11: 553(19.8) | L11: 220 | M11: 1권555(19.8) | P11: 106 | R11: =MIN(F11,H11,J11,L11,N11,P11) -> 106 | Z11: 106
B12: 8 | C12: 아스팔트유제 | D12: RSC-4 | E12: D/M | H12: 230000 | I12: 114(26.2) | J12: 230000 | K12: 178(26.2) | L12: 180000 | M12: 172(26.2) | N12: 230000 | O12: 177(26.2) | R12: =MIN(F12,H12,J12,L12,N12,P12) -> 180000 | Z12: 180000
B13: 9 | C13: 도로표지용페인트(융착식) | D13: KSM-6080(백색,R5) | E13: kg | H13: 4550 | I13: 597(26.2) | J13: 4550 | K13: 471(26.2) | R13: =MIN(F13,H13,J13,L13,N13,P13) -> 4550 | Z13: 4550
B14: 10 | C14: 유리알 | D14: 1호,고휘도 | E14: kg | H14: 5000 | I14: 597(26.2) | J14: 5000 | K14: 228(26.2) | L14: 5000 | M14: 229(26.2) | N14: 5000 | O14: 244(26.2) | R14: =MIN(F14,H14,J14,L14,N14,P14) -> 5000 | Z14: 5000
B15: 11 | C15: 융착식 프라이머 | D15: 도로용 접착제 | E15: ℓ | H15: 4500 | I15: 597(26.2) | J15: 4500 | K15: 471(26.2) | L15: 4500 | M15: 229(26.2) | N15: 4550 | O15: 244(26.2) | R15: =MIN(F15,H15,J15,L15,N15,P15) -> 4500 | Z15: 4500
B16: 12 | C16: 프로판가스 | D16: 일반용 | E16: kg | H16: 2224 | I16: 하32(26.2) | J16: 2222 | K16: 1189(26.2) | L16: 2311 | M16: 1438(26.2) | N16: 1887 | O16: 1451(26.2) | R16: =MIN(F16,H16,J16,L16,N16,P16) -> 1887 | Z16: 1887
B17: 13 | C17: 교통안전표지판 | D17: 900,삼각(고휘도) | E17: EA | J17: 111900 | K17: 225(26.2) | L17: 93500 | M17: 267(26.2) | N17: 110600 | O17: 247(26.2) | R17: =MIN(F17,H17,J17,L17,N17,P17) -> 93500 | Z17: 93500
B18: 14 | C18: 교통안전표지판 | D18: 600,원형(고휘도) | E18: EA | J18: 113400 | K18: 225(26.2) | L18: 93500 | M18: 267(26.2) | N18: 79800 | O18: 247(26.2) | R18: =MIN(F18,H18,J18,L18,N18,P18) -> 79800 | Z18: 79800
B19: 15 | C19: 교통안전표지판 | D19: 300×900×900×2T,오각(고휘도) | E19: EA | L19: 154000 | M19: 267(26.2) | R19: =MIN(F19,H19,J19,L19,N19,P19) -> 154000 | Z19: 154000
B20: 16 | C20: 회전식경광등 | E20: 개 | N20: 64200 | O20: 1102(26.2) | R20: =MIN(F20,H20,J20,L20,N20,P20) -> 64200 | Z20: 64200
B21: 17 | C21: 라바콘 | D21: 360×360×700mm | E21: EA | L21: 9000 | R21: =MIN(F21,H21,J21,L21,N21,P21) -> 9000 | Z21: 9000
B22: 18 | C22: PE드럼(분리형) | D22: Φ550×850 | E22: EA | H22: 18000 | I22: 167(26.2) | L22: 18000 | M22: 234(26.2) | R22: =MIN(F22,H22,J22,L22,N22,P22) -> 18000 | Z22: 18000
B23: 19 | C23: 로봇신호수(한팔형) | D23: 설치시 1,500×1,850×800 본체 | E23: 조 | L23: 1500000 | M23: 242(26.2) | R23: =MIN(F23,H23,J23,L23,N23,P23) -> 1500000 | Z23: 1500000
B24: 20 | C24: 배터리 | D24: 12V60A | E24: EA | L24: 190000 | M24: 242(26.2) | R24: =MIN(F24,H24,J24,L24,N24,P24) -> 190000 | Z24: 190000
B25: 21 | C25: 철근방청제 | D25: BA-ARA | E25: kg | N25: 25000 | O25: 1112(24.11) | R25: =MIN(F25,H25,J25,L25,N25,P25) -> 25000 | Z25: 25000
B26: 22 | C26: 내황산염단면복구재 | D26: SSR-M100 | E26: kg | N26: 2500 | O26: 628(24.11) | R26: =MIN(F26,H26,J26,L26,N26,P26) -> 2500 | Z26: 2500
B27: 23 | C27: SSR코트 - 하도 | D27: SSR-COAT-P | E27: kg | N27: 69000 | O27: 628(24.11) | R27: =MIN(F27,H27,J27,L27,N27,P27) -> 69000 | Z27: 69000
B28: 24 | C28: SSR코트 - 중도 | D28: SSR-COAT-C | E28: kg | N28: 68000 | O28: 628(24.11) | R28: =MIN(F28,H28,J28,L28,N28,P28) -> 68000 | Z28: 68000
B29: 25 | C29: SSR코트 - 상도 | D29: SSR-COAT-T | E29: kg | N29: 68000 | O29: 628(24.11) | R29: =MIN(F29,H29,J29,L29,N29,P29) -> 68000 | Z29: 68000
B30: 26 | C30: 탄성퍼티 | D30: DNS-7500 | E30: kg | J30: 6111 | K30: 469(26.2) | L30: 6111 | M30: 504(26.2) | N30: 4400 | O30: 622(26.2) | R30: =MIN(F30,H30,J30,L30,N30,P30) -> 4400 | Z30: 4400
B31: 27 | C31: 균열 주입제(에폭시) | E31: kg | P31: 22000 | R31: =MIN(F31,H31,J31,L31,N31,P31) -> 22000 | Z31: 22000
B32: 28 | C32: 에폭시계신너 | D32: 균열보수용 | E32: L | P32: 6737 | R32: =MIN(F32,H32,J32,L32,N32,P32) -> 6737 | Z32: 6737
B33: 29 | C33: 에폭시주입기구부품 | E33: EA | P33: 1000 | R33: =MIN(F33,H33,J33,L33,N33,P33) -> 1000 | Z33: 1000
B34: 30 | C34: 폐기물처리비 | D34: 폐콘크리트 | E34: Ton | H34: 31142 | I34: 하151(26.3) | L34: 31142 | M34: 부412(26.3) | N34: 31142 | O34: 1585(26.3) | R34: =MIN(F34,H34,J34,L34,N34,P34) -> 31142 | S34: VAT별도(경비) | Z34: 31142
B35: 31 | C35: 폐기물운반비(상차제외) | D35: 30km이하,덤프15톤 | E35: Ton | H35: 19700 | I35: 하150(26.3) | N35: 19700 | O35: 1586(26.3) | R35: =MIN(F35,H35,J35,L35,N35,P35) -> 19700 | S35: VAT별도(경비) | Z35: 19700
B36: 32 | C36: 아스콘(관급)-서울,인천,경기(강북,노원,도봉구 제외) | D36: 조합공통품목, WC-6, 가열, 1등급 | E36: 톤 | F36: 100120 | G36: 조달 26.2 | R36: =MIN(F36,H36,J36,L36,N36,P36) -> 100120 | S36: 23734488 | Z36: 100120

Sheet 노임단가
B1: 노임단가
B3: No | C3: 품 명 | D3: 규 격 | E3: 단위 | F3: 적용단가 | G3: 비 고 | Z3: 당초합계 | AA3: 당초노무비 | AB3: 당초재료비 | AC3: 당초경비
B4: 1 | C4: 포 장 공 | E4: 인 | F4: 273308 | G4: 2026년(상) | Z4: 273308
B5: 2 | C5: 보통인부 | E5: 인 | F5: 172068 | G5: 2026년(상) | Z5: 172068
B6: 3 | C6: 건설기계운전사 | E6: 인 | F6: 283297 | G6: 2026년(상) | Z6: 283297
B7: 4 | C7: 화물차운전사 | E7: 인 | F7: 238936 | G7: 2026년(상) | Z7: 238936
B8: 5 | C8: 방 수 공 | E8: 인 | F8: 228286 | G8: 2026년(상) | Z8: 228286
B9: 6 | C9: 특별인부 | E9: 인 | F9: 226122 | G9: 2026년(상) | Z9: 226122
B10: 7 | C10: 도 장 공 | E10: 인 | F10: 263017 | G10: 2026년(상) | Z10: 263017
B11: 8 | C11: 일반기계운전사 | E11: 인 | F11: 173995 | G11: 2026년(상) | Z11: 173995
B12: 9 | C12: 미 장 공 | E12: 인 | F12: 277276 | G12: 2026년(상) | Z12: 277276
B13: 10 | C13: 건설기계조장 | E13: 인 | F13: 205028 | G13: 2025년(하)-노임증가율반영 | Z13: 205028
B14: 11 | C14: 초급기술자 | E14: 인 | F14: 235459 | G14: 2026년(건설) | Z14: 235459
B15: 12 | C15: 고급기술자 | E15: 인 | F15: 310884 | G15: 2026년(건설) | Z15: 310884
B16: 13 | C16: 중급기술자 | E16: 인 | F16: 295138 | G16: 2026년(건설) | Z16: 295138
B17: 14
B18: 15
B19: 16
B20: 17
B21: 18
B22: 19
B23: 20
B24: 21
B25: 22
B26: 23
B27: 24
B28: 25
... B33: 30
